Workbook

Sheet Anleitung
A1: LoopforgeLab GmbH – Financial Projection Model
A3: Projektionszeitraum: 52 Monate (ca. 4,3 Jahre)
A5: INHALTSVERZEICHNIS
A6: Sheet 1: Anleitung – Diese Seite mit Übersicht und Legende
A7: Sheet 2: Inputs – Zentrale Eingabewerte (HIER STARTEN)
A8: Sheet 3: P&L – Gewinn- und Verlustrechnung (monatlich + jährlich)
A9: Sheet 4: Revenue – Detaillierte Umsatzmodellierung
A10: Sheet 5: Costs – Detaillierte Kostenaufschlüsselung
A11: Sheet 6: Balance Sheet – Vereinfachte Bilanz
A12: Sheet 7: Cash Flow – Kapitalflussrechnung mit Runway
A14: FARBCODIERUNG
A15: Blau | B15: Editierbare Eingabefelder
A16: Schwarz | B16: Formeln – nicht manuell ändern
A17: Grün | B17: Verweise auf andere Sheets
A18: Gelb hinterlegt | B18: Kritische Annahmen
A20: KURZANLEITUNG
A21: 1. Gehen Sie zum Sheet 'Inputs' und passen Sie alle blau markierten Werte an.
A22: 2. Alle anderen Sheets berechnen sich automatisch aus den Inputs.
A23: 3. Prüfen Sie die P&L, Revenue und Cash Flow Sheets auf Plausibilität.
A24: 4. Achten Sie auf rot markierte Warnungen (z.B. Runway < 6 Monate).
A25: 5. Exportieren Sie relevante Sheets als PDF für Investoren-Präsentationen.
A27: DISCLAIMER: Diese Projektion dient ausschließlich der Planung.
A28: Tatsächliche Ergebnisse können erheblich abweichen. Keine Garantie.

Sheet Treiber_Matrix
A1: LoopForgeLab – Treiber- & Annahmen-Matrix (importiert aus 260305_LFL_Treiber_Matrix_v1.xlsx)
A2: Alle Umsatz- und Kostentreiber | Szenarien: Gering · Normal · Stark | Spalten L & M: Eigene Bewertungen und Alternativwerte | NEU-markierte Zeilen: noch nicht im Modell — Entwicklungspotenzial
A3: Kategorie | B3: Unterkategorie | C3: Parameter / Treiber | D3: Aktueller Wert | E3: Einheit | F3: Szenario-Abhängigkeit | G3: Gering | H3: Normal | I3: Stark | J3: Einflussfaktor & Wirkungslogik | K3: Annahmen & Begründung | L3: ► Ihre Bewertung | M3: ► Neue Annahme
A5: Revenue 1: SaaS / Lizenzen
A6: UMSATZ | B6: SaaS / Lizenzen | C6: Startpreis pro Seat/Jahr | D6: 9.600 – 12.000 € | E6: €/Jahr | F6: Szenario | G6: 9.600 € | H6: 12.000 € | I6: 6.000 € | J6: Bestimmt den initialen Lizenzpreis je Nutzer-Seat. Direkter Multiplikator auf alle Lizenzerlöse. | K6: Automotive: höherer Preis durch Compliance-Wert (TISAX). Packaging: niedrigerer Einstiegspreis, Wachstum über Volumen & NRR. Value-based Pricing orientiert sich am TCO-Einsparpotenzial.
A7: UMSATZ | B7: SaaS / Lizenzen | C7: Jährliche Preiserhöhung | D7: 10 % | E7: % p.a. | F7: Fest | G7: 10 % | H7: 10 % | I7: 10 % | J7: Erhöht den Seat-Preis jährlich. Kompensiert Inflations- und Innovationskosten (Inferenz, neue Features). | K7: Standard für AI-SaaS 2026. Typisch: 3–10% p.a. Höherer Wert möglich bei starker Produktdifferenzierung.
A8: UMSATZ | B8: SaaS / Lizenzen | C8: Erster Umsatzmonat (Kunden) | D8: Monat 8–14 | E8: Monat | F8: Szenario | G8: Monat 14 | H8: Monat 8 | I8: Monat 9 | J8: Verschiebt den gesamten SaaS-Umsatz-Stream. Jeder Monat Verzögerung = direkte Liquiditätslücke. | K8: Automotive (Gering): lange Sales-Zyklen (9–12 Mon.) + TISAX-Prüfung. Packaging (Stark): kürzere IT-Entscheidungswege, frühere Piloten möglich.
A9: UMSATZ | B9: SaaS / Lizenzen | C9: Initiale Seats (1. Kunde) | D9: 5 | E9: Seats | F9: Fest | G9: 5 | H9: 5 | I9: 5 | J9: Anzahl der Seats beim ersten Kunden. Beeinflusst den initialen ARR-Wert und das Wachstums-Baseline. | K9: Konservative Annahme: 1–2 Pilotprojekte pro Werk. Land & Expand-Strategie: erst 1 Werk, dann Roll-out.
A10: UMSATZ | B10: SaaS / Lizenzen | C10: Monatliche Seat-Wachstumsrate | D10: 8 % | E10: % / Monat | F10: Fest | G10: 8 % | H10: 8 % | I10: 8 % | J10: Bestimmt, wie schnell neue Seats hinzukommen. Treiber für den kumulativen ARR-Aufbau. | K10: Alternative: Account-basierte Planung mit Stufenfunktion (Roll-out pro Werk statt linearer Rate). Realistischer Wert abhängig von Vertriebskapazität.
A11: UMSATZ | B11: SaaS / Lizenzen | C11: Enterprise-Deals ab Monat | D11: Monat 18 | E11: Monat | F11: Fest | G11: Monat 18 | H11: Monat 18 | I11: Monat 18 | J11: Ab diesem Monat werden größere Enterprise-Verträge abgeschlossen. Erhöht den durchschnittlichen ARR pro Kunde sprunghaft. | K11: Automotive: Verschiebung durch Technical Validation + Compliance. Typisch: 50.000–200.000 €/Jahr pro Enterprise-Kunde.
A12: UMSATZ | B12: SaaS / Lizenzen | C12: Durchschnittlicher Enterprise ARR | D12: 50.000 € | E12: €/Jahr | F12: Fest | G12: 50.000 € | H12: 50.000 € | I12: 50.000 € | J12: Erlös pro Enterprise-Vertrag. Beeinflusst den ARR-Sprung ab Monat 18 erheblich. | K12: Höheres Volumen durch tiefe Integration (DPP, Sustainability). Realistisch: 50.000–200.000 € je nach Kundentyp.
A13: UMSATZ | B13: SaaS / Lizenzen | C13: Enterprise Deals pro Quartal | D13: 2 | E13: Deals/Quartal | F13: Fest | G13: 2 | H13: 2 | I13: 2 | J13: Anzahl neuer Enterprise-Verträge pro Quartal. Direkter Treiber für den ARR-Aufbau nach Monat 18. | K13: Abhängig von Vertriebskapazität und Sales-Zyklus-Länge. Sollte mit Einstellungsplan abgestimmt sein.
A14: UMSATZ | B14: SaaS / Lizenzen | C14: Jährliche Churn Rate | D14: 6 % | E14: % p.a. | F14: Fest | G14: 6 % | H14: 6 % | I14: 6 % | J14: Anteil der Kunden, die jährlich abwandern. Reduziert den kumulativen ARR direkt. | K14: Konservative Planung für komplexe industrielle Buying Center. Typisch SaaS: 5–10%. Im Pilot-Jahr höher, ab Jahr 3 niedriger.
A15: UMSATZ | B15: SaaS / Lizenzen | C15: Net Revenue Retention (NRR) | D15: 125 % | E15: % | F15: Fest | G15: 125 % | H15: 125 % | I15: 125 % | J15: Expansion-Umsatz minus Churn. NRR > 100% bedeutet: Bestandskunden wachsen schneller als sie abwandern. | K15: Realisierbar durch DPP-Zusatzmodule und Material-Analytics-Upgrades. Typisch: 100–120%. 125% ist ambitioniert, aber bei starkem Upselling möglich.
A16: Revenue 2: Consulting
A17: UMSATZ | B17: Consulting | C17: Consulting-Tagessatz | D17: 1.000 – 1.500 € | E17: €/Tag | F17: Szenario | G17: 1.000 € | H17: 1.200 € | I17: 1.500 € | J17: Verrechnungssatz für Beratungsleistungen. Multipliziert mit Tagen/Kunde ergibt den Erlös je Projekt. | K17: Automotive: niedrigerer Satz durch Preisdruck im Mittelstand. Packaging: höherer Satz durch Expertenstatus und Integrationskomplexität. Quelle: Marktanalyse Lothar.bm / Candemir.
A18: UMSATZ | B18: Consulting | C18: Consulting-Tage/Kunde | D18: 4 – 20 Tage | E18: Tage/Kunde | F18: Szenario | G18: 4 Tage | H18: 10 Tage | I18: 20 Tage | J18: Abrechnungsfähige Beratungstage je Kundenprojekt. Bestimmt zusammen mit dem Tagessatz den Erlös pro Consulting-Kunde. | K18: Gering: standardisierter Onboarding-Prozess (4 Tage). Stark: tiefe Prozessintegration im Packaging (20 Tage). Formel: Consulting-Umsatz/Kunde = Tagessatz × Tage/Kunde.
A19: UMSATZ | B19: Consulting | C19: Consulting-Umsatz/Kunde | D19: 4.000 – 30.000 € | E19: €/Kunde | F19: Berechnet | G19: 4.000 € | H19: 12.000 € | I19: 30.000 € | J19: Erlös pro beauftragendem Kunden. Berechnung: Tagessatz × Tage/Kunde. Beeinflusst den gesamten Consulting-Umsatz-Stream. | K19: Gering: 1.000€ × 4 Tage = 4.000€/Kunde. Normal: 1.200€ × 10 Tage = 12.000€/Kunde. Stark: 1.500€ × 20 Tage = 30.000€/Kunde.
A20: UMSATZ | B20: Consulting | C20: Consulting-Quote (% Kunden) | D20: 20 – 100 % | E20: % Kunden | F20: Unabhängig | G20: 20 % (Niedrig) | H20: 50 % (Mittel) | I20: 100 % (Hoch) | J20: Anteil der Neukunden, die Consulting beauftragen. UNABHÄNGIG vom strategischen Szenario einstellbar. Kombinierbar mit jedem der drei Szenarien (3×3-Matrix). | K20: Niedrig (20%): Self-Service-Kunden, minimaler Beratungsbedarf. Mittel (50%): Standardannahme, jeder zweite Kunde bucht Consulting. Hoch (100%): Alle Kunden benötigen Onboarding-Unterstützung.
A21: UMSATZ | B21: Consulting | C21: Consulting-Startmonat | D21: Monat 3–6 | E21: Monat | F21: Szenario | G21: Monat 3 | H21: Monat 4 | I21: Monat 6 | J21: Monat des ersten Consulting-Umsatzes. Consulting startet als Enabler vor dem SaaS-Produkt. | K21: Gering: früher Start (Monat 3), da Automotive-Kunden sofort IT-Begleitung benötigen. Stark: späterer Start (Monat 6), da Packaging-Kunden länger Self-Service nutzen können.
A22: KOSTEN (OpEx)
A23: Personal & Gehälter
A24: KOSTEN | B24: Personal | C24: AI-Personal-Hebel | D24: 0 / 6 / 99 Monate | E24: Monate Verzögerung | F24: Szenario | G24: 0 (kein Effekt) | H24: +6 Monate | I24: Monat 99 (Elimination) | J24: Wichtigster Kostenhebel des Modells. Verschiebt den Einstellungszeitpunkt für KI-Hebel-Positionen oder eliminiert KI-Agent-Positionen vollständig. | K24: Fix-Positionen (CEO, CTO, Senior Eng. 1): immer zum Plantermin. KI-Hebel-Positionen (Junior Eng., Marketing): +6 Monate im Normal-Szenario. KI-Agent-Positionen (Sales Rep, Customer Success): Monat 99 im Stark-Szenario.
A25: KOSTEN | B25: Personal | C25: CEO Gehalt (Brutto/Jahr) | D25: 72.000 € | E25: €/Jahr | F25: Fest | G25: 72.000 € | H25: 72.000 € | I25: 72.000 € | J25: Gründer-Gehalt in der Pre-Seed-Phase. Beeinflusst die monatliche Burn Rate direkt. | K25: Gründer-Satz Pre-Seed. Anpassung ab Seed-Runde auf Marktgehalt. Typisch Startup: 60.000–90.000 €/Jahr.
A26: KOSTEN | B26: Personal | C26: CTO Gehalt (Brutto/Jahr) | D26: 72.000 € | E26: €/Jahr | F26: Fest | G26: 72.000 € | H26: 72.000 € | I26: 72.000 € | J26: Gründer-Gehalt in der Pre-Seed-Phase. Beeinflusst die monatliche Burn Rate direkt. | K26: Gründer-Satz Pre-Seed. Anpassung ab Seed-Runde auf Marktgehalt. Typisch Startup: 60.000–90.000 €/Jahr.
A27: KOSTEN | B27: Personal | C27: Senior Engineer (1) Gehalt | D27: 90.000 € | E27: €/Jahr | F27: Fest | G27: 90.000 € | H27: 90.000 € | I27: 90.000 € | J27: Erste strategische Einstellung. Fix-Position, nicht durch AI-Personal-Hebel verzögerbar. | K27: Berliner Marktgehalt für Senior ML-Engineer. Typisch: 80.000–110.000 €/Jahr.
A28: KOSTEN | B28: Personal | C28: Arbeitgeber-Nebenkosten | D28: 20 % | E28: % auf Bruttogehalt | F28: Fest | G28: 20 % | H28: 20 % | I28: 20 % | J28: Sozialversicherungsbeiträge des Arbeitgebers. Erhöht die effektiven Personalkosten um 20%. | K28: Standardsatz Deutschland 2026. Gesamtkosten pro MA = Bruttogehalt × 1,20.
A29: KOSTEN | B29: Personal | C29: Onboarding-Aufwand | D29: 30–120 Stunden | E29: Stunden/Kunde | F29: Szenario | G29: 120 Stunden | H29: 60 Stunden | I29: 30 Stunden | J29: Interner Aufwand für das Kunden-Onboarding. Bindet Entwickler- und Support-Kapazität. | K29: Gering: hoher Aufwand bei alten IT-Systemen (Automotive). Stark: standardisierter Self-Service-Prozess (Packaging). Quelle: Lothar.bm-Transkripte.
A30: Technologie & Cloud
A31: KOSTEN | B31: Technologie | C31: Cloud/Hosting Basis | D31: 2.000 € | E31: €/Monat | F31: Fest | G31: 2.000 € | H31: 2.000 € | I31: 2.000 € | J31: Fixe monatliche Grundkosten für Cloud-Infrastruktur. Unabhängig von der Kundenzahl. | K31: AWS/Azure/GCP Grundkonfiguration. Steigt mit Kundenzahl über den Skalierungsfaktor.
A32: KOSTEN | B32: Technologie | C32: Cloud-Skalierung pro Seat | D32: 80 € | E32: €/Seat/Monat | F32: Skalierend | G32: 80 € | H32: 80 € | I32: 80 € | J32: Variable Cloud-Kosten pro aktivem Seat. Wächst proportional zur Kundenbasis (szenarioabhängig). | K32: Gesamte Cloud-Kosten = Basis + (Seats × 80€). Im Stark-Szenario entstehen durch mehr Seats höhere Gesamtkosten.
A33: KOSTEN | B33: Technologie | C33: AI/ML APIs Basis | D33: 2.000 € | E33: €/Monat | F33: Fest | G33: 2.000 € | H33: 2.000 € | I33: 2.000 € | J33: Monatliche Grundkosten für KI-API-Nutzung (OpenAI/Anthropic/Frontier Models). | K33: Nutzung von GPT-5/Claude für Design-Logic. Wächst mit 8%/Monat proportional zur Nutzungsintensität.
A34: KOSTEN | B34: Technologie | C34: AI-Kosten Wachstum/Monat | D34: 8 % | E34: % / Monat | F34: Fest | G34: 8 % | H34: 8 % | I34: 8 % | J34: Monatliche Steigerungsrate der AI/ML-API-Kosten. Skaliert proportional zur Nutzung und Datentiefe. | K34: Skalierung proportional zur Nutzung und Datentiefe. Kann durch Open-Source-Modelle reduziert werden.
A35: KOSTEN | B35: Technologie | C35: SaaS Tools intern (Basis) | D35: 400 € | E35: €/Monat | F35: Fest | G35: 400 € | H35: 400 € | I35: 400 € | J35: Fixe monatliche Kosten für interne Tools (Slack, Notion, GitHub etc.). | K35: Standardpaket für Tech-Startups. Wächst mit Mitarbeiterzahl über den Pro-MA-Satz.
A36: KOSTEN | B36: Technologie | C36: SaaS Tools pro Mitarbeiter | D36: 100 € | E36: €/MA/Monat | F36: Skalierend | G36: 100 € | H36: 100 € | I36: 100 € | J36: Variable Tool-Kosten pro Mitarbeiter. Inkl. KI-Coding-Tools (Copilot/Cursor). | K36: Gesamte Tool-Kosten = Basis + (MAs × 100€). Im Gering-Szenario (mehr MAs) entstehen höhere Gesamtkosten.
A37: KOSTEN | B37: Technologie | C37: Sicherheit & Compliance | D37: 3.500 € | E37: €/Monat | F37: Fest | G37: 3.500 € | H37: 3.500 € | I37: 3.500 € | J37: Monatliche Kosten für Security-Tools und Compliance-Monitoring. Kritisch für TISAX-Zertifizierung im Automotive-Bereich. | K37: Puffer für TISAX-Audits und laufendes Compliance-Monitoring. Besonders relevant im Gering-Szenario (Automotive-Fokus).
A38: Marketing & Vertrieb
A39: KOSTEN | B39: Marketing & Vertrieb | C39: Paid Ads Budget (Initial) | D39: 1.000 € | E39: €/Monat | F39: Fest | G39: 1.000 € | H39: 1.000 € | I39: 1.000 € | J39: Monatliches Startbudget für bezahlte Werbung (Google, LinkedIn). Wächst mit 8%/Monat. | K39: Fokus eher auf Content/SEO im Industrie-Vertrieb. Skalierung mit Marktbekanntheit.
A40: KOSTEN | B40: Marketing & Vertrieb | C40: Content & SEO | D40: 2.500 € | E40: €/Monat | F40: Fest | G40: 2.500 € | H40: 2.500 € | I40: 2.500 € | J40: Monatliche Kosten für Content-Marketing und SEO. Fokus auf Whitepaper zu ROI, TCO und DPP-Compliance. | K40: Wichtiger Kanal für B2B-SaaS im Industriebereich. Langfristiger Aufbau von organischem Traffic.
A41: KOSTEN | B41: Marketing & Vertrieb | C41: Events & Messen/Jahr | D41: 50.000 € | E41: €/Jahr | F41: Fest | G41: 50.000 € | H41: 50.000 € | I41: 50.000 € | J41: Jährliche Kosten für Messeauftritte und Events. Wichtiger Kanal für Enterprise-Kundenkontakte. | K41: Präsenz auf Leitmessen (Hannover Messe, SPS). Hoher Posten – Überprüfung der Priorität empfohlen.
...

Sheet Szenarien_Analyse
A1: Faktor | B1: Referenz (Basis) | C1: Szenario: Gering | D1: Szenario: Normal | E1: Szenario: Stark | F1: DELTA: (Stark vs Nomal) | G1: Argumentation (Lothar.bm & Transkripte) | I1: ⚑ HINWEIS: Werte in den Spalten C/D/E (Gering/Normal/Stark) sind direkt bearbeitbar. Änderungen in DIESEM Blatt fließen automatisch über Sandbox → Inputs → Revenue/P&L.
A2: Fokus: Packaging | B2: 0.3 | C2: 0.1 | D2: 0.6 | E2: 0.8 | F2: =E2-D2 | G2: Höhere Margen, schnellere Zyklen als Auto.
A3: Fokus: Automotive | B3: 0.7 | C3: 0.9 | D3: 0.4 | E3: 0.2 | F3: =E3-D3 | G3: Hohe IT-Hürden und Margendruck (Lothar).
A4: Erste zahlende Kunden Monat | B4: 6 | C4: 14 | D4: 8 | E4: 4 | F4: =E4-D4 | G4: IT-Integration ist der Flaschenhals.
A5: Buchungs-Wahrscheinlichkeit Consulting je Kunde | B5: 0.5 | C5: 0.2 | D5: 0.5 | E5: 1 | F5: =E5-D5 | G5: Wahrscheinlichkeit, dass ein gewonnener Kunde Consulting bucht: a) 20 % (gering) = jeder 5. Kunde – Automotive, wenig Beratungsbedarf b) 50 % (normal) = jeder 2. Kunde – Hybrid-Markt c) 100 % (stark) = jeder Kunde – Packaging, hohe Implementierungstiefe → Fließt über Sandbox Z.12 → Inputs Z.139 → Revenue Z.28 | H5: → Sandbox → Inputs
A6: Startpreis pro Seat/Jahr | B6: 1 | C6: 0.8 | D6: 1 | E6: 1.2 | F6: =E6-D6 | G6: Value-Pricing eher in Packaging möglich.
A7: Personal (Experten) | B7: 5 FTE | C7: 3 FTE | D7: 7 FTE | E7: 12 FTE | F7: =E7-D7 | G7: Bedarf an "Übersetzern" für IT-Landschaft.
A8: Consulting-Tage/Einsatz | B8: 10 | C8: 5 | D8: 10 | E8: 20 | F8: =E8-D8 | G8: Consulting-Tage pro Kunde je Einsatz: gering=5 (Basisschulung + Systemcheck) normal=10 (Implementierungsbegleitung + Anwenderschulung) stark=20 (Spez. Anforderungen, Datenbereinigung, Stammdaten-Harmonisierung) → Fließt über Sandbox Z.11 → Inputs Z.140 → Revenue Z.28 | H8: → Sandbox → Inputs
A9: Net Revenue Retention (NRR) | B9: 1.15 | C9: 1.05 | D9: 1.15 | E9: 1.3 | F9: =E9-D9 | G9: Treiber-Matrix: NRR szenarioabhängig machen (bisher fest 125%). Gering=105%: Automotive, wenig Upselling-Potenzial. Normal=115%: Hybrid, DPP-Module. Stark=130%: Packaging, Analytics-Premium + Multi-Werk-Rollouts. | H9: → Sandbox → Inputs
A10: Jährliche Churn Rate | B10: 0.06 | C10: 0.1 | D10: 0.06 | E10: 0.03 | F10: =E10-D10 | G10: Treiber-Matrix: Churn szenarioabhängig (bisher fest 6%). Gering=10%: Automotive-Budgetzyklen, höheres Abwanderungsrisiko. Normal=6%: Standardwert (SaaS-Industrie). Stark=3%: Packaging, tiefe API-Integration → hoher Switching-Cost. | H10: → Sandbox → Inputs
A11: Consulting-Startmonat | B11: 4 | C11: 3 | D11: 4 | E11: 6 | F11: =E11-D11 | G11: Treiber-Matrix Z.21: Consulting startet als Enabler vor dem SaaS-Produkt. Gering=Monat 3: Automotive benötigt sofort IT-Begleitung. Stark=Monat 6: Packaging-Kunden länger Self-Service-fähig. | H11: → Sandbox → Inputs

Sheet Inputs
A1: ZENTRALE EINGABEWERTE | B1: Wert | C1: Erklärung / Hinweis | D1: Bemerkungen | E1: Einstellungsplan: KI-Strategie | F1: Szenarioauswahl: gering, normal, stark
F2: ='00_Input_Sandbox'!$B$2
A3: ALLGEMEINE EINSTELLUNGEN
A4: Firmenname | B4: LoopforgeLab GmbH | C4: Name des Unternehmens
A5: Startdatum | B5: 46113 | C5: Beginn der Projektionen
A6: Währung | B6: EUR | C6: EUR für DACH-Startups
A7: Steuersatz | B7: 0.3 | C7: KSt + GewSt (~30% in DE) | D7: Übernahme des Standardsatzes (KSt + GewSt in Deutschland).
A9: FINANZIERUNGSRUNDEN
A10: Ideation Phase | B10: 90000 | C10: Typisch: 100.000-500.000€ | D10: Phase: 1.4.26 bis 15.7.2026 MVP-Anschubfinanzierung; stellt keine Unternehmensbewertung dar.
A11: Ideation Phase | B11: 1 | C11: Monat der Einzahlung | D11: MVP-Entwicklung und IP-Aufbau starten unmittelbar.
A12: Pre-Seed Betrag | B12: 1500000 | C12: Typisch: 500.000-2.000.000€ | D12: Pre-Seed Phase ab VC Pitch im Juli '26 (1.5M-3M Bewertung).
A13: Pre-Seed Monat | B13: 5 | C13: Typisch: Monat 5 | D13: Juli 2026 entspricht Monat 5 Fokus auf Pilot-Traction.
A14: Seed Betrag | B14: 4000000 | C14: Typisch: 3.000.000-10.000.000€ | D14: Abhängig von Pilotprojekten und Reife des Produktes
A15: Seed Monat | B15: 17 | C15: Typisch: Monat 17 | D15: Geplant für Mitte 2027.
A16: Series A Betrag | B16: 10000000 | C16: Typisch: 10.000.000-25.000.000€ | D16: Vorerst unverändert als langfristige Wachstumsambition.
A17: Series A Monat | B17: 36 | C17: Typisch: Monat 35 | D17: Geplant für Herbst 2028.
A19: REVENUE-ANNAHMEN (SaaS/ARR)
A20: Startpreis pro Seat/Jahr | B20: =VLOOKUP("Startpreis Seat/Jahr", '00_Input_Sandbox'!$B$3:$F$20, '00_Input_Sandbox'!$B$2-1, FALSE) * 12 | C20: Jährliche Lizenzgebühr pro Nutzer | D20: 1. Realistisch? Hängt auch ab vom Business Modell..Pricing basierend auf Wettbewerb oder auf voraussichtlichem Einsparpotential? 2. weitere Erlösquellen? Beratung? Implementierungsaufwand? Hybrid-Modell: Deckt Fixkosten und partizipiert am TCO-Einsparwert. [1] | G20: 2. Regulatory Moat (DPP): JE nach Branche (hier: Annahme von neuen Zielbranche in Bezuf auf DPP Verpflichtung) Die Zielbranchen Batterien und Elektronik unterliegen ab 2027 der DPP-Pflicht. Dies rechtfertigt höhere Preise und eine stärkere NRR, da LFL hiermit zur "Compliance Engine" des Kunden wird. -->"Compliance" könnte aber auch durch andere Benefits ersetzt werden
A21: Preiserhöhung/Jahr | B21: 0.05 | C21: Typisch: 3-5% p.a. | D21: Standard für AI-SaaS 2026 (Kompensation Inferenz/Innovation). [4]
A22: Erste zahlende Kunden Monat | B22: =VLOOKUP("Startmonat Kunden", '00_Input_Sandbox'!$B$3:$F$20, '00_Input_Sandbox'!$B$2-1, FALSE) | C22: Wann erster Umsatz? | D22: Erster Umsatz in Monat 8 (Start: 04/26)…Realistisch? Wie lange Lead-Time? Zielkunden? Beachhead-Market? Weitere Begründung: wenn im Automotivebereich: Puffer für Sales-Zyklen (9-12 Mon.) und TISAX im Mittelstand. [1
A23: Initiale Seats | B23: 3 | C23: Anzahl Seats beim ersten Kunden | D23: Realistisch? Hängt von Kundengrösse ab. Implementierungsaufwand je Kunde mit einkalkulieren weitere Aspekte: Kalkulieren mit 1-2 Projekten/ Start mit Pilotprojekten (Werke) zur ROI-Validierung ("Land&Expand")
A24: Monatliche Seat-Wachstumsrate | B24: 0.03 | C24: Wachstum neue Seats/Monat | D24: -->hier eine Annahme bzgll Vertriebsplanung treffen. Wie hoch ist die Zahl der Verkauften Sitze nach 1, 2, 3 Jahren? Gibt es noch andere Erlösströme? ALTERNATIVE: Account-basierte Planng: Wechsel auf "Stufenfunktion" beim Aufbau des Geschäfts (Roll-out pro Werk statt linearer Rate)
A25: Enterprise-Deals ab Monat | B25: 30 | C25: Wann starten große Verträge? Wenn Automotive: Verschiebung durch längere Technical Validation und Compliance-Hürden. | G25: 3. Vertriebsrealismus: Der Start des Umsatzes wurde nach hinten geschoben da der industrielle Mittelstand ("Hidden Champions") langsame Entscheidungsprozesse und hohe Sicherheitsanforderungen (TISAX) hat. Die Zeit bis zum Juli 2026 wird für die Validierung der TCO-Einsparungen (Ausschuss-Reduktion) bei Pilotkunden genutzt.
A26: Durchschnitt Enterprise ARR | B26: 25000 | C26: Typisch: 50.000-200.000€/Jahr | D26: Höheres Volumen durch Tiefe der Integration: hier Annahme von weiteren Benefits wie Einbeziehung von DPP & Sustainability
A27: Enterprise Deals pro Quartal | B27: 1 | C27: Neue Enterprise-Deals pro Quartal
A28: Jährliche Churn Rate | B28: =VLOOKUP("Churn Rate",'00_Input_Sandbox'!$B$3:$F$20,'00_Input_Sandbox'!$B$2-1,FALSE) | C28: Jährliche Churn Rate (szenarioabhängig): Gering=10% | Normal=6% | Stark=3% | D28: Treiber-Matrix: Churn jetzt szenarioabhängig (vorher fest 15%). Automotive: 10% (Budgetzyklen). Packaging: 3% (hoher Switching-Cost).
A29: Net Revenue Retention | B29: =VLOOKUP("Net Revenue Retention (NRR)",'00_Input_Sandbox'!$B$3:$F$20,'00_Input_Sandbox'!$B$2-1,FALSE) | C29: Net Revenue Retention (szenarioabhängig): Gering=105% | Normal=115% | Stark=130% | D29: Treiber-Matrix: NRR jetzt szenarioabhängig (vorher fest 125%). Expansion-Umsatz minus Churn. NRR>100%=Bestandskunden wachsen. | F29: das ist schon wieder falsch. Die Gehälter für die Executive-Funktionen stehen nicht in den von dir genannten Zellen B26 bis B28
A31: GEHÄLTER (Brutto/Jahr)
A32: CEO Gehalt | B32: 72000 | C32: Typisch Startup: 60.000-90.000€ | D32: Gründer-Satz Pre-Seed); Anpassung ab Seed-Runde. Muss noch genauer präzisiert werden
A33: CTO Gehalt | B33: 72000 | C33: Typisch Startup: 60.000-90.000€ | D33: Gründer-Satz Pre-Seed); Anpassung ab Seed-Runde. Muss noch genauer präzisiert werden
A34: CCO Gehalt | B34: 72000 | C34: Typisch Startup: 60.000-90.000€ | D34: Gründer-Satz Pre-Seed); Anpassung ab Seed-Runde. Muss noch genauer präzisiert werden
A35: Senior Engineer Gehalt | B35: 90000 | C35: Typisch: 70.000-90.000€ | D35: Berliner Tech-Benchmark 2025/26 für Senior-Fullstack/Backends. [9]
A36: Junior Engineer Gehalt | B36: 60000 | C36: Typisch: 45.000-60.000€ | D36: Anpassung an gestiegene Einstiegsgehälter für Top-Tech-Talente. [9]
A37: ML/AI Engineer Gehalt | B37: 110000 | C37: Typisch: 75.000-100.000€ | D37: Höchste Marktnachfrage; KI-Experten in Berlin deutlich über SWE-Schnitt. [10]
A38: Product Manager Gehalt | B38: 80000 | C38: Typisch: 65.000-85.000€ | D38: Durchschnitt für Technical PMs (Industrial AI) am Standort Berlin
A39: Sales Representative Gehalt | B39: 130000 | C39: Typisch: 50.000-70.000€ + Provision | D39: Split 50/50 (65k fix + 65k var); zwingend für Enterprise-Vertrieb. [12
A40: Marketing Manager Gehalt | B40: 65000 | C40: Typisch: 55.000-75.000€ | D40: Anpassung an Marktniveau für B2B-Industrie-Spezialisten.
A41: Customer Success Gehalt | B41: 65000 | C41: Typisch: 45.000-60.000€ | D41: Shift hin zu Solution Architect Profil (techn. Implementierung). [13]
A42: Office/Admin Gehalt | B42: 45000 | C42: Typisch: 40.000-50.000€ | D42: (marktüblich für Berlin).
A43: Finance Manager | B43: 80000
...

Sheet 00_Input_Sandbox
A1: Aktives Szenario | B1: gering | C1: Einheit | D1: Gering (Auto-Fokus) | E1: Normal (Hybrid) | F1: Stark (Pack-Fokus) | G1: Argumentation / Quelle
A2: Spalten-Index (intern) | B2: =IF(B1="gering", 4, IF(B1="normal", 5, 6))
A3: Kategorie | B3: Variable | C3: Einheit | D3: Gering | E3: Normal | F3: Stark | G3: Quelle
A4: Markt-Mix | B4: Anteil Packaging | C4: % | D4: 0.1 | E4: 0.6 | F4: 0.8 | G4: Lothar.bm: Packaging hat schnellere Zyklen.
A5: Vertrieb | B5: Startmonat Kunden | C5: Monate | D5: 17 | E5: 8 | F5: 4 | G5: Lothar.bm: IT-Hürden bei Automotive Tier-1.
A6: Revenue 1 | B6: Startpreis Seat/Jahr | C6: €/Monat | D6: 200 | E6: 1000 | F6: 1200 | G6: Value-based Pricing in Packaging (White Paper).
A7: Revenue 2 | B7: Consulting-Tagessatz | C7: €/Tag | D7: 1000 | E7: 1200 | F7: 1500 | G7: Consulting-Tagessatz: gering=1.000 €/Tag | normal=1.200 €/Tag | stark=1.500 €/Tag. Basiert auf Expertenstatus (Haag/Candemir) und Marktniveau B2B Industrie.
A8: Effizienz | B8: Iterations-Reduktion | C8: Faktor | D8: 1,2x | E8: 2,0x | F8: 3,0x | G8: White Paper: Redesign Trap vermeiden.
A9: Kosten | B9: Onboarding-Aufwand | C9: Stunden | D9: 120 | E9: 60 | F9: 30 | G9: Lothar.bm: Hoher Aufwand bei alten IT-Systemen.
A10: Effizienz | B10: AI-Personal-Hebel | D10: 0 | E10: 6 | F10: 99
A11: Consulting | B11: Consulting-Tage/Einsatz | C11: Tage/Einsatz | D11: =Szenarien_Analyse!C8 | E11: =Szenarien_Analyse!D8 | F11: =Szenarien_Analyse!E8 | G11: Referenziert Szenarien_Analyse Z.8 (dort bearbeitbar). gering=5 Tage | normal=10 Tage | stark=20 Tage. Direkte Eingabe hier überschreibt die Szenarien-Referenz.
A12: Consulting | B12: Buchungs-Wahrscheinlichkeit Consulting | C12: % | D12: =Szenarien_Analyse!C5 | E12: =Szenarien_Analyse!D5 | F12: =Szenarien_Analyse!E5 | G12: Referenziert Szenarien_Analyse Z.5 (dort bearbeitbar). a) gering=20% – jeder 5. Kunde kauft Consulting, b) normal=50% – jeder 2. Kunde, c) stark=100% – jeder Kunde kauft Consulting-Tage.
A13: Retention | B13: Net Revenue Retention (NRR) | C13: % | D13: =Szenarien_Analyse!C9 | E13: =Szenarien_Analyse!D9 | F13: =Szenarien_Analyse!E9 | G13: Szenarioabhängig (Szenarien_Analyse Z.9). Gering=105% | Normal=115% | Stark=130%.
A14: Retention | B14: Churn Rate | C14: %/Jahr | D14: =Szenarien_Analyse!C10 | E14: =Szenarien_Analyse!D10 | F14: =Szenarien_Analyse!E10 | G14: Szenarioabhängig (Szenarien_Analyse Z.10). Gering=10% | Normal=6% | Stark=3%.
A15: Consulting | B15: Consulting-Startmonat | C15: Monat | D15: =Szenarien_Analyse!C11 | E15: =Szenarien_Analyse!D11 | F15: =Szenarien_Analyse!E11 | G15: Szenarioabhängig (Szenarien_Analyse Z.11). Gering=3 | Normal=4 | Stark=6.

Sheet P&L
A1: GEWINN- UND VERLUSTRECHNUNG (P&L)
A3: Position | B3: M1 | C3: M2 | D3: M3 | E3: M4 | F3: M5 | G3: M6 | H3: M7 | I3: M8 | J3: M9 | K3: M10 | L3: M11 | M3: M12 | N3: M13 | O3: M14 | P3: M15 | Q3: M16 | R3: M17 | S3: M18 | T3: M19 | U3: M20 | V3: M21 | W3: M22 | X3: M23 | Y3: M24 | Z3: M25 | AA3: M26 | AB3: M27 | AC3: M28 | AD3: M29 | AE3: M30 | AF3: M31 | AG3: M32 | AH3: M33 | AI3: M34 | AJ3: M35 | AK3: M36 | AL3: M37 | AM3: M38 | AN3: M39 | AO3: M40 | AP3: M41 | AQ3: M42 | AR3: M43 | AS3: M44 | AT3: M45 | AU3: M46 | AV3: M47 | AW3: M48 | AX3: M49 | AY3: M50 | AZ3: M51 | BA3: M52
A4: REVENUE
A5: Subscription Revenue | B5: =Revenue!B9 | C5: =Revenue!C9 | D5: =Revenue!D9 | E5: =Revenue!E9 | F5: =Revenue!F9 | G5: =Revenue!G9 | H5: =Revenue!H9 | I5: =Revenue!I9 | ... BA5: =Revenue!BA9
A6: Enterprise Revenue | B6: =Revenue!B16 | C6: =Revenue!C16 | D6: =Revenue!D16 | E6: =Revenue!E16 | F6: =Revenue!F16 | G6: =Revenue!G16 | H6: =Revenue!H16 | I6: =Revenue!I16 | ... BA6: =Revenue!BA16
A7: TOTAL REVENUE | B7: =B5+B6+B8 | C7: =C5+C6+C8 | D7: =D5+D6+D8 | E7: =E5+E6+E8 | F7: =F5+F6+F8 | G7: =G5+G6+G8 | H7: =H5+H6+H8 | I7: =I5+I6+I8 | ... BA7: =BA5+BA6+BA8
A8: Consulting Revenue | B8: =Revenue!B29 | C8: =Revenue!C29 | D8: =Revenue!D29 | E8: =Revenue!E29 | F8: =Revenue!F29 | G8: =Revenue!G29 | H8: =Revenue!H29 | I8: =Revenue!I29 | ... BA8: =Revenue!BA29
A9: COST OF GOODS SOLD (COGS)
A10: Cloud Hosting (variable) | B10: =Costs!B82 | C10: =Costs!C82 | D10: =Costs!D82 | E10: =Costs!E82 | F10: =Costs!F82 | G10: =Costs!G82 | H10: =Costs!H82 | I10: =Costs!I82 | ... BA10: =Costs!BA82
A11: AI/ML API Kosten | B11: =Costs!B83 | C11: =Costs!C83 | D11: =Costs!D83 | E11: =Costs!E83 | F11: =Costs!F83 | G11: =Costs!G83 | H11: =Costs!H83 | I11: =Costs!I83 | ... BA11: =Costs!BA83
A12: Payment Processing | B12: =Costs!B128 | C12: =Costs!C128 | D12: =Costs!D128 | E12: =Costs!E128 | F12: =Costs!F128 | G12: =Costs!G128 | H12: =Costs!H128 | I12: =Costs!I128 | ... BA12: =Costs!BA128
A13: TOTAL COGS | B13: =SUM(B10:B12) | C13: =SUM(C10:C12) | D13: =SUM(D10:D12) | E13: =SUM(E10:E12) | F13: =SUM(F10:F12) | G13: =SUM(G10:G12) | H13: =SUM(H10:H12) | I13: =SUM(I10:I12) | ... BA13: =SUM(BA10:BA12)
A15: GROSS PROFIT | B15: =B7-B13 | C15: =C7-C13 | D15: =D7-D13 | E15: =E7-E13 | F15: =F7-F13 | G15: =G7-G13 | H15: =H7-H13 | I15: =I7-I13 | ... BA15: =BA7-BA13
A16: Gross Margin % | B16: =IFERROR(B15/B7,0) | C16: =IFERROR(C15/C7,0) | D16: =IFERROR(D15/D7,0) | E16: =IFERROR(E15/E7,0) | F16: =IFERROR(F15/F7,0) | G16: =IFERROR(G15/G7,0) | H16: =IFERROR(H15/H7,0) | I16: =IFERROR(I15/I7,0) | ... BA16: =IFERROR(BA15/BA7,0)
A18: OPERATING EXPENSES
A19: Total Personnel | B19: =Costs!B78 | C19: =Costs!C78 | D19: =Costs!D78 | E19: =Costs!E78 | F19: =Costs!F78 | G19: =Costs!G78 | H19: =Costs!H78 | I19: =Costs!I78 | ... BA19: =Costs!BA78
A20: Total Technology | B20: =Costs!B87 | C20: =Costs!C87 | D20: =Costs!D87 | E20: =Costs!E87 | F20: =Costs!F87 | G20: =Costs!G87 | H20: =Costs!H87 | I20: =Costs!I87 | ... BA20: =Costs!BA87
A21: Total Office/Facilities | B21: =Costs!B94 | C21: =Costs!C94 | D21: =Costs!D94 | E21: =Costs!E94 | F21: =Costs!F94 | G21: =Costs!G94 | H21: =Costs!H94 | I21: =Costs!I94 | ... BA21: =Costs!BA94
A22: Total Professional Services | B22: =Costs!B101 | C22: =Costs!C101 | D22: =Costs!D101 | E22: =Costs!E101 | F22: =Costs!F101 | G22: =Costs!G101 | H22: =Costs!H101 | I22: =Costs!I101 | ... BA22: =Costs!BA101
A23: Total Insurance & Bank | B23: =Costs!B108 | C23: =Costs!C108 | D23: =Costs!D108 | E23: =Costs!E108 | F23: =Costs!F108 | G23: =Costs!G108 | H23: =Costs!H108 | I23: =Costs!I108 | ... BA23: =Costs!BA108
A24: Total Marketing & Sales | B24: =Costs!B117 | C24: =Costs!C117 | D24: =Costs!D117 | E24: =Costs!E117 | F24: =Costs!F117 | G24: =Costs!G117 | H24: =Costs!H117 | I24: =Costs!I117 | ... BA24: =Costs!BA117
A25: Total Other OpEx | B25: =Costs!B125 | C25: =Costs!C125 | D25: =Costs!D125 | E25: =Costs!E125 | F25: =Costs!F125 | G25: =Costs!G125 | H25: =Costs!H125 | I25: =Costs!I125 | ... BA25: =Costs!BA125
A26: Contingency/Buffer | B26: =Costs!B130 | C26: =Costs!C130 | D26: =Costs!D130 | E26: =Costs!E130 | F26: =Costs!F130 | G26: =Costs!G130 | H26: =Costs!H130 | I26: =Costs!I130 | ... BA26: =Costs!BA130
A27: TOTAL OPERATING EXPENSES | B27: =SUM(B19:B26) | C27: =SUM(C19:C26) | D27: =SUM(D19:D26) | E27: =SUM(E19:E26) | F27: =SUM(F19:F26) | G27: =SUM(G19:G26) | H27: =SUM(H19:H26) | I27: =SUM(I19:I26) | ... BA27: =SUM(BA19:BA26)
A29: EBITDA | B29: =B15-B27 | C29: =C15-C27 | D29: =D15-D27 | E29: =E15-E27 | F29: =F15-F27 | G29: =G15-G27 | H29: =H15-H27 | I29: =I15-I27 | ... BA29: =BA15-BA27
A30: EBITDA Margin % | B30: =IFERROR(B29/B7,0) | C30: =IFERROR(C29/C7,0) | D30: =IFERROR(D29/D7,0) | E30: =IFERROR(E29/E7,0) | F30: =IFERROR(F29/F7,0) | G30: =IFERROR(G29/G7,0) | H30: =IFERROR(H29/H7,0) | I30: =IFERROR(I29/I7,0) | ... BA30: =IFERROR(BA29/BA7,0)
A32: Depreciation & Amortization | B32: =Costs!B123/Inputs!$B$135/12 | C32: =Costs!C123/Inputs!$B$135/12 | D32: =Costs!D123/Inputs!$B$135/12 | E32: =Costs!E123/Inputs!$B$135/12 | F32: =Costs!F123/Inputs!$B$135/12 | G32: =Costs!G123/Inputs!$B$135/12 | H32: =Costs!H123/Inputs!$B$135/12 | I32: =Costs!I123/Inputs!$B$135/12 | ... BA32: =Costs!BA123/Inputs!$B$135/12
A34: EBIT (Operating Income) | B34: =B29-B32 | C34: =C29-C32 | D34: =D29-D32 | E34: =E29-E32 | F34: =F29-F32 | G34: =G29-G32 | H34: =H29-H32 | I34: =I29-I32 | ... BA34: =BA29-BA32
A36: EBT (Earnings Before Tax) | B36: =B34 | C36: =C34 | D36: =D34 | E36: =E34 | F36: =F34 | G36: =G34 | H36: =H34 | I36: =I34 | ... BA36: =BA34
A37: Income Tax | B37: =IF(B36>0,B36*Inputs!$B$7,0) | C37: =IF(C36>0,C36*Inputs!$B$7,0) | D37: =IF(D36>0,D36*Inputs!$B$7,0) | E37: =IF(E36>0,E36*Inputs!$B$7,0) | F37: =IF(F36>0,F36*Inputs!$B$7,0) | G37: =IF(G36>0,G36*Inputs!$B$7,0) | H37: =IF(H36>0,H36*Inputs!$B$7,0) | I37: =IF(I36>0,I36*Inputs!$B$7,0) | ... BA37: =IF(BA36>0,BA36*Inputs!$B$7,0)
A39: NET INCOME | B39: =B36-B37 | C39: =C36-C37 | D39: =D36-D37 | E39: =E36-E37 | F39: =F36-F37 | G39: =G36-G37 | H39: =H36-H37 | I39: =I36-I37 | ... BA39: =BA36-BA37
A40: Net Margin % | B40: =IFERROR(B39/B7,0) | C40: =IFERROR(C39/C7,0) | D40: =IFERROR(D39/D7,0) | E40: =IFERROR(E39/E7,0) | F40: =IFERROR(F39/F7,0) | G40: =IFERROR(G39/G7,0) | H40: =IFERROR(H39/H7,0) | I40: =IFERROR(I39/I7,0) | ... BA40: =IFERROR(BA39/BA7,0)

Sheet Revenue
A1: UMSATZMODELL - Detaillierte Aufschlüsselung
B2: 46113 | C2: 46143 | D2: 46174 | E2: 46204 | F2: 46235 | G2: 46266 | H2: 46296 | I2: 46327 | J2: 46357 | K2: 46388 | L2: 46419 | M2: 46447 | N2: 46478 | O2: 46508 | P2: 46539 | Q2: 46569 | R2: 46600 | S2: 46631 | T2: 46661 | U2: 46692 | V2: 46722 | W2: 46753 | X2: 46784 | Y2: 46813 | Z2: 46844 | AA2: 46874 | AB2: 46905 | AC2: 46935 | AD2: 46966 | AE2: 46997 | AF2: 47027 | AG2: 47058 | AH2: 47088 | AI2: 47119 | AJ2: 47150 | AK2: 47178 | AL2: 47209 | AM2: 47239 | AN2: 47270 | AO2: 47300 | AP2: 47331 | AQ2: 47362 | AR2: 47392 | AS2: 47423 | AT2: 47453 | AU2: 47484 | AV2: 47515 | AW2: 47543 | AX2: 47574 | AY2: 47604 | AZ2: 47635 | BA2: 47665
A3: Kennzahl | B3: M1 | C3: M2 | D3: M3 | E3: M4 | F3: M5 | G3: M6 | H3: M7 | I3: M8 | J3: M9 | K3: M10 | L3: M11 | M3: M12 | N3: M13 | O3: M14 | P3: M15 | Q3: M16 | R3: M17 | S3: M18 | T3: M19 | U3: M20 | V3: M21 | W3: M22 | X3: M23 | Y3: M24 | Z3: M25 | AA3: M26 | AB3: M27 | AC3: M28 | AD3: M29 | AE3: M30 | AF3: M31 | AG3: M32 | AH3: M33 | AI3: M34 | AJ3: M35 | AK3: M36 | AL3: M37 | AM3: M38 | AN3: M39 | AO3: M40 | AP3: M41 | AQ3: M42 | AR3: M43 | AS3: M44 | AT3: M45 | AU3: M46 | AV3: M47 | AW3: M48 | AX3: M49 | AY3: M50 | AZ3: M51 | BA3: M52
A4: Preis pro Seat/Monat (€) | B4: =IFERROR(Inputs!$B$20/12*(1+Inputs!$B$21)^(INT((1-1)/12)),0) | C4: =Inputs!$B$20/12*(1+Inputs!$B$21)^INT((2-1)/12) | D4: =Inputs!$B$20/12*(1+Inputs!$B$21)^INT((3-1)/12) | E4: =Inputs!$B$20/12*(1+Inputs!$B$21)^INT((4-1)/12) | F4: =Inputs!$B$20/12*(1+Inputs!$B$21)^INT((5-1)/12) | G4: =Inputs!$B$20/12*(1+Inputs!$B$21)^INT((6-1)/12) | H4: =Inputs!$B$20/12*(1+Inputs!$B$21)^INT((7-1)/12) | I4: =Inputs!$B$20/12*(1+Inputs!$B$21)^INT((8-1)/12) | J4: =Inputs!$B$20/12*(1+Inputs!$B$21)^INT((9-1)/12) | K4: =Inputs!$B$20/12*(1+Inputs!$B$21)^INT((10-1)/12) | L4: =Inputs!$B$20/12*(1+Inputs!$B$21)^INT((11-1)/12) | M4: =Inputs!$B$20/12*(1+Inputs!$B$21)^INT((12-1)/12) | N4: =Inputs!$B$20/12*(1+Inputs!$B$21)^INT((13-1)/12) | O4: =Inputs!$B$20/12*(1+Inputs!$B$21)^INT((14-1)/12) | P4: =Inputs!$B$20/12*(1+Inputs!$B$21)^INT((15-1)/12) | Q4: =Inputs!$B$20/12*(1+Inputs!$B$21)^INT((16-1)/12) | R4: =Inputs!$B$20/12*(1+Inputs!$B$21)^INT((17-1)/12) | S4: =Inputs!$B$20/12*(1+Inputs!$B$21)^INT((18-1)/12) | T4: =Inputs!$B$20/12*(1+Inputs!$B$21)^INT((19-1)/12) | U4: =Inputs!$B$20/12*(1+Inputs!$B$21)^INT((20-1)/12) | V4: =Inputs!$B$20/12*(1+Inputs!$B$21)^INT((21-1)/12) | W4: =Inputs!$B$20/12*(1+Inputs!$B$21)^INT((22-1)/12) | X4: =Inputs!$B$20/12*(1+Inputs!$B$21)^INT((23-1)/12) | Y4: =Inputs!$B$20/12*(1+Inputs!$B$21)^INT((24-1)/12) | Z4: =Inputs!$B$20/12*(1+Inputs!$B$21)^INT((25-1)/12) | AA4: =Inputs!$B$20/12*(1+Inputs!$B$21)^INT((26-1)/12) | AB4: =Inputs!$B$20/12*(1+Inputs!$B$21)^INT((27-1)/12) | AC4: =Inputs!$B$20/12*(1+Inputs!$B$21)^INT((28-1)/12) | AD4: =Inputs!$B$20/12*(1+Inputs!$B$21)^INT((29-1)/12) | AE4: =Inputs!$B$20/12*(1+Inputs!$B$21)^INT((30-1)/12) | AF4: =Inputs!$B$20/12*(1+Inputs!$B$21)^INT((31-1)/12) | AG4: =Inputs!$B$20/12*(1+Inputs!$B$21)^INT((32-1)/12) | AH4: =Inputs!$B$20/12*(1+Inputs!$B$21)^INT((33-1)/12) | AI4: =Inputs!$B$20/12*(1+Inputs!$B$21)^INT((34-1)/12) | AJ4: =Inputs!$B$20/12*(1+Inputs!$B$21)^INT((35-1)/12) | AK4: =Inputs!$B$20/12*(1+Inputs!$B$21)^INT((36-1)/12) | AL4: =Inputs!$B$20/12*(1+Inputs!$B$21)^INT((37-1)/12) | AM4: =Inputs!$B$20/12*(1+Inputs!$B$21)^INT((38-1)/12) | AN4: =Inputs!$B$20/12*(1+Inputs!$B$21)^INT((39-1)/12) | AO4: =Inputs!$B$20/12*(1+Inputs!$B$21)^INT((40-1)/12) | AP4: =Inputs!$B$20/12*(1+Inputs!$B$21)^INT((41-1)/12) | AQ4: =Inputs!$B$20/12*(1+Inputs!$B$21)^INT((42-1)/12) | AR4: =Inputs!$B$20/12*(1+Inputs!$B$21)^INT((43-1)/12) | AS4: =Inputs!$B$20/12*(1+Inputs!$B$21)^INT((44-1)/12) | AT4: =Inputs!$B$20/12*(1+Inputs!$B$21)^INT((45-1)/12) | AU4: =Inputs!$B$20/12*(1+Inputs!$B$21)^INT((46-1)/12) | AV4: =Inputs!$B$20/12*(1+Inputs!$B$21)^INT((47-1)/12) | AW4: =Inputs!$B$20/12*(1+Inputs!$B$21)^INT((48-1)/12) | AX4: =Inputs!$B$20/12*(1+Inputs!$B$21)^INT((49-1)/12) | AY4: =Inputs!$B$20/12*(1+Inputs!$B$21)^INT((50-1)/12) | AZ4: =Inputs!$B$20/12*(1+Inputs!$B$21)^INT((51-1)/12) | BA4: =Inputs!$B$20/12*(1+Inputs!$B$21)^INT((52-1)/12)
A5: Neue Seats | B5: =IF(1>=Inputs!$B$22,Inputs!$B$23,0) | C5: =IF(2>=Inputs!$B$22,IF(2=Inputs!$B$22,Inputs!$B$23,ROUND(B8*Inputs!$B$24,0)),0) | D5: =IF(3>=Inputs!$B$22,IF(3=Inputs!$B$22,Inputs!$B$23,ROUND(C8*Inputs!$B$24,0)),0) | E5: =IF(4>=Inputs!$B$22,IF(4=Inputs!$B$22,Inputs!$B$23,ROUND(D8*Inputs!$B$24,0)),0) | F5: =IF(5>=Inputs!$B$22,IF(5=Inputs!$B$22,Inputs!$B$23,ROUND(E8*Inputs!$B$24,0)),0) | G5: =IF(6>=Inputs!$B$22,IF(6=Inputs!$B$22,Inputs!$B$23,ROUND(F8*Inputs!$B$24,0)),0) | H5: =IF(7>=Inputs!$B$22,IF(7=Inputs!$B$22,Inputs!$B$23,ROUND(G8*Inputs!$B$24,0)),0) | I5: =IF(8>=Inputs!$B$22,IF(8=Inputs!$B$22,Inputs!$B$23,ROUND(H8*Inputs!$B$24,0)),0) | J5: =IF(9>=Inputs!$B$22,IF(9=Inputs!$B$22,Inputs!$B$23,ROUND(I8*Inputs!$B$24,0)),0) | K5: =IF(10>=Inputs!$B$22,IF(10=Inputs!$B$22,Inputs!$B$23,ROUND(J8*Inputs!$B$24,0)),0) | L5: =IF(11>=Inputs!$B$22,IF(11=Inputs!$B$22,Inputs!$B$23,ROUND(K8*Inputs!$B$24,0)),0) | M5: =IF(12>=Inputs!$B$22,IF(12=Inputs!$B$22,Inputs!$B$23,ROUND(L8*Inputs!$B$24,0)),0) | N5: =IF(13>=Inputs!$B$22,IF(13=Inputs!$B$22,Inputs!$B$23,ROUND(M8*Inputs!$B$24,0)),0) | O5: =IF(14>=Inputs!$B$22,IF(14=Inputs!$B$22,Inputs!$B$23,ROUND(N8*Inputs!$B$24,0)),0) | P5: =IF(15>=Inputs!$B$22,IF(15=Inputs!$B$22,Inputs!$B$23,ROUND(O8*Inputs!$B$24,0)),0) | Q5: =IF(16>=Inputs!$B$22,IF(16=Inputs!$B$22,Inputs!$B$23,ROUND(P8*Inputs!$B$24,0)),0) | R5: =IF(17>=Inputs!$B$22,IF(17=Inputs!$B$22,Inputs!$B$23,ROUND(Q8*Inputs!$B$24,0)),0) | S5: =IF(18>=Inputs!$B$22,IF(18=Inputs!$B$22,Inputs!$B$23,ROUND(R8*Inputs!$B$24,0)),0) | T5: =IF(19>=Inputs!$B$22,IF(19=Inputs!$B$22,Inputs!$B$23,ROUND(S8*Inputs!$B$24,0)),0) | U5: =IF(20>=Inputs!$B$22,IF(20=Inputs!$B$22,Inputs!$B$23,ROUND(T8*Inputs!$B$24,0)),0) | V5: =IF(21>=Inputs!$B$22,IF(21=Inputs!$B$22,Inputs!$B$23,ROUND(U8*Inputs!$B$24,0)),0) | W5: =IF(22>=Inputs!$B$22,IF(22=Inputs!$B$22,Inputs!$B$23,ROUND(V8*Inputs!$B$24,0)),0) | X5: =IF(23>=Inputs!$B$22,IF(23=Inputs!$B$22,Inputs!$B$23,ROUND(W8*Inputs!$B$24,0)),0) | Y5: =IF(24>=Inputs!$B$22,IF(24=Inputs!$B$22,Inputs!$B$23,ROUND(X8*Inputs!$B$24,0)),0) | Z5: =IF(25>=Inputs!$B$22,IF(25=Inputs!$B$22,Inputs!$B$23,ROUND(Y8*Inputs!$B$24,0)),0) | AA5: =IF(26>=Inputs!$B$22,IF(26=Inputs!$B$22,Inputs!$B$23,ROUND(Z8*Inputs!$B$24,0)),0) | AB5: =IF(27>=Inputs!$B$22,IF(27=Inputs!$B$22,Inputs!$B$23,ROUND(AA8*Inputs!$B$24,0)),0) | AC5: =IF(28>=Inputs!$B$22,IF(28=Inputs!$B$22,Inputs!$B$23,ROUND(AB8*Inputs!$B$24,0)),0) | AD5: =IF(29>=Inputs!$B$22,IF(29=Inputs!$B$22,Inputs!$B$23,ROUND(AC8*Inputs!$B$24,0)),0) | AE5: =IF(30>=Inputs!$B$22,IF(30=Inputs!$B$22,Inputs!$B$23,ROUND(AD8*Inputs!$B$24,0)),0) | AF5: =IF(31>=Inputs!$B$22,IF(31=Inputs!$B$22,Inputs!$B$23,ROUND(AE8*Inputs!$B$24,0)),0) | AG5: =IF(32>=Inputs!$B$22,IF(32=Inputs!$B$22,Inputs!$B$23,ROUND(AF8*Inputs!$B$24,0)),0) | AH5: =IF(33>=Inputs!$B$22,IF(33=Inputs!$B$22,Inputs!$B$23,ROUND(AG8*Inputs!$B$24,0)),0) | AI5: =IF(34>=Inputs!$B$22,IF(34=Inputs!$B$22,Inputs!$B$23,ROUND(AH8*Inputs!$B$24,0)),0) | AJ5: =IF(35>=Inputs!$B$22,IF(35=Inputs!$B$22,Inputs!$B$23,ROUND(AI8*Inputs!$B$24,0)),0) | AK5: =IF(36>=Inputs!$B$22,IF(36=Inputs!$B$22,Inputs!$B$23,ROUND(AJ8*Inputs!$B$24,0)),0) | AL5: =IF(37>=Inputs!$B$22,IF(37=Inputs!$B$22,Inputs!$B$23,ROUND(AK8*Inputs!$B$24,0)),0) | AM5: =IF(38>=Inputs!$B$22,IF(38=Inputs!$B$22,Inputs!$B$23,ROUND(AL8*Inputs!$B$24,0)),0) | AN5: =IF(39>=Inputs!$B$22,IF(39=Inputs!$B$22,Inputs!$B$23,ROUND(AM8*Inputs!$B$24,0)),0) | AO5: =IF(40>=Inputs!$B$22,IF(40=Inputs!$B$22,Inputs!$B$23,ROUND(AN8*Inputs!$B$24,0)),0) | AP5: =IF(41>=Inputs!$B$22,IF(41=Inputs!$B$22,Inputs!$B$23,ROUND(AO8*Inputs!$B$24,0)),0) | AQ5: =IF(42>=Inputs!$B$22,IF(42=Inputs!$B$22,Inputs!$B$23,ROUND(AP8*Inputs!$B$24,0)),0) | AR5: =IF(43>=Inputs!$B$22,IF(43=Inputs!$B$22,Inputs!$B$23,ROUND(AQ8*Inputs!$B$24,0)),0) | AS5: =IF(44>=Inputs!$B$22,IF(44=Inputs!$B$22,Inputs!$B$23,ROUND(AR8*Inputs!$B$24,0)),0) | AT5: =IF(45>=Inputs!$B$22,IF(45=Inputs!$B$22,Inputs!$B$23,ROUND(AS8*Inputs!$B$24,0)),0) | AU5: =IF(46>=Inputs!$B$22,IF(46=Inputs!$B$22,Inputs!$B$23,ROUND(AT8*Inputs!$B$24,0)),0) | AV5: =IF(47>=Inputs!$B$22,IF(47=Inputs!$B$22,Inputs!$B$23,ROUND(AU8*Inputs!$B$24,0)),0) | AW5: =IF(48>=Inputs!$B$22,IF(48=Inputs!$B$22,Inputs!$B$23,ROUND(AV8*Inputs!$B$24,0)),0) | AX5: =IF(49>=Inputs!$B$22,IF(49=Inputs!$B$22,Inputs!$B$23,ROUND(AW8*Inputs!$B$24,0)),0) | AY5: =IF(50>=Inputs!$B$22,IF(50=Inputs!$B$22,Inputs!$B$23,ROUND(AX8*Inputs!$B$24,0)),0) | AZ5: =IF(51>=Inputs!$B$22,IF(51=Inputs!$B$22,Inputs!$B$23,ROUND(AY8*Inputs!$B$24,0)),0) | BA5: =IF(52>=Inputs!$B$22,IF(52=Inputs!$B$22,Inputs!$B$23,ROUND(AZ8*Inputs!$B$24,0)),0)
A6: Churned Seats | B6: =0 | C6: =IF(B8>0,ROUND(B8*Inputs!$B$28/12,0),0) | D6: =IF(C8>0,ROUND(C8*Inputs!$B$28/12,0),0) | E6: =IF(D8>0,ROUND(D8*Inputs!$B$28/12,0),0) | F6: =IF(E8>0,ROUND(E8*Inputs!$B$28/12,0),0) | G6: =IF(F8>0,ROUND(F8*Inputs!$B$28/12,0),0) | H6: =IF(G8>0,ROUND(G8*Inputs!$B$28/12,0),0) | I6: =IF(H8>0,ROUND(H8*Inputs!$B$28/12,0),0) | J6: =IF(I8>0,ROUND(I8*Inputs!$B$28/12,0),0) | ... BA6: =IF(AZ8>0,ROUND(AZ8*Inputs!$B$28/12,0),0)
A7: Net New Seats | B7: =B5-B6 | C7: =C5-C6 | D7: =D5-D6 | E7: =E5-E6 | F7: =F5-F6 | G7: =G5-G6 | H7: =H5-H6 | I7: =I5-I6 | ... BA7: =BA5-BA6
A8: Total Active Seats | B8: =B7 | C8: =B8+C7 | D8: =C8+D7 | E8: =D8+E7 | F8: =E8+F7 | G8: =F8+G7 | H8: =G8+H7 | I8: =H8+I7 | J8: =I8+J7 | ... BA8: =AZ8+BA7
A9: Monthly Subscription Revenue (€) | B9: =B8*B4 | C9: =C8*C4 | D9: =D8*D4 | E9: =E8*E4 | F9: =F8*F4 | G9: =G8*G4 | H9: =H8*H4 | I9: =I8*I4 | ... BA9: =BA8*BA4
A10: Subscription ARR (€) | B10: =B9*12 | C10: =C9*12 | D10: =D9*12 | E10: =E9*12 | F10: =F9*12 | G10: =G9*12 | H10: =H9*12 | I10: =I9*12 | ... BA10: =BA9*12
A12: Neue Enterprise-Deals (Quartal) | B12: =IF(AND(1>=Inputs!$B$25,MOD(1-Inputs!$B$25,3)=0),Inputs!$B$27,0) | C12: =IF(AND(2>=Inputs!$B$25,MOD(2-Inputs!$B$25,3)=0),Inputs!$B$27,0) | D12: =IF(AND(3>=Inputs!$B$25,MOD(3-Inputs!$B$25,3)=0),Inputs!$B$27,0) | E12: =IF(AND(4>=Inputs!$B$25,MOD(4-Inputs!$B$25,3)=0),Inputs!$B$27,0) | F12: =IF(AND(5>=Inputs!$B$25,MOD(5-Inputs!$B$25,3)=0),Inputs!$B$27,0) | G12: =IF(AND(6>=Inputs!$B$25,MOD(6-Inputs!$B$25,3)=0),Inputs!$B$27,0) | H12: =IF(AND(7>=Inputs!$B$25,MOD(7-Inputs!$B$25,3)=0),Inputs!$B$27,0) | I12: =IF(AND(8>=Inputs!$B$25,MOD(8-Inputs!$B$25,3)=0),Inputs!$B$27,0) | J12: =IF(AND(9>=Inputs!$B$25,MOD(9-Inputs!$B$25,3)=0),Inputs!$B$27,0) | K12: =IF(AND(10>=Inputs!$B$25,MOD(10-Inputs!$B$25,3)=0),Inputs!$B$27,0) | L12: =IF(AND(11>=Inputs!$B$25,MOD(11-Inputs!$B$25,3)=0),Inputs!$B$27,0) | M12: =IF(AND(12>=Inputs!$B$25,MOD(12-Inputs!$B$25,3)=0),Inputs!$B$27,0) | N12: =IF(AND(13>=Inputs!$B$25,MOD(13-Inputs!$B$25,3)=0),Inputs!$B$27,0) | O12: =IF(AND(14>=Inputs!$B$25,MOD(14-Inputs!$B$25,3)=0),Inputs!$B$27,0) | P12: =IF(AND(15>=Inputs!$B$25,MOD(15-Inputs!$B$25,3)=0),Inputs!$B$27,0) | Q12: =IF(AND(16>=Inputs!$B$25,MOD(16-Inputs!$B$25,3)=0),Inputs!$B$27,0) | R12: =IF(AND(17>=Inputs!$B$25,MOD(17-Inputs!$B$25,3)=0),Inputs!$B$27,0) | S12: =IF(AND(18>=Inputs!$B$25,MOD(18-Inputs!$B$25,3)=0),Inputs!$B$27,0) | T12: =IF(AND(19>=Inputs!$B$25,MOD(19-Inputs!$B$25,3)=0),Inputs!$B$27,0) | U12: =IF(AND(20>=Inputs!$B$25,MOD(20-Inputs!$B$25,3)=0),Inputs!$B$27,0) | V12: =IF(AND(21>=Inputs!$B$25,MOD(21-Inputs!$B$25,3)=0),Inputs!$B$27,0) | W12: =IF(AND(22>=Inputs!$B$25,MOD(22-Inputs!$B$25,3)=0),Inputs!$B$27,0) | X12: =IF(AND(23>=Inputs!$B$25,MOD(23-Inputs!$B$25,3)=0),Inputs!$B$27,0) | Y12: =IF(AND(24>=Inputs!$B$25,MOD(24-Inputs!$B$25,3)=0),Inputs!$B$27,0) | Z12: =IF(AND(25>=Inputs!$B$25,MOD(25-Inputs!$B$25,3)=0),Inputs!$B$27,0) | AA12: =IF(AND(26>=Inputs!$B$25,MOD(26-Inputs!$B$25,3)=0),Inputs!$B$27,0) | AB12: =IF(AND(27>=Inputs!$B$25,MOD(27-Inputs!$B$25,3)=0),Inputs!$B$27,0) | AC12: =IF(AND(28>=Inputs!$B$25,MOD(28-Inputs!$B$25,3)=0),Inputs!$B$27,0) | AD12: =IF(AND(29>=Inputs!$B$25,MOD(29-Inputs!$B$25,3)=0),Inputs!$B$27,0) | AE12: =IF(AND(30>=Inputs!$B$25,MOD(30-Inputs!$B$25,3)=0),Inputs!$B$27,0) | AF12: =IF(AND(31>=Inputs!$B$25,MOD(31-Inputs!$B$25,3)=0),Inputs!$B$27,0) | AG12: =IF(AND(32>=Inputs!$B$25,MOD(32-Inputs!$B$25,3)=0),Inputs!$B$27,0) | AH12: =IF(AND(33>=Inputs!$B$25,MOD(33-Inputs!$B$25,3)=0),Inputs!$B$27,0) | AI12: =IF(AND(34>=Inputs!$B$25,MOD(34-Inputs!$B$25,3)=0),Inputs!$B$27,0) | AJ12: =IF(AND(35>=Inputs!$B$25,MOD(35-Inputs!$B$25,3)=0),Inputs!$B$27,0) | AK12: =IF(AND(36>=Inputs!$B$25,MOD(36-Inputs!$B$25,3)=0),Inputs!$B$27,0) | AL12: =IF(AND(37>=Inputs!$B$25,MOD(37-Inputs!$B$25,3)=0),Inputs!$B$27,0) | AM12: =IF(AND(38>=Inputs!$B$25,MOD(38-Inputs!$B$25,3)=0),Inputs!$B$27,0) | AN12: =IF(AND(39>=Inputs!$B$25,MOD(39-Inputs!$B$25,3)=0),Inputs!$B$27,0) | AO12: =IF(AND(40>=Inputs!$B$25,MOD(40-Inputs!$B$25,3)=0),Inputs!$B$27,0) | AP12: =IF(AND(41>=Inputs!$B$25,MOD(41-Inputs!$B$25,3)=0),Inputs!$B$27,0) | AQ12: =IF(AND(42>=Inputs!$B$25,MOD(42-Inputs!$B$25,3)=0),Inputs!$B$27,0) | AR12: =IF(AND(43>=Inputs!$B$25,MOD(43-Inputs!$B$25,3)=0),Inputs!$B$27,0) | AS12: =IF(AND(44>=Inputs!$B$25,MOD(44-Inputs!$B$25,3)=0),Inputs!$B$27,0) | AT12: =IF(AND(45>=Inputs!$B$25,MOD(45-Inputs!$B$25,3)=0),Inputs!$B$27,0) | AU12: =IF(AND(46>=Inputs!$B$25,MOD(46-Inputs!$B$25,3)=0),Inputs!$B$27,0) | AV12: =IF(AND(47>=Inputs!$B$25,MOD(47-Inputs!$B$25,3)=0),Inputs!$B$27,0) | AW12: =IF(AND(48>=Inputs!$B$25,MOD(48-Inputs!$B$25,3)=0),Inputs!$B$27,0) | AX12: =IF(AND(49>=Inputs!$B$25,MOD(49-Inputs!$B$25,3)=0),Inputs!$B$27,0) | AY12: =IF(AND(50>=Inputs!$B$25,MOD(50-Inputs!$B$25,3)=0),Inputs!$B$27,0) | AZ12: =IF(AND(51>=Inputs!$B$25,MOD(51-Inputs!$B$25,3)=0),Inputs!$B$27,0) | BA12: =IF(AND(52>=Inputs!$B$25,MOD(52-Inputs!$B$25,3)=0),Inputs!$B$27,0)
A13: Churned Enterprise | B13: =0 | C13: =IF(B14>0,IF(MOD(2,12)=0,ROUND(B14*Inputs!$B$28,0),0),0) | D13: =IF(C14>0,IF(MOD(3,12)=0,ROUND(C14*Inputs!$B$28,0),0),0) | E13: =IF(D14>0,IF(MOD(4,12)=0,ROUND(D14*Inputs!$B$28,0),0),0) | F13: =IF(E14>0,IF(MOD(5,12)=0,ROUND(E14*Inputs!$B$28,0),0),0) | G13: =IF(F14>0,IF(MOD(6,12)=0,ROUND(F14*Inputs!$B$28,0),0),0) | H13: =IF(G14>0,IF(MOD(7,12)=0,ROUND(G14*Inputs!$B$28,0),0),0) | I13: =IF(H14>0,IF(MOD(8,12)=0,ROUND(H14*Inputs!$B$28,0),0),0) | J13: =IF(I14>0,IF(MOD(9,12)=0,ROUND(I14*Inputs!$B$28,0),0),0) | K13: =IF(J14>0,IF(MOD(10,12)=0,ROUND(J14*Inputs!$B$28,0),0),0) | L13: =IF(K14>0,IF(MOD(11,12)=0,ROUND(K14*Inputs!$B$28,0),0),0) | M13: =IF(L14>0,IF(MOD(12,12)=0,ROUND(L14*Inputs!$B$28,0),0),0) | N13: =IF(M14>0,IF(MOD(13,12)=0,ROUND(M14*Inputs!$B$28,0),0),0) | O13: =IF(N14>0,IF(MOD(14,12)=0,ROUND(N14*Inputs!$B$28,0),0),0) | P13: =IF(O14>0,IF(MOD(15,12)=0,ROUND(O14*Inputs!$B$28,0),0),0) | Q13: =IF(P14>0,IF(MOD(16,12)=0,ROUND(P14*Inputs!$B$28,0),0),0) | R13: =IF(Q14>0,IF(MOD(17,12)=0,ROUND(Q14*Inputs!$B$28,0),0),0) | S13: =IF(R14>0,IF(MOD(18,12)=0,ROUND(R14*Inputs!$B$28,0),0),0) | T13: =IF(S14>0,IF(MOD(19,12)=0,ROUND(S14*Inputs!$B$28,0),0),0) | U13: =IF(T14>0,IF(MOD(20,12)=0,ROUND(T14*Inputs!$B$28,0),0),0) | V13: =IF(U14>0,IF(MOD(21,12)=0,ROUND(U14*Inputs!$B$28,0),0),0) | W13: =IF(V14>0,IF(MOD(22,12)=0,ROUND(V14*Inputs!$B$28,0),0),0) | X13: =IF(W14>0,IF(MOD(23,12)=0,ROUND(W14*Inputs!$B$28,0),0),0) | Y13: =IF(X14>0,IF(MOD(24,12)=0,ROUND(X14*Inputs!$B$28,0),0),0) | Z13: =IF(Y14>0,IF(MOD(25,12)=0,ROUND(Y14*Inputs!$B$28,0),0),0) | AA13: =IF(Z14>0,IF(MOD(26,12)=0,ROUND(Z14*Inputs!$B$28,0),0),0) | AB13: =IF(AA14>0,IF(MOD(27,12)=0,ROUND(AA14*Inputs!$B$28,0),0),0) | AC13: =IF(AB14>0,IF(MOD(28,12)=0,ROUND(AB14*Inputs!$B$28,0),0),0) | AD13: =IF(AC14>0,IF(MOD(29,12)=0,ROUND(AC14*Inputs!$B$28,0),0),0) | AE13: =IF(AD14>0,IF(MOD(30,12)=0,ROUND(AD14*Inputs!$B$28,0),0),0) | AF13: =IF(AE14>0,IF(MOD(31,12)=0,ROUND(AE14*Inputs!$B$28,0),0),0) | AG13: =IF(AF14>0,IF(MOD(32,12)=0,ROUND(AF14*Inputs!$B$28,0),0),0) | AH13: =IF(AG14>0,IF(MOD(33,12)=0,ROUND(AG14*Inputs!$B$28,0),0),0) | AI13: =IF(AH14>0,IF(MOD(34,12)=0,ROUND(AH14*Inputs!$B$28,0),0),0) | AJ13: =IF(AI14>0,IF(MOD(35,12)=0,ROUND(AI14*Inputs!$B$28,0),0),0) | AK13: =IF(AJ14>0,IF(MOD(36,12)=0,ROUND(AJ14*Inputs!$B$28,0),0),0) | AL13: =IF(AK14>0,IF(MOD(37,12)=0,ROUND(AK14*Inputs!$B$28,0),0),0) | AM13: =IF(AL14>0,IF(MOD(38,12)=0,ROUND(AL14*Inputs!$B$28,0),0),0) | AN13: =IF(AM14>0,IF(MOD(39,12)=0,ROUND(AM14*Inputs!$B$28,0),0),0) | AO13: =IF(AN14>0,IF(MOD(40,12)=0,ROUND(AN14*Inputs!$B$28,0),0),0) | AP13: =IF(AO14>0,IF(MOD(41,12)=0,ROUND(AO14*Inputs!$B$28,0),0),0) | AQ13: =IF(AP14>0,IF(MOD(42,12)=0,ROUND(AP14*Inputs!$B$28,0),0),0) | AR13: =IF(AQ14>0,IF(MOD(43,12)=0,ROUND(AQ14*Inputs!$B$28,0),0),0) | AS13: =IF(AR14>0,IF(MOD(44,12)=0,ROUND(AR14*Inputs!$B$28,0),0),0) | AT13: =IF(AS14>0,IF(MOD(45,12)=0,ROUND(AS14*Inputs!$B$28,0),0),0) | AU13: =IF(AT14>0,IF(MOD(46,12)=0,ROUND(AT14*Inputs!$B$28,0),0),0) | AV13: =IF(AU14>0,IF(MOD(47,12)=0,ROUND(AU14*Inputs!$B$28,0),0),0) | AW13: =IF(AV14>0,IF(MOD(48,12)=0,ROUND(AV14*Inputs!$B$28,0),0),0) | AX13: =IF(AW14>0,IF(MOD(49,12)=0,ROUND(AW14*Inputs!$B$28,0),0),0) | AY13: =IF(AX14>0,IF(MOD(50,12)=0,ROUND(AX14*Inputs!$B$28,0),0),0) | AZ13: =IF(AY14>0,IF(MOD(51,12)=0,ROUND(AY14*Inputs!$B$28,0),0),0) | BA13: =IF(AZ14>0,IF(MOD(52,12)=0,ROUND(AZ14*Inputs!$B$28,0),0),0)
A14: Active Enterprise Contracts | B14: =B12-B13 | C14: =B14+C12-C13 | D14: =C14+D12-D13 | E14: =D14+E12-E13 | F14: =E14+F12-F13 | G14: =F14+G12-G13 | H14: =G14+H12-H13 | I14: =H14+I12-I13 | J14: =I14+J12-J13 | ... BA14: =AZ14+BA12-BA13
A15: Avg Enterprise ACV (€) | B15: =Inputs!$B$26*(1+Inputs!$B$21)^INT((1-1)/12) | C15: =Inputs!$B$26*(1+Inputs!$B$21)^INT((2-1)/12) | D15: =Inputs!$B$26*(1+Inputs!$B$21)^INT((3-1)/12) | E15: =Inputs!$B$26*(1+Inputs!$B$21)^INT((4-1)/12) | F15: =Inputs!$B$26*(1+Inputs!$B$21)^INT((5-1)/12) | G15: =Inputs!$B$26*(1+Inputs!$B$21)^INT((6-1)/12) | H15: =Inputs!$B$26*(1+Inputs!$B$21)^INT((7-1)/12) | I15: =Inputs!$B$26*(1+Inputs!$B$21)^INT((8-1)/12) | J15: =Inputs!$B$26*(1+Inputs!$B$21)^INT((9-1)/12) | K15: =Inputs!$B$26*(1+Inputs!$B$21)^INT((10-1)/12) | L15: =Inputs!$B$26*(1+Inputs!$B$21)^INT((11-1)/12) | M15: =Inputs!$B$26*(1+Inputs!$B$21)^INT((12-1)/12) | N15: =Inputs!$B$26*(1+Inputs!$B$21)^INT((13-1)/12) | O15: =Inputs!$B$26*(1+Inputs!$B$21)^INT((14-1)/12) | P15: =Inputs!$B$26*(1+Inputs!$B$21)^INT((15-1)/12) | Q15: =Inputs!$B$26*(1+Inputs!$B$21)^INT((16-1)/12) | R15: =Inputs!$B$26*(1+Inputs!$B$21)^INT((17-1)/12) | S15: =Inputs!$B$26*(1+Inputs!$B$21)^INT((18-1)/12) | T15: =Inputs!$B$26*(1+Inputs!$B$21)^INT((19-1)/12) | U15: =Inputs!$B$26*(1+Inputs!$B$21)^INT((20-1)/12) | V15: =Inputs!$B$26*(1+Inputs!$B$21)^INT((21-1)/12) | W15: =Inputs!$B$26*(1+Inputs!$B$21)^INT((22-1)/12) | X15: =Inputs!$B$26*(1+Inputs!$B$21)^INT((23-1)/12) | Y15: =Inputs!$B$26*(1+Inputs!$B$21)^INT((24-1)/12) | Z15: =Inputs!$B$26*(1+Inputs!$B$21)^INT((25-1)/12) | AA15: =Inputs!$B$26*(1+Inputs!$B$21)^INT((26-1)/12) | AB15: =Inputs!$B$26*(1+Inputs!$B$21)^INT((27-1)/12) | AC15: =Inputs!$B$26*(1+Inputs!$B$21)^INT((28-1)/12) | AD15: =Inputs!$B$26*(1+Inputs!$B$21)^INT((29-1)/12) | AE15: =Inputs!$B$26*(1+Inputs!$B$21)^INT((30-1)/12) | AF15: =Inputs!$B$26*(1+Inputs!$B$21)^INT((31-1)/12) | AG15: =Inputs!$B$26*(1+Inputs!$B$21)^INT((32-1)/12) | AH15: =Inputs!$B$26*(1+Inputs!$B$21)^INT((33-1)/12) | AI15: =Inputs!$B$26*(1+Inputs!$B$21)^INT((34-1)/12) | AJ15: =Inputs!$B$26*(1+Inputs!$B$21)^INT((35-1)/12) | AK15: =Inputs!$B$26*(1+Inputs!$B$21)^INT((36-1)/12) | AL15: =Inputs!$B$26*(1+Inputs!$B$21)^INT((37-1)/12) | AM15: =Inputs!$B$26*(1+Inputs!$B$21)^INT((38-1)/12) | AN15: =Inputs!$B$26*(1+Inputs!$B$21)^INT((39-1)/12) | AO15: =Inputs!$B$26*(1+Inputs!$B$21)^INT((40-1)/12) | AP15: =Inputs!$B$26*(1+Inputs!$B$21)^INT((41-1)/12) | AQ15: =Inputs!$B$26*(1+Inputs!$B$21)^INT((42-1)/12) | AR15: =Inputs!$B$26*(1+Inputs!$B$21)^INT((43-1)/12) | AS15: =Inputs!$B$26*(1+Inputs!$B$21)^INT((44-1)/12) | AT15: =Inputs!$B$26*(1+Inputs!$B$21)^INT((45-1)/12) | AU15: =Inputs!$B$26*(1+Inputs!$B$21)^INT((46-1)/12) | AV15: =Inputs!$B$26*(1+Inputs!$B$21)^INT((47-1)/12) | AW15: =Inputs!$B$26*(1+Inputs!$B$21)^INT((48-1)/12) | AX15: =Inputs!$B$26*(1+Inputs!$B$21)^INT((49-1)/12) | AY15: =Inputs!$B$26*(1+Inputs!$B$21)^INT((50-1)/12) | AZ15: =Inputs!$B$26*(1+Inputs!$B$21)^INT((51-1)/12) | BA15: =Inputs!$B$26*(1+Inputs!$B$21)^INT((52-1)/12)
A16: Enterprise Monthly Revenue (€) | B16: =B14*B15/12 | C16: =C14*C15/12 | D16: =D14*D15/12 | E16: =E14*E15/12 | F16: =F14*F15/12 | G16: =G14*G15/12 | H16: =H14*H15/12 | I16: =I14*I15/12 | ... BA16: =BA14*BA15/12
A17: ── RECURRING REVENUE (SaaS-Metriken, ohne Consulting) ──
A18: MRR – Monthly Recurring Revenue (Lizenzen) | B18: =B9+B16 | C18: =C9+C16 | D18: =D9+D16 | E18: =E9+E16 | F18: =F9+F16 | G18: =G9+G16 | H18: =H9+H16 | I18: =I9+I16 | ... BA18: =BA9+BA16
A19: ARR – Annual Recurring Revenue (Lizenzen = MRR × 12) | B19: =B18*12 | C19: =C18*12 | D19: =D18*12 | E19: =E18*12 | F19: =F18*12 | G19: =G18*12 | H19: =H18*12 | I19: =I18*12 | ... BA19: =BA18*12
A20: Total Monthly Revenue (Lizenzen + Consulting) | B20: =B18+B29 | C20: =C18+C29 | D20: =D18+D29 | E20: =E18+E29 | F20: =F18+F29 | G20: =G18+G29 | H20: =H18+H29 | I20: =I18+I29 | ... BA20: =BA18+BA29
A21: ARR Growth % (MoM) | B21: ="" | C21: =IFERROR(C19/B19-1,"") | D21: =IFERROR(D19/C19-1,"") | E21: =IFERROR(E19/D19-1,"") | F21: =IFERROR(F19/E19-1,"") | G21: =IFERROR(G19/F19-1,"") | H21: =IFERROR(H19/G19-1,"") | I21: =IFERROR(I19/H19-1,"") | J21: =IFERROR(J19/I19-1,"") | ... BA21: =IFERROR(BA19/AZ19-1,"")
A22: Net Revenue Retention % | B22: =Inputs!$B$29 | C22: =Inputs!$B$29 | D22: =Inputs!$B$29 | E22: =Inputs!$B$29 | F22: =Inputs!$B$29 | G22: =Inputs!$B$29 | H22: =Inputs!$B$29 | I22: =Inputs!$B$29 | ... BA22: =Inputs!$B$29
A23: Gross New ARR (€) | B23: =B5*B4*12+B12*B15 | C23: =C5*C4*12+C12*C15 | D23: =D5*D4*12+D12*D15 | E23: =E5*E4*12+E12*E15 | F23: =F5*F4*12+F12*F15 | G23: =G5*G4*12+G12*G15 | H23: =H5*H4*12+H12*H15 | I23: =I5*I4*12+I12*I15 | ... BA23: =BA5*BA4*12+BA12*BA15
A25: ── CONSULTING REVENUE ──
A26: Active Subscription Customers | B26: =IF(B8>0, MAX(1, ROUND(B8/Inputs!$B$23, 0)), 0) | C26: =IF(C8>0, MAX(1, ROUND(C8/Inputs!$B$23, 0)), 0) | D26: =IF(D8>0, MAX(1, ROUND(D8/Inputs!$B$23, 0)), 0) | E26: =IF(E8>0, MAX(1, ROUND(E8/Inputs!$B$23, 0)), 0) | F26: =IF(F8>0, MAX(1, ROUND(F8/Inputs!$B$23, 0)), 0) | G26: =IF(G8>0, MAX(1, ROUND(G8/Inputs!$B$23, 0)), 0) | H26: =IF(H8>0, MAX(1, ROUND(H8/Inputs!$B$23, 0)), 0) | I26: =IF(I8>0, MAX(1, ROUND(I8/Inputs!$B$23, 0)), 0) | ... BA26: =IF(BA8>0, MAX(1, ROUND(BA8/Inputs!$B$23, 0)), 0)
A27: Total Active Customers (inkl. Enterprise) | B27: =B26+B14 | C27: =C26+C14 | D27: =D26+D14 | E27: =E26+E14 | F27: =F26+F14 | G27: =G26+G14 | H27: =H26+H14 | I27: =I26+I14 | ... BA27: =BA26+BA14
A28: Consulting-Tage/Monat [ab Startmonat; Kunden × Wskt. × Tage/Einsatz] | B28: =IF(1>=Inputs!$B$141,B27*Inputs!$B$139*Inputs!$B$140,0) | C28: =IF(2>=Inputs!$B$141,C27*Inputs!$B$139*Inputs!$B$140,0) | D28: =IF(3>=Inputs!$B$141,D27*Inputs!$B$139*Inputs!$B$140,0) | E28: =IF(4>=Inputs!$B$141,E27*Inputs!$B$139*Inputs!$B$140,0) | F28: =IF(5>=Inputs!$B$141,F27*Inputs!$B$139*Inputs!$B$140,0) | G28: =IF(6>=Inputs!$B$141,G27*Inputs!$B$139*Inputs!$B$140,0) | H28: =IF(7>=Inputs!$B$141,H27*Inputs!$B$139*Inputs!$B$140,0) | I28: =IF(8>=Inputs!$B$141,I27*Inputs!$B$139*Inputs!$B$140,0) | J28: =IF(9>=Inputs!$B$141,J27*Inputs!$B$139*Inputs!$B$140,0) | K28: =IF(10>=Inputs!$B$141,K27*Inputs!$B$139*Inputs!$B$140,0) | L28: =IF(11>=Inputs!$B$141,L27*Inputs!$B$139*Inputs!$B$140,0) | M28: =IF(12>=Inputs!$B$141,M27*Inputs!$B$139*Inputs!$B$140,0) | N28: =IF(13>=Inputs!$B$141,N27*Inputs!$B$139*Inputs!$B$140,0) | O28: =IF(14>=Inputs!$B$141,O27*Inputs!$B$139*Inputs!$B$140,0) | P28: =IF(15>=Inputs!$B$141,P27*Inputs!$B$139*Inputs!$B$140,0) | Q28: =IF(16>=Inputs!$B$141,Q27*Inputs!$B$139*Inputs!$B$140,0) | R28: =IF(17>=Inputs!$B$141,R27*Inputs!$B$139*Inputs!$B$140,0) | S28: =IF(18>=Inputs!$B$141,S27*Inputs!$B$139*Inputs!$B$140,0) | T28: =IF(19>=Inputs!$B$141,T27*Inputs!$B$139*Inputs!$B$140,0) | U28: =IF(20>=Inputs!$B$141,U27*Inputs!$B$139*Inputs!$B$140,0) | V28: =IF(21>=Inputs!$B$141,V27*Inputs!$B$139*Inputs!$B$140,0) | W28: =IF(22>=Inputs!$B$141,W27*Inputs!$B$139*Inputs!$B$140,0) | X28: =IF(23>=Inputs!$B$141,X27*Inputs!$B$139*Inputs!$B$140,0) | Y28: =IF(24>=Inputs!$B$141,Y27*Inputs!$B$139*Inputs!$B$140,0) | Z28: =IF(25>=Inputs!$B$141,Z27*Inputs!$B$139*Inputs!$B$140,0) | AA28: =IF(26>=Inputs!$B$141,AA27*Inputs!$B$139*Inputs!$B$140,0) | AB28: =IF(27>=Inputs!$B$141,AB27*Inputs!$B$139*Inputs!$B$140,0) | AC28: =IF(28>=Inputs!$B$141,AC27*Inputs!$B$139*Inputs!$B$140,0) | AD28: =IF(29>=Inputs!$B$141,AD27*Inputs!$B$139*Inputs!$B$140,0) | AE28: =IF(30>=Inputs!$B$141,AE27*Inputs!$B$139*Inputs!$B$140,0) | AF28: =IF(31>=Inputs!$B$141,AF27*Inputs!$B$139*Inputs!$B$140,0) | AG28: =IF(32>=Inputs!$B$141,AG27*Inputs!$B$139*Inputs!$B$140,0) | AH28: =IF(33>=Inputs!$B$141,AH27*Inputs!$B$139*Inputs!$B$140,0) | AI28: =IF(34>=Inputs!$B$141,AI27*Inputs!$B$139*Inputs!$B$140,0) | AJ28: =IF(35>=Inputs!$B$141,AJ27*Inputs!$B$139*Inputs!$B$140,0) | AK28: =IF(36>=Inputs!$B$141,AK27*Inputs!$B$139*Inputs!$B$140,0) | AL28: =IF(37>=Inputs!$B$141,AL27*Inputs!$B$139*Inputs!$B$140,0) | AM28: =IF(38>=Inputs!$B$141,AM27*Inputs!$B$139*Inputs!$B$140,0) | AN28: =IF(39>=Inputs!$B$141,AN27*Inputs!$B$139*Inputs!$B$140,0) | AO28: =IF(40>=Inputs!$B$141,AO27*Inputs!$B$139*Inputs!$B$140,0) | AP28: =IF(41>=Inputs!$B$141,AP27*Inputs!$B$139*Inputs!$B$140,0) | AQ28: =IF(42>=Inputs!$B$141,AQ27*Inputs!$B$139*Inputs!$B$140,0) | AR28: =IF(43>=Inputs!$B$141,AR27*Inputs!$B$139*Inputs!$B$140,0) | AS28: =IF(44>=Inputs!$B$141,AS27*Inputs!$B$139*Inputs!$B$140,0) | AT28: =IF(45>=Inputs!$B$141,AT27*Inputs!$B$139*Inputs!$B$140,0) | AU28: =IF(46>=Inputs!$B$141,AU27*Inputs!$B$139*Inputs!$B$140,0) | AV28: =IF(47>=Inputs!$B$141,AV27*Inputs!$B$139*Inputs!$B$140,0) | AW28: =IF(48>=Inputs!$B$141,AW27*Inputs!$B$139*Inputs!$B$140,0) | AX28: =IF(49>=Inputs!$B$141,AX27*Inputs!$B$139*Inputs!$B$140,0) | AY28: =IF(50>=Inputs!$B$141,AY27*Inputs!$B$139*Inputs!$B$140,0) | AZ28: =IF(51>=Inputs!$B$141,AZ27*Inputs!$B$139*Inputs!$B$140,0) | BA28: =IF(52>=Inputs!$B$141,BA27*Inputs!$B$139*Inputs!$B$140,0)
A29: Consulting Revenue (€/Monat) [= Tage/Mo × Tagessatz] | B29: =B28*Inputs!$B$138 | C29: =C28*Inputs!$B$138 | D29: =D28*Inputs!$B$138 | E29: =E28*Inputs!$B$138 | F29: =F28*Inputs!$B$138 | G29: =G28*Inputs!$B$138 | H29: =H28*Inputs!$B$138 | I29: =I28*Inputs!$B$138 | ... BA29: =BA28*Inputs!$B$138
A31: ℹ Hinweis MRR/ARR vs. Total Revenue: MRR/ARR (Z18/19) = ausschließlich wiederkehrende Lizenzumsätze (Subscription Seats + Enterprise-Verträge). Consulting ist projektbezogen, nicht-wiederkehrend → kein Bestandteil von MRR/ARR (SaaS-Standard: SaaStr/OpenView/a16z). Total Monthly Revenue (Z20) = MRR + Consulting → fließt in P&L TOTAL REVENUE.

Sheet Costs
A1: KOSTENDETAILS
