Workbook

Sheet Anleitung
A1: LoopforgeLab GmbH – Financial Projection Model
A3: Projektionszeitraum: 52 Monate (ca. 4,3 Jahre)
A5: INHALTSVERZEICHNIS
A6: Sheet 1: Anleitung – Diese Seite mit Übersicht und Legende
A7: Sheet 2: Inputs – Zentrale Eingabewerte (HIER STARTEN)
A8: Sheet 3: P&L – Gewinn- und Verlustrechnung (monatlich + jährlich)
A9: Sheet 4: Revenue – Detaillierte Umsatzmodellierung
A10: Sheet 5: Costs – Detaillierte Kostenaufschlüsselung
A11: Sheet 6: Balance Sheet – Vereinfachte Bilanz
A12: Sheet 7: Cash Flow – Kapitalflussrechnung mit Runway
A14: FARBCODIERUNG
A15: Blau | B15: Editierbare Eingabefelder
A16: Schwarz | B16: Formeln – nicht manuell ändern
A17: Grün | B17: Verweise auf andere Sheets
A18: Gelb hinterlegt | B18: Kritische Annahmen
A20: KURZANLEITUNG
A21: 1. Gehen Sie zum Sheet 'Inputs' und passen Sie alle blau markierten Werte an.
A22: 2. Alle anderen Sheets berechnen sich automatisch aus den Inputs.
A23: 3. Prüfen Sie die P&L, Revenue und Cash Flow Sheets auf Plausibilität.
A24: 4. Achten Sie auf rot markierte Warnungen (z.B. Runway < 6 Monate).
A25: 5. Exportieren Sie relevante Sheets als PDF für Investoren-Präsentationen.
A27: DISCLAIMER: Diese Projektion dient ausschließlich der Planung.
A28: Tatsächliche Ergebnisse können erheblich abweichen. Keine Garantie.

Sheet Inputs
A1: ZENTRALE EINGABEWERTE | B1: Wert | C1: Erklärung / Hinweis | D1: Bemerkungen
A3: ALLGEMEINE EINSTELLUNGEN
A4: Firmenname | B4: LoopforgeLab GmbH | C4: Name des Unternehmens
A5: Startdatum | B5: 46113 | C5: Beginn der Projektionen
A6: Währung | B6: EUR | C6: EUR für DACH-Startups
A7: Steuersatz | B7: 0.3 | C7: KSt + GewSt (~30% in DE) | D7: Übernahme des Standardsatzes (KSt + GewSt in Deutschland).
A9: FINANZIERUNGSRUNDEN
A10: Ideation Phase | B10: 90000 | C10: Typisch: 100.000-500.000€ | D10: Phase: 1.4.26 bis 15.7.2026 MVP-Anschubfinanzierung; stellt keine Unternehmensbewertung dar.
A11: Ideation Phase | B11: 1 | C11: Monat der Einzahlung | D11: MVP-Entwicklung und IP-Aufbau starten unmittelbar.
A12: Pre-Seed Betrag | B12: 1500000 | C12: Typisch: 500.000-2.000.000€ | D12: Pre-Seed Phase ab VC Pitch im Juli '26 (1.5M-3M Bewertung).
A13: Pre-Seed Monat | B13: 5 | C13: Typisch: Monat 5 | D13: Juli 2026 entspricht Monat 5 Fokus auf Pilot-Traction.
A14: Seed Betrag | B14: 6000000 | C14: Typisch: 3.000.000-10.000.000€ | D14: Abhängig von Pilotprojekten und Reife des Produktes
A15: Seed Monat | B15: 17 | C15: Typisch: Monat 17 | D15: Geplant für Mitte 2027.
A16: Series A Betrag | B16: 15000000 | C16: Typisch: 10.000.000-25.000.000€ | D16: Vorerst unverändert als langfristige Wachstumsambition.
A17: Series A Monat | B17: 35 | C17: Typisch: Monat 35 | D17: Geplant für Herbst 2028.
A19: REVENUE-ANNAHMEN (SaaS/ARR)
A20: Startpreis pro Seat/Jahr | B20: 12000 | C20: Jährliche Lizenzgebühr pro Nutzer | D20: 1. Realistisch? Hängt auch ab vom Business Modell..Pricing basierend auf Wettbewerb oder auf voraussichtlichem Einsparpotential? 2. weitere Erlösquellen? Beratung? Implementierungsaufwand? Hybrid-Modell: Deckt Fixkosten und partizipiert am TCO-Einsparwert. [1] | E20: 2. Regulatory Moat (DPP): JE nach Branche (hier: Annahme von neuen Zielbranche in Bezuf auf DPP Verpflichtung) Die Zielbranchen Batterien und Elektronik unterliegen ab 2027 der DPP-Pflicht. Dies rechtfertigt höhere Preise und eine stärkere NRR, da LFL hiermit zur "Compliance Engine" des Kunden wird. -->"Compliance" könnte aber auch durch andere Benefits ersetzt werden
A21: Preiserhöhung/Jahr | B21: 0.08 | C21: Typisch: 3-5% p.a. | D21: Standard für AI-SaaS 2026 (Kompensation Inferenz/Innovation). [4]
A22: Erste zahlende Kunden Monat | B22: 9 | C22: Wann erster Umsatz? | D22: Erster Umsatz in Monat 8 (Start: 04/26)…Realistisch? Wie lange Lead-Time? Zielkunden? Beachhead-Market? Weitere Begründung: wenn im Automotivebereich: Puffer für Sales-Zyklen (9-12 Mon.) und TISAX im Mittelstand. [1
A23: Initiale Seats | B23: 5 | C23: Anzahl Seats beim ersten Kunden | D23: Realistisch? Hängt von Kundengrösse ab. Implementierungsaufwand je Kunde mit einkalkulieren weitere Aspekte: Kalkulieren mit 1-2 Projekten/ Start mit Pilotprojekten (Werke) zur ROI-Validierung ("Land&Expand")
A24: Monatliche Seat-Wachstumsrate | B24: 0.05 | C24: Wachstum neue Seats/Monat | D24: -->hier eine Annahme bzgll Vertriebsplanung treffen. Wie hoch ist die Zahl der Verkauften Sitze nach 1, 2, 3 Jahren? Gibt es noch andere Erlösströme? ALTERNATIVE: Account-basierte Planng: Wechsel auf "Stufenfunktion" beim Aufbau des Geschäfts (Roll-out pro Werk statt linearer Rate)
A25: Enterprise-Deals ab Monat | B25: 24 | C25: Wann starten große Verträge? Wenn Automotive: Verschiebung durch längere Technical Validation und Compliance-Hürden. | E25: 3. Vertriebsrealismus: Der Start des Umsatzes wurde nach hinten geschoben da der industrielle Mittelstand ("Hidden Champions") langsame Entscheidungsprozesse und hohe Sicherheitsanforderungen (TISAX) hat. Die Zeit bis zum Juli 2026 wird für die Validierung der TCO-Einsparungen (Ausschuss-Reduktion) bei Pilotkunden genutzt.
A26: Durchschnitt Enterprise ARR | B26: 150000 | C26: Typisch: 50.000-200.000€/Jahr | D26: Höheres Volumen durch Tiefe der Integration: hier Annahme von weiteren Benefits wie Einbeziehung von DPP & Sustainability
A27: Enterprise Deals pro Quartal | B27: 1 | C27: Neue Enterprise-Deals pro Quartal
A28: Jährliche Churn Rate | B28: 0.08 | C28: Typisch SaaS: 5-10% | D28: Konservative Planung für komplexe industrielle Buying Center. Plausibel im Mittel (höher im Pilot-Jahr 1; niedriger ab Jahr 3).
A29: Net Revenue Retention | B29: 1.18 | C29: Expansion - Churn, typisch: 100-120% | D29: Erklärung: Realisierbar durch DPP-Zusatzmodule und Material-Analytics-Upgrades, ergo weiteren monetarisierbaren Benefits
A31: GEHÄLTER (Brutto/Jahr)
A32: CEO Gehalt | B32: 72000 | C32: Typisch Startup: 60.000-90.000€ | D32: Gründer-Satz Pre-Seed); Anpassung ab Seed-Runde. Muss noch genauer präzisiert werden
A33: CTO Gehalt | B33: 72000 | C33: Typisch Startup: 60.000-90.000€ | D33: Gründer-Satz Pre-Seed); Anpassung ab Seed-Runde. Muss noch genauer präzisiert werden
A34: CCO Gehalt | B34: 72000 | C34: Typisch Startup: 60.000-90.000€ | D34: Gründer-Satz Pre-Seed); Anpassung ab Seed-Runde. Muss noch genauer präzisiert werden
A35: Senior Engineer Gehalt | B35: 90000 | C35: Typisch: 70.000-90.000€ | D35: Berliner Tech-Benchmark 2025/26 für Senior-Fullstack/Backends. [9]
A36: Junior Engineer Gehalt | B36: 60000 | C36: Typisch: 45.000-60.000€ | D36: Anpassung an gestiegene Einstiegsgehälter für Top-Tech-Talente. [9]
A37: ML/AI Engineer Gehalt | B37: 110000 | C37: Typisch: 75.000-100.000€ | D37: Höchste Marktnachfrage; KI-Experten in Berlin deutlich über SWE-Schnitt. [10]
A38: Product Manager Gehalt | B38: 80000 | C38: Typisch: 65.000-85.000€ | D38: Durchschnitt für Technical PMs (Industrial AI) am Standort Berlin
A39: Sales Representative Gehalt | B39: 130000 | C39: Typisch: 50.000-70.000€ + Provision | D39: Split 50/50 (65k fix + 65k var); zwingend für Enterprise-Vertrieb. [12
A40: Marketing Manager Gehalt | B40: 65000 | C40: Typisch: 55.000-75.000€ | D40: Anpassung an Marktniveau für B2B-Industrie-Spezialisten.
A41: Customer Success Gehalt | B41: 65000 | C41: Typisch: 45.000-60.000€ | D41: Shift hin zu Solution Architect Profil (techn. Implementierung). [13]
A42: Office/Admin Gehalt | B42: 45000 | C42: Typisch: 40.000-50.000€ | D42: (marktüblich für Berlin).
A43: Jährliche Gehaltserhöhung | B43: 0.05 | C43: Typisch: 3-5% | D43: Berücksichtigt Inflations- und Kompetenzentwicklung im Tech-Sektor.
A44: Lohnnebenkosten | B44: 0.21 | C44: AG-Anteil Sozialversicherung ~20-21% | D44: Übernahme des gesetzlichen AG-Anteils.
...

Sheet P&L
A1: GEWINN- UND VERLUSTRECHNUNG (P&L)
A3: Position | B3: M1 | C3: M2 | D3: M3 | E3: M4 | F3: M5 | G3: M6 | H3: M7 | I3: M8 | J3: M9 | K3: M10 | L3: M11 | M3: M12 | N3: M13 | O3: M14 | P3: M15 | Q3: M16 | R3: M17 | S3: M18 | T3: M19 | U3: M20 | V3: M21 | W3: M22 | X3: M23 | Y3: M24 | Z3: M25 | AA3: M26 | AB3: M27 | AC3: M28 | AD3: M29 | AE3: M30 | AF3: M31 | AG3: M32 | AH3: M33 | AI3: M34 | AJ3: M35 | AK3: M36 | AL3: M37 | AM3: M38 | AN3: M39 | AO3: M40 | AP3: M41 | AQ3: M42 | AR3: M43 | AS3: M44 | AT3: M45 | AU3: M46 | AV3: M47 | AW3: M48 | AX3: M49 | AY3: M50 | AZ3: M51 | BA3: M52
A4: REVENUE
A5: Subscription Revenue | B5: =Revenue!B9 -> 0 | C5: =Revenue!C9 -> 0 | D5: =Revenue!D9 -> 0 | E5: =Revenue!E9 -> 0 | F5: =Revenue!F9 -> 0 | G5: =Revenue!G9 -> 0 | H5: =Revenue!H9 -> 0 | I5: =Revenue!I9 -> 0 | ... BA5: =Revenue!BA9 -> 6802.4448
A6: Enterprise Revenue | B6: =Revenue!B16 -> 0 | C6: =Revenue!C16 -> 0 | D6: =Revenue!D16 -> 0 | E6: =Revenue!E16 -> 0 | F6: =Revenue!F16 -> 0 | G6: =Revenue!G16 -> 0 | H6: =Revenue!H16 -> 0 | I6: =Revenue!I16 -> 0 | ... BA6: =Revenue!BA16 -> 153055.01
A7: TOTAL REVENUE | B7: =B5+B6 -> 0 | C7: =C5+C6 -> 0 | D7: =D5+D6 -> 0 | E7: =E5+E6 -> 0 | F7: =F5+F6 -> 0 | G7: =G5+G6 -> 0 | H7: =H5+H6 -> 0 | I7: =I5+I6 -> 0 | ... BA7: =BA5+BA6 -> 159857.45
A9: COST OF GOODS SOLD (COGS)
A10: Cloud Hosting (variable) | B10: =Costs!B82 -> 0 | C10: =Costs!C82 -> 0 | D10: =Costs!D82 -> 0 | E10: =Costs!E82 -> 0 | F10: =Costs!F82 -> 0 | G10: =Costs!G82 -> 0 | H10: =Costs!H82 -> 0 | I10: =Costs!I82 -> 0 | ... BA10: =Costs!BA82 -> 250
A11: AI/ML API Kosten | B11: =Costs!B83 -> 1000 | C11: =Costs!C83 -> 1050 | D11: =Costs!D83 -> 1102.5 | E11: =Costs!E83 -> 1157.625 | F11: =Costs!F83 -> 1215.5062 | G11: =Costs!G83 -> 1276.2816 | H11: =Costs!H83 -> 1340.0956 | I11: =Costs!I83 -> 1407.1004 | ... BA11: =Costs!BA83 -> 12040.77
A12: Payment Processing | B12: =Costs!B128 -> 0 | C12: =Costs!C128 -> 0 | D12: =Costs!D128 -> 0 | E12: =Costs!E128 -> 0 | F12: =Costs!F128 -> 0 | G12: =Costs!G128 -> 0 | H12: =Costs!H128 -> 0 | I12: =Costs!I128 -> 0 | ... BA12: =Costs!BA128 -> 3996.4363
A13: TOTAL COGS | B13: =SUM(B10:B12) -> 1000 | C13: =SUM(C10:C12) -> 1050 | D13: =SUM(D10:D12) -> 1102.5 | E13: =SUM(E10:E12) -> 1157.625 | F13: =SUM(F10:F12) -> 1215.5062 | G13: =SUM(G10:G12) -> 1276.2816 | H13: =SUM(H10:H12) -> 1340.0956 | I13: =SUM(I10:I12) -> 1407.1004 | ... BA13: =SUM(BA10:BA12) -> 16287.206
A15: GROSS PROFIT | B15: =B7-B13 -> -1000 | C15: =C7-C13 -> -1050 | D15: =D7-D13 -> -1102.5 | E15: =E7-E13 -> -1157.625 | F15: =F7-F13 -> -1215.5062 | G15: =G7-G13 -> -1276.2816 | H15: =H7-H13 -> -1340.0956 | I15: =I7-I13 -> -1407.1004 | ... BA15: =BA7-BA13 -> 143570.25
A16: Gross Margin % | B16: =IFERROR(B15/B7,0) -> 0 | C16: =IFERROR(C15/C7,0) -> 0 | D16: =IFERROR(D15/D7,0) -> 0 | E16: =IFERROR(E15/E7,0) -> 0 | F16: =IFERROR(F15/F7,0) -> 0 | G16: =IFERROR(G15/G7,0) -> 0 | H16: =IFERROR(H15/H7,0) -> 0 | I16: =IFERROR(I15/I7,0) -> 0 | ... BA16: =IFERROR(BA15/BA7,0) -> 0.89811419
A18: OPERATING EXPENSES
A19: Total Personnel | B19: =Costs!B78 -> 21780 | C19: =Costs!C78 -> 21780 | D19: =Costs!D78 -> 21780 | E19: =Costs!E78 -> 21780 | F19: =Costs!F78 -> 21780 | G19: =Costs!G78 -> 21780 | H19: =Costs!H78 -> 30855 | I19: =Costs!I78 -> 41946.667 | ... BA19: =Costs!BA78 -> 366587.57
A20: Total Technology | B20: =Costs!B87 -> 6816.6667 | C20: =Costs!C87 -> 6866.6667 | D20: =Costs!D87 -> 6919.1667 | E20: =Costs!E87 -> 6974.2917 | F20: =Costs!F87 -> 7032.1729 | G20: =Costs!G87 -> 7092.9482 | H20: =Costs!H87 -> 7256.7623 | I20: =Costs!I87 -> 7423.7671 | ... BA20: =Costs!BA87 -> 21307.436
A21: Total Office/Facilities | B21: =Costs!B94 -> 2040 | C21: =Costs!C94 -> 2040 | D21: =Costs!D94 -> 2040 | E21: =Costs!E94 -> 2040 | F21: =Costs!F94 -> 2040 | G21: =Costs!G94 -> 2040 | H21: =Costs!H94 -> 2070 | I21: =Costs!I94 -> 2100 | ... BA21: =Costs!BA94 -> 6000
A22: Total Professional Services | B22: =Costs!B101 -> 16883.333 | C22: =Costs!C101 -> 1883.3333 | D22: =Costs!D101 -> 1883.3333 | E22: =Costs!E101 -> 1883.3333 | F22: =Costs!F101 -> 16883.333 | G22: =Costs!G101 -> 1883.3333 | H22: =Costs!H101 -> 1883.3333 | I22: =Costs!I101 -> 1883.3333 | ... BA22: =Costs!BA101 -> 2883.3333
A23: Total Insurance & Bank | B23: =Costs!B108 -> 591.66667 | C23: =Costs!C108 -> 591.66667 | D23: =Costs!D108 -> 591.66667 | E23: =Costs!E108 -> 591.66667 | F23: =Costs!F108 -> 591.66667 | G23: =Costs!G108 -> 591.66667 | H23: =Costs!H108 -> 591.66667 | I23: =Costs!I108 -> 591.66667 | ... BA23: =Costs!BA108 -> 591.66667
A24: Total Marketing & Sales | B24: =Costs!B117 -> 4383.3333 | C24: =Costs!C117 -> 4408.3333 | D24: =Costs!D117 -> 4434.5833 | E24: =Costs!E117 -> 4462.1458 | F24: =Costs!F117 -> 4491.0865 | G24: =Costs!G117 -> 4521.4741 | H24: =Costs!H117 -> 4553.3812 | I24: =Costs!I117 -> 4586.8835 | ... BA24: =Costs!BA117 -> 12403.718
A25: Total Other OpEx | B25: =Costs!B125 -> 11191.667 | C25: =Costs!C125 -> 1291.6667 | D25: =Costs!D125 -> 1291.6667 | E25: =Costs!E125 -> 1291.6667 | F25: =Costs!F125 -> 1291.6667 | G25: =Costs!G125 -> 1291.6667 | H25: =Costs!H125 -> 4966.6667 | I25: =Costs!I125 -> 5341.6667 | ... BA25: =Costs!BA125 -> 13291.667
A26: Contingency/Buffer | B26: =Costs!B130 -> 3184.3333 | C26: =Costs!C130 -> 1943.0833 | D26: =Costs!D130 -> 1947.0208 | E26: =Costs!E130 -> 1951.1552 | F26: =Costs!F130 -> 2705.4963 | G26: =Costs!G130 -> 1960.0545 | H26: =Costs!H130 -> 2608.8405 | I26: =Costs!I130 -> 3193.6992 | ... BA26: =Costs!BA130 -> 21153.27
A27: TOTAL OPERATING EXPENSES | B27: =SUM(B19:B26) -> 66871 | C27: =SUM(C19:C26) -> 40804.75 | D27: =SUM(D19:D26) -> 40887.438 | E27: =SUM(E19:E26) -> 40974.259 | F27: =SUM(F19:F26) -> 56815.422 | G27: =SUM(G19:G26) -> 41161.143 | H27: =SUM(H19:H26) -> 54785.651 | I27: =SUM(I19:I26) -> 67067.683 | ... BA27: =SUM(BA19:BA26) -> 444218.66
A29: EBITDA | B29: =B15-B27 -> -67871 | C29: =C15-C27 -> -41854.75 | D29: =D15-D27 -> -41989.938 | E29: =E15-E27 -> -42131.884 | F29: =F15-F27 -> -58030.929 | G29: =G15-G27 -> -42437.425 | H29: =H15-H27 -> -56125.746 | I29: =I15-I27 -> -68474.784 | ... BA29: =BA15-BA27 -> -300648.41
A30: EBITDA Margin % | B30: =IFERROR(B29/B7,0) -> 0 | C30: =IFERROR(C29/C7,0) -> 0 | D30: =IFERROR(D29/D7,0) -> 0 | E30: =IFERROR(E29/E7,0) -> 0 | F30: =IFERROR(F29/F7,0) -> 0 | G30: =IFERROR(G29/G7,0) -> 0 | H30: =IFERROR(H29/H7,0) -> 0 | I30: =IFERROR(I29/I7,0) -> 0 | ... BA30: =IFERROR(BA29/BA7,0) -> -1.8807282
A32: Depreciation & Amortization | B32: =Costs!B123/Inputs!$B$134/12 -> 275 | C32: =Costs!C123/Inputs!$B$134/12 -> 0 | D32: =Costs!D123/Inputs!$B$134/12 -> 0 | E32: =Costs!E123/Inputs!$B$134/12 -> 0 | F32: =Costs!F123/Inputs!$B$134/12 -> 0 | G32: =Costs!G123/Inputs!$B$134/12 -> 0 | H32: =Costs!H123/Inputs!$B$134/12 -> 91.666667 | I32: =Costs!I123/Inputs!$B$134/12 -> 91.666667 | ... BA32: =Costs!BA123/Inputs!$B$134/12 -> 0
A34: EBIT (Operating Income) | B34: =B29-B32 -> -68146 | C34: =C29-C32 -> -41854.75 | D34: =D29-D32 -> -41989.938 | E34: =E29-E32 -> -42131.884 | F34: =F29-F32 -> -58030.929 | G34: =G29-G32 -> -42437.425 | H34: =H29-H32 -> -56217.413 | I34: =I29-I32 -> -68566.45 | ... BA34: =BA29-BA32 -> -300648.41
A36: EBT (Earnings Before Tax) | B36: =B34 -> -68146 | C36: =C34 -> -41854.75 | D36: =D34 -> -41989.938 | E36: =E34 -> -42131.884 | F36: =F34 -> -58030.929 | G36: =G34 -> -42437.425 | H36: =H34 -> -56217.413 | I36: =I34 -> -68566.45 | ... BA36: =BA34 -> -300648.41
A37: Income Tax | B37: =IF(B36>0,B36*Inputs!$B$7,0) -> 0 | C37: =IF(C36>0,C36*Inputs!$B$7,0) -> 0 | D37: =IF(D36>0,D36*Inputs!$B$7,0) -> 0 | E37: =IF(E36>0,E36*Inputs!$B$7,0) -> 0 | F37: =IF(F36>0,F36*Inputs!$B$7,0) -> 0 | G37: =IF(G36>0,G36*Inputs!$B$7,0) -> 0 | H37: =IF(H36>0,H36*Inputs!$B$7,0) -> 0 | I37: =IF(I36>0,I36*Inputs!$B$7,0) -> 0 | ... BA37: =IF(BA36>0,BA36*Inputs!$B$7,0) -> 0
A39: NET INCOME | B39: =B36-B37 -> -68146 | C39: =C36-C37 -> -41854.75 | D39: =D36-D37 -> -41989.938 | E39: =E36-E37 -> -42131.884 | F39: =F36-F37 -> -58030.929 | G39: =G36-G37 -> -42437.425 | H39: =H36-H37 -> -56217.413 | I39: =I36-I37 -> -68566.45 | ... BA39: =BA36-BA37 -> -300648.41
A40: Net Margin % | B40: =IFERROR(B39/B7,0) -> 0 | C40: =IFERROR(C39/C7,0) -> 0 | D40: =IFERROR(D39/D7,0) -> 0 | E40: =IFERROR(E39/E7,0) -> 0 | F40: =IFERROR(F39/F7,0) -> 0 | G40: =IFERROR(G39/G7,0) -> 0 | H40: =IFERROR(H39/H7,0) -> 0 | I40: =IFERROR(I39/I7,0) -> 0 | ... BA40: =IFERROR(BA39/BA7,0) -> -1.8807282

Sheet Revenue
A1: UMSATZMODELL - Detaillierte Aufschlüsselung
B2: 46113 | C2: 46143 | D2: 46174 | E2: 46204 | F2: 46235 | G2: 46266 | H2: 46296 | I2: 46327 | J2: 46357 | K2: 46388 | L2: 46419 | M2: 46447 | N2: 46478 | O2: 46508 | P2: 46539 | Q2: 46569 | R2: 46600 | S2: 46631 | T2: 46661 | U2: 46692 | V2: 46722 | W2: 46753 | X2: 46784 | Y2: 46813 | Z2: 46844 | AA2: 46874 | AB2: 46905 | AC2: 46935 | AD2: 46966 | AE2: 46997 | AF2: 47027 | AG2: 47058 | AH2: 47088 | AI2: 47119 | AJ2: 47150 | AK2: 47178 | AL2: 47209 | AM2: 47239 | AN2: 47270 | AO2: 47300 | AP2: 47331 | AQ2: 47362 | AR2: 47392 | AS2: 47423 | AT2: 47453 | AU2: 47484 | AV2: 47515 | AW2: 47543 | AX2: 47574 | AY2: 47604 | AZ2: 47635 | BA2: 47665
A3: Kennzahl | B3: M1 | C3: M2 | D3: M3 | E3: M4 | F3: M5 | G3: M6 | H3: M7 | I3: M8 | J3: M9 | K3: M10 | L3: M11 | M3: M12 | N3: M13 | O3: M14 | P3: M15 | Q3: M16 | R3: M17 | S3: M18 | T3: M19 | U3: M20 | V3: M21 | W3: M22 | X3: M23 | Y3: M24 | Z3: M25 | AA3: M26 | AB3: M27 | AC3: M28 | AD3: M29 | AE3: M30 | AF3: M31 | AG3: M32 | AH3: M33 | AI3: M34 | AJ3: M35 | AK3: M36 | AL3: M37 | AM3: M38 | AN3: M39 | AO3: M40 | AP3: M41 | AQ3: M42 | AR3: M43 | AS3: M44 | AT3: M45 | AU3: M46 | AV3: M47 | AW3: M48 | AX3: M49 | AY3: M50 | AZ3: M51 | BA3: M52
A4: Preis pro Seat/Monat (€) | B4: =IFERROR(Inputs!$B$20/12*(1+Inputs!$B$21)^(INT((1-1)/12)),0) -> 1000 | C4: =Inputs!$B$20/12*(1+Inputs!$B$21)^INT((2-1)/12) -> 1000 | D4: =Inputs!$B$20/12*(1+Inputs!$B$21)^INT((3-1)/12) -> 1000 | E4: =Inputs!$B$20/12*(1+Inputs!$B$21)^INT((4-1)/12) -> 1000 | F4: =Inputs!$B$20/12*(1+Inputs!$B$21)^INT((5-1)/12) -> 1000 | G4: =Inputs!$B$20/12*(1+Inputs!$B$21)^INT((6-1)/12) -> 1000 | H4: =Inputs!$B$20/12*(1+Inputs!$B$21)^INT((7-1)/12) -> 1000 | I4: =Inputs!$B$20/12*(1+Inputs!$B$21)^INT((8-1)/12) -> 1000 | J4: =Inputs!$B$20/12*(1+Inputs!$B$21)^INT((9-1)/12) -> 1000 | K4: =Inputs!$B$20/12*(1+Inputs!$B$21)^INT((10-1)/12) -> 1000 | L4: =Inputs!$B$20/12*(1+Inputs!$B$21)^INT((11-1)/12) -> 1000 | M4: =Inputs!$B$20/12*(1+Inputs!$B$21)^INT((12-1)/12) -> 1000 | N4: =Inputs!$B$20/12*(1+Inputs!$B$21)^INT((13-1)/12) -> 1080 | O4: =Inputs!$B$20/12*(1+Inputs!$B$21)^INT((14-1)/12) -> 1080 | P4: =Inputs!$B$20/12*(1+Inputs!$B$21)^INT((15-1)/12) -> 1080 | Q4: =Inputs!$B$20/12*(1+Inputs!$B$21)^INT((16-1)/12) -> 1080 | R4: =Inputs!$B$20/12*(1+Inputs!$B$21)^INT((17-1)/12) -> 1080 | S4: =Inputs!$B$20/12*(1+Inputs!$B$21)^INT((18-1)/12) -> 1080 | T4: =Inputs!$B$20/12*(1+Inputs!$B$21)^INT((19-1)/12) -> 1080 | U4: =Inputs!$B$20/12*(1+Inputs!$B$21)^INT((20-1)/12) -> 1080 | V4: =Inputs!$B$20/12*(1+Inputs!$B$21)^INT((21-1)/12) -> 1080 | W4: =Inputs!$B$20/12*(1+Inputs!$B$21)^INT((22-1)/12) -> 1080 | X4: =Inputs!$B$20/12*(1+Inputs!$B$21)^INT((23-1)/12) -> 1080 | Y4: =Inputs!$B$20/12*(1+Inputs!$B$21)^INT((24-1)/12) -> 1080 | Z4: =Inputs!$B$20/12*(1+Inputs!$B$21)^INT((25-1)/12) -> 1166.4 | AA4: =Inputs!$B$20/12*(1+Inputs!$B$21)^INT((26-1)/12) -> 1166.4 | AB4: =Inputs!$B$20/12*(1+Inputs!$B$21)^INT((27-1)/12) -> 1166.4 | AC4: =Inputs!$B$20/12*(1+Inputs!$B$21)^INT((28-1)/12) -> 1166.4 | AD4: =Inputs!$B$20/12*(1+Inputs!$B$21)^INT((29-1)/12) -> 1166.4 | AE4: =Inputs!$B$20/12*(1+Inputs!$B$21)^INT((30-1)/12) -> 1166.4 | AF4: =Inputs!$B$20/12*(1+Inputs!$B$21)^INT((31-1)/12) -> 1166.4 | AG4: =Inputs!$B$20/12*(1+Inputs!$B$21)^INT((32-1)/12) -> 1166.4 | AH4: =Inputs!$B$20/12*(1+Inputs!$B$21)^INT((33-1)/12) -> 1166.4 | AI4: =Inputs!$B$20/12*(1+Inputs!$B$21)^INT((34-1)/12) -> 1166.4 | AJ4: =Inputs!$B$20/12*(1+Inputs!$B$21)^INT((35-1)/12) -> 1166.4 | AK4: =Inputs!$B$20/12*(1+Inputs!$B$21)^INT((36-1)/12) -> 1166.4 | AL4: =Inputs!$B$20/12*(1+Inputs!$B$21)^INT((37-1)/12) -> 1259.712 | AM4: =Inputs!$B$20/12*(1+Inputs!$B$21)^INT((38-1)/12) -> 1259.712 | AN4: =Inputs!$B$20/12*(1+Inputs!$B$21)^INT((39-1)/12) -> 1259.712 | AO4: =Inputs!$B$20/12*(1+Inputs!$B$21)^INT((40-1)/12) -> 1259.712 | AP4: =Inputs!$B$20/12*(1+Inputs!$B$21)^INT((41-1)/12) -> 1259.712 | AQ4: =Inputs!$B$20/12*(1+Inputs!$B$21)^INT((42-1)/12) -> 1259.712 | AR4: =Inputs!$B$20/12*(1+Inputs!$B$21)^INT((43-1)/12) -> 1259.712 | AS4: =Inputs!$B$20/12*(1+Inputs!$B$21)^INT((44-1)/12) -> 1259.712 | AT4: =Inputs!$B$20/12*(1+Inputs!$B$21)^INT((45-1)/12) -> 1259.712 | AU4: =Inputs!$B$20/12*(1+Inputs!$B$21)^INT((46-1)/12) -> 1259.712 | AV4: =Inputs!$B$20/12*(1+Inputs!$B$21)^INT((47-1)/12) -> 1259.712 | AW4: =Inputs!$B$20/12*(1+Inputs!$B$21)^INT((48-1)/12) -> 1259.712 | AX4: =Inputs!$B$20/12*(1+Inputs!$B$21)^INT((49-1)/12) -> 1360.489 | AY4: =Inputs!$B$20/12*(1+Inputs!$B$21)^INT((50-1)/12) -> 1360.489 | AZ4: =Inputs!$B$20/12*(1+Inputs!$B$21)^INT((51-1)/12) -> 1360.489 | BA4: =Inputs!$B$20/12*(1+Inputs!$B$21)^INT((52-1)/12) -> 1360.489
A5: Neue Seats | B5: =IF(1>=Inputs!$B$22,Inputs!$B$23,0) -> 0 | C5: =IF(2>=Inputs!$B$22,IF(2=Inputs!$B$22,Inputs!$B$23,ROUND(B8*Inputs!$B$24,0)),0) -> 0 | D5: =IF(3>=Inputs!$B$22,IF(3=Inputs!$B$22,Inputs!$B$23,ROUND(C8*Inputs!$B$24,0)),0) -> 0 | E5: =IF(4>=Inputs!$B$22,IF(4=Inputs!$B$22,Inputs!$B$23,ROUND(D8*Inputs!$B$24,0)),0) -> 0 | F5: =IF(5>=Inputs!$B$22,IF(5=Inputs!$B$22,Inputs!$B$23,ROUND(E8*Inputs!$B$24,0)),0) -> 0 | G5: =IF(6>=Inputs!$B$22,IF(6=Inputs!$B$22,Inputs!$B$23,ROUND(F8*Inputs!$B$24,0)),0) -> 0 | H5: =IF(7>=Inputs!$B$22,IF(7=Inputs!$B$22,Inputs!$B$23,ROUND(G8*Inputs!$B$24,0)),0) -> 0 | I5: =IF(8>=Inputs!$B$22,IF(8=Inputs!$B$22,Inputs!$B$23,ROUND(H8*Inputs!$B$24,0)),0) -> 0 | J5: =IF(9>=Inputs!$B$22,IF(9=Inputs!$B$22,Inputs!$B$23,ROUND(I8*Inputs!$B$24,0)),0) -> 5 | K5: =IF(10>=Inputs!$B$22,IF(10=Inputs!$B$22,Inputs!$B$23,ROUND(J8*Inputs!$B$24,0)),0) -> 0 | L5: =IF(11>=Inputs!$B$22,IF(11=Inputs!$B$22,Inputs!$B$23,ROUND(K8*Inputs!$B$24,0)),0) -> 0 | M5: =IF(12>=Inputs!$B$22,IF(12=Inputs!$B$22,Inputs!$B$23,ROUND(L8*Inputs!$B$24,0)),0) -> 0 | N5: =IF(13>=Inputs!$B$22,IF(13=Inputs!$B$22,Inputs!$B$23,ROUND(M8*Inputs!$B$24,0)),0) -> 0 | O5: =IF(14>=Inputs!$B$22,IF(14=Inputs!$B$22,Inputs!$B$23,ROUND(N8*Inputs!$B$24,0)),0) -> 0 | P5: =IF(15>=Inputs!$B$22,IF(15=Inputs!$B$22,Inputs!$B$23,ROUND(O8*Inputs!$B$24,0)),0) -> 0 | Q5: =IF(16>=Inputs!$B$22,IF(16=Inputs!$B$22,Inputs!$B$23,ROUND(P8*Inputs!$B$24,0)),0) -> 0 | R5: =IF(17>=Inputs!$B$22,IF(17=Inputs!$B$22,Inputs!$B$23,ROUND(Q8*Inputs!$B$24,0)),0) -> 0 | S5: =IF(18>=Inputs!$B$22,IF(18=Inputs!$B$22,Inputs!$B$23,ROUND(R8*Inputs!$B$24,0)),0) -> 0 | T5: =IF(19>=Inputs!$B$22,IF(19=Inputs!$B$22,Inputs!$B$23,ROUND(S8*Inputs!$B$24,0)),0) -> 0 | U5: =IF(20>=Inputs!$B$22,IF(20=Inputs!$B$22,Inputs!$B$23,ROUND(T8*Inputs!$B$24,0)),0) -> 0 | V5: =IF(21>=Inputs!$B$22,IF(21=Inputs!$B$22,Inputs!$B$23,ROUND(U8*Inputs!$B$24,0)),0) -> 0 | W5: =IF(22>=Inputs!$B$22,IF(22=Inputs!$B$22,Inputs!$B$23,ROUND(V8*Inputs!$B$24,0)),0) -> 0 | X5: =IF(23>=Inputs!$B$22,IF(23=Inputs!$B$22,Inputs!$B$23,ROUND(W8*Inputs!$B$24,0)),0) -> 0 | Y5: =IF(24>=Inputs!$B$22,IF(24=Inputs!$B$22,Inputs!$B$23,ROUND(X8*Inputs!$B$24,0)),0) -> 0 | Z5: =IF(25>=Inputs!$B$22,IF(25=Inputs!$B$22,Inputs!$B$23,ROUND(Y8*Inputs!$B$24,0)),0) -> 0 | AA5: =IF(26>=Inputs!$B$22,IF(26=Inputs!$B$22,Inputs!$B$23,ROUND(Z8*Inputs!$B$24,0)),0) -> 0 | AB5: =IF(27>=Inputs!$B$22,IF(27=Inputs!$B$22,Inputs!$B$23,ROUND(AA8*Inputs!$B$24,0)),0) -> 0 | AC5: =IF(28>=Inputs!$B$22,IF(28=Inputs!$B$22,Inputs!$B$23,ROUND(AB8*Inputs!$B$24,0)),0) -> 0 | AD5: =IF(29>=Inputs!$B$22,IF(29=Inputs!$B$22,Inputs!$B$23,ROUND(AC8*Inputs!$B$24,0)),0) -> 0 | AE5: =IF(30>=Inputs!$B$22,IF(30=Inputs!$B$22,Inputs!$B$23,ROUND(AD8*Inputs!$B$24,0)),0) -> 0 | AF5: =IF(31>=Inputs!$B$22,IF(31=Inputs!$B$22,Inputs!$B$23,ROUND(AE8*Inputs!$B$24,0)),0) -> 0 | AG5: =IF(32>=Inputs!$B$22,IF(32=Inputs!$B$22,Inputs!$B$23,ROUND(AF8*Inputs!$B$24,0)),0) -> 0 | AH5: =IF(33>=Inputs!$B$22,IF(33=Inputs!$B$22,Inputs!$B$23,ROUND(AG8*Inputs!$B$24,0)),0) -> 0 | AI5: =IF(34>=Inputs!$B$22,IF(34=Inputs!$B$22,Inputs!$B$23,ROUND(AH8*Inputs!$B$24,0)),0) -> 0 | AJ5: =IF(35>=Inputs!$B$22,IF(35=Inputs!$B$22,Inputs!$B$23,ROUND(AI8*Inputs!$B$24,0)),0) -> 0 | AK5: =IF(36>=Inputs!$B$22,IF(36=Inputs!$B$22,Inputs!$B$23,ROUND(AJ8*Inputs!$B$24,0)),0) -> 0 | AL5: =IF(37>=Inputs!$B$22,IF(37=Inputs!$B$22,Inputs!$B$23,ROUND(AK8*Inputs!$B$24,0)),0) -> 0 | AM5: =IF(38>=Inputs!$B$22,IF(38=Inputs!$B$22,Inputs!$B$23,ROUND(AL8*Inputs!$B$24,0)),0) -> 0 | AN5: =IF(39>=Inputs!$B$22,IF(39=Inputs!$B$22,Inputs!$B$23,ROUND(AM8*Inputs!$B$24,0)),0) -> 0 | AO5: =IF(40>=Inputs!$B$22,IF(40=Inputs!$B$22,Inputs!$B$23,ROUND(AN8*Inputs!$B$24,0)),0) -> 0 | AP5: =IF(41>=Inputs!$B$22,IF(41=Inputs!$B$22,Inputs!$B$23,ROUND(AO8*Inputs!$B$24,0)),0) -> 0 | AQ5: =IF(42>=Inputs!$B$22,IF(42=Inputs!$B$22,Inputs!$B$23,ROUND(AP8*Inputs!$B$24,0)),0) -> 0 | AR5: =IF(43>=Inputs!$B$22,IF(43=Inputs!$B$22,Inputs!$B$23,ROUND(AQ8*Inputs!$B$24,0)),0) -> 0 | AS5: =IF(44>=Inputs!$B$22,IF(44=Inputs!$B$22,Inputs!$B$23,ROUND(AR8*Inputs!$B$24,0)),0) -> 0 | AT5: =IF(45>=Inputs!$B$22,IF(45=Inputs!$B$22,Inputs!$B$23,ROUND(AS8*Inputs!$B$24,0)),0) -> 0 | AU5: =IF(46>=Inputs!$B$22,IF(46=Inputs!$B$22,Inputs!$B$23,ROUND(AT8*Inputs!$B$24,0)),0) -> 0 | AV5: =IF(47>=Inputs!$B$22,IF(47=Inputs!$B$22,Inputs!$B$23,ROUND(AU8*Inputs!$B$24,0)),0) -> 0 | AW5: =IF(48>=Inputs!$B$22,IF(48=Inputs!$B$22,Inputs!$B$23,ROUND(AV8*Inputs!$B$24,0)),0) -> 0 | AX5: =IF(49>=Inputs!$B$22,IF(49=Inputs!$B$22,Inputs!$B$23,ROUND(AW8*Inputs!$B$24,0)),0) -> 0 | AY5: =IF(50>=Inputs!$B$22,IF(50=Inputs!$B$22,Inputs!$B$23,ROUND(AX8*Inputs!$B$24,0)),0) -> 0 | AZ5: =IF(51>=Inputs!$B$22,IF(51=Inputs!$B$22,Inputs!$B$23,ROUND(AY8*Inputs!$B$24,0)),0) -> 0 | BA5: =IF(52>=Inputs!$B$22,IF(52=Inputs!$B$22,Inputs!$B$23,ROUND(AZ8*Inputs!$B$24,0)),0) -> 0
A6: Churned Seats | B6: =0 -> 0 | C6: =IF(B8>0,ROUND(B8*Inputs!$B$28/12,0),0) -> 0 | D6: =IF(C8>0,ROUND(C8*Inputs!$B$28/12,0),0) -> 0 | E6: =IF(D8>0,ROUND(D8*Inputs!$B$28/12,0),0) -> 0 | F6: =IF(E8>0,ROUND(E8*Inputs!$B$28/12,0),0) -> 0 | G6: =IF(F8>0,ROUND(F8*Inputs!$B$28/12,0),0) -> 0 | H6: =IF(G8>0,ROUND(G8*Inputs!$B$28/12,0),0) -> 0 | I6: =IF(H8>0,ROUND(H8*Inputs!$B$28/12,0),0) -> 0 | J6: =IF(I8>0,ROUND(I8*Inputs!$B$28/12,0),0) -> 0 | ... BA6: =IF(AZ8>0,ROUND(AZ8*Inputs!$B$28/12,0),0) -> 0
A7: Net New Seats | B7: =B5-B6 -> 0 | C7: =C5-C6 -> 0 | D7: =D5-D6 -> 0 | E7: =E5-E6 -> 0 | F7: =F5-F6 -> 0 | G7: =G5-G6 -> 0 | H7: =H5-H6 -> 0 | I7: =I5-I6 -> 0 | ... BA7: =BA5-BA6 -> 0
A8: Total Active Seats | B8: =B7 -> 0 | C8: =B8+C7 -> 0 | D8: =C8+D7 -> 0 | E8: =D8+E7 -> 0 | F8: =E8+F7 -> 0 | G8: =F8+G7 -> 0 | H8: =G8+H7 -> 0 | I8: =H8+I7 -> 0 | J8: =I8+J7 -> 5 | ... BA8: =AZ8+BA7 -> 5
A9: Monthly Subscription Revenue (€) | B9: =B8*B4 -> 0 | C9: =C8*C4 -> 0 | D9: =D8*D4 -> 0 | E9: =E8*E4 -> 0 | F9: =F8*F4 -> 0 | G9: =G8*G4 -> 0 | H9: =H8*H4 -> 0 | I9: =I8*I4 -> 0 | ... BA9: =BA8*BA4 -> 6802.4448
A10: Subscription ARR (€) | B10: =B9*12 -> 0 | C10: =C9*12 -> 0 | D10: =D9*12 -> 0 | E10: =E9*12 -> 0 | F10: =F9*12 -> 0 | G10: =G9*12 -> 0 | H10: =H9*12 -> 0 | I10: =I9*12 -> 0 | ... BA10: =BA9*12 -> 81629.338
A12: Neue Enterprise Deals | B12: =IF(AND(1>=Inputs!$B$25,MOD(1-Inputs!$B$25,3)=0),Inputs!$B$27,0) -> 0 | C12: =IF(AND(2>=Inputs!$B$25,MOD(2-Inputs!$B$25,3)=0),Inputs!$B$27,0) -> 0 | D12: =IF(AND(3>=Inputs!$B$25,MOD(3-Inputs!$B$25,3)=0),Inputs!$B$27,0) -> 0 | E12: =IF(AND(4>=Inputs!$B$25,MOD(4-Inputs!$B$25,3)=0),Inputs!$B$27,0) -> 0 | F12: =IF(AND(5>=Inputs!$B$25,MOD(5-Inputs!$B$25,3)=0),Inputs!$B$27,0) -> 0 | G12: =IF(AND(6>=Inputs!$B$25,MOD(6-Inputs!$B$25,3)=0),Inputs!$B$27,0) -> 0 | H12: =IF(AND(7>=Inputs!$B$25,MOD(7-Inputs!$B$25,3)=0),Inputs!$B$27,0) -> 0 | I12: =IF(AND(8>=Inputs!$B$25,MOD(8-Inputs!$B$25,3)=0),Inputs!$B$27,0) -> 0 | J12: =IF(AND(9>=Inputs!$B$25,MOD(9-Inputs!$B$25,3)=0),Inputs!$B$27,0) -> 0 | K12: =IF(AND(10>=Inputs!$B$25,MOD(10-Inputs!$B$25,3)=0),Inputs!$B$27,0) -> 0 | L12: =IF(AND(11>=Inputs!$B$25,MOD(11-Inputs!$B$25,3)=0),Inputs!$B$27,0) -> 0 | M12: =IF(AND(12>=Inputs!$B$25,MOD(12-Inputs!$B$25,3)=0),Inputs!$B$27,0) -> 0 | N12: =IF(AND(13>=Inputs!$B$25,MOD(13-Inputs!$B$25,3)=0),Inputs!$B$27,0) -> 0 | O12: =IF(AND(14>=Inputs!$B$25,MOD(14-Inputs!$B$25,3)=0),Inputs!$B$27,0) -> 0 | P12: =IF(AND(15>=Inputs!$B$25,MOD(15-Inputs!$B$25,3)=0),Inputs!$B$27,0) -> 0 | Q12: =IF(AND(16>=Inputs!$B$25,MOD(16-Inputs!$B$25,3)=0),Inputs!$B$27,0) -> 0 | R12: =IF(AND(17>=Inputs!$B$25,MOD(17-Inputs!$B$25,3)=0),Inputs!$B$27,0) -> 0 | S12: =IF(AND(18>=Inputs!$B$25,MOD(18-Inputs!$B$25,3)=0),Inputs!$B$27,0) -> 0 | T12: =IF(AND(19>=Inputs!$B$25,MOD(19-Inputs!$B$25,3)=0),Inputs!$B$27,0) -> 0 | U12: =IF(AND(20>=Inputs!$B$25,MOD(20-Inputs!$B$25,3)=0),Inputs!$B$27,0) -> 0 | V12: =IF(AND(21>=Inputs!$B$25,MOD(21-Inputs!$B$25,3)=0),Inputs!$B$27,0) -> 0 | W12: =IF(AND(22>=Inputs!$B$25,MOD(22-Inputs!$B$25,3)=0),Inputs!$B$27,0) -> 0 | X12: =IF(AND(23>=Inputs!$B$25,MOD(23-Inputs!$B$25,3)=0),Inputs!$B$27,0) -> 0 | Y12: =IF(AND(24>=Inputs!$B$25,MOD(24-Inputs!$B$25,3)=0),Inputs!$B$27,0) -> 1 | Z12: =IF(AND(25>=Inputs!$B$25,MOD(25-Inputs!$B$25,3)=0),Inputs!$B$27,0) -> 0 | AA12: =IF(AND(26>=Inputs!$B$25,MOD(26-Inputs!$B$25,3)=0),Inputs!$B$27,0) -> 0 | AB12: =IF(AND(27>=Inputs!$B$25,MOD(27-Inputs!$B$25,3)=0),Inputs!$B$27,0) -> 1 | AC12: =IF(AND(28>=Inputs!$B$25,MOD(28-Inputs!$B$25,3)=0),Inputs!$B$27,0) -> 0 | AD12: =IF(AND(29>=Inputs!$B$25,MOD(29-Inputs!$B$25,3)=0),Inputs!$B$27,0) -> 0 | AE12: =IF(AND(30>=Inputs!$B$25,MOD(30-Inputs!$B$25,3)=0),Inputs!$B$27,0) -> 1 | AF12: =IF(AND(31>=Inputs!$B$25,MOD(31-Inputs!$B$25,3)=0),Inputs!$B$27,0) -> 0 | AG12: =IF(AND(32>=Inputs!$B$25,MOD(32-Inputs!$B$25,3)=0),Inputs!$B$27,0) -> 0 | AH12: =IF(AND(33>=Inputs!$B$25,MOD(33-Inputs!$B$25,3)=0),Inputs!$B$27,0) -> 1 | AI12: =IF(AND(34>=Inputs!$B$25,MOD(34-Inputs!$B$25,3)=0),Inputs!$B$27,0) -> 0 | AJ12: =IF(AND(35>=Inputs!$B$25,MOD(35-Inputs!$B$25,3)=0),Inputs!$B$27,0) -> 0 | AK12: =IF(AND(36>=Inputs!$B$25,MOD(36-Inputs!$B$25,3)=0),Inputs!$B$27,0) -> 1 | AL12: =IF(AND(37>=Inputs!$B$25,MOD(37-Inputs!$B$25,3)=0),Inputs!$B$27,0) -> 0 | AM12: =IF(AND(38>=Inputs!$B$25,MOD(38-Inputs!$B$25,3)=0),Inputs!$B$27,0) -> 0 | AN12: =IF(AND(39>=Inputs!$B$25,MOD(39-Inputs!$B$25,3)=0),Inputs!$B$27,0) -> 1 | AO12: =IF(AND(40>=Inputs!$B$25,MOD(40-Inputs!$B$25,3)=0),Inputs!$B$27,0) -> 0 | AP12: =IF(AND(41>=Inputs!$B$25,MOD(41-Inputs!$B$25,3)=0),Inputs!$B$27,0) -> 0 | AQ12: =IF(AND(42>=Inputs!$B$25,MOD(42-Inputs!$B$25,3)=0),Inputs!$B$27,0) -> 1 | AR12: =IF(AND(43>=Inputs!$B$25,MOD(43-Inputs!$B$25,3)=0),Inputs!$B$27,0) -> 0 | AS12: =IF(AND(44>=Inputs!$B$25,MOD(44-Inputs!$B$25,3)=0),Inputs!$B$27,0) -> 0 | AT12: =IF(AND(45>=Inputs!$B$25,MOD(45-Inputs!$B$25,3)=0),Inputs!$B$27,0) -> 1 | AU12: =IF(AND(46>=Inputs!$B$25,MOD(46-Inputs!$B$25,3)=0),Inputs!$B$27,0) -> 0 | AV12: =IF(AND(47>=Inputs!$B$25,MOD(47-Inputs!$B$25,3)=0),Inputs!$B$27,0) -> 0 | AW12: =IF(AND(48>=Inputs!$B$25,MOD(48-Inputs!$B$25,3)=0),Inputs!$B$27,0) -> 1 | AX12: =IF(AND(49>=Inputs!$B$25,MOD(49-Inputs!$B$25,3)=0),Inputs!$B$27,0) -> 0 | AY12: =IF(AND(50>=Inputs!$B$25,MOD(50-Inputs!$B$25,3)=0),Inputs!$B$27,0) -> 0 | AZ12: =IF(AND(51>=Inputs!$B$25,MOD(51-Inputs!$B$25,3)=0),Inputs!$B$27,0) -> 1 | BA12: =IF(AND(52>=Inputs!$B$25,MOD(52-Inputs!$B$25,3)=0),Inputs!$B$27,0) -> 0
A13: Churned Enterprise | B13: =0 -> 0 | C13: =IF(B14>0,IF(MOD(2,12)=0,ROUND(B14*Inputs!$B$28,0),0),0) -> 0 | D13: =IF(C14>0,IF(MOD(3,12)=0,ROUND(C14*Inputs!$B$28,0),0),0) -> 0 | E13: =IF(D14>0,IF(MOD(4,12)=0,ROUND(D14*Inputs!$B$28,0),0),0) -> 0 | F13: =IF(E14>0,IF(MOD(5,12)=0,ROUND(E14*Inputs!$B$28,0),0),0) -> 0 | G13: =IF(F14>0,IF(MOD(6,12)=0,ROUND(F14*Inputs!$B$28,0),0),0) -> 0 | H13: =IF(G14>0,IF(MOD(7,12)=0,ROUND(G14*Inputs!$B$28,0),0),0) -> 0 | I13: =IF(H14>0,IF(MOD(8,12)=0,ROUND(H14*Inputs!$B$28,0),0),0) -> 0 | J13: =IF(I14>0,IF(MOD(9,12)=0,ROUND(I14*Inputs!$B$28,0),0),0) -> 0 | K13: =IF(J14>0,IF(MOD(10,12)=0,ROUND(J14*Inputs!$B$28,0),0),0) -> 0 | L13: =IF(K14>0,IF(MOD(11,12)=0,ROUND(K14*Inputs!$B$28,0),0),0) -> 0 | M13: =IF(L14>0,IF(MOD(12,12)=0,ROUND(L14*Inputs!$B$28,0),0),0) -> 0 | N13: =IF(M14>0,IF(MOD(13,12)=0,ROUND(M14*Inputs!$B$28,0),0),0) -> 0 | O13: =IF(N14>0,IF(MOD(14,12)=0,ROUND(N14*Inputs!$B$28,0),0),0) -> 0 | P13: =IF(O14>0,IF(MOD(15,12)=0,ROUND(O14*Inputs!$B$28,0),0),0) -> 0 | Q13: =IF(P14>0,IF(MOD(16,12)=0,ROUND(P14*Inputs!$B$28,0),0),0) -> 0 | R13: =IF(Q14>0,IF(MOD(17,12)=0,ROUND(Q14*Inputs!$B$28,0),0),0) -> 0 | S13: =IF(R14>0,IF(MOD(18,12)=0,ROUND(R14*Inputs!$B$28,0),0),0) -> 0 | T13: =IF(S14>0,IF(MOD(19,12)=0,ROUND(S14*Inputs!$B$28,0),0),0) -> 0 | U13: =IF(T14>0,IF(MOD(20,12)=0,ROUND(T14*Inputs!$B$28,0),0),0) -> 0 | V13: =IF(U14>0,IF(MOD(21,12)=0,ROUND(U14*Inputs!$B$28,0),0),0) -> 0 | W13: =IF(V14>0,IF(MOD(22,12)=0,ROUND(V14*Inputs!$B$28,0),0),0) -> 0 | X13: =IF(W14>0,IF(MOD(23,12)=0,ROUND(W14*Inputs!$B$28,0),0),0) -> 0 | Y13: =IF(X14>0,IF(MOD(24,12)=0,ROUND(X14*Inputs!$B$28,0),0),0) -> 0 | Z13: =IF(Y14>0,IF(MOD(25,12)=0,ROUND(Y14*Inputs!$B$28,0),0),0) -> 0 | AA13: =IF(Z14>0,IF(MOD(26,12)=0,ROUND(Z14*Inputs!$B$28,0),0),0) -> 0 | AB13: =IF(AA14>0,IF(MOD(27,12)=0,ROUND(AA14*Inputs!$B$28,0),0),0) -> 0 | AC13: =IF(AB14>0,IF(MOD(28,12)=0,ROUND(AB14*Inputs!$B$28,0),0),0) -> 0 | AD13: =IF(AC14>0,IF(MOD(29,12)=0,ROUND(AC14*Inputs!$B$28,0),0),0) -> 0 | AE13: =IF(AD14>0,IF(MOD(30,12)=0,ROUND(AD14*Inputs!$B$28,0),0),0) -> 0 | AF13: =IF(AE14>0,IF(MOD(31,12)=0,ROUND(AE14*Inputs!$B$28,0),0),0) -> 0 | AG13: =IF(AF14>0,IF(MOD(32,12)=0,ROUND(AF14*Inputs!$B$28,0),0),0) -> 0 | AH13: =IF(AG14>0,IF(MOD(33,12)=0,ROUND(AG14*Inputs!$B$28,0),0),0) -> 0 | AI13: =IF(AH14>0,IF(MOD(34,12)=0,ROUND(AH14*Inputs!$B$28,0),0),0) -> 0 | AJ13: =IF(AI14>0,IF(MOD(35,12)=0,ROUND(AI14*Inputs!$B$28,0),0),0) -> 0 | AK13: =IF(AJ14>0,IF(MOD(36,12)=0,ROUND(AJ14*Inputs!$B$28,0),0),0) -> 0 | AL13: =IF(AK14>0,IF(MOD(37,12)=0,ROUND(AK14*Inputs!$B$28,0),0),0) -> 0 | AM13: =IF(AL14>0,IF(MOD(38,12)=0,ROUND(AL14*Inputs!$B$28,0),0),0) -> 0 | AN13: =IF(AM14>0,IF(MOD(39,12)=0,ROUND(AM14*Inputs!$B$28,0),0),0) -> 0 | AO13: =IF(AN14>0,IF(MOD(40,12)=0,ROUND(AN14*Inputs!$B$28,0),0),0) -> 0 | AP13: =IF(AO14>0,IF(MOD(41,12)=0,ROUND(AO14*Inputs!$B$28,0),0),0) -> 0 | AQ13: =IF(AP14>0,IF(MOD(42,12)=0,ROUND(AP14*Inputs!$B$28,0),0),0) -> 0 | AR13: =IF(AQ14>0,IF(MOD(43,12)=0,ROUND(AQ14*Inputs!$B$28,0),0),0) -> 0 | AS13: =IF(AR14>0,IF(MOD(44,12)=0,ROUND(AR14*Inputs!$B$28,0),0),0) -> 0 | AT13: =IF(AS14>0,IF(MOD(45,12)=0,ROUND(AS14*Inputs!$B$28,0),0),0) -> 0 | AU13: =IF(AT14>0,IF(MOD(46,12)=0,ROUND(AT14*Inputs!$B$28,0),0),0) -> 0 | AV13: =IF(AU14>0,IF(MOD(47,12)=0,ROUND(AU14*Inputs!$B$28,0),0),0) -> 0 | AW13: =IF(AV14>0,IF(MOD(48,12)=0,ROUND(AV14*Inputs!$B$28,0),0),0) -> 1 | AX13: =IF(AW14>0,IF(MOD(49,12)=0,ROUND(AW14*Inputs!$B$28,0),0),0) -> 0 | AY13: =IF(AX14>0,IF(MOD(50,12)=0,ROUND(AX14*Inputs!$B$28,0),0),0) -> 0 | AZ13: =IF(AY14>0,IF(MOD(51,12)=0,ROUND(AY14*Inputs!$B$28,0),0),0) -> 0 | BA13: =IF(AZ14>0,IF(MOD(52,12)=0,ROUND(AZ14*Inputs!$B$28,0),0),0) -> 0
A14: Active Enterprise Contracts | B14: =B12-B13 -> 0 | C14: =B14+C12-C13 -> 0 | D14: =C14+D12-D13 -> 0 | E14: =D14+E12-E13 -> 0 | F14: =E14+F12-F13 -> 0 | G14: =F14+G12-G13 -> 0 | H14: =G14+H12-H13 -> 0 | I14: =H14+I12-I13 -> 0 | J14: =I14+J12-J13 -> 0 | ... BA14: =AZ14+BA12-BA13 -> 9
A15: Avg Enterprise ACV (€) | B15: =Inputs!$B$26*(1+Inputs!$B$21)^INT((1-1)/12) -> 150000 | C15: =Inputs!$B$26*(1+Inputs!$B$21)^INT((2-1)/12) -> 150000 | D15: =Inputs!$B$26*(1+Inputs!$B$21)^INT((3-1)/12) -> 150000 | E15: =Inputs!$B$26*(1+Inputs!$B$21)^INT((4-1)/12) -> 150000 | F15: =Inputs!$B$26*(1+Inputs!$B$21)^INT((5-1)/12) -> 150000 | G15: =Inputs!$B$26*(1+Inputs!$B$21)^INT((6-1)/12) -> 150000 | H15: =Inputs!$B$26*(1+Inputs!$B$21)^INT((7-1)/12) -> 150000 | I15: =Inputs!$B$26*(1+Inputs!$B$21)^INT((8-1)/12) -> 150000 | J15: =Inputs!$B$26*(1+Inputs!$B$21)^INT((9-1)/12) -> 150000 | K15: =Inputs!$B$26*(1+Inputs!$B$21)^INT((10-1)/12) -> 150000 | L15: =Inputs!$B$26*(1+Inputs!$B$21)^INT((11-1)/12) -> 150000 | M15: =Inputs!$B$26*(1+Inputs!$B$21)^INT((12-1)/12) -> 150000 | N15: =Inputs!$B$26*(1+Inputs!$B$21)^INT((13-1)/12) -> 162000 | O15: =Inputs!$B$26*(1+Inputs!$B$21)^INT((14-1)/12) -> 162000 | P15: =Inputs!$B$26*(1+Inputs!$B$21)^INT((15-1)/12) -> 162000 | Q15: =Inputs!$B$26*(1+Inputs!$B$21)^INT((16-1)/12) -> 162000 | R15: =Inputs!$B$26*(1+Inputs!$B$21)^INT((17-1)/12) -> 162000 | S15: =Inputs!$B$26*(1+Inputs!$B$21)^INT((18-1)/12) -> 162000 | T15: =Inputs!$B$26*(1+Inputs!$B$21)^INT((19-1)/12) -> 162000 | U15: =Inputs!$B$26*(1+Inputs!$B$21)^INT((20-1)/12) -> 162000 | V15: =Inputs!$B$26*(1+Inputs!$B$21)^INT((21-1)/12) -> 162000 | W15: =Inputs!$B$26*(1+Inputs!$B$21)^INT((22-1)/12) -> 162000 | X15: =Inputs!$B$26*(1+Inputs!$B$21)^INT((23-1)/12) -> 162000 | Y15: =Inputs!$B$26*(1+Inputs!$B$21)^INT((24-1)/12) -> 162000 | Z15: =Inputs!$B$26*(1+Inputs!$B$21)^INT((25-1)/12) -> 174960 | AA15: =Inputs!$B$26*(1+Inputs!$B$21)^INT((26-1)/12) -> 174960 | AB15: =Inputs!$B$26*(1+Inputs!$B$21)^INT((27-1)/12) -> 174960 | AC15: =Inputs!$B$26*(1+Inputs!$B$21)^INT((28-1)/12) -> 174960 | AD15: =Inputs!$B$26*(1+Inputs!$B$21)^INT((29-1)/12) -> 174960 | AE15: =Inputs!$B$26*(1+Inputs!$B$21)^INT((30-1)/12) -> 174960 | AF15: =Inputs!$B$26*(1+Inputs!$B$21)^INT((31-1)/12) -> 174960 | AG15: =Inputs!$B$26*(1+Inputs!$B$21)^INT((32-1)/12) -> 174960 | AH15: =Inputs!$B$26*(1+Inputs!$B$21)^INT((33-1)/12) -> 174960 | AI15: =Inputs!$B$26*(1+Inputs!$B$21)^INT((34-1)/12) -> 174960 | AJ15: =Inputs!$B$26*(1+Inputs!$B$21)^INT((35-1)/12) -> 174960 | AK15: =Inputs!$B$26*(1+Inputs!$B$21)^INT((36-1)/12) -> 174960 | AL15: =Inputs!$B$26*(1+Inputs!$B$21)^INT((37-1)/12) -> 188956.8 | AM15: =Inputs!$B$26*(1+Inputs!$B$21)^INT((38-1)/12) -> 188956.8 | AN15: =Inputs!$B$26*(1+Inputs!$B$21)^INT((39-1)/12) -> 188956.8 | AO15: =Inputs!$B$26*(1+Inputs!$B$21)^INT((40-1)/12) -> 188956.8 | AP15: =Inputs!$B$26*(1+Inputs!$B$21)^INT((41-1)/12) -> 188956.8 | AQ15: =Inputs!$B$26*(1+Inputs!$B$21)^INT((42-1)/12) -> 188956.8 | AR15: =Inputs!$B$26*(1+Inputs!$B$21)^INT((43-1)/12) -> 188956.8 | AS15: =Inputs!$B$26*(1+Inputs!$B$21)^INT((44-1)/12) -> 188956.8 | AT15: =Inputs!$B$26*(1+Inputs!$B$21)^INT((45-1)/12) -> 188956.8 | AU15: =Inputs!$B$26*(1+Inputs!$B$21)^INT((46-1)/12) -> 188956.8 | AV15: =Inputs!$B$26*(1+Inputs!$B$21)^INT((47-1)/12) -> 188956.8 | AW15: =Inputs!$B$26*(1+Inputs!$B$21)^INT((48-1)/12) -> 188956.8 | AX15: =Inputs!$B$26*(1+Inputs!$B$21)^INT((49-1)/12) -> 204073.34 | AY15: =Inputs!$B$26*(1+Inputs!$B$21)^INT((50-1)/12) -> 204073.34 | AZ15: =Inputs!$B$26*(1+Inputs!$B$21)^INT((51-1)/12) -> 204073.34 | BA15: =Inputs!$B$26*(1+Inputs!$B$21)^INT((52-1)/12) -> 204073.34
A16: Enterprise Monthly Revenue (€) | B16: =B14*B15/12 -> 0 | C16: =C14*C15/12 -> 0 | D16: =D14*D15/12 -> 0 | E16: =E14*E15/12 -> 0 | F16: =F14*F15/12 -> 0 | G16: =G14*G15/12 -> 0 | H16: =H14*H15/12 -> 0 | I16: =I14*I15/12 -> 0 | ... BA16: =BA14*BA15/12 -> 153055.01
A18: TOTAL MRR (€) | B18: =B9+B16 -> 0 | C18: =C9+C16 -> 0 | D18: =D9+D16 -> 0 | E18: =E9+E16 -> 0 | F18: =F9+F16 -> 0 | G18: =G9+G16 -> 0 | H18: =H9+H16 -> 0 | I18: =I9+I16 -> 0 | ... BA18: =BA9+BA16 -> 159857.45
A19: TOTAL ARR (€) | B19: =B18*12 -> 0 | C19: =C18*12 -> 0 | D19: =D18*12 -> 0 | E19: =E18*12 -> 0 | F19: =F18*12 -> 0 | G19: =G18*12 -> 0 | H19: =H18*12 -> 0 | I19: =I18*12 -> 0 | ... BA19: =BA18*12 -> 1918289.4
A20: Total Monthly Revenue (€) | B20: =B18 -> 0 | C20: =C18 -> 0 | D20: =D18 -> 0 | E20: =E18 -> 0 | F20: =F18 -> 0 | G20: =G18 -> 0 | H20: =H18 -> 0 | I20: =I18 -> 0 | ... BA20: =BA18 -> 159857.45
A21: ARR Growth % (MoM) | B21: ="" | C21: =IFERROR(C19/B19-1,"") | D21: =IFERROR(D19/C19-1,"") | E21: =IFERROR(E19/D19-1,"") | F21: =IFERROR(F19/E19-1,"") | G21: =IFERROR(G19/F19-1,"") | H21: =IFERROR(H19/G19-1,"") | I21: =IFERROR(I19/H19-1,"") | J21: =IFERROR(J19/I19-1,"") | ... BA21: =IFERROR(BA19/AZ19-1,"") -> 0
A22: Net Revenue Retention % | B22: =Inputs!$B$29 -> 1.18 | C22: =Inputs!$B$29 -> 1.18 | D22: =Inputs!$B$29 -> 1.18 | E22: =Inputs!$B$29 -> 1.18 | F22: =Inputs!$B$29 -> 1.18 | G22: =Inputs!$B$29 -> 1.18 | H22: =Inputs!$B$29 -> 1.18 | I22: =Inputs!$B$29 -> 1.18 | ... BA22: =Inputs!$B$29 -> 1.18
A23: Gross New ARR (€) | B23: =B5*B4*12+B12*B15 -> 0 | C23: =C5*C4*12+C12*C15 -> 0 | D23: =D5*D4*12+D12*D15 -> 0 | E23: =E5*E4*12+E12*E15 -> 0 | F23: =F5*F4*12+F12*F15 -> 0 | G23: =G5*G4*12+G12*G15 -> 0 | H23: =H5*H4*12+H12*H15 -> 0 | I23: =I5*I4*12+I12*I15 -> 0 | ... BA23: =BA5*BA4*12+BA12*BA15 -> 0

Sheet Costs
A1: KOSTENDETAILS
B2: 46113 | C2: 46143 | D2: 46174 | E2: 46204 | F2: 46235 | G2: 46266 | H2: 46296 | I2: 46327 | J2: 46357 | K2: 46388 | L2: 46419 | M2: 46447 | N2: 46478 | O2: 46508 | P2: 46539 | Q2: 46569 | R2: 46600 | S2: 46631 | T2: 46661 | U2: 46692 | V2: 46722 | W2: 46753 | X2: 46784 | Y2: 46813 | Z2: 46844 | AA2: 46874 | AB2: 46905 | AC2: 46935 | AD2: 46966 | AE2: 46997 | AF2: 47027 | AG2: 47058 | AH2: 47088 | AI2: 47119 | AJ2: 47150 | AK2: 47178 | AL2: 47209 | AM2: 47239 | AN2: 47270 | AO2: 47300 | AP2: 47331 | AQ2: 47362 | AR2: 47392 | AS2: 47423 | AT2: 47453 | AU2: 47484 | AV2: 47515 | AW2: 47543 | AX2: 47574 | AY2: 47604 | AZ2: 47635 | BA2: 47665
A3: Kostenposition | B3: M1 | C3: M2 | D3: M3 | E3: M4 | F3: M5 | G3: M6 | H3: M7 | I3: M8 | J3: M9 | K3: M10 | L3: M11 | M3: M12 | N3: M13 | O3: M14 | P3: M15 | Q3: M16 | R3: M17 | S3: M18 | T3: M19 | U3: M20 | V3: M21 | W3: M22 | X3: M23 | Y3: M24 | Z3: M25 | AA3: M26 | AB3: M27 | AC3: M28 | AD3: M29 | AE3: M30 | AF3: M31 | AG3: M32 | AH3: M33 | AI3: M34 | AJ3: M35 | AK3: M36 | AL3: M37 | AM3: M38 | AN3: M39 | AO3: M40 | AP3: M41 | AQ3: M42 | AR3: M43 | AS3: M44 | AT3: M45 | AU3: M46 | AV3: M47 | AW3: M48 | AX3: M49 | AY3: M50 | AZ3: M51 | BA3: M52
A4: HEADCOUNT PLAN
A5: Executives (CEO, CTO, CCO) | B5: 3 | C5: 3 | D5: 3 | E5: 3 | F5: 3 | G5: 3 | H5: 3 | I5: 3 | J5: 3 | K5: 3 | L5: 3 | M5: 3 | N5: 3 | O5: 3 | P5: 3 | Q5: 3 | R5: 3 | S5: 3 | T5: 3 | U5: 3 | V5: 3 | W5: 3 | X5: 3 | Y5: 3 | Z5: 3 | AA5: 3 | AB5: 3 | AC5: 3 | AD5: 3 | AE5: 3 | AF5: 3 | AG5: 3 | AH5: 3 | AI5: 3 | AJ5: 3 | AK5: 3 | AL5: 3 | AM5: 3 | AN5: 3 | AO5: 3 | AP5: 3 | AQ5: 3 | AR5: 3 | AS5: 3 | AT5: 3 | AU5: 3 | AV5: 3 | AW5: 3 | AX5: 3 | AY5: 3 | AZ5: 3 | BA5: 3
A6: 1. Senior Engineer | B6: =IF(1>=Inputs!$B$47,1,0) -> 0 | C6: =IF(2>=Inputs!$B$47,1,0) -> 0 | D6: =IF(3>=Inputs!$B$47,1,0) -> 0 | E6: =IF(4>=Inputs!$B$47,1,0) -> 0 | F6: =IF(5>=Inputs!$B$47,1,0) -> 0 | G6: =IF(6>=Inputs!$B$47,1,0) -> 0 | H6: =IF(7>=Inputs!$B$47,1,0) -> 1 | I6: =IF(8>=Inputs!$B$47,1,0) -> 1 | J6: =IF(9>=Inputs!$B$47,1,0) -> 1 | K6: =IF(10>=Inputs!$B$47,1,0) -> 1 | L6: =IF(11>=Inputs!$B$47,1,0) -> 1 | M6: =IF(12>=Inputs!$B$47,1,0) -> 1 | N6: =IF(13>=Inputs!$B$47,1,0) -> 1 | O6: =IF(14>=Inputs!$B$47,1,0) -> 1 | P6: =IF(15>=Inputs!$B$47,1,0) -> 1 | Q6: =IF(16>=Inputs!$B$47,1,0) -> 1 | R6: =IF(17>=Inputs!$B$47,1,0) -> 1 | S6: =IF(18>=Inputs!$B$47,1,0) -> 1 | T6: =IF(19>=Inputs!$B$47,1,0) -> 1 | U6: =IF(20>=Inputs!$B$47,1,0) -> 1 | V6: =IF(21>=Inputs!$B$47,1,0) -> 1 | W6: =IF(22>=Inputs!$B$47,1,0) -> 1 | X6: =IF(23>=Inputs!$B$47,1,0) -> 1 | Y6: =IF(24>=Inputs!$B$47,1,0) -> 1 | Z6: =IF(25>=Inputs!$B$47,1,0) -> 1 | AA6: =IF(26>=Inputs!$B$47,1,0) -> 1 | AB6: =IF(27>=Inputs!$B$47,1,0) -> 1 | AC6: =IF(28>=Inputs!$B$47,1,0) -> 1 | AD6: =IF(29>=Inputs!$B$47,1,0) -> 1 | AE6: =IF(30>=Inputs!$B$47,1,0) -> 1 | AF6: =IF(31>=Inputs!$B$47,1,0) -> 1 | AG6: =IF(32>=Inputs!$B$47,1,0) -> 1 | AH6: =IF(33>=Inputs!$B$47,1,0) -> 1 | AI6: =IF(34>=Inputs!$B$47,1,0) -> 1 | AJ6: =IF(35>=Inputs!$B$47,1,0) -> 1 | AK6: =IF(36>=Inputs!$B$47,1,0) -> 1 | AL6: =IF(37>=Inputs!$B$47,1,0) -> 1 | AM6: =IF(38>=Inputs!$B$47,1,0) -> 1 | AN6: =IF(39>=Inputs!$B$47,1,0) -> 1 | AO6: =IF(40>=Inputs!$B$47,1,0) -> 1 | AP6: =IF(41>=Inputs!$B$47,1,0) -> 1 | AQ6: =IF(42>=Inputs!$B$47,1,0) -> 1 | AR6: =IF(43>=Inputs!$B$47,1,0) -> 1 | AS6: =IF(44>=Inputs!$B$47,1,0) -> 1 | AT6: =IF(45>=Inputs!$B$47,1,0) -> 1 | AU6: =IF(46>=Inputs!$B$47,1,0) -> 1 | AV6: =IF(47>=Inputs!$B$47,1,0) -> 1 | AW6: =IF(48>=Inputs!$B$47,1,0) -> 1 | AX6: =IF(49>=Inputs!$B$47,1,0) -> 1 | AY6: =IF(50>=Inputs!$B$47,1,0) -> 1 | AZ6: =IF(51>=Inputs!$B$47,1,0) -> 1 | BA6: =IF(52>=Inputs!$B$47,1,0) -> 1
A7: 2. Senior Engineer | B7: =IF(1>=Inputs!$B$48,1,0) -> 0 | C7: =IF(2>=Inputs!$B$48,1,0) -> 0 | D7: =IF(3>=Inputs!$B$48,1,0) -> 0 | E7: =IF(4>=Inputs!$B$48,1,0) -> 0 | F7: =IF(5>=Inputs!$B$48,1,0) -> 0 | G7: =IF(6>=Inputs!$B$48,1,0) -> 0 | H7: =IF(7>=Inputs!$B$48,1,0) -> 0 | I7: =IF(8>=Inputs!$B$48,1,0) -> 0 | J7: =IF(9>=Inputs!$B$48,1,0) -> 0 | K7: =IF(10>=Inputs!$B$48,1,0) -> 1 | L7: =IF(11>=Inputs!$B$48,1,0) -> 1 | M7: =IF(12>=Inputs!$B$48,1,0) -> 1 | N7: =IF(13>=Inputs!$B$48,1,0) -> 1 | O7: =IF(14>=Inputs!$B$48,1,0) -> 1 | P7: =IF(15>=Inputs!$B$48,1,0) -> 1 | Q7: =IF(16>=Inputs!$B$48,1,0) -> 1 | R7: =IF(17>=Inputs!$B$48,1,0) -> 1 | S7: =IF(18>=Inputs!$B$48,1,0) -> 1 | T7: =IF(19>=Inputs!$B$48,1,0) -> 1 | U7: =IF(20>=Inputs!$B$48,1,0) -> 1 | V7: =IF(21>=Inputs!$B$48,1,0) -> 1 | W7: =IF(22>=Inputs!$B$48,1,0) -> 1 | X7: =IF(23>=Inputs!$B$48,1,0) -> 1 | Y7: =IF(24>=Inputs!$B$48,1,0) -> 1 | Z7: =IF(25>=Inputs!$B$48,1,0) -> 1 | AA7: =IF(26>=Inputs!$B$48,1,0) -> 1 | AB7: =IF(27>=Inputs!$B$48,1,0) -> 1 | AC7: =IF(28>=Inputs!$B$48,1,0) -> 1 | AD7: =IF(29>=Inputs!$B$48,1,0) -> 1 | AE7: =IF(30>=Inputs!$B$48,1,0) -> 1 | AF7: =IF(31>=Inputs!$B$48,1,0) -> 1 | AG7: =IF(32>=Inputs!$B$48,1,0) -> 1 | AH7: =IF(33>=Inputs!$B$48,1,0) -> 1 | AI7: =IF(34>=Inputs!$B$48,1,0) -> 1 | AJ7: =IF(35>=Inputs!$B$48,1,0) -> 1 | AK7: =IF(36>=Inputs!$B$48,1,0) -> 1 | AL7: =IF(37>=Inputs!$B$48,1,0) -> 1 | AM7: =IF(38>=Inputs!$B$48,1,0) -> 1 | AN7: =IF(39>=Inputs!$B$48,1,0) -> 1 | AO7: =IF(40>=Inputs!$B$48,1,0) -> 1 | AP7: =IF(41>=Inputs!$B$48,1,0) -> 1 | AQ7: =IF(42>=Inputs!$B$48,1,0) -> 1 | AR7: =IF(43>=Inputs!$B$48,1,0) -> 1 | AS7: =IF(44>=Inputs!$B$48,1,0) -> 1 | AT7: =IF(45>=Inputs!$B$48,1,0) -> 1 | AU7: =IF(46>=Inputs!$B$48,1,0) -> 1 | AV7: =IF(47>=Inputs!$B$48,1,0) -> 1 | AW7: =IF(48>=Inputs!$B$48,1,0) -> 1 | AX7: =IF(49>=Inputs!$B$48,1,0) -> 1 | AY7: =IF(50>=Inputs!$B$48,1,0) -> 1 | AZ7: =IF(51>=Inputs!$B$48,1,0) -> 1 | BA7: =IF(52>=Inputs!$B$48,1,0) -> 1
A8: 1. Junior Engineer | B8: =IF(1>=Inputs!$B$49,1,0) -> 0 | C8: =IF(2>=Inputs!$B$49,1,0) -> 0 | D8: =IF(3>=Inputs!$B$49,1,0) -> 0 | E8: =IF(4>=Inputs!$B$49,1,0) -> 0 | F8: =IF(5>=Inputs!$B$49,1,0) -> 0 | G8: =IF(6>=Inputs!$B$49,1,0) -> 0 | H8: =IF(7>=Inputs!$B$49,1,0) -> 0 | I8: =IF(8>=Inputs!$B$49,1,0) -> 0 | J8: =IF(9>=Inputs!$B$49,1,0) -> 1 | K8: =IF(10>=Inputs!$B$49,1,0) -> 1 | L8: =IF(11>=Inputs!$B$49,1,0) -> 1 | M8: =IF(12>=Inputs!$B$49,1,0) -> 1 | N8: =IF(13>=Inputs!$B$49,1,0) -> 1 | O8: =IF(14>=Inputs!$B$49,1,0) -> 1 | P8: =IF(15>=Inputs!$B$49,1,0) -> 1 | Q8: =IF(16>=Inputs!$B$49,1,0) -> 1 | R8: =IF(17>=Inputs!$B$49,1,0) -> 1 | S8: =IF(18>=Inputs!$B$49,1,0) -> 1 | T8: =IF(19>=Inputs!$B$49,1,0) -> 1 | U8: =IF(20>=Inputs!$B$49,1,0) -> 1 | V8: =IF(21>=Inputs!$B$49,1,0) -> 1 | W8: =IF(22>=Inputs!$B$49,1,0) -> 1 | X8: =IF(23>=Inputs!$B$49,1,0) -> 1 | Y8: =IF(24>=Inputs!$B$49,1,0) -> 1 | Z8: =IF(25>=Inputs!$B$49,1,0) -> 1 | AA8: =IF(26>=Inputs!$B$49,1,0) -> 1 | AB8: =IF(27>=Inputs!$B$49,1,0) -> 1 | AC8: =IF(28>=Inputs!$B$49,1,0) -> 1 | AD8: =IF(29>=Inputs!$B$49,1,0) -> 1 | AE8: =IF(30>=Inputs!$B$49,1,0) -> 1 | AF8: =IF(31>=Inputs!$B$49,1,0) -> 1 | AG8: =IF(32>=Inputs!$B$49,1,0) -> 1 | AH8: =IF(33>=Inputs!$B$49,1,0) -> 1 | AI8: =IF(34>=Inputs!$B$49,1,0) -> 1 | AJ8: =IF(35>=Inputs!$B$49,1,0) -> 1 | AK8: =IF(36>=Inputs!$B$49,1,0) -> 1 | AL8: =IF(37>=Inputs!$B$49,1,0) -> 1 | AM8: =IF(38>=Inputs!$B$49,1,0) -> 1 | AN8: =IF(39>=Inputs!$B$49,1,0) -> 1 | AO8: =IF(40>=Inputs!$B$49,1,0) -> 1 | AP8: =IF(41>=Inputs!$B$49,1,0) -> 1 | AQ8: =IF(42>=Inputs!$B$49,1,0) -> 1 | AR8: =IF(43>=Inputs!$B$49,1,0) -> 1 | AS8: =IF(44>=Inputs!$B$49,1,0) -> 1 | AT8: =IF(45>=Inputs!$B$49,1,0) -> 1 | AU8: =IF(46>=Inputs!$B$49,1,0) -> 1 | AV8: =IF(47>=Inputs!$B$49,1,0) -> 1 | AW8: =IF(48>=Inputs!$B$49,1,0) -> 1 | AX8: =IF(49>=Inputs!$B$49,1,0) -> 1 | AY8: =IF(50>=Inputs!$B$49,1,0) -> 1 | AZ8: =IF(51>=Inputs!$B$49,1,0) -> 1 | BA8: =IF(52>=Inputs!$B$49,1,0) -> 1
A9: 1. ML/AI Engineer | B9: =IF(1>=Inputs!$B$50,1,0) -> 0 | C9: =IF(2>=Inputs!$B$50,1,0) -> 0 | D9: =IF(3>=Inputs!$B$50,1,0) -> 0 | E9: =IF(4>=Inputs!$B$50,1,0) -> 0 | F9: =IF(5>=Inputs!$B$50,1,0) -> 0 | G9: =IF(6>=Inputs!$B$50,1,0) -> 0 | H9: =IF(7>=Inputs!$B$50,1,0) -> 0 | I9: =IF(8>=Inputs!$B$50,1,0) -> 1 | J9: =IF(9>=Inputs!$B$50,1,0) -> 1 | K9: =IF(10>=Inputs!$B$50,1,0) -> 1 | L9: =IF(11>=Inputs!$B$50,1,0) -> 1 | M9: =IF(12>=Inputs!$B$50,1,0) -> 1 | N9: =IF(13>=Inputs!$B$50,1,0) -> 1 | O9: =IF(14>=Inputs!$B$50,1,0) -> 1 | P9: =IF(15>=Inputs!$B$50,1,0) -> 1 | Q9: =IF(16>=Inputs!$B$50,1,0) -> 1 | R9: =IF(17>=Inputs!$B$50,1,0) -> 1 | S9: =IF(18>=Inputs!$B$50,1,0) -> 1 | T9: =IF(19>=Inputs!$B$50,1,0) -> 1 | U9: =IF(20>=Inputs!$B$50,1,0) -> 1 | V9: =IF(21>=Inputs!$B$50,1,0) -> 1 | W9: =IF(22>=Inputs!$B$50,1,0) -> 1 | X9: =IF(23>=Inputs!$B$50,1,0) -> 1 | Y9: =IF(24>=Inputs!$B$50,1,0) -> 1 | Z9: =IF(25>=Inputs!$B$50,1,0) -> 1 | AA9: =IF(26>=Inputs!$B$50,1,0) -> 1 | AB9: =IF(27>=Inputs!$B$50,1,0) -> 1 | AC9: =IF(28>=Inputs!$B$50,1,0) -> 1 | AD9: =IF(29>=Inputs!$B$50,1,0) -> 1 | AE9: =IF(30>=Inputs!$B$50,1,0) -> 1 | AF9: =IF(31>=Inputs!$B$50,1,0) -> 1 | AG9: =IF(32>=Inputs!$B$50,1,0) -> 1 | AH9: =IF(33>=Inputs!$B$50,1,0) -> 1 | AI9: =IF(34>=Inputs!$B$50,1,0) -> 1 | AJ9: =IF(35>=Inputs!$B$50,1,0) -> 1 | AK9: =IF(36>=Inputs!$B$50,1,0) -> 1 | AL9: =IF(37>=Inputs!$B$50,1,0) -> 1 | AM9: =IF(38>=Inputs!$B$50,1,0) -> 1 | AN9: =IF(39>=Inputs!$B$50,1,0) -> 1 | AO9: =IF(40>=Inputs!$B$50,1,0) -> 1 | AP9: =IF(41>=Inputs!$B$50,1,0) -> 1 | AQ9: =IF(42>=Inputs!$B$50,1,0) -> 1 | AR9: =IF(43>=Inputs!$B$50,1,0) -> 1 | AS9: =IF(44>=Inputs!$B$50,1,0) -> 1 | AT9: =IF(45>=Inputs!$B$50,1,0) -> 1 | AU9: =IF(46>=Inputs!$B$50,1,0) -> 1 | AV9: =IF(47>=Inputs!$B$50,1,0) -> 1 | AW9: =IF(48>=Inputs!$B$50,1,0) -> 1 | AX9: =IF(49>=Inputs!$B$50,1,0) -> 1 | AY9: =IF(50>=Inputs!$B$50,1,0) -> 1 | AZ9: =IF(51>=Inputs!$B$50,1,0) -> 1 | BA9: =IF(52>=Inputs!$B$50,1,0) -> 1
A10: 2. ML/AI Engineer | B10: =IF(1>=Inputs!$B$51,1,0) -> 0 | C10: =IF(2>=Inputs!$B$51,1,0) -> 0 | D10: =IF(3>=Inputs!$B$51,1,0) -> 0 | E10: =IF(4>=Inputs!$B$51,1,0) -> 0 | F10: =IF(5>=Inputs!$B$51,1,0) -> 0 | G10: =IF(6>=Inputs!$B$51,1,0) -> 0 | H10: =IF(7>=Inputs!$B$51,1,0) -> 0 | I10: =IF(8>=Inputs!$B$51,1,0) -> 0 | J10: =IF(9>=Inputs!$B$51,1,0) -> 0 | K10: =IF(10>=Inputs!$B$51,1,0) -> 0 | L10: =IF(11>=Inputs!$B$51,1,0) -> 0 | M10: =IF(12>=Inputs!$B$51,1,0) -> 0 | N10: =IF(13>=Inputs!$B$51,1,0) -> 0 | O10: =IF(14>=Inputs!$B$51,1,0) -> 1 | P10: =IF(15>=Inputs!$B$51,1,0) -> 1 | Q10: =IF(16>=Inputs!$B$51,1,0) -> 1 | R10: =IF(17>=Inputs!$B$51,1,0) -> 1 | S10: =IF(18>=Inputs!$B$51,1,0) -> 1 | T10: =IF(19>=Inputs!$B$51,1,0) -> 1 | U10: =IF(20>=Inputs!$B$51,1,0) -> 1 | V10: =IF(21>=Inputs!$B$51,1,0) -> 1 | W10: =IF(22>=Inputs!$B$51,1,0) -> 1 | X10: =IF(23>=Inputs!$B$51,1,0) -> 1 | Y10: =IF(24>=Inputs!$B$51,1,0) -> 1 | Z10: =IF(25>=Inputs!$B$51,1,0) -> 1 | AA10: =IF(26>=Inputs!$B$51,1,0) -> 1 | AB10: =IF(27>=Inputs!$B$51,1,0) -> 1 | AC10: =IF(28>=Inputs!$B$51,1,0) -> 1 | AD10: =IF(29>=Inputs!$B$51,1,0) -> 1 | AE10: =IF(30>=Inputs!$B$51,1,0) -> 1 | AF10: =IF(31>=Inputs!$B$51,1,0) -> 1 | AG10: =IF(32>=Inputs!$B$51,1,0) -> 1 | AH10: =IF(33>=Inputs!$B$51,1,0) -> 1 | AI10: =IF(34>=Inputs!$B$51,1,0) -> 1 | AJ10: =IF(35>=Inputs!$B$51,1,0) -> 1 | AK10: =IF(36>=Inputs!$B$51,1,0) -> 1 | AL10: =IF(37>=Inputs!$B$51,1,0) -> 1 | AM10: =IF(38>=Inputs!$B$51,1,0) -> 1 | AN10: =IF(39>=Inputs!$B$51,1,0) -> 1 | AO10: =IF(40>=Inputs!$B$51,1,0) -> 1 | AP10: =IF(41>=Inputs!$B$51,1,0) -> 1 | AQ10: =IF(42>=Inputs!$B$51,1,0) -> 1 | AR10: =IF(43>=Inputs!$B$51,1,0) -> 1 | AS10: =IF(44>=Inputs!$B$51,1,0) -> 1 | AT10: =IF(45>=Inputs!$B$51,1,0) -> 1 | AU10: =IF(46>=Inputs!$B$51,1,0) -> 1 | AV10: =IF(47>=Inputs!$B$51,1,0) -> 1 | AW10: =IF(48>=Inputs!$B$51,1,0) -> 1 | AX10: =IF(49>=Inputs!$B$51,1,0) -> 1 | AY10: =IF(50>=Inputs!$B$51,1,0) -> 1 | AZ10: =IF(51>=Inputs!$B$51,1,0) -> 1 | BA10: =IF(52>=Inputs!$B$51,1,0) -> 1
A11: 1. Sales Rep | B11: =IF(1>=Inputs!$B$52,1,0) -> 0 | C11: =IF(2>=Inputs!$B$52,1,0) -> 0 | D11: =IF(3>=Inputs!$B$52,1,0) -> 0 | E11: =IF(4>=Inputs!$B$52,1,0) -> 0 | F11: =IF(5>=Inputs!$B$52,1,0) -> 0 | G11: =IF(6>=Inputs!$B$52,1,0) -> 0 | H11: =IF(7>=Inputs!$B$52,1,0) -> 0 | I11: =IF(8>=Inputs!$B$52,1,0) -> 0 | J11: =IF(9>=Inputs!$B$52,1,0) -> 0 | K11: =IF(10>=Inputs!$B$52,1,0) -> 1 | L11: =IF(11>=Inputs!$B$52,1,0) -> 1 | M11: =IF(12>=Inputs!$B$52,1,0) -> 1 | N11: =IF(13>=Inputs!$B$52,1,0) -> 1 | O11: =IF(14>=Inputs!$B$52,1,0) -> 1 | P11: =IF(15>=Inputs!$B$52,1,0) -> 1 | Q11: =IF(16>=Inputs!$B$52,1,0) -> 1 | R11: =IF(17>=Inputs!$B$52,1,0) -> 1 | S11: =IF(18>=Inputs!$B$52,1,0) -> 1 | T11: =IF(19>=Inputs!$B$52,1,0) -> 1 | U11: =IF(20>=Inputs!$B$52,1,0) -> 1 | V11: =IF(21>=Inputs!$B$52,1,0) -> 1 | W11: =IF(22>=Inputs!$B$52,1,0) -> 1 | X11: =IF(23>=Inputs!$B$52,1,0) -> 1 | Y11: =IF(24>=Inputs!$B$52,1,0) -> 1 | Z11: =IF(25>=Inputs!$B$52,1,0) -> 1 | AA11: =IF(26>=Inputs!$B$52,1,0) -> 1 | AB11: =IF(27>=Inputs!$B$52,1,0) -> 1 | AC11: =IF(28>=Inputs!$B$52,1,0) -> 1 | AD11: =IF(29>=Inputs!$B$52,1,0) -> 1 | AE11: =IF(30>=Inputs!$B$52,1,0) -> 1 | AF11: =IF(31>=Inputs!$B$52,1,0) -> 1 | AG11: =IF(32>=Inputs!$B$52,1,0) -> 1 | AH11: =IF(33>=Inputs!$B$52,1,0) -> 1 | AI11: =IF(34>=Inputs!$B$52,1,0) -> 1 | AJ11: =IF(35>=Inputs!$B$52,1,0) -> 1 | AK11: =IF(36>=Inputs!$B$52,1,0) -> 1 | AL11: =IF(37>=Inputs!$B$52,1,0) -> 1 | AM11: =IF(38>=Inputs!$B$52,1,0) -> 1 | AN11: =IF(39>=Inputs!$B$52,1,0) -> 1 | AO11: =IF(40>=Inputs!$B$52,1,0) -> 1 | AP11: =IF(41>=Inputs!$B$52,1,0) -> 1 | AQ11: =IF(42>=Inputs!$B$52,1,0) -> 1 | AR11: =IF(43>=Inputs!$B$52,1,0) -> 1 | AS11: =IF(44>=Inputs!$B$52,1,0) -> 1 | AT11: =IF(45>=Inputs!$B$52,1,0) -> 1 | AU11: =IF(46>=Inputs!$B$52,1,0) -> 1 | AV11: =IF(47>=Inputs!$B$52,1,0) -> 1 | AW11: =IF(48>=Inputs!$B$52,1,0) -> 1 | AX11: =IF(49>=Inputs!$B$52,1,0) -> 1 | AY11: =IF(50>=Inputs!$B$52,1,0) -> 1 | AZ11: =IF(51>=Inputs!$B$52,1,0) -> 1 | BA11: =IF(52>=Inputs!$B$52,1,0) -> 1
A12: 2. Sales Rep | B12: =IF(1>=Inputs!$B$53,1,0) -> 0 | C12: =IF(2>=Inputs!$B$53,1,0) -> 0 | D12: =IF(3>=Inputs!$B$53,1,0) -> 0 | E12: =IF(4>=Inputs!$B$53,1,0) -> 0 | F12: =IF(5>=Inputs!$B$53,1,0) -> 0 | G12: =IF(6>=Inputs!$B$53,1,0) -> 0 | H12: =IF(7>=Inputs!$B$53,1,0) -> 0 | I12: =IF(8>=Inputs!$B$53,1,0) -> 0 | J12: =IF(9>=Inputs!$B$53,1,0) -> 0 | K12: =IF(10>=Inputs!$B$53,1,0) -> 0 | L12: =IF(11>=Inputs!$B$53,1,0) -> 0 | M12: =IF(12>=Inputs!$B$53,1,0) -> 0 | N12: =IF(13>=Inputs!$B$53,1,0) -> 0 | O12: =IF(14>=Inputs!$B$53,1,0) -> 0 | P12: =IF(15>=Inputs!$B$53,1,0) -> 0 | Q12: =IF(16>=Inputs!$B$53,1,0) -> 0 | R12: =IF(17>=Inputs!$B$53,1,0) -> 0 | S12: =IF(18>=Inputs!$B$53,1,0) -> 1 | T12: =IF(19>=Inputs!$B$53,1,0) -> 1 | U12: =IF(20>=Inputs!$B$53,1,0) -> 1 | V12: =IF(21>=Inputs!$B$53,1,0) -> 1 | W12: =IF(22>=Inputs!$B$53,1,0) -> 1 | X12: =IF(23>=Inputs!$B$53,1,0) -> 1 | Y12: =IF(24>=Inputs!$B$53,1,0) -> 1 | Z12: =IF(25>=Inputs!$B$53,1,0) -> 1 | AA12: =IF(26>=Inputs!$B$53,1,0) -> 1 | AB12: =IF(27>=Inputs!$B$53,1,0) -> 1 | AC12: =IF(28>=Inputs!$B$53,1,0) -> 1 | AD12: =IF(29>=Inputs!$B$53,1,0) -> 1 | AE12: =IF(30>=Inputs!$B$53,1,0) -> 1 | AF12: =IF(31>=Inputs!$B$53,1,0) -> 1 | AG12: =IF(32>=Inputs!$B$53,1,0) -> 1 | AH12: =IF(33>=Inputs!$B$53,1,0) -> 1 | AI12: =IF(34>=Inputs!$B$53,1,0) -> 1 | AJ12: =IF(35>=Inputs!$B$53,1,0) -> 1 | AK12: =IF(36>=Inputs!$B$53,1,0) -> 1 | AL12: =IF(37>=Inputs!$B$53,1,0) -> 1 | AM12: =IF(38>=Inputs!$B$53,1,0) -> 1 | AN12: =IF(39>=Inputs!$B$53,1,0) -> 1 | AO12: =IF(40>=Inputs!$B$53,1,0) -> 1 | AP12: =IF(41>=Inputs!$B$53,1,0) -> 1 | AQ12: =IF(42>=Inputs!$B$53,1,0) -> 1 | AR12: =IF(43>=Inputs!$B$53,1,0) -> 1 | AS12: =IF(44>=Inputs!$B$53,1,0) -> 1 | AT12: =IF(45>=Inputs!$B$53,1,0) -> 1 | AU12: =IF(46>=Inputs!$B$53,1,0) -> 1 | AV12: =IF(47>=Inputs!$B$53,1,0) -> 1 | AW12: =IF(48>=Inputs!$B$53,1,0) -> 1 | AX12: =IF(49>=Inputs!$B$53,1,0) -> 1 | AY12: =IF(50>=Inputs!$B$53,1,0) -> 1 | AZ12: =IF(51>=Inputs!$B$53,1,0) -> 1 | BA12: =IF(52>=Inputs!$B$53,1,0) -> 1
A13: 1. Customer Success | B13: =IF(1>=Inputs!$B$54,1,0) -> 0 | C13: =IF(2>=Inputs!$B$54,1,0) -> 0 | D13: =IF(3>=Inputs!$B$54,1,0) -> 0 | E13: =IF(4>=Inputs!$B$54,1,0) -> 0 | F13: =IF(5>=Inputs!$B$54,1,0) -> 0 | G13: =IF(6>=Inputs!$B$54,1,0) -> 0 | H13: =IF(7>=Inputs!$B$54,1,0) -> 0 | I13: =IF(8>=Inputs!$B$54,1,0) -> 0 | J13: =IF(9>=Inputs!$B$54,1,0) -> 0 | K13: =IF(10>=Inputs!$B$54,1,0) -> 0 | L13: =IF(11>=Inputs!$B$54,1,0) -> 0 | M13: =IF(12>=Inputs!$B$54,1,0) -> 1 | N13: =IF(13>=Inputs!$B$54,1,0) -> 1 | O13: =IF(14>=Inputs!$B$54,1,0) -> 1 | P13: =IF(15>=Inputs!$B$54,1,0) -> 1 | Q13: =IF(16>=Inputs!$B$54,1,0) -> 1 | R13: =IF(17>=Inputs!$B$54,1,0) -> 1 | S13: =IF(18>=Inputs!$B$54,1,0) -> 1 | T13: =IF(19>=Inputs!$B$54,1,0) -> 1 | U13: =IF(20>=Inputs!$B$54,1,0) -> 1 | V13: =IF(21>=Inputs!$B$54,1,0) -> 1 | W13: =IF(22>=Inputs!$B$54,1,0) -> 1 | X13: =IF(23>=Inputs!$B$54,1,0) -> 1 | Y13: =IF(24>=Inputs!$B$54,1,0) -> 1 | Z13: =IF(25>=Inputs!$B$54,1,0) -> 1 | AA13: =IF(26>=Inputs!$B$54,1,0) -> 1 | AB13: =IF(27>=Inputs!$B$54,1,0) -> 1 | AC13: =IF(28>=Inputs!$B$54,1,0) -> 1 | AD13: =IF(29>=Inputs!$B$54,1,0) -> 1 | AE13: =IF(30>=Inputs!$B$54,1,0) -> 1 | AF13: =IF(31>=Inputs!$B$54,1,0) -> 1 | AG13: =IF(32>=Inputs!$B$54,1,0) -> 1 | AH13: =IF(33>=Inputs!$B$54,1,0) -> 1 | AI13: =IF(34>=Inputs!$B$54,1,0) -> 1 | AJ13: =IF(35>=Inputs!$B$54,1,0) -> 1 | AK13: =IF(36>=Inputs!$B$54,1,0) -> 1 | AL13: =IF(37>=Inputs!$B$54,1,0) -> 1 | AM13: =IF(38>=Inputs!$B$54,1,0) -> 1 | AN13: =IF(39>=Inputs!$B$54,1,0) -> 1 | AO13: =IF(40>=Inputs!$B$54,1,0) -> 1 | AP13: =IF(41>=Inputs!$B$54,1,0) -> 1 | AQ13: =IF(42>=Inputs!$B$54,1,0) -> 1 | AR13: =IF(43>=Inputs!$B$54,1,0) -> 1 | AS13: =IF(44>=Inputs!$B$54,1,0) -> 1 | AT13: =IF(45>=Inputs!$B$54,1,0) -> 1 | AU13: =IF(46>=Inputs!$B$54,1,0) -> 1 | AV13: =IF(47>=Inputs!$B$54,1,0) -> 1 | AW13: =IF(48>=Inputs!$B$54,1,0) -> 1 | AX13: =IF(49>=Inputs!$B$54,1,0) -> 1 | AY13: =IF(50>=Inputs!$B$54,1,0) -> 1 | AZ13: =IF(51>=Inputs!$B$54,1,0) -> 1 | BA13: =IF(52>=Inputs!$B$54,1,0) -> 1
A14: 1. Marketing Manager | B14: =IF(1>=Inputs!$B$55,1,0) -> 0 | C14: =IF(2>=Inputs!$B$55,1,0) -> 0 | D14: =IF(3>=Inputs!$B$55,1,0) -> 0 | E14: =IF(4>=Inputs!$B$55,1,0) -> 0 | F14: =IF(5>=Inputs!$B$55,1,0) -> 0 | G14: =IF(6>=Inputs!$B$55,1,0) -> 0 | H14: =IF(7>=Inputs!$B$55,1,0) -> 0 | I14: =IF(8>=Inputs!$B$55,1,0) -> 0 | J14: =IF(9>=Inputs!$B$55,1,0) -> 0 | K14: =IF(10>=Inputs!$B$55,1,0) -> 0 | L14: =IF(11>=Inputs!$B$55,1,0) -> 1 | M14: =IF(12>=Inputs!$B$55,1,0) -> 1 | N14: =IF(13>=Inputs!$B$55,1,0) -> 1 | O14: =IF(14>=Inputs!$B$55,1,0) -> 1 | P14: =IF(15>=Inputs!$B$55,1,0) -> 1 | Q14: =IF(16>=Inputs!$B$55,1,0) -> 1 | R14: =IF(17>=Inputs!$B$55,1,0) -> 1 | S14: =IF(18>=Inputs!$B$55,1,0) -> 1 | T14: =IF(19>=Inputs!$B$55,1,0) -> 1 | U14: =IF(20>=Inputs!$B$55,1,0) -> 1 | V14: =IF(21>=Inputs!$B$55,1,0) -> 1 | W14: =IF(22>=Inputs!$B$55,1,0) -> 1 | X14: =IF(23>=Inputs!$B$55,1,0) -> 1 | Y14: =IF(24>=Inputs!$B$55,1,0) -> 1 | Z14: =IF(25>=Inputs!$B$55,1,0) -> 1 | AA14: =IF(26>=Inputs!$B$55,1,0) -> 1 | AB14: =IF(27>=Inputs!$B$55,1,0) -> 1 | AC14: =IF(28>=Inputs!$B$55,1,0) -> 1 | AD14: =IF(29>=Inputs!$B$55,1,0) -> 1 | AE14: =IF(30>=Inputs!$B$55,1,0) -> 1 | AF14: =IF(31>=Inputs!$B$55,1,0) -> 1 | AG14: =IF(32>=Inputs!$B$55,1,0) -> 1 | AH14: =IF(33>=Inputs!$B$55,1,0) -> 1 | AI14: =IF(34>=Inputs!$B$55,1,0) -> 1 | AJ14: =IF(35>=Inputs!$B$55,1,0) -> 1 | AK14: =IF(36>=Inputs!$B$55,1,0) -> 1 | AL14: =IF(37>=Inputs!$B$55,1,0) -> 1 | AM14: =IF(38>=Inputs!$B$55,1,0) -> 1 | AN14: =IF(39>=Inputs!$B$55,1,0) -> 1 | AO14: =IF(40>=Inputs!$B$55,1,0) -> 1 | AP14: =IF(41>=Inputs!$B$55,1,0) -> 1 | AQ14: =IF(42>=Inputs!$B$55,1,0) -> 1 | AR14: =IF(43>=Inputs!$B$55,1,0) -> 1 | AS14: =IF(44>=Inputs!$B$55,1,0) -> 1 | AT14: =IF(45>=Inputs!$B$55,1,0) -> 1 | AU14: =IF(46>=Inputs!$B$55,1,0) -> 1 | AV14: =IF(47>=Inputs!$B$55,1,0) -> 1 | AW14: =IF(48>=Inputs!$B$55,1,0) -> 1 | AX14: =IF(49>=Inputs!$B$55,1,0) -> 1 | AY14: =IF(50>=Inputs!$B$55,1,0) -> 1 | AZ14: =IF(51>=Inputs!$B$55,1,0) -> 1 | BA14: =IF(52>=Inputs!$B$55,1,0) -> 1
