Workbook

Sheet Anleitung
A1: LoopforgeLab GmbH – Financial Projection Model
A3: Projektionszeitraum: 52 Monate (ca. 4,3 Jahre)
A5: INHALTSVERZEICHNIS
A6: Sheet 1: Anleitung – Diese Seite mit Übersicht und Legende
A7: Sheet 2: Inputs – Zentrale Eingabewerte (HIER STARTEN)
A8: Sheet 3: P&L – Gewinn- und Verlustrechnung (monatlich + jährlich)
A9: Sheet 4: Revenue – Detaillierte Umsatzmodellierung
A10: Sheet 5: Costs – Detaillierte Kostenaufschlüsselung
A11: Sheet 6: Balance Sheet – Vereinfachte Bilanz
A12: Sheet 7: Cash Flow – Kapitalflussrechnung mit Runway
A14: FARBCODIERUNG
A15: Blau | B15: Editierbare Eingabefelder
A16: Schwarz | B16: Formeln – nicht manuell ändern
A17: Grün | B17: Verweise auf andere Sheets
A18: Gelb hinterlegt | B18: Kritische Annahmen
A20: KURZANLEITUNG
A21: 1. Gehen Sie zum Sheet 'Inputs' und passen Sie alle blau markierten Werte an.
A22: 2. Alle anderen Sheets berechnen sich automatisch aus den Inputs.
A23: 3. Prüfen Sie die P&L, Revenue und Cash Flow Sheets auf Plausibilität.
A24: 4. Achten Sie auf rot markierte Warnungen (z.B. Runway < 6 Monate).
A25: 5. Exportieren Sie relevante Sheets als PDF für Investoren-Präsentationen.
A27: DISCLAIMER: Diese Projektion dient ausschließlich der Planung.
A28: Tatsächliche Ergebnisse können erheblich abweichen. Keine Garantie.

Sheet Treiber_Matrix
A1: LoopForgeLab – Treiber- & Annahmen-Matrix (importiert aus 260305_LFL_Treiber_Matrix_v1.xlsx)
A2: Alle Umsatz- und Kostentreiber | Szenarien: Gering · Normal · Stark | Spalten L & M: Eigene Bewertungen und Alternativwerte | NEU-markierte Zeilen: noch nicht im Modell — Entwicklungspotenzial
A3: Kategorie | B3: Unterkategorie | C3: Parameter / Treiber | D3: Aktueller Wert | E3: Einheit | F3: Szenario-Abhängigkeit | G3: Gering | H3: Normal | I3: Stark | J3: Einflussfaktor & Wirkungslogik | K3: Annahmen & Begründung | L3: ► Ihre Bewertung | M3: ► Neue Annahme
A5: Revenue 1: SaaS / Lizenzen
A6: UMSATZ | B6: SaaS / Lizenzen | C6: Startpreis pro Seat/Jahr | D6: 9.600 – 12.000 € | E6: €/Jahr | F6: Szenario | G6: 9600 | H6: 12000 | I6: 6000 | J6: Bestimmt den initialen Lizenzpreis je Nutzer-Seat. Direkter Multiplikator auf alle Lizenzerlöse. | K6: Automotive: höherer Preis durch Compliance-Wert (TISAX). Packaging: niedrigerer Einstiegspreis, Wachstum über Volumen & NRR. Value-based Pricing orientiert sich am TCO-Einsparpotenzial.
A7: UMSATZ | B7: SaaS / Lizenzen | C7: Jährliche Preiserhöhung | D7: 0.1 | E7: % p.a. | F7: Fest | G7: 0.1 | H7: 0.1 | I7: 0.1 | J7: Erhöht den Seat-Preis jährlich. Kompensiert Inflations- und Innovationskosten (Inferenz, neue Features). | K7: Standard für AI-SaaS 2026. Typisch: 3–10% p.a. Höherer Wert möglich bei starker Produktdifferenzierung.
A8: UMSATZ | B8: SaaS / Lizenzen | C8: Erster Umsatzmonat (Kunden) | D8: Monat 8–14 | E8: Monat | F8: Szenario | G8: Monat 14 | H8: Monat 8 | I8: Monat 9 | J8: Verschiebt den gesamten SaaS-Umsatz-Stream. Jeder Monat Verzögerung = direkte Liquiditätslücke. | K8: Automotive (Gering): lange Sales-Zyklen (9–12 Mon.) + TISAX-Prüfung. Packaging (Stark): kürzere IT-Entscheidungswege, frühere Piloten möglich.
A9: UMSATZ | B9: SaaS / Lizenzen | C9: Initiale Seats (1. Kunde) | D9: 5 | E9: Seats | F9: Fest | G9: 5 | H9: 5 | I9: 5 | J9: Anzahl der Seats beim ersten Kunden. Beeinflusst den initialen ARR-Wert und das Wachstums-Baseline. | K9: Konservative Annahme: 1–2 Pilotprojekte pro Werk. Land & Expand-Strategie: erst 1 Werk, dann Roll-out.
A10: UMSATZ | B10: SaaS / Lizenzen | C10: Monatliche Seat-Wachstumsrate | D10: 0.08 | E10: % / Monat | F10: Fest | G10: 0.08 | H10: 0.08 | I10: 0.08 | J10: Bestimmt, wie schnell neue Seats hinzukommen. Treiber für den kumulativen ARR-Aufbau. | K10: Alternative: Account-basierte Planung mit Stufenfunktion (Roll-out pro Werk statt linearer Rate). Realistischer Wert abhängig von Vertriebskapazität.
A11: UMSATZ | B11: SaaS / Lizenzen | C11: Enterprise-Deals ab Monat | D11: Monat 18 | E11: Monat | F11: Fest | G11: Monat 18 | H11: Monat 18 | I11: Monat 18 | J11: Ab diesem Monat werden größere Enterprise-Verträge abgeschlossen. Erhöht den durchschnittlichen ARR pro Kunde sprunghaft. | K11: Automotive: Verschiebung durch Technical Validation + Compliance. Typisch: 50.000–200.000 €/Jahr pro Enterprise-Kunde.
A12: UMSATZ | B12: SaaS / Lizenzen | C12: Durchschnittlicher Enterprise ARR | D12: 50000 | E12: €/Jahr | F12: Fest | G12: 50000 | H12: 50000 | I12: 50000 | J12: Erlös pro Enterprise-Vertrag. Beeinflusst den ARR-Sprung ab Monat 18 erheblich. | K12: Höheres Volumen durch tiefe Integration (DPP, Sustainability). Realistisch: 50.000–200.000 € je nach Kundentyp.
A13: UMSATZ | B13: SaaS / Lizenzen | C13: Enterprise Deals pro Quartal | D13: 2 | E13: Deals/Quartal | F13: Fest | G13: 2 | H13: 2 | I13: 2 | J13: Anzahl neuer Enterprise-Verträge pro Quartal. Direkter Treiber für den ARR-Aufbau nach Monat 18. | K13: Abhängig von Vertriebskapazität und Sales-Zyklus-Länge. Sollte mit Einstellungsplan abgestimmt sein.
A14: UMSATZ | B14: SaaS / Lizenzen | C14: Jährliche Churn Rate | D14: 0.06 | E14: % p.a. | F14: Fest | G14: 0.06 | H14: 0.06 | I14: 0.06 | J14: Anteil der Kunden, die jährlich abwandern. Reduziert den kumulativen ARR direkt. | K14: Konservative Planung für komplexe industrielle Buying Center. Typisch SaaS: 5–10%. Im Pilot-Jahr höher, ab Jahr 3 niedriger.
A15: UMSATZ | B15: SaaS / Lizenzen | C15: Net Revenue Retention (NRR) | D15: 1.25 | E15: % | F15: Fest | G15: 1.25 | H15: 1.25 | I15: 1.25 | J15: Expansion-Umsatz minus Churn. NRR > 100% bedeutet: Bestandskunden wachsen schneller als sie abwandern. | K15: Realisierbar durch DPP-Zusatzmodule und Material-Analytics-Upgrades. Typisch: 100–120%. 125% ist ambitioniert, aber bei starkem Upselling möglich.
A16: Revenue 2: Implementation-Support
A17: UMSATZ | B17: Implementation-Support | C17: Implementation-Support-Tagessatz | D17: 1.000 – 1.500 € | E17: €/Tag | F17: Szenario | G17: 1000 | H17: 1200 | I17: 1500 | J17: Verrechnungssatz für Beratungsleistungen. Multipliziert mit Tagen/Kunde ergibt den Erlös je Projekt. | K17: Automotive: niedrigerer Satz durch Preisdruck im Mittelstand. Packaging: höherer Satz durch Expertenstatus und Integrationskomplexität. Quelle: Marktanalyse Lothar.bm / Candemir.
A18: UMSATZ | B18: Implementation-Support | C18: Implementation-Support-Tage/Kunde | D18: 4 – 20 Tage | E18: Tage/Kunde | F18: Szenario | G18: 4 Tage | H18: 10 Tage | I18: 20 Tage | J18: Abrechnungsfähige Beratungstage je Kundenprojekt. Bestimmt zusammen mit dem Tagessatz den Erlös pro Implementation-Support-Kunde. | K18: Gering: standardisierter Onboarding-Prozess (4 Tage). Stark: tiefe Prozessintegration im Packaging (20 Tage). Formel: Implementation-Support-Umsatz/Kunde = Tagessatz × Tage/Kunde.
A19: UMSATZ | B19: Implementation-Support | C19: Implementation-Support-Umsatz/Kunde | D19: 4.000 – 30.000 € | E19: €/Kunde | F19: Berechnet | G19: 4000 | H19: 12000 | I19: 30000 | J19: Erlös pro beauftragendem Kunden. Berechnung: Tagessatz × Tage/Kunde. Beeinflusst den gesamten Implementation-Support-Umsatz-Stream. | K19: Gering: 1.000€ × 4 Tage = 4.000€/Kunde. Normal: 1.200€ × 10 Tage = 12.000€/Kunde. Stark: 1.500€ × 20 Tage = 30.000€/Kunde.
A20: UMSATZ | B20: Implementation-Support | C20: Implementation-Support-Quote (% Kunden) | D20: 20 – 100 % | E20: % Kunden | F20: Unabhängig | G20: 20 % (Niedrig) | H20: 50 % (Mittel) | I20: 100 % (Hoch) | J20: Anteil der Neukunden, die Implementation-Support beauftragen. UNABHÄNGIG vom strategischen Szenario einstellbar. Kombinierbar mit jedem der drei Szenarien (3×3-Matrix). | K20: Niedrig (20%): Self-Service-Kunden, minimaler Beratungsbedarf. Mittel (50%): Standardannahme, jeder zweite Kunde bucht Implementation-Support. Hoch (100%): Alle Kunden benötigen Onboarding-Unterstützung.
A21: UMSATZ | B21: Implementation-Support | C21: Implementation-Support-Startmonat | D21: Monat 3–6 | E21: Monat | F21: Szenario | G21: Monat 3 | H21: Monat 4 | I21: Monat 6 | J21: Monat des ersten Implementation-Support-Umsatzes. Implementation-Support startet als Enabler vor dem SaaS-Produkt. | K21: Gering: früher Start (Monat 3), da Automotive-Kunden sofort IT-Begleitung benötigen. Stark: späterer Start (Monat 6), da Packaging-Kunden länger Self-Service nutzen können.
A22: KOSTEN (OpEx)
A23: Personal & Gehälter
A24: KOSTEN | B24: Personal | C24: CEO Gehalt (Brutto/Jahr) | D24: 100000 | E24: €/Jahr | F24: Fest | G24: 100000 | H24: 100000 | I24: 100000 | J24: Gründer-Gehalt in der Pre-Seed-Phase. Beeinflusst die monatliche Burn Rate direkt. | K24: Gründer-Satz Pre-Seed. Anpassung ab Seed-Runde auf Marktgehalt. Typisch Startup: 60.000–90.000 €/Jahr.
A25: KOSTEN | B25: Personal | C25: CTO Gehalt (Brutto/Jahr) | D25: 100000 | E25: €/Jahr | F25: Fest | G25: 100000 | H25: 100000 | I25: 100000 | J25: Gründer-Gehalt in der Pre-Seed-Phase. Beeinflusst die monatliche Burn Rate direkt. | K25: Gründer-Satz Pre-Seed. Anpassung ab Seed-Runde auf Marktgehalt. Typisch Startup: 60.000–90.000 €/Jahr.
A26: KOSTEN | B26: Personal | C26: CCO Gehalt (Brutto/Jahr) | D26: 100000 | E26: €/Jahr | F26: Fest | G26: 100000 | H26: 100000 | I26: 100000 | J26: Gründer-Gehalt in der Pre-Seed-Phase. Beeinflusst die monatliche Burn Rate direkt. | K26: Gründer-Satz Pre-Seed. Anpassung ab Seed-Runde auf Marktgehalt. Typisch Startup: 60.000–90.000 €/Jahr.
A27: KOSTEN | B27: Personal | C27: Software Developer Gehalt | D27: 75000 | E27: €/Jahr | F27: Fest | G27: 75000 | H27: 75000 | I27: 75000 | J27: Erste strategische Einstellung. Fix-Position, nicht durch AI-Personal-Hebel verzögerbar.
A28: KOSTEN | B28: Personal | C28: Arbeitgeber-Nebenkosten | D28: 0.2 | E28: % auf Bruttogehalt | F28: Fest | G28: 0.2 | H28: 0.2 | I28: 0.2 | J28: Sozialversicherungsbeiträge des Arbeitgebers. Erhöht die effektiven Personalkosten um 20%. | K28: Standardsatz Deutschland 2026. Gesamtkosten pro MA = Bruttogehalt × 1,20.
A29: KOSTEN | B29: Personal | C29: Onboarding-Aufwand | D29: 30–120 Stunden | E29: Stunden/Kunde | F29: Szenario | G29: 120 Stunden | H29: 60 Stunden | I29: 30 Stunden | J29: Interner Aufwand für das Kunden-Onboarding. Bindet Entwickler- und Support-Kapazität. | K29: Gering: hoher Aufwand bei alten IT-Systemen (Automotive). Stark: standardisierter Self-Service-Prozess (Packaging). Quelle: Lothar.bm-Transkripte.
A30: Technologie & Cloud
A31: KOSTEN | B31: Technologie | C31: Cloud/Hosting Basis | D31: 2000 | E31: €/Monat | F31: Fest | G31: 2000 | H31: 2000 | I31: 2000 | J31: Fixe monatliche Grundkosten für Cloud-Infrastruktur. Unabhängig von der Kundenzahl. | K31: AWS/Azure/GCP Grundkonfiguration. Steigt mit Kundenzahl über den Skalierungsfaktor.
A32: KOSTEN | B32: Technologie | C32: Cloud-Skalierung pro Seat | D32: 80 | E32: €/Seat/Monat | F32: Skalierend | G32: 80 | H32: 80 | I32: 80 | J32: Variable Cloud-Kosten pro aktivem Seat. Wächst proportional zur Kundenbasis (szenarioabhängig). | K32: Gesamte Cloud-Kosten = Basis + (Seats × 80€). Im Stark-Szenario entstehen durch mehr Seats höhere Gesamtkosten.
A33: KOSTEN | B33: Technologie | C33: AI/ML APIs Basis | D33: 2000 | E33: €/Monat | F33: Fest | G33: 2000 | H33: 2000 | I33: 2000 | J33: Monatliche Grundkosten für KI-API-Nutzung (OpenAI/Anthropic/Frontier Models). | K33: Nutzung von GPT-5/Claude für Design-Logic. Wächst mit 8%/Monat proportional zur Nutzungsintensität.
A34: KOSTEN | B34: Technologie | C34: AI-Kosten Wachstum/Monat | D34: 0.08 | E34: % / Monat | F34: Fest | G34: 0.08 | H34: 0.08 | I34: 0.08 | J34: Monatliche Steigerungsrate der AI/ML-API-Kosten. Skaliert proportional zur Nutzung und Datentiefe. | K34: Skalierung proportional zur Nutzung und Datentiefe. Kann durch Open-Source-Modelle reduziert werden.
A35: KOSTEN | B35: Technologie | C35: SaaS Tools intern (Basis) | D35: 400 | E35: €/Monat | F35: Fest | G35: 400 | H35: 400 | I35: 400 | J35: Fixe monatliche Kosten für interne Tools (Slack, Notion, GitHub etc.). | K35: Standardpaket für Tech-Startups. Wächst mit Mitarbeiterzahl über den Pro-MA-Satz.
A36: KOSTEN | B36: Technologie | C36: SaaS Tools pro Mitarbeiter | D36: 100 | E36: €/MA/Monat | F36: Skalierend | G36: 100 | H36: 100 | I36: 100 | J36: Variable Tool-Kosten pro Mitarbeiter. Inkl. KI-Coding-Tools (Copilot/Cursor). | K36: Gesamte Tool-Kosten = Basis + (MAs × 100€). Im Gering-Szenario (mehr MAs) entstehen höhere Gesamtkosten.
A37: KOSTEN | B37: Technologie | C37: Sicherheit & Compliance | D37: 3500 | E37: €/Monat | F37: Fest | G37: 3500 | H37: 3500 | I37: 3500 | J37: Monatliche Kosten für Security-Tools und Compliance-Monitoring. Kritisch für TISAX-Zertifizierung im Automotive-Bereich. | K37: Puffer für TISAX-Audits und laufendes Compliance-Monitoring. Besonders relevant im Gering-Szenario (Automotive-Fokus).
A38: Marketing & Vertrieb
A39: KOSTEN | B39: Marketing & Vertrieb | C39: Paid Ads Budget (Initial) | D39: 1000 | E39: €/Monat | F39: Fest | G39: 1000 | H39: 1000 | I39: 1000 | J39: Monatliches Startbudget für bezahlte Werbung (Google, LinkedIn). Wächst mit 8%/Monat. | K39: Fokus eher auf Content/SEO im Industrie-Vertrieb. Skalierung mit Marktbekanntheit.
A40: KOSTEN | B40: Marketing & Vertrieb | C40: Content & SEO | D40: 2500 | E40: €/Monat | F40: Fest | G40: 2500 | H40: 2500 | I40: 2500 | J40: Monatliche Kosten für Content-Marketing und SEO. Fokus auf Whitepaper zu ROI, TCO und DPP-Compliance. | K40: Wichtiger Kanal für B2B-SaaS im Industriebereich. Langfristiger Aufbau von organischem Traffic.
A41: KOSTEN | B41: Marketing & Vertrieb | C41: Events & Messen/Ideation | D41: 3000 | E41: €/Jahr | F41: Fest | G41: 3000 | H41: 3000 | I41: 3000 | J41: Jährliche Kosten für Messeauftritte und Events. Wichtiger Kanal für Enterprise-Kundenkontakte. | K41: Erste Messeteilnahme/ Fachmessen
...

Sheet Szenarien_Analyse
A1: Faktor | B1: Referenz (Basis) | C1: Szenario: Gering | D1: Szenario: Normal | E1: Szenario: Stark | F1: DELTA: (Stark vs Normal) | G1: Argumentation (Interviews & Transkripte) | I1: ⚑ HINWEIS: Werte in den Spalten C/D/E (Gering/Normal/Stark) sind direkt bearbeitbar. Änderungen in DIESEM Blatt fließen automatisch über Sandbox → Inputs → Revenue/P&L.
A2: Fokus: Packaging | B2: 0.3 | C2: 0.1 | D2: 0.6 | E2: 0.8 | F2: =E2-D2 | G2: Höhere Margen, schnellere Zyklen als Auto.
A3: Fokus: Automotive | B3: 0.7 | C3: 0.9 | D3: 0.4 | E3: 0.2 | F3: =E3-D3 | G3: Hohe IT-Hürden und Margendruck (Lothar).
A4: Erste zahlende Kunden Monat | B4: 6 | C4: 14 | D4: 8 | E4: 4 | F4: =E4-D4 | G4: IT-Integration ist der Flaschenhals.
A5: Buchungs-Wahrscheinlichkeit Implementation-Support je Kunde | B5: 0.5 | C5: 0.2 | D5: 0.5 | E5: 1 | F5: =E5-D5 | G5: Wahrscheinlichkeit, dass ein gewonnener Kunde Implementation-Support bucht: a) 20 % (gering) = jeder 5. Kunde – Automotive, wenig Beratungsbedarf b) 50 % (normal) = jeder 2. Kunde – Hybrid-Markt c) 100 % (stark) = jeder Kunde – Packaging, hohe Implementierungstiefe → Fließt über Sandbox Z.12 → Inputs Z.139 → Revenue Z.28 | H5: → Sandbox → Inputs
A6: Startpreis pro Seat/Jahr | B6: 1 | C6: 0.8 | D6: 1 | E6: 1.2 | F6: =E6-D6 | G6: Value-Pricing eher in Packaging möglich.
A7: Personal (Experten) in FTE | B7: 5 | C7: 3 | D7: 7 | E7: 12 | F7: =E7-D7 | G7: Bedarf an "Übersetzern" für IT-Landschaft.
A8: Implementation-Support-Tage/Einsatz | B8: 10 | C8: 5 | D8: 10 | E8: 20 | F8: =E8-D8 | G8: Implementation-Support-Tage pro Kunde je Einsatz: gering=5 (Basisschulung + Systemcheck) normal=10 (Implementierungsbegleitung + Anwenderschulung) stark=20 (Spez. Anforderungen, Datenbereinigung, Stammdaten-Harmonisierung) → Fließt über Sandbox Z.11 → Inputs Z.140 → Revenue Z.28 | H8: → Sandbox → Inputs
A9: Net Revenue Retention (NRR) Umsatz von bestehenden Kunden im Vergleich zum Vorjahr – inklusive Upgrades, Downgrades und Kündigungen. Ein NRR von 110% bedeutet z.B., dass Bestandskunden dieses Jahr 10% mehr zahlen als letztes Jahr, selbst ohne einen einzigen Neukunden. Für SaaS-Startups gilt ein NRR über 100% als starkes Signal für Product-Market-Fit, weil es zeigt, dass Kunden bleiben und mehr ausgeben. Benchmark im B2B-SaaS: >120% ist exzellent, >100% ist solide. | B9: 1.15 | C9: 1.8 | D9: 1.15 | E9: 1.3 | F9: =E9-D9 | G9: Treiber-Matrix: NRR szenarioabhängig machen (bisher fest 125%). Gering=105%: Automotive, wenig Upselling-Potenzial. Normal=115%: Hybrid, DPP-Module. Stark=130%: Packaging, Analytics-Premium + Multi-Werk-Rollouts. | H9: → Sandbox → Inputs
A10: Jährliche Churn Rate | B10: 0.06 | C10: 0.1 | D10: 0.06 | E10: 0.03 | F10: =E10-D10 | G10: Treiber-Matrix: Churn szenarioabhängig (bisher fest 6%). Gering=10%: Automotive-Budgetzyklen, höheres Abwanderungsrisiko. Normal=6%: Standardwert (SaaS-Industrie). Stark=3%: Packaging, tiefe API-Integration → hoher Switching-Cost. | H10: → Sandbox → Inputs
A11: Implementation-Support-Startmonat | B11: 4 | C11: 3 | D11: 4 | E11: 6 | F11: =E11-D11 | G11: Treiber-Matrix Z.21: Implementation-Support startet als Enabler vor dem SaaS-Produkt. Gering=Monat 3: Automotive benötigt sofort IT-Begleitung. Stark=Monat 6: Packaging-Kunden länger Self-Service-fähig. | H11: → Sandbox → Inputs

Sheet 00_Input_Sandbox
A1: Aktives Szenario | B1: gering | C1: Einheit | D1: Gering (Auto-Fokus) | E1: Normal (Hybrid) | F1: Stark (Pack-Fokus) | G1: Argumentation / Quelle
A2: Kategorie | B2: Variable | C2: Einheit | D2: Gering | E2: Normal | F2: Stark | G2: Quelle
A3: Markt-Mix | B3: Anteil Packaging | C3: % | D3: 0.1 | E3: 0.6 | F3: 0.8 | G3: Lothar: Packaging hat schnellere Zyklen.
A4: Vertrieb | B4: Startmonat Kunden | C4: Monate | D4: 17 | E4: 8 | F4: 4 | G4: Lothar: IT-Hürden bei Automotive Tier-1.
A5: Revenue 1 | B5: Startpreis Seat/Monat | C5: €/Monat | D5: 200 | E5: 350 | F5: 450 | G5: Value-based Pricing in Packaging (White Paper).
A6: Revenue 2 | B6: Implementation-Support-Tagessatz | C6: €/Tag | D6: 1000 | E6: 1200 | F6: 1500 | G6: Implementation-Support-Tagessatz: gering=1.000 €/Tag | normal=1.200 €/Tag | stark=1.500 €/Tag. Basiert auf Expertenstatus (Haag/Candemir) und Marktniveau B2B Industrie.
A7: Effizienz | B7: Iterations-Reduktion | C7: Faktor | D7: 1,2x | E7: 2,0x | F7: 3,0x | G7: White Paper: Redesign Trap vermeiden.
A8: Kosten | B8: Onboarding-Aufwand | C8: Stunden | D8: 120 | E8: 60 | F8: 30 | G8: Lothar: Hoher Aufwand bei alten IT-Systemen.
A9: Detailbeschreibung
A10: Revenue 2: Implementation-Support Einsatztage je Kunde initial | B10: Implementation-Support-Tage/Einsatz | C10: Tage/Einsatz | D10: =Szenarien_Analyse!C8 | E10: =Szenarien_Analyse!D8 | F10: =Szenarien_Analyse!E8 | G10: Referenziert Szenarien_Analyse Z.8 (dort bearbeitbar). gering=5 Tage | normal=10 Tage | stark=20 Tage. Direkte Eingabe hier überschreibt die Szenarien-Referenz.
A11: Revenue 2: Buchungs-Wahrscheinlichkeit Implementation-Support je Kunde | B11: Buchungs-Wahrscheinlichkeit Implementation-Support | C11: % | D11: =Szenarien_Analyse!C5 | E11: =Szenarien_Analyse!D5 | F11: =Szenarien_Analyse!E5 | G11: Referenziert Szenarien_Analyse Z.5 (dort bearbeitbar). a) gering=20% – jeder 5. Kunde kauft Implementation-Support, b) normal=50% – jeder 2. Kunde, c) stark=100% – jeder Kunde kauft Implementation-Support-Tage.
A12: Retention: Net Revenue Retention (NRR) | B12: Net Revenue Retention (NRR) | C12: % | D12: 1.05 | E12: =Szenarien_Analyse!D9 | F12: =Szenarien_Analyse!E9 | G12: Szenarioabhängig (Szenarien_Analyse Z.9). Gering=105% | Normal=115% | Stark=130%.
A13: Retention: Jährliche Churn Rate | B13: Churn Rate | C13: %/Jahr | D13: =Szenarien_Analyse!C10 | E13: =Szenarien_Analyse!D10 | F13: =Szenarien_Analyse!E10 | G13: Szenarioabhängig (Szenarien_Analyse Z.10). Gering=10% | Normal=6% | Stark=3%.
A14: Implementation-Support: Startmonat erster Implementation-Support-Umsatz | B14: Implementation-Support-Startmonat | C14: Monat | D14: =Szenarien_Analyse!C11 | E14: =Szenarien_Analyse!D11 | F14: =Szenarien_Analyse!E11 | G14: Szenarioabhängig (Szenarien_Analyse Z.11). Gering=3 | Normal=4 | Stark=6.

Sheet Inputs
A1: ZENTRALE EINGABEWERTE | B1: Wert | C1: Erklärung / Hinweis | D1: Bemerkungen | E1: Szenarioauswahl: gering, normal, stark
A2: To Do 10.3.26: * Den Begriff Consulting verändern in Implementierungs Support. * Checken ob die wesentlichen Parameter in Bezug auf Kostenhöhe et cetera abgeglichen worden sind mit den Informationen aus der Tabelle für den initialen Startpunkt Funding ideation Phase. * Einen anderen Kostensatz annehmen in Bezug auf Anwaltskosten. * Checken ob die absoluten Kostenhöhen so passen. * Checken welche Annahmen hinter den Produkt Feature Entwicklungen stecken können. * Wie es mit der entsprechenden Mannschaft eine Produktentwicklung und ein Rollout stattfinden kann wie er geplant ist. * Berücksichtigen dass einerseits Produkte gebaut andererseits aber auch Implementierung Projekte geleitet und umgesetzt werden müssen. * Diese Fragen auch auf das Thema Customer Success und Sales beziehungsweise Investor Relations ausrollen. * Prüfen ob Olaf René für diese Aufgaben ausreichend Zeit und Kapazität haben. * Mouaz in der Lage ist in dem verfügbaren Zeitrahmen diese Aufgaben umzusetzen, was realistischerweise berücksichtigt werden muss um diese Aufgaben tatsächlich auch umzusetzen. * Ziel sollte eine Szenario beschreibungs sein der besprochenen Vorgehensweise. * Ziel sollte auch sein hier die entsprechenden Bezüge zu den einzelnen Phasen herzustellen und genau zu beschreiben was in jeder Phase gemacht wird, was in jeder Phase kundenseitig und Revenue-seitig erreicht werden muss, welche Anforderungen damit verbunden sind und wie die Kunden gefunden werden sollen. * Also sprich wie viele Letters of Intent, wie viele Pilot-Kunden brauchen wir, in welchen Branchen und was bedeutet das Final für das Produkt. | E2: ='00_Input_Sandbox'!$B$1
A3: ALLGEMEINE EINSTELLUNGEN
A4: Firmenname | B4: LoopforgeLab GmbH | C4: Name des Unternehmens
A5: Startdatum | B5: 46113 | C5: Beginn der Projektionen
A6: Währung | B6: EUR | C6: EUR für DACH-Startups
A7: Steuersatz | B7: 0.3 | C7: KSt + GewSt (~30% in DE) | D7: Übernahme des Standardsatzes (KSt + GewSt in Deutschland).
A9: FINANZIERUNGSRUNDEN
A10: Ideation Phase | B10: 90000 | C10: Typisch: 100.000-500.000€ | D10: Phase: 1.4.26 bis 15.7.2026 MVP-Anschubfinanzierung; stellt keine Unternehmensbewertung dar.
A11: Ideation Phase | B11: 1 | C11: Monat der Einzahlung | D11: MVP-Entwicklung und IP-Aufbau starten unmittelbar.
A12: Pre-Seed Betrag | B12: 1500000 | C12: Typisch: 500.000-2.000.000€ | D12: Pre-Seed Phase ab VC Pitch im Juli '26 (1.5M-3M Bewertung).
A13: Pre-Seed Monat | B13: 5 | C13: Typisch: Monat 5 | D13: Juli 2026 entspricht Monat 5 Fokus auf Pilot-Traction.
A14: Seed Betrag | B14: 4000000 | C14: Typisch: 3.000.000-10.000.000€ | D14: Abhängig von Pilotprojekten und Reife des Produktes
A15: Seed Monat | B15: 17 | C15: Typisch: Monat 17 | D15: Geplant für Mitte 2027.
A16: Series A Betrag | B16: 10000000 | C16: Typisch: 10.000.000-25.000.000€ | D16: Vorerst unverändert als langfristige Wachstumsambition.
A17: Series A Monat | B17: 36 | C17: Typisch: Monat 35 | D17: Geplant für Herbst 2028.
A19: REVENUE-ANNAHMEN (SaaS/ARR)
A20: Startpreis pro Seat/Jahr | B20: =VLOOKUP("Startpreis Seat/Monat",'00_Input_Sandbox'!$B$2:$F$19,IF('00_Input_Sandbox'!$B$1="gering",3,IF('00_Input_Sandbox'!$B$1="normal",4,5)),FALSE)*12 | C20: Jährliche Lizenzgebühr pro Nutzer | D20: 1. Realistisch? Hängt auch ab vom Business Modell..Pricing basierend auf Wettbewerb oder auf voraussichtlichem Einsparpotential? 2. weitere Erlösquellen? Beratung? Implementierungsaufwand? Hybrid-Modell: Deckt Fixkosten und partizipiert am TCO-Einsparwert. [1] | F20: 2. Regulatory Moat (DPP): JE nach Branche (hier: Annahme von neuen Zielbranche in Bezuf auf DPP Verpflichtung) Die Zielbranchen Batterien und Elektronik unterliegen ab 2027 der DPP-Pflicht. Dies rechtfertigt höhere Preise und eine stärkere NRR, da LFL hiermit zur "Compliance Engine" des Kunden wird. -->"Compliance" könnte aber auch durch andere Benefits ersetzt werden
A21: Preiserhöhung/Jahr | B21: 0.05 | C21: Typisch: 3-5% p.a. | D21: Standard für AI-SaaS 2026 (Kompensation Inferenz/Innovation). [4]
A22: Erste zahlende Kunden Monat | B22: =VLOOKUP("Startmonat Kunden",'00_Input_Sandbox'!$B$2:$F$19,IF('00_Input_Sandbox'!$B$1="gering",3,IF('00_Input_Sandbox'!$B$1="normal",4,5)),FALSE) | C22: Wann erster Umsatz? | D22: Erster Umsatz in Monat 8 (Start: 04/26)…Realistisch? Wie lange Lead-Time? Zielkunden? Beachhead-Market? Weitere Begründung: wenn im Automotivebereich: Puffer für Sales-Zyklen (9-12 Mon.) und TISAX im Mittelstand. [1
A23: Initiale Seats | B23: 3 | C23: Anzahl Seats beim Kunden | D23: Realistisch? Hängt von Kundengrösse ab. Implementierungsaufwand je Kunde mit einkalkulieren weitere Aspekte: Kalkulieren mit 1-2 Projekten/ Start mit Pilotprojekten (Werke) zur ROI-Validierung ("Land&Expand")
A24: Monatliche Seat-Wachstumsrate | B24: 0.03 | C24: Wachstum neue Seats/Monat | D24: -->hier eine Annahme bzgll Vertriebsplanung treffen. Wie hoch ist die Zahl der Verkauften Sitze nach 1, 2, 3 Jahren? Gibt es noch andere Erlösströme? ALTERNATIVE: Account-basierte Planng: Wechsel auf "Stufenfunktion" beim Aufbau des Geschäfts (Roll-out pro Werk statt linearer Rate)
A25: Enterprise-Deals ab Monat | B25: 20 | C25: Fokus auf Packaging Industrie Wenn Automotive: Verschiebung durch längere Technical Validation und Compliance-Hürden. | D25: Start ab Fertigstellung MVP in der Seed Phase | F25: 3. Vertriebsrealismus: Der Start des Umsatzes wurde nach hinten geschoben da der industrielle Mittelstand ("Hidden Champions") langsame Entscheidungsprozesse und hohe Sicherheitsanforderungen (TISAX) hat. Die Zeit bis zum Juli 2026 wird für die Validierung der TCO-Einsparungen (Ausschuss-Reduktion) bei Pilotkunden genutzt.
A26: Durchschnitt Enterprise ARR | B26: 25000 | C26: Typisch: 50.000-200.000€/Jahr | D26: Höheres Volumen durch Tiefe der Integration: hier Annahme von weiteren Benefits wie Einbeziehung von DPP & Sustainability
A27: Enterprise Deals pro Quartal | B27: 1 | C27: Neue Enterprise-Deals pro Quartal
A28: Jährliche Churn Rate | B28: =VLOOKUP("Churn Rate",'00_Input_Sandbox'!$B$2:$F$19,IF('00_Input_Sandbox'!$B$1="gering",3,IF('00_Input_Sandbox'!$B$1="normal",4,5)),FALSE) | C28: Jährliche Churn Rate (szenarioabhängig): Gering=10% | Normal=6% | Stark=3% | D28: Treiber-Matrix: Churn jetzt szenarioabhängig (vorher fest 15%). Automotive: 10% (Budgetzyklen). Packaging: 3% (hoher Switching-Cost).
A29: Net Revenue Retention | B29: =VLOOKUP("Net Revenue Retention (NRR)",'00_Input_Sandbox'!$B$2:$F$19,IF('00_Input_Sandbox'!$B$1="gering",3,IF('00_Input_Sandbox'!$B$1="normal",4,5)),FALSE) | C29: Net Revenue Retention (szenarioabhängig): Gering=105% | Normal=115% | Stark=130% | D29: Treiber-Matrix: NRR jetzt szenarioabhängig (vorher fest 125%). Expansion-Umsatz minus Churn. NRR>100%=Bestandskunden wachsen.
A31: GEHÄLTER (Brutto/Jahr)
A32: CEO Gehalt | B32: 100000 | C32: Bestätigtes Gründergehalt: CEO/CTO/CCO je €100.000/Jahr (Brutto) | D32: Rene: negotiatable for Ideation Phase
A33: CTO Gehalt | B33: 100000 | C33: Bestätigtes Gründergehalt: CEO/CTO/CCO je €100.000/Jahr (Brutto)
A34: CCO Gehalt | B34: 100000 | C34: Bestätigtes Gründergehalt: CEO/CTO/CCO je €100.000/Jahr (Brutto)
A35: Software Developer | B35: 75000 | C35: Typisch: 55.000-90.000€ | D35: Source: various Sources (https://claude.ai/chat/0f63ea1a-6930-460c-954d-87864e88929e)
A36: Junior Software Developer | B36: 52000 | C36: Typisch: 42.000-58.000€ | D36: Source: various Sources (https://claude.ai/chat/0f63ea1a-6930-460c-954d-87864e88929e)
A37: ML/AI Engineer Gehalt | B37: 70000 | C37: Typisch: 50.000-125.000€ | D37: Source: various Sources (https://claude.ai/chat/0f63ea1a-6930-460c-954d-87864e88929e)
A38: Site Reliability Engineer | B38: 70000 | C38: Typisch: 50.000-110.000€ | D38: Source: various Sources (https://claude.ai/chat/0f63ea1a-6930-460c-954d-87864e88929e)
A39: UX/UI Designer | B39: 50000 | C39: Typisch: 42.000-80.000€ | D39: Source: various Sources (https://claude.ai/chat/0f63ea1a-6930-460c-954d-87864e88929e)
A40: Mechanical Engineer (incl. SoftwareDev) | B40: 70000 | C40: Typisch: 45.000-85.000€ | D40: Source: various Sources (https://claude.ai/chat/0f63ea1a-6930-460c-954d-87864e88929e)
A41: Customer Key Account Gehalt | B41: 100000 | C41: Typisch: 50.000-70.000€ + Provision | D41: Split 50/50 (65k fix + 65k var); zwingend für Enterprise-Vertrieb. [12
A42: Marketing Manager Gehalt | B42: 65000 | C42: Typisch: 55.000-75.000€ | D42: Anpassung an Marktniveau für B2B-Industrie-Spezialisten.
A43: Marketing Assistant Gehalt | B43: 45000
...

Sheet P&L
A1: GEWINN- UND VERLUSTRECHNUNG (P&L)
A3: Position | B3: M1 | C3: M2 | D3: M3 | E3: M4 | F3: M5 | G3: M6 | H3: M7 | I3: M8 | J3: M9 | K3: M10 | L3: M11 | M3: M12 | N3: M13 | O3: M14 | P3: M15 | Q3: M16 | R3: M17 | S3: M18 | T3: M19 | U3: M20 | V3: M21 | W3: M22 | X3: M23 | Y3: M24 | Z3: M25 | AA3: M26 | AB3: M27 | AC3: M28 | AD3: M29 | AE3: M30 | AF3: M31 | AG3: M32 | AH3: M33 | AI3: M34 | AJ3: M35 | AK3: M36 | AL3: M37 | AM3: M38 | AN3: M39 | AO3: M40 | AP3: M41 | AQ3: M42 | AR3: M43 | AS3: M44 | AT3: M45 | AU3: M46 | AV3: M47 | AW3: M48 | AX3: M49 | AY3: M50 | AZ3: M51 | BA3: M52
A4: REVENUE
A5: Subscription Revenue | B5: =Revenue!B10 | C5: =Revenue!C10 | D5: =Revenue!D10 | E5: =Revenue!E10 | F5: =Revenue!F10 | G5: =Revenue!G10 | H5: =Revenue!H10 | I5: =Revenue!I10 | ... BA5: =Revenue!BA10
A6: Enterprise Revenue | B6: =Revenue!B17 | C6: =Revenue!C17 | D6: =Revenue!D17 | E6: =Revenue!E17 | F6: =Revenue!F17 | G6: =Revenue!G17 | H6: =Revenue!H17 | I6: =Revenue!I17 | ... BA6: =Revenue!BA17
A7: Implementation Support Revenue | B7: =Revenue!B30 | C7: =Revenue!C30 | D7: =Revenue!D30 | E7: =Revenue!E30 | F7: =Revenue!F30 | G7: =Revenue!G30 | H7: =Revenue!H30 | I7: =Revenue!I30 | ... BA7: =Revenue!BA30
A8: TOTAL REVENUE | B8: =B5+B6+B7 | C8: =C5+C6+C7 | D8: =D5+D6+D7 | E8: =E5+E6+E7 | F8: =F5+F6+F7 | G8: =G5+G6+G7 | H8: =H5+H6+H7 | I8: =I5+I6+I7 | ... BA8: =BA5+BA6+BA7
A9: COST OF GOODS SOLD (COGS)
A10: Cloud Hosting (variable) | B10: =Costs!B49 | C10: =Costs!C49 | D10: =Costs!D49 | E10: =Costs!E49 | F10: =Costs!F49 | G10: =Costs!G49 | H10: =Costs!H49 | I10: =Costs!I49 | ... BA10: =Costs!BA49
A11: AI/ML API Kosten | B11: =Costs!B50 | C11: =Costs!C50 | D11: =Costs!D50 | E11: =Costs!E50 | F11: =Costs!F50 | G11: =Costs!G50 | H11: =Costs!H50 | I11: =Costs!I50 | ... BA11: =Costs!BA50
A12: Payment Processing | B12: =Costs!B95 | C12: =Costs!C95 | D12: =Costs!D95 | E12: =Costs!E95 | F12: =Costs!F95 | G12: =Costs!G95 | H12: =Costs!H95 | I12: =Costs!I95 | ... BA12: =Costs!BA95
A13: TOTAL COGS | B13: =SUM(B10:B12) | C13: =SUM(C10:C12) | D13: =SUM(D10:D12) | E13: =SUM(E10:E12) | F13: =SUM(F10:F12) | G13: =SUM(G10:G12) | H13: =SUM(H10:H12) | I13: =SUM(I10:I12) | ... BA13: =SUM(BA10:BA12)
A15: GROSS PROFIT | B15: =B8-B13 | C15: =C8-C13 | D15: =D8-D13 | E15: =E8-E13 | F15: =F8-F13 | G15: =G8-G13 | H15: =H8-H13 | I15: =I8-I13 | ... BA15: =BA8-BA13
A16: Gross Margin % | B16: =IFERROR(B15/B8,0) | C16: =IFERROR(C15/C8,0) | D16: =IFERROR(D15/D8,0) | E16: =IFERROR(E15/E8,0) | F16: =IFERROR(F15/F8,0) | G16: =IFERROR(G15/G8,0) | H16: =IFERROR(H15/H8,0) | I16: =IFERROR(I15/I8,0) | ... BA16: =IFERROR(BA15/BA8,0)
A18: OPERATING EXPENSES
A19: Total Personnel | B19: =Costs!B45 | C19: =Costs!C45 | D19: =Costs!D45 | E19: =Costs!E45 | F19: =Costs!F45 | G19: =Costs!G45 | H19: =Costs!H45 | I19: =Costs!I45 | ... BA19: =Costs!BA45
A20: Total Technology | B20: =Costs!B54 | C20: =Costs!C54 | D20: =Costs!D54 | E20: =Costs!E54 | F20: =Costs!F54 | G20: =Costs!G54 | H20: =Costs!H54 | I20: =Costs!I54 | ... BA20: =Costs!BA54
A21: Total Office/Facilities | B21: =Costs!B61 | C21: =Costs!C61 | D21: =Costs!D61 | E21: =Costs!E61 | F21: =Costs!F61 | G21: =Costs!G61 | H21: =Costs!H61 | I21: =Costs!I61 | ... BA21: =Costs!BA61
A22: Total Professional Services | B22: =Costs!B68 | C22: =Costs!C68 | D22: =Costs!D68 | E22: =Costs!E68 | F22: =Costs!F68 | G22: =Costs!G68 | H22: =Costs!H68 | I22: =Costs!I68 | ... BA22: =Costs!BA68
A23: Total Insurance & Bank | B23: =Costs!B75 | C23: =Costs!C75 | D23: =Costs!D75 | E23: =Costs!E75 | F23: =Costs!F75 | G23: =Costs!G75 | H23: =Costs!H75 | I23: =Costs!I75 | ... BA23: =Costs!BA75
A24: Total Marketing & Sales | B24: =Costs!B84 | C24: =Costs!C84 | D24: =Costs!D84 | E24: =Costs!E84 | F24: =Costs!F84 | G24: =Costs!G84 | H24: =Costs!H84 | I24: =Costs!I84 | ... BA24: =Costs!BA84
A25: Total Other OpEx | B25: =Costs!B92 | C25: =Costs!C92 | D25: =Costs!D92 | E25: =Costs!E92 | F25: =Costs!F92 | G25: =Costs!G92 | H25: =Costs!H92 | I25: =Costs!I92 | ... BA25: =Costs!BA92
A26: Contingency/Buffer | B26: =Costs!B97 | C26: =Costs!C97 | D26: =Costs!D97 | E26: =Costs!E97 | F26: =Costs!F97 | G26: =Costs!G97 | H26: =Costs!H97 | I26: =Costs!I97 | ... BA26: =Costs!BA97
A27: TOTAL OPERATING EXPENSES | B27: =SUM(B19:B26) | C27: =SUM(C19:C26) | D27: =SUM(D19:D26) | E27: =SUM(E19:E26) | F27: =SUM(F19:F26) | G27: =SUM(G19:G26) | H27: =SUM(H19:H26) | I27: =SUM(I19:I26) | ... BA27: =SUM(BA19:BA26)
A29: EBITDA | B29: =B15-B27 | C29: =C15-C27 | D29: =D15-D27 | E29: =E15-E27 | F29: =F15-F27 | G29: =G15-G27 | H29: =H15-H27 | I29: =I15-I27 | ... BA29: =BA15-BA27
A30: EBITDA Margin % | B30: =IFERROR(B29/B8,0) | C30: =IFERROR(C29/C8,0) | D30: =IFERROR(D29/D8,0) | E30: =IFERROR(E29/E8,0) | F30: =IFERROR(F29/F8,0) | G30: =IFERROR(G29/G8,0) | H30: =IFERROR(H29/H8,0) | I30: =IFERROR(I29/I8,0) | ... BA30: =IFERROR(BA29/BA8,0)
A32: Depreciation & Amortization | B32: =Costs!B90/Inputs!$B$125/12 | C32: =Costs!C90/Inputs!$B$125/12 | D32: =Costs!D90/Inputs!$B$125/12 | E32: =Costs!E90/Inputs!$B$125/12 | F32: =Costs!F90/Inputs!$B$125/12 | G32: =Costs!G90/Inputs!$B$125/12 | H32: =Costs!H90/Inputs!$B$125/12 | I32: =Costs!I90/Inputs!$B$125/12 | ... BA32: =Costs!BA90/Inputs!$B$125/12
A34: EBIT (Operating Income) | B34: =B29-B32 | C34: =C29-C32 | D34: =D29-D32 | E34: =E29-E32 | F34: =F29-F32 | G34: =G29-G32 | H34: =H29-H32 | I34: =I29-I32 | ... BA34: =BA29-BA32
A36: EBT (Earnings Before Tax) | B36: =B34 | C36: =C34 | D36: =D34 | E36: =E34 | F36: =F34 | G36: =G34 | H36: =H34 | I36: =I34 | ... BA36: =BA34
A37: Income Tax | B37: =IF(B36>0,B36*Inputs!$B$7,0) | C37: =IF(C36>0,C36*Inputs!$B$7,0) | D37: =IF(D36>0,D36*Inputs!$B$7,0) | E37: =IF(E36>0,E36*Inputs!$B$7,0) | F37: =IF(F36>0,F36*Inputs!$B$7,0) | G37: =IF(G36>0,G36*Inputs!$B$7,0) | H37: =IF(H36>0,H36*Inputs!$B$7,0) | I37: =IF(I36>0,I36*Inputs!$B$7,0) | ... BA37: =IF(BA36>0,BA36*Inputs!$B$7,0)
A39: NET INCOME | B39: =B36-B37 | C39: =C36-C37 | D39: =D36-D37 | E39: =E36-E37 | F39: =F36-F37 | G39: =G36-G37 | H39: =H36-H37 | I39: =I36-I37 | ... BA39: =BA36-BA37
A40: Net Margin % | B40: =IFERROR(B39/B8,0) | C40: =IFERROR(C39/C8,0) | D40: =IFERROR(D39/D8,0) | E40: =IFERROR(E39/E8,0) | F40: =IFERROR(F39/F8,0) | G40: =IFERROR(G39/G8,0) | H40: =IFERROR(H39/H8,0) | I40: =IFERROR(I39/I8,0) | ... BA40: =IFERROR(BA39/BA8,0)

Sheet Tabelle1
A1: IT/Product Development/Framework | B1: Phase | C1: Content | D1: Phase | E1: Content | F1: Phase | G1: Content | H1: Phase | I1: Content | J1: Phase | K1: Content
A2: Month (starting Apr 26) | B2: M1-M4 | D2: M5-M16 | F2: M17-M28 | H2: M29-M40 | J2: M41-M52
B3: April to Jul 2026 | D3: Aug 2026 to Jul 2027 | F3: Aug 2027 to Jul 2028 | H3: Aug 2028 to Jul 2029 | J3: Aug 2029 to Jul 2030
B4: IDEATION Phase | D4: PRE-SEED | F4: SEED | H4: SERIES A | J4: Series B?? NOT PART OF OUR C13 Forecast
A5: Companies to be served | D5: 3 (SME) | E5: "Bottleneck" is Sales (Rene/Olaf) -->Existence of "MVP" is essential!! | G5: 2 Enterprises, 15 Mid-Size and 10 SMEs (27 cumulative) | I5: 6 Enterprises, 44 Mid-Size Companies, 30 SMEs (80 cumulative) (ARR: 5.6M by mid July 2029)
A6: Large OEM (Enterprise Deals) | B6: 0 | D6: 0 | F6: 2 | H6: 3 | J6: 6
A7: Mid-size OEM | B7: 0 | D7: 0 | F7: 15 | H7: 30 | J7: 50
A8: SME | B8: 0 | D8: 3 | F8: 10 | H8: 20 | J8: 60
A9: Cumulative | D9: 3 | F9: =D9+F6+F7+F8 | H9: =F9+H6+H7+H8 | J9: =H9+J6+J7+J8
A11: Co Founder Salary | C11: see: INPUT: Agreement: 100k€ per Cofounder as "AG-Brutto", ie. Approx. 52.000€/yr Netto
A12: Product features Product Development per Phase | C12: `-MVP "light" Getting LOIs | E12: -Plugins into one incumbent solution -Calculate manufacturing costs (BOM requirements) FEATURES of the MVP: -Core Engine -API for data ingestion & Normalisation -Data Integration (CAD, BOM, Processes costs, Supply data, EU regulations) -Manufacturing Cost engine -Operator Cost (TOC) engine -User Interface -(think about creating RfQ documents..is necessary for the mvp?) | G12: `-Integration into more incumbent solutions -Similarity and tribal knowledge engine -Compliance engine -Trade off and scnario analysis -Functional model and failure mode integration -… | I12: -Product Scaling -TCO Engine -Lifecycle Cost Engine -Propriatory Scoring Model for Products (depending on requirements) -Recommending alternative features of products/ decisions to take("Recommending System")
A13: People (IT) | E13: -Number of SW Engineers needed for MVP: -2 Developers -1 ML/AI Engineer (optional) -1 Site Reliability Engineer -1 UX/UI (optional) -1 Mechanical Engineer/Developer (who would love to work as a developer) -->people estimation are "conservative" -->ramp up of personnel over 12 month | G13: 1 Developer
A14: People (Marketing) | E14: `-1 Customer Key Account | G14: `-2 to 3 Sales/Marketing People -big budget for Sales/Marketing | I14: `-2 to 3 Sales/Marketing People -big budget for Sales/Marketing
A15: IT Licenses | E15: -Licenses for incumbent solutions (Autodesk, Siemens NX, Catia, PTC??
A16: IT Equipment | C16: -Budget for IT Licenses: 200€/month -no new equipment needed for the founders
A18: Office (permanent) | C18: no office in the first month | G18: Office Space
A19: Office (Coworking Space) | C19: `-400€/Desk/month | E19: 3 Desks/month? -->Meeting Place and conference room optional
A23: Fees (Lawyers, Notary,..) | C23: less spent in the ideation phase | E23: regular sum from here onwards | H23: higher? Sum according to more Stakeholders and bigger financing round

Sheet Revenue
A1: UMSATZMODELL - Detaillierte Aufschlüsselung
B2: 46113 | C2: 46143 | D2: 46174 | E2: 46204 | F2: 46235 | G2: 46266 | H2: 46296 | I2: 46327 | J2: 46357 | K2: 46388 | L2: 46419 | M2: 46447 | N2: 46478 | O2: 46508 | P2: 46539 | Q2: 46569 | R2: 46600 | S2: 46631 | T2: 46661 | U2: 46692 | V2: 46722 | W2: 46753 | X2: 46784 | Y2: 46813 | Z2: 46844 | AA2: 46874 | AB2: 46905 | AC2: 46935 | AD2: 46966 | AE2: 46997 | AF2: 47027 | AG2: 47058 | AH2: 47088 | AI2: 47119 | AJ2: 47150 | AK2: 47178 | AL2: 47209 | AM2: 47239 | AN2: 47270 | AO2: 47300 | AP2: 47331 | AQ2: 47362 | AR2: 47392 | AS2: 47423 | AT2: 47453 | AU2: 47484 | AV2: 47515 | AW2: 47543 | AX2: 47574 | AY2: 47604 | AZ2: 47635 | BA2: 47665
A3: Startup-Phasen | B3: Ideation | C3: Ideation | D3: Ideation | E3: Ideation | F3: Pre-Seed | G3: Pre-Seed | H3: Pre-Seed | I3: Pre-Seed | J3: Pre-Seed | K3: Pre-Seed | L3: Pre-Seed | M3: Pre-Seed | N3: Pre-Seed | O3: Pre-Seed | P3: Pre-Seed | Q3: Pre-Seed | R3: Seed | S3: Seed | T3: Seed | U3: Seed | V3: Seed | W3: Seed | X3: Seed | Y3: Seed | Z3: Seed | AA3: Seed | AB3: Seed | AC3: Seed | AD3: Series A | AE3: Series A | AF3: Series A | AG3: Series A | AH3: Series A | AI3: Series A | AJ3: Series A | AK3: Series A | AL3: Series A | AM3: Series A | AN3: Series A | AO3: Series A | AP3: Series B | AQ3: Series B | AR3: Series B | AS3: Series B | AT3: Series B | AU3: Series B | AV3: Series B | AW3: Series B | AX3: Series B | AY3: Series B | AZ3: Series B | BA3: Series B
A4: Kennzahl | B4: M1 | C4: M2 | D4: M3 | E4: M4 | F4: M5 | G4: M6 | H4: M7 | I4: M8 | J4: M9 | K4: M10 | L4: M11 | M4: M12 | N4: M13 | O4: M14 | P4: M15 | Q4: M16 | R4: M17 | S4: M18 | T4: M19 | U4: M20 | V4: M21 | W4: M22 | X4: M23 | Y4: M24 | Z4: M25 | AA4: M26 | AB4: M27 | AC4: M28 | AD4: M29 | AE4: M30 | AF4: M31 | AG4: M32 | AH4: M33 | AI4: M34 | AJ4: M35 | AK4: M36 | AL4: M37 | AM4: M38 | AN4: M39 | AO4: M40 | AP4: M41 | AQ4: M42 | AR4: M43 | AS4: M44 | AT4: M45 | AU4: M46 | AV4: M47 | AW4: M48 | AX4: M49 | AY4: M50 | AZ4: M51 | BA4: M52
A5: Preis pro Seat/Monat (€) (gilt für SME und Mid-Comps) | B5: =IFERROR(Inputs!$B$20/12*(1+Inputs!$B$21)^(INT((1-1)/12)),0) | C5: =Inputs!$B$20/12*(1+Inputs!$B$21)^INT((2-1)/12) | D5: =Inputs!$B$20/12*(1+Inputs!$B$21)^INT((3-1)/12) | E5: =Inputs!$B$20/12*(1+Inputs!$B$21)^INT((4-1)/12) | F5: =Inputs!$B$20/12*(1+Inputs!$B$21)^INT((5-1)/12) | G5: =Inputs!$B$20/12*(1+Inputs!$B$21)^INT((6-1)/12) | H5: =Inputs!$B$20/12*(1+Inputs!$B$21)^INT((7-1)/12) | I5: =Inputs!$B$20/12*(1+Inputs!$B$21)^INT((8-1)/12) | J5: =Inputs!$B$20/12*(1+Inputs!$B$21)^INT((9-1)/12) | K5: =Inputs!$B$20/12*(1+Inputs!$B$21)^INT((10-1)/12) | L5: =Inputs!$B$20/12*(1+Inputs!$B$21)^INT((11-1)/12) | M5: =Inputs!$B$20/12*(1+Inputs!$B$21)^INT((12-1)/12) | N5: =Inputs!$B$20/12*(1+Inputs!$B$21)^INT((13-1)/12) | O5: =Inputs!$B$20/12*(1+Inputs!$B$21)^INT((14-1)/12) | P5: =Inputs!$B$20/12*(1+Inputs!$B$21)^INT((15-1)/12) | Q5: =Inputs!$B$20/12*(1+Inputs!$B$21)^INT((16-1)/12) | R5: =Inputs!$B$20/12*(1+Inputs!$B$21)^INT((17-1)/12) | S5: =Inputs!$B$20/12*(1+Inputs!$B$21)^INT((18-1)/12) | T5: =Inputs!$B$20/12*(1+Inputs!$B$21)^INT((19-1)/12) | U5: =Inputs!$B$20/12*(1+Inputs!$B$21)^INT((20-1)/12) | V5: =Inputs!$B$20/12*(1+Inputs!$B$21)^INT((21-1)/12) | W5: =Inputs!$B$20/12*(1+Inputs!$B$21)^INT((22-1)/12) | X5: =Inputs!$B$20/12*(1+Inputs!$B$21)^INT((23-1)/12) | Y5: =Inputs!$B$20/12*(1+Inputs!$B$21)^INT((24-1)/12) | Z5: =Inputs!$B$20/12*(1+Inputs!$B$21)^INT((25-1)/12) | AA5: =Inputs!$B$20/12*(1+Inputs!$B$21)^INT((26-1)/12) | AB5: =Inputs!$B$20/12*(1+Inputs!$B$21)^INT((27-1)/12) | AC5: =Inputs!$B$20/12*(1+Inputs!$B$21)^INT((28-1)/12) | AD5: =Inputs!$B$20/12*(1+Inputs!$B$21)^INT((29-1)/12) | AE5: =Inputs!$B$20/12*(1+Inputs!$B$21)^INT((30-1)/12) | AF5: =Inputs!$B$20/12*(1+Inputs!$B$21)^INT((31-1)/12) | AG5: =Inputs!$B$20/12*(1+Inputs!$B$21)^INT((32-1)/12) | AH5: =Inputs!$B$20/12*(1+Inputs!$B$21)^INT((33-1)/12) | AI5: =Inputs!$B$20/12*(1+Inputs!$B$21)^INT((34-1)/12) | AJ5: =Inputs!$B$20/12*(1+Inputs!$B$21)^INT((35-1)/12) | AK5: =Inputs!$B$20/12*(1+Inputs!$B$21)^INT((36-1)/12) | AL5: =Inputs!$B$20/12*(1+Inputs!$B$21)^INT((37-1)/12) | AM5: =Inputs!$B$20/12*(1+Inputs!$B$21)^INT((38-1)/12) | AN5: =Inputs!$B$20/12*(1+Inputs!$B$21)^INT((39-1)/12) | AO5: =Inputs!$B$20/12*(1+Inputs!$B$21)^INT((40-1)/12) | AP5: =Inputs!$B$20/12*(1+Inputs!$B$21)^INT((41-1)/12) | AQ5: =Inputs!$B$20/12*(1+Inputs!$B$21)^INT((42-1)/12) | AR5: =Inputs!$B$20/12*(1+Inputs!$B$21)^INT((43-1)/12) | AS5: =Inputs!$B$20/12*(1+Inputs!$B$21)^INT((44-1)/12) | AT5: =Inputs!$B$20/12*(1+Inputs!$B$21)^INT((45-1)/12) | AU5: =Inputs!$B$20/12*(1+Inputs!$B$21)^INT((46-1)/12) | AV5: =Inputs!$B$20/12*(1+Inputs!$B$21)^INT((47-1)/12) | AW5: =Inputs!$B$20/12*(1+Inputs!$B$21)^INT((48-1)/12) | AX5: =Inputs!$B$20/12*(1+Inputs!$B$21)^INT((49-1)/12) | AY5: =Inputs!$B$20/12*(1+Inputs!$B$21)^INT((50-1)/12) | AZ5: =Inputs!$B$20/12*(1+Inputs!$B$21)^INT((51-1)/12) | BA5: =Inputs!$B$20/12*(1+Inputs!$B$21)^INT((52-1)/12)
A6: Neue Seats | B6: =IF(1>=Inputs!$B$22,Inputs!$B$23,0) | C6: =IF(2>=Inputs!$B$22,IF(2=Inputs!$B$22,Inputs!$B$23,ROUND(B9*Inputs!$B$24,0)),0) | D6: =IF(3>=Inputs!$B$22,IF(3=Inputs!$B$22,Inputs!$B$23,ROUND(C9*Inputs!$B$24,0)),0) | E6: =IF(4>=Inputs!$B$22,IF(4=Inputs!$B$22,Inputs!$B$23,ROUND(D9*Inputs!$B$24,0)),0) | F6: =IF(5>=Inputs!$B$22,IF(5=Inputs!$B$22,Inputs!$B$23,ROUND(E9*Inputs!$B$24,0)),0) | G6: =IF(6>=Inputs!$B$22,IF(6=Inputs!$B$22,Inputs!$B$23,ROUND(F9*Inputs!$B$24,0)),0) | H6: =IF(7>=Inputs!$B$22,IF(7=Inputs!$B$22,Inputs!$B$23,ROUND(G9*Inputs!$B$24,0)),0) | I6: =IF(8>=Inputs!$B$22,IF(8=Inputs!$B$22,Inputs!$B$23,ROUND(H9*Inputs!$B$24,0)),0) | J6: =IF(9>=Inputs!$B$22,IF(9=Inputs!$B$22,Inputs!$B$23,ROUND(I9*Inputs!$B$24,0)),0) | K6: =IF(10>=Inputs!$B$22,IF(10=Inputs!$B$22,Inputs!$B$23,ROUND(J9*Inputs!$B$24,0)),0) | L6: =IF(11>=Inputs!$B$22,IF(11=Inputs!$B$22,Inputs!$B$23,ROUND(K9*Inputs!$B$24,0)),0) | M6: =IF(12>=Inputs!$B$22,IF(12=Inputs!$B$22,Inputs!$B$23,ROUND(L9*Inputs!$B$24,0)),0) | N6: =IF(13>=Inputs!$B$22,IF(13=Inputs!$B$22,Inputs!$B$23,ROUND(M9*Inputs!$B$24,0)),0) | O6: =IF(14>=Inputs!$B$22,IF(14=Inputs!$B$22,Inputs!$B$23,ROUND(N9*Inputs!$B$24,0)),0) | P6: =IF(15>=Inputs!$B$22,IF(15=Inputs!$B$22,Inputs!$B$23,ROUND(O9*Inputs!$B$24,0)),0) | Q6: =IF(16>=Inputs!$B$22,IF(16=Inputs!$B$22,Inputs!$B$23,ROUND(P9*Inputs!$B$24,0)),0) | R6: =IF(17>=Inputs!$B$22,IF(17=Inputs!$B$22,Inputs!$B$23,ROUND(Q9*Inputs!$B$24,0)),0) | S6: =IF(18>=Inputs!$B$22,IF(18=Inputs!$B$22,Inputs!$B$23,ROUND(R9*Inputs!$B$24,0)),0) | T6: =IF(19>=Inputs!$B$22,IF(19=Inputs!$B$22,Inputs!$B$23,ROUND(S9*Inputs!$B$24,0)),0) | U6: =IF(20>=Inputs!$B$22,IF(20=Inputs!$B$22,Inputs!$B$23,ROUND(T9*Inputs!$B$24,0)),0) | V6: =IF(21>=Inputs!$B$22,IF(21=Inputs!$B$22,Inputs!$B$23,ROUND(U9*Inputs!$B$24,0)),0) | W6: =IF(22>=Inputs!$B$22,IF(22=Inputs!$B$22,Inputs!$B$23,ROUND(V9*Inputs!$B$24,0)),0) | X6: =IF(23>=Inputs!$B$22,IF(23=Inputs!$B$22,Inputs!$B$23,ROUND(W9*Inputs!$B$24,0)),0) | Y6: =IF(24>=Inputs!$B$22,IF(24=Inputs!$B$22,Inputs!$B$23,ROUND(X9*Inputs!$B$24,0)),0) | Z6: =IF(25>=Inputs!$B$22,IF(25=Inputs!$B$22,Inputs!$B$23,ROUND(Y9*Inputs!$B$24,0)),0) | AA6: =IF(26>=Inputs!$B$22,IF(26=Inputs!$B$22,Inputs!$B$23,ROUND(Z9*Inputs!$B$24,0)),0) | AB6: =IF(27>=Inputs!$B$22,IF(27=Inputs!$B$22,Inputs!$B$23,ROUND(AA9*Inputs!$B$24,0)),0) | AC6: =IF(28>=Inputs!$B$22,IF(28=Inputs!$B$22,Inputs!$B$23,ROUND(AB9*Inputs!$B$24,0)),0) | AD6: =IF(29>=Inputs!$B$22,IF(29=Inputs!$B$22,Inputs!$B$23,ROUND(AC9*Inputs!$B$24,0)),0) | AE6: =IF(30>=Inputs!$B$22,IF(30=Inputs!$B$22,Inputs!$B$23,ROUND(AD9*Inputs!$B$24,0)),0) | AF6: =IF(31>=Inputs!$B$22,IF(31=Inputs!$B$22,Inputs!$B$23,ROUND(AE9*Inputs!$B$24,0)),0) | AG6: =IF(32>=Inputs!$B$22,IF(32=Inputs!$B$22,Inputs!$B$23,ROUND(AF9*Inputs!$B$24,0)),0) | AH6: =IF(33>=Inputs!$B$22,IF(33=Inputs!$B$22,Inputs!$B$23,ROUND(AG9*Inputs!$B$24,0)),0) | AI6: =IF(34>=Inputs!$B$22,IF(34=Inputs!$B$22,Inputs!$B$23,ROUND(AH9*Inputs!$B$24,0)),0) | AJ6: =IF(35>=Inputs!$B$22,IF(35=Inputs!$B$22,Inputs!$B$23,ROUND(AI9*Inputs!$B$24,0)),0) | AK6: =IF(36>=Inputs!$B$22,IF(36=Inputs!$B$22,Inputs!$B$23,ROUND(AJ9*Inputs!$B$24,0)),0) | AL6: =IF(37>=Inputs!$B$22,IF(37=Inputs!$B$22,Inputs!$B$23,ROUND(AK9*Inputs!$B$24,0)),0) | AM6: =IF(38>=Inputs!$B$22,IF(38=Inputs!$B$22,Inputs!$B$23,ROUND(AL9*Inputs!$B$24,0)),0) | AN6: =IF(39>=Inputs!$B$22,IF(39=Inputs!$B$22,Inputs!$B$23,ROUND(AM9*Inputs!$B$24,0)),0) | AO6: =IF(40>=Inputs!$B$22,IF(40=Inputs!$B$22,Inputs!$B$23,ROUND(AN9*Inputs!$B$24,0)),0) | AP6: =IF(41>=Inputs!$B$22,IF(41=Inputs!$B$22,Inputs!$B$23,ROUND(AO9*Inputs!$B$24,0)),0) | AQ6: =IF(42>=Inputs!$B$22,IF(42=Inputs!$B$22,Inputs!$B$23,ROUND(AP9*Inputs!$B$24,0)),0) | AR6: =IF(43>=Inputs!$B$22,IF(43=Inputs!$B$22,Inputs!$B$23,ROUND(AQ9*Inputs!$B$24,0)),0) | AS6: =IF(44>=Inputs!$B$22,IF(44=Inputs!$B$22,Inputs!$B$23,ROUND(AR9*Inputs!$B$24,0)),0) | AT6: =IF(45>=Inputs!$B$22,IF(45=Inputs!$B$22,Inputs!$B$23,ROUND(AS9*Inputs!$B$24,0)),0) | AU6: =IF(46>=Inputs!$B$22,IF(46=Inputs!$B$22,Inputs!$B$23,ROUND(AT9*Inputs!$B$24,0)),0) | AV6: =IF(47>=Inputs!$B$22,IF(47=Inputs!$B$22,Inputs!$B$23,ROUND(AU9*Inputs!$B$24,0)),0) | AW6: =IF(48>=Inputs!$B$22,IF(48=Inputs!$B$22,Inputs!$B$23,ROUND(AV9*Inputs!$B$24,0)),0) | AX6: =IF(49>=Inputs!$B$22,IF(49=Inputs!$B$22,Inputs!$B$23,ROUND(AW9*Inputs!$B$24,0)),0) | AY6: =IF(50>=Inputs!$B$22,IF(50=Inputs!$B$22,Inputs!$B$23,ROUND(AX9*Inputs!$B$24,0)),0) | AZ6: =IF(51>=Inputs!$B$22,IF(51=Inputs!$B$22,Inputs!$B$23,ROUND(AY9*Inputs!$B$24,0)),0) | BA6: =IF(52>=Inputs!$B$22,IF(52=Inputs!$B$22,Inputs!$B$23,ROUND(AZ9*Inputs!$B$24,0)),0)
A7: Churned Seats | B7: =0 | C7: =IF(B9>0,ROUND(B9*Inputs!$B$28/12,0),0) | D7: =IF(C9>0,ROUND(C9*Inputs!$B$28/12,0),0) | E7: =IF(D9>0,ROUND(D9*Inputs!$B$28/12,0),0) | F7: =IF(E9>0,ROUND(E9*Inputs!$B$28/12,0),0) | G7: =IF(F9>0,ROUND(F9*Inputs!$B$28/12,0),0) | H7: =IF(G9>0,ROUND(G9*Inputs!$B$28/12,0),0) | I7: =IF(H9>0,ROUND(H9*Inputs!$B$28/12,0),0) | J7: =IF(I9>0,ROUND(I9*Inputs!$B$28/12,0),0) | ... BA7: =IF(AZ9>0,ROUND(AZ9*Inputs!$B$28/12,0),0)
A8: Net New Seats | B8: =B6-B7 | C8: =C6-C7 | D8: =D6-D7 | E8: =E6-E7 | F8: =F6-F7 | G8: =G6-G7 | H8: =H6-H7 | I8: =I6-I7 | ... BA8: =BA6-BA7
A9: Total Active Seats | B9: =B8 | C9: =B9+C8 | D9: =C9+D8 | E9: =D9+E8 | F9: =E9+F8 | G9: =F9+G8 | H9: =G9+H8 | I9: =H9+I8 | J9: =I9+J8 | ... BA9: =AZ9+BA8
A10: Monthly Subscription Revenue (€) | B10: =B9*B5 | C10: =C9*C5 | D10: =D9*D5 | E10: =E9*E5 | F10: =F9*F5 | G10: =G9*G5 | H10: =H9*H5 | I10: =I9*I5 | ... BA10: =BA9*BA5
A11: Subscription ARR (€) | B11: =B10*12 | C11: =C10*12 | D11: =D10*12 | E11: =E10*12 | F11: =F10*12 | G11: =G10*12 | H11: =H10*12 | I11: =I10*12 | ... BA11: =BA10*12
A13: Neue Enterprise-Deals (Quartal) | B13: =IF(AND(1>=Inputs!$B$25,MOD(1-Inputs!$B$25,3)=0),Inputs!$B$27,0) | C13: =IF(AND(2>=Inputs!$B$25,MOD(2-Inputs!$B$25,3)=0),Inputs!$B$27,0) | D13: =IF(AND(3>=Inputs!$B$25,MOD(3-Inputs!$B$25,3)=0),Inputs!$B$27,0) | E13: =IF(AND(4>=Inputs!$B$25,MOD(4-Inputs!$B$25,3)=0),Inputs!$B$27,0) | F13: =IF(AND(5>=Inputs!$B$25,MOD(5-Inputs!$B$25,3)=0),Inputs!$B$27,0) | G13: =IF(AND(6>=Inputs!$B$25,MOD(6-Inputs!$B$25,3)=0),Inputs!$B$27,0) | H13: =IF(AND(7>=Inputs!$B$25,MOD(7-Inputs!$B$25,3)=0),Inputs!$B$27,0) | I13: =IF(AND(8>=Inputs!$B$25,MOD(8-Inputs!$B$25,3)=0),Inputs!$B$27,0) | J13: =IF(AND(9>=Inputs!$B$25,MOD(9-Inputs!$B$25,3)=0),Inputs!$B$27,0) | K13: =IF(AND(10>=Inputs!$B$25,MOD(10-Inputs!$B$25,3)=0),Inputs!$B$27,0) | L13: =IF(AND(11>=Inputs!$B$25,MOD(11-Inputs!$B$25,3)=0),Inputs!$B$27,0) | M13: =IF(AND(12>=Inputs!$B$25,MOD(12-Inputs!$B$25,3)=0),Inputs!$B$27,0) | N13: =IF(AND(13>=Inputs!$B$25,MOD(13-Inputs!$B$25,3)=0),Inputs!$B$27,0) | O13: =IF(AND(14>=Inputs!$B$25,MOD(14-Inputs!$B$25,3)=0),Inputs!$B$27,0) | P13: =IF(AND(15>=Inputs!$B$25,MOD(15-Inputs!$B$25,3)=0),Inputs!$B$27,0) | Q13: =IF(AND(16>=Inputs!$B$25,MOD(16-Inputs!$B$25,3)=0),Inputs!$B$27,0) | R13: =IF(AND(17>=Inputs!$B$25,MOD(17-Inputs!$B$25,3)=0),Inputs!$B$27,0) | S13: =IF(AND(18>=Inputs!$B$25,MOD(18-Inputs!$B$25,3)=0),Inputs!$B$27,0) | T13: =IF(AND(19>=Inputs!$B$25,MOD(19-Inputs!$B$25,3)=0),Inputs!$B$27,0) | U13: =IF(AND(20>=Inputs!$B$25,MOD(20-Inputs!$B$25,3)=0),Inputs!$B$27,0) | V13: =IF(AND(21>=Inputs!$B$25,MOD(21-Inputs!$B$25,3)=0),Inputs!$B$27,0) | W13: =IF(AND(22>=Inputs!$B$25,MOD(22-Inputs!$B$25,3)=0),Inputs!$B$27,0) | X13: =IF(AND(23>=Inputs!$B$25,MOD(23-Inputs!$B$25,3)=0),Inputs!$B$27,0) | Y13: =IF(AND(24>=Inputs!$B$25,MOD(24-Inputs!$B$25,3)=0),Inputs!$B$27,0) | Z13: =IF(AND(25>=Inputs!$B$25,MOD(25-Inputs!$B$25,3)=0),Inputs!$B$27,0) | AA13: =IF(AND(26>=Inputs!$B$25,MOD(26-Inputs!$B$25,3)=0),Inputs!$B$27,0) | AB13: =IF(AND(27>=Inputs!$B$25,MOD(27-Inputs!$B$25,3)=0),Inputs!$B$27,0) | AC13: =IF(AND(28>=Inputs!$B$25,MOD(28-Inputs!$B$25,3)=0),Inputs!$B$27,0) | AD13: =IF(AND(29>=Inputs!$B$25,MOD(29-Inputs!$B$25,3)=0),Inputs!$B$27,0) | AE13: =IF(AND(30>=Inputs!$B$25,MOD(30-Inputs!$B$25,3)=0),Inputs!$B$27,0) | AF13: =IF(AND(31>=Inputs!$B$25,MOD(31-Inputs!$B$25,3)=0),Inputs!$B$27,0) | AG13: =IF(AND(32>=Inputs!$B$25,MOD(32-Inputs!$B$25,3)=0),Inputs!$B$27,0) | AH13: =IF(AND(33>=Inputs!$B$25,MOD(33-Inputs!$B$25,3)=0),Inputs!$B$27,0) | AI13: =IF(AND(34>=Inputs!$B$25,MOD(34-Inputs!$B$25,3)=0),Inputs!$B$27,0) | AJ13: =IF(AND(35>=Inputs!$B$25,MOD(35-Inputs!$B$25,3)=0),Inputs!$B$27,0) | AK13: =IF(AND(36>=Inputs!$B$25,MOD(36-Inputs!$B$25,3)=0),Inputs!$B$27,0) | AL13: =IF(AND(37>=Inputs!$B$25,MOD(37-Inputs!$B$25,3)=0),Inputs!$B$27,0) | AM13: =IF(AND(38>=Inputs!$B$25,MOD(38-Inputs!$B$25,3)=0),Inputs!$B$27,0) | AN13: =IF(AND(39>=Inputs!$B$25,MOD(39-Inputs!$B$25,3)=0),Inputs!$B$27,0) | AO13: =IF(AND(40>=Inputs!$B$25,MOD(40-Inputs!$B$25,3)=0),Inputs!$B$27,0) | AP13: =IF(AND(41>=Inputs!$B$25,MOD(41-Inputs!$B$25,3)=0),Inputs!$B$27,0) | AQ13: =IF(AND(42>=Inputs!$B$25,MOD(42-Inputs!$B$25,3)=0),Inputs!$B$27,0) | AR13: =IF(AND(43>=Inputs!$B$25,MOD(43-Inputs!$B$25,3)=0),Inputs!$B$27,0) | AS13: =IF(AND(44>=Inputs!$B$25,MOD(44-Inputs!$B$25,3)=0),Inputs!$B$27,0) | AT13: =IF(AND(45>=Inputs!$B$25,MOD(45-Inputs!$B$25,3)=0),Inputs!$B$27,0) | AU13: =IF(AND(46>=Inputs!$B$25,MOD(46-Inputs!$B$25,3)=0),Inputs!$B$27,0) | AV13: =IF(AND(47>=Inputs!$B$25,MOD(47-Inputs!$B$25,3)=0),Inputs!$B$27,0) | AW13: =IF(AND(48>=Inputs!$B$25,MOD(48-Inputs!$B$25,3)=0),Inputs!$B$27,0) | AX13: =IF(AND(49>=Inputs!$B$25,MOD(49-Inputs!$B$25,3)=0),Inputs!$B$27,0) | AY13: =IF(AND(50>=Inputs!$B$25,MOD(50-Inputs!$B$25,3)=0),Inputs!$B$27,0) | AZ13: =IF(AND(51>=Inputs!$B$25,MOD(51-Inputs!$B$25,3)=0),Inputs!$B$27,0) | BA13: =IF(AND(52>=Inputs!$B$25,MOD(52-Inputs!$B$25,3)=0),Inputs!$B$27,0)
A14: Churned Enterprise | B14: =0 | C14: =IF(B15>0,IF(MOD(2,12)=0,ROUND(B15*Inputs!$B$28,0),0),0) | D14: =IF(C15>0,IF(MOD(3,12)=0,ROUND(C15*Inputs!$B$28,0),0),0) | E14: =IF(D15>0,IF(MOD(4,12)=0,ROUND(D15*Inputs!$B$28,0),0),0) | F14: =IF(E15>0,IF(MOD(5,12)=0,ROUND(E15*Inputs!$B$28,0),0),0) | G14: =IF(F15>0,IF(MOD(6,12)=0,ROUND(F15*Inputs!$B$28,0),0),0) | H14: =IF(G15>0,IF(MOD(7,12)=0,ROUND(G15*Inputs!$B$28,0),0),0) | I14: =IF(H15>0,IF(MOD(8,12)=0,ROUND(H15*Inputs!$B$28,0),0),0) | J14: =IF(I15>0,IF(MOD(9,12)=0,ROUND(I15*Inputs!$B$28,0),0),0) | K14: =IF(J15>0,IF(MOD(10,12)=0,ROUND(J15*Inputs!$B$28,0),0),0) | L14: =IF(K15>0,IF(MOD(11,12)=0,ROUND(K15*Inputs!$B$28,0),0),0) | M14: =IF(L15>0,IF(MOD(12,12)=0,ROUND(L15*Inputs!$B$28,0),0),0) | N14: =IF(M15>0,IF(MOD(13,12)=0,ROUND(M15*Inputs!$B$28,0),0),0) | O14: =IF(N15>0,IF(MOD(14,12)=0,ROUND(N15*Inputs!$B$28,0),0),0) | P14: =IF(O15>0,IF(MOD(15,12)=0,ROUND(O15*Inputs!$B$28,0),0),0) | Q14: =IF(P15>0,IF(MOD(16,12)=0,ROUND(P15*Inputs!$B$28,0),0),0) | R14: =IF(Q15>0,IF(MOD(17,12)=0,ROUND(Q15*Inputs!$B$28,0),0),0) | S14: =IF(R15>0,IF(MOD(18,12)=0,ROUND(R15*Inputs!$B$28,0),0),0) | T14: =IF(S15>0,IF(MOD(19,12)=0,ROUND(S15*Inputs!$B$28,0),0),0) | U14: =IF(T15>0,IF(MOD(20,12)=0,ROUND(T15*Inputs!$B$28,0),0),0) | V14: =IF(U15>0,IF(MOD(21,12)=0,ROUND(U15*Inputs!$B$28,0),0),0) | W14: =IF(V15>0,IF(MOD(22,12)=0,ROUND(V15*Inputs!$B$28,0),0),0) | X14: =IF(W15>0,IF(MOD(23,12)=0,ROUND(W15*Inputs!$B$28,0),0),0) | Y14: =IF(X15>0,IF(MOD(24,12)=0,ROUND(X15*Inputs!$B$28,0),0),0) | Z14: =IF(Y15>0,IF(MOD(25,12)=0,ROUND(Y15*Inputs!$B$28,0),0),0) | AA14: =IF(Z15>0,IF(MOD(26,12)=0,ROUND(Z15*Inputs!$B$28,0),0),0) | AB14: =IF(AA15>0,IF(MOD(27,12)=0,ROUND(AA15*Inputs!$B$28,0),0),0) | AC14: =IF(AB15>0,IF(MOD(28,12)=0,ROUND(AB15*Inputs!$B$28,0),0),0) | AD14: =IF(AC15>0,IF(MOD(29,12)=0,ROUND(AC15*Inputs!$B$28,0),0),0) | AE14: =IF(AD15>0,IF(MOD(30,12)=0,ROUND(AD15*Inputs!$B$28,0),0),0) | AF14: =IF(AE15>0,IF(MOD(31,12)=0,ROUND(AE15*Inputs!$B$28,0),0),0) | AG14: =IF(AF15>0,IF(MOD(32,12)=0,ROUND(AF15*Inputs!$B$28,0),0),0) | AH14: =IF(AG15>0,IF(MOD(33,12)=0,ROUND(AG15*Inputs!$B$28,0),0),0) | AI14: =IF(AH15>0,IF(MOD(34,12)=0,ROUND(AH15*Inputs!$B$28,0),0),0) | AJ14: =IF(AI15>0,IF(MOD(35,12)=0,ROUND(AI15*Inputs!$B$28,0),0),0) | AK14: =IF(AJ15>0,IF(MOD(36,12)=0,ROUND(AJ15*Inputs!$B$28,0),0),0) | AL14: =IF(AK15>0,IF(MOD(37,12)=0,ROUND(AK15*Inputs!$B$28,0),0),0) | AM14: =IF(AL15>0,IF(MOD(38,12)=0,ROUND(AL15*Inputs!$B$28,0),0),0) | AN14: =IF(AM15>0,IF(MOD(39,12)=0,ROUND(AM15*Inputs!$B$28,0),0),0) | AO14: =IF(AN15>0,IF(MOD(40,12)=0,ROUND(AN15*Inputs!$B$28,0),0),0) | AP14: =IF(AO15>0,IF(MOD(41,12)=0,ROUND(AO15*Inputs!$B$28,0),0),0) | AQ14: =IF(AP15>0,IF(MOD(42,12)=0,ROUND(AP15*Inputs!$B$28,0),0),0) | AR14: =IF(AQ15>0,IF(MOD(43,12)=0,ROUND(AQ15*Inputs!$B$28,0),0),0) | AS14: =IF(AR15>0,IF(MOD(44,12)=0,ROUND(AR15*Inputs!$B$28,0),0),0) | AT14: =IF(AS15>0,IF(MOD(45,12)=0,ROUND(AS15*Inputs!$B$28,0),0),0) | AU14: =IF(AT15>0,IF(MOD(46,12)=0,ROUND(AT15*Inputs!$B$28,0),0),0) | AV14: =IF(AU15>0,IF(MOD(47,12)=0,ROUND(AU15*Inputs!$B$28,0),0),0) | AW14: =IF(AV15>0,IF(MOD(48,12)=0,ROUND(AV15*Inputs!$B$28,0),0),0) | AX14: =IF(AW15>0,IF(MOD(49,12)=0,ROUND(AW15*Inputs!$B$28,0),0),0) | AY14: =IF(AX15>0,IF(MOD(50,12)=0,ROUND(AX15*Inputs!$B$28,0),0),0) | AZ14: =IF(AY15>0,IF(MOD(51,12)=0,ROUND(AY15*Inputs!$B$28,0),0),0) | BA14: =IF(AZ15>0,IF(MOD(52,12)=0,ROUND(AZ15*Inputs!$B$28,0),0),0)
A15: Active Enterprise Contracts | B15: =B13-B14 | C15: =B15+C13-C14 | D15: =C15+D13-D14 | E15: =D15+E13-E14 | F15: =E15+F13-F14 | G15: =F15+G13-G14 | H15: =G15+H13-H14 | I15: =H15+I13-I14 | J15: =I15+J13-J14 | ... BA15: =AZ15+BA13-BA14
A16: Avg Enterprise ACV (€) | B16: =Inputs!$B$26*(1+Inputs!$B$21)^INT((1-1)/12) | C16: =Inputs!$B$26*(1+Inputs!$B$21)^INT((2-1)/12) | D16: =Inputs!$B$26*(1+Inputs!$B$21)^INT((3-1)/12) | E16: =Inputs!$B$26*(1+Inputs!$B$21)^INT((4-1)/12) | F16: =Inputs!$B$26*(1+Inputs!$B$21)^INT((5-1)/12) | G16: =Inputs!$B$26*(1+Inputs!$B$21)^INT((6-1)/12) | H16: =Inputs!$B$26*(1+Inputs!$B$21)^INT((7-1)/12) | I16: =Inputs!$B$26*(1+Inputs!$B$21)^INT((8-1)/12) | J16: =Inputs!$B$26*(1+Inputs!$B$21)^INT((9-1)/12) | K16: =Inputs!$B$26*(1+Inputs!$B$21)^INT((10-1)/12) | L16: =Inputs!$B$26*(1+Inputs!$B$21)^INT((11-1)/12) | M16: =Inputs!$B$26*(1+Inputs!$B$21)^INT((12-1)/12) | N16: =Inputs!$B$26*(1+Inputs!$B$21)^INT((13-1)/12) | O16: =Inputs!$B$26*(1+Inputs!$B$21)^INT((14-1)/12) | P16: =Inputs!$B$26*(1+Inputs!$B$21)^INT((15-1)/12) | Q16: =Inputs!$B$26*(1+Inputs!$B$21)^INT((16-1)/12) | R16: =Inputs!$B$26*(1+Inputs!$B$21)^INT((17-1)/12) | S16: =Inputs!$B$26*(1+Inputs!$B$21)^INT((18-1)/12) | T16: =Inputs!$B$26*(1+Inputs!$B$21)^INT((19-1)/12) | U16: =Inputs!$B$26*(1+Inputs!$B$21)^INT((20-1)/12) | V16: =Inputs!$B$26*(1+Inputs!$B$21)^INT((21-1)/12) | W16: =Inputs!$B$26*(1+Inputs!$B$21)^INT((22-1)/12) | X16: =Inputs!$B$26*(1+Inputs!$B$21)^INT((23-1)/12) | Y16: =Inputs!$B$26*(1+Inputs!$B$21)^INT((24-1)/12) | Z16: =Inputs!$B$26*(1+Inputs!$B$21)^INT((25-1)/12) | AA16: =Inputs!$B$26*(1+Inputs!$B$21)^INT((26-1)/12) | AB16: =Inputs!$B$26*(1+Inputs!$B$21)^INT((27-1)/12) | AC16: =Inputs!$B$26*(1+Inputs!$B$21)^INT((28-1)/12) | AD16: =Inputs!$B$26*(1+Inputs!$B$21)^INT((29-1)/12) | AE16: =Inputs!$B$26*(1+Inputs!$B$21)^INT((30-1)/12) | AF16: =Inputs!$B$26*(1+Inputs!$B$21)^INT((31-1)/12) | AG16: =Inputs!$B$26*(1+Inputs!$B$21)^INT((32-1)/12) | AH16: =Inputs!$B$26*(1+Inputs!$B$21)^INT((33-1)/12) | AI16: =Inputs!$B$26*(1+Inputs!$B$21)^INT((34-1)/12) | AJ16: =Inputs!$B$26*(1+Inputs!$B$21)^INT((35-1)/12) | AK16: =Inputs!$B$26*(1+Inputs!$B$21)^INT((36-1)/12) | AL16: =Inputs!$B$26*(1+Inputs!$B$21)^INT((37-1)/12) | AM16: =Inputs!$B$26*(1+Inputs!$B$21)^INT((38-1)/12) | AN16: =Inputs!$B$26*(1+Inputs!$B$21)^INT((39-1)/12) | AO16: =Inputs!$B$26*(1+Inputs!$B$21)^INT((40-1)/12) | AP16: =Inputs!$B$26*(1+Inputs!$B$21)^INT((41-1)/12) | AQ16: =Inputs!$B$26*(1+Inputs!$B$21)^INT((42-1)/12) | AR16: =Inputs!$B$26*(1+Inputs!$B$21)^INT((43-1)/12) | AS16: =Inputs!$B$26*(1+Inputs!$B$21)^INT((44-1)/12) | AT16: =Inputs!$B$26*(1+Inputs!$B$21)^INT((45-1)/12) | AU16: =Inputs!$B$26*(1+Inputs!$B$21)^INT((46-1)/12) | AV16: =Inputs!$B$26*(1+Inputs!$B$21)^INT((47-1)/12) | AW16: =Inputs!$B$26*(1+Inputs!$B$21)^INT((48-1)/12) | AX16: =Inputs!$B$26*(1+Inputs!$B$21)^INT((49-1)/12) | AY16: =Inputs!$B$26*(1+Inputs!$B$21)^INT((50-1)/12) | AZ16: =Inputs!$B$26*(1+Inputs!$B$21)^INT((51-1)/12) | BA16: =Inputs!$B$26*(1+Inputs!$B$21)^INT((52-1)/12)
A17: Enterprise Monthly Revenue (€) | B17: =B15*B16/12 | C17: =C15*C16/12 | D17: =D15*D16/12 | E17: =E15*E16/12 | F17: =F15*F16/12 | G17: =G15*G16/12 | H17: =H15*H16/12 | I17: =I15*I16/12 | ... BA17: =BA15*BA16/12
A18: ── RECURRING REVENUE (SaaS-Metriken, ohne Implementation-Support) ──
A19: MRR – Monthly Recurring Revenue (Lizenzen) | B19: =B10+B17 | C19: =C10+C17 | D19: =D10+D17 | E19: =E10+E17 | F19: =F10+F17 | G19: =G10+G17 | H19: =H10+H17 | I19: =I10+I17 | ... BA19: =BA10+BA17
A20: ARR – Annual Recurring Revenue (Lizenzen = MRR × 12) | B20: =B19*12 | C20: =C19*12 | D20: =D19*12 | E20: =E19*12 | F20: =F19*12 | G20: =G19*12 | H20: =H19*12 | I20: =I19*12 | ... BA20: =BA19*12
A21: Total Monthly Revenue (Lizenzen + Implementation-Support) | B21: =B19+B30 | C21: =C19+C30 | D21: =D19+D30 | E21: =E19+E30 | F21: =F19+F30 | G21: =G19+G30 | H21: =H19+H30 | I21: =I19+I30 | ... BA21: =BA19+BA30
