Workbook

Sheet 0_Anleitung
A1: LoopForgeLab_Financial Projection Model: ANLEITUNG ZUM AUSFUELLEN DES BUSINESS MODELS
A2: Bearbeitungstand: | B2: =TODAY() -> 46096
A3: 1. SHEET-UEBERSICHT
A4: Sheet | B4: Funktion | C4: Editierbar? | D4: Abhaengigkeit
A5: 0_Anleitung | B5: Diese Anleitung | C5: Nein | D5: -
A6: 1_Szenario | B6: Dropdown: gering/normal/stark | C6: JA: nur C1 | D6: Keine (Quelle)
A7: Szenario_Beschreibung | B7: Szenario-Auswirkungen, dynamisch | C7: Nein | D7: 1_Szenario
A8: 2_Inputs | B8: Gehaelter, Kosten, Finanzierung, Hiring, Neukunden | C8: JA: blaue Zellen | D8: 1_Szenario
A9: 3_Roadmap | B9: Dashboard je Startup-Phase | C9: Nein | D9: 4_Rev, 5_Costs
A10: 4_Revenue | B10: 52-Mo Umsatz SME/Mid/Enterprise | C10: Nein | D10: 2_Inputs
A11: 5_Costs | B11: 52-Mo Kosten, 8 Kategorien, phasenabh. | C11: Nein | D11: 2_Inputs
A12: 6_P&L | B12: Gewinn- & Verlustrechnung | C12: Nein | D12: 4_Rev, 5_Costs
A13: 7_BS_CF | B13: Cashflow, Burn Rate, Runway | C13: Nein | D13: 6_P&L, 2_Inputs
A15: 2. SZENARIO EINSTELLEN (1_Szenario)
A16: Zelle C1 | B16: Dropdown: gering / normal / stark | C16: Aendert ALLE szenarioabh. Parameter
A17: Zeilen 3-22 | B17: Spalte C = aktiver Wert, E/F/G = alle 3 Szenarien
A18: Steuerbare Parameter:
A19: Seats/Kunde SME & Mid | B19: gering=3/8, normal=5/15, stark=10/25
A20: Seat-Preis SME & Mid | B20: 250 / 350 / 450 EUR pro Monat
A21: Enterprise Fee | B21: 18k / 25k / 40k EUR pro Jahr
A22: Impl.-Support | B22: Tagessatz, Tage/Kunde, Buchungsquote
A23: Retention/Preise | B23: NRR, Churn, Preiserhoehung/Jahr
A25: 3. MANUELLE EINGABEN IN 2_INPUTS
A26: Farbcode: | B26: BLAU = manuell aenderbar | C26: BLAU-BG = aus Szenario (NICHT aendern) | D26: GELB = Achtung
A27: Bereich | B27: Zeilen | C27: Inhalt | D27: Hinweis
A28: Allgemein | B28: Zeilen 2-7 | C28: Firma, Startdatum, Waehrung, Steuersatz | D28: Steuersatz = gelb
A29: Finanzierungsrunden | B29: Zeilen 8-16 | C29: Betraege & Monate: Ideation bis Series A | D29: -> Cash Flow (7_BS_CF)
A30: Business Angels | B30: 17-23 | C30: 3 Platzhalter (A/B/C): Betrag + Monat | D30: Monat=0 -> nicht aktiv
A31: Grants / Foerdermittel | B31: 24-30 | C31: 3 Platzhalter (A/B/C): Betrag + Monat | D31: Monat=0 -> nicht aktiv
A32: Revenue-Annahmen | B32: 32-40 | C32: Seats, Preise, Churn, Startmonat | D32: Blau-BG = Auto aus Szenario!
A33: Impl.-Support | B33: 42-46 | C33: Tagessatz, Tage, Quote, Startmonat | D33: Blau-BG = Auto aus Szenario!
A34: Gehaelter Gruender (Phasen) | B34: 47-69 | C34: CEO/CTO/CCO: AG-Brutto je Phase (5 Stufen) | D34: Ideation kann 0 EUR sein
A35: Gehaelter Mitarbeiter | B35: 71-84 | C35: AN-Brutto je Rolle + AG-Aufschlag (22%) | D35: Spalte C = AG-Brutto (autom.)
A36: Technologie | B36: 86-91 | C36: Cloud Hosting, AI/ML APIs, SaaS pro MA | D36: Blau = manuell
A37: SaaS Tools (Phasen) | B37: 92-97 | C37: SaaS-Lizenzen je Startup-Phase | D37: 5 Phasen-Werte
... A47: NEUKUNDEN-PLAN (!) | B47: 185-190 | C47: MANUELL: Neukunden je Monat & Groesse | D47: -> Direkt in 4_Revenue
A49: 4. WICHTIGE HINWEISE
A50: Alle Kosten in 5_Costs sind phasenabhaengig (Ideation/Pre-Seed/Seed/Series A/Series B) und werden ausschliesslich ueber 2_Inputs gesteuert. Im Costs-Blatt keine direkten Eingaben vornehmen!

Sheet 1_Szenario
B1: Aktives Szenario: hier einstellen → | C1: normal | E1: Gering | F1: Normal | G1: Stark
A2: Kategorie | B2: Parameter | C2: Aktiver Wert | D2: Einheit | E2: Gering | F2: Normal | G2: Stark
A3: Markt | B3: Anteil Packaging | C3: =IF($C$1="gering",E3,IF($C$1="normal",F3,G3)) -> 0.7 | D3: % | E3: 0.5 | F3: 0.7 | G3: 0.8
A4: Vertrieb | B4: Startmonat Kunden | C4: =IF($C$1="gering",E4,IF($C$1="normal",F4,G4)) -> 8 | D4: Monat | E4: 17 | F4: 8 | G4: 6
A5: Revenue | B5: Impl.-Support Tagessatz (€) | C5: =IF($C$1="gering",E5,IF($C$1="normal",F5,G5)) -> 1500 | D5: €/Tag | E5: 1500 | F5: 1500 | G5: 2500
A6: Revenue | B6: Impl.-Support Tage/Kunde | C6: =IF($C$1="gering",E6,IF($C$1="normal",F6,G6)) -> 20 | D6: Tage | E6: 10 | F6: 20 | G6: 30
A7: Revenue | B7: Impl.-Support Buchungsquote | C7: =IF($C$1="gering",E7,IF($C$1="normal",F7,G7)) -> 1 | D7: % | E7: 0.8 | F7: 1 | G7: 1
A8: Revenue | B8: Impl.-Support Startmonat | C8: =IF($C$1="gering",E8,IF($C$1="normal",F8,G8)) -> 6 | D8: Monat | E8: 10 | F8: 6 | G8: 5
A9: Retention | B9: Net Revenue Retention (NRR) | C9: =IF($C$1="gering",E9,IF($C$1="normal",F9,G9)) -> 1.15 | D9: % | E9: 1.15 | F9: 1.15 | G9: 1.3
A10: Retention | B10: Jährliche Churn Rate | C10: =IF($C$1="gering",E10,IF($C$1="normal",F10,G10)) -> 0.05 | D10: % | E10: 0.05 | F10: 0.05 | G10: 0.03
A11: Effizienz | B11: Iterations-Reduktion | C11: =IF($C$1="gering",E11,IF($C$1="normal",F11,G11)) -> 2,0x | D11: Faktor | E11: 1,2x | F11: 2,0x | G11: 3,0x
A12: Kosten | B12: Onboarding-Aufwand (Std.) | C12: =IF($C$1="gering",E12,IF($C$1="normal",F12,G12)) -> 60 | D12: Stunden | E12: 120 | F12: 60 | G12: 30
A13: Personal | B13: externe Experten als Untersützung (FTE-Plan) -->Puffer wenn benötigt | C13: =IF($C$1="gering",E13,IF($C$1="normal",F13,G13)) -> 0 | D13: FTE | E13: 0 | F13: 0 | G13: 0
A14: Revenue | B14: Impl.-Support Umsatz/Kunde | C14: =C5*C6 -> 30000 | D14: €/Kunde | E14: =E5*E6 -> 15000 | F14: =F5*F6 -> 30000 | G14: =G5*G6 -> 75000
A15: Revenue | B15: Seats/Kunde SME | C15: =IF($C$1="gering",E15,IF($C$1="normal",F15,G15)) -> 6 | D15: Seats | E15: 4 | F15: 6 | G15: 10
A16: Revenue | B16: Seats/Kunde Mid-Company | C16: =IF($C$1="gering",E16,IF($C$1="normal",F16,G16)) -> 12 | D16: Seats | E16: 8 | F16: 12 | G16: 15
A17: Revenue | B17: Seat-Preis SME (€/Monat) | C17: =IF($C$1="gering",E17,IF($C$1="normal",F17,G17)) -> 460 | D17: €/Monat | E17: 350 | F17: 460 | G17: 500
A18: Revenue | B18: Seat-Preis Mid-Company (€/Monat) | C18: =IF($C$1="gering",E18,IF($C$1="normal",F18,G18)) -> 530 | D18: €/Monat | E18: 450 | F18: 530 | G18: 550
A19: Revenue | B19: Enterprise Jahres-Fee (€/Jahr) | C19: =IF($C$1="gering",E19,IF($C$1="normal",F19,G19)) -> 50000 | D19: €/Jahr | E19: 30000 | F19: 50000 | G19: 45000
A20: Revenue | B20: Preiserhöhung/Jahr | C20: =IF($C$1="gering",E20,IF($C$1="normal",F20,G20)) -> 0.04 | D20: % | E20: 0.03 | F20: 0.04 | G20: 0.06

Sheet Szenario_Beschreibung
A1: SZENARIO-BESCHREIBUNG & AUSWIRKUNGSANALYSE
A3: 1. SZENARIO-VERGLEICH: PARAMETER & AUSWIRKUNGEN
A4: Parameter | B4: Gering | C4: Normal | D4: Stark | E4: Einfluss auf | F4: Beschreibung
A5: Seats/Kunde SME | B5: ='1_Szenario'!E15 -> 4 | C5: ='1_Szenario'!F15 -> 6 | D5: ='1_Szenario'!G15 -> 10 | E5: Revenue | F5: Weniger Seats = weniger MRR je Kunde. Typisch: 3-10 User für SME.
A6: Seats/Kunde Mid | B6: ='1_Szenario'!E16 -> 8 | C6: ='1_Szenario'!F16 -> 12 | D6: ='1_Szenario'!G16 -> 15 | E6: Revenue | F6: Mid-Market hat 3-5x mehr Seats als SME.
A7: Seat-Preis SME (€/Mo) | B7: ='1_Szenario'!E17 -> 350 | C7: ='1_Szenario'!F17 -> 460 | D7: ='1_Szenario'!G17 -> 500 | E7: Revenue, Margin | F7: Höherer Preis = mehr Umsatz, aber auch höhere Churn-Gefahr.
A8: Seat-Preis Mid (€/Mo) | B8: ='1_Szenario'!E18 -> 450 | C8: ='1_Szenario'!F18 -> 530 | D8: ='1_Szenario'!G18 -> 550 | E8: Revenue, Margin | F8: Mid-Companies zahlen höhere Preise für mehr Features.
A9: Enterprise Fee (€/Jahr) | B9: ='1_Szenario'!E19 -> 30000 | C9: ='1_Szenario'!F19 -> 50000 | D9: ='1_Szenario'!G19 -> 45000 | E9: Revenue, ARR | F9: Jahresverträge mit Custom-Pricing. Enterprise-ACV kann 47k€+ erreichen.
A10: Startmonat Kunden | B10: ='1_Szenario'!E4 -> 17 | C10: ='1_Szenario'!F4 -> 8 | D10: ='1_Szenario'!G4 -> 6 | E10: Revenue, Break-Even | F10: Späterer Start = länger kein Revenue = höherer Burn.
A11: Impl.-Support Tage/Kunde | B11: ='1_Szenario'!E6 -> 10 | C11: ='1_Szenario'!F6 -> 20 | D11: ='1_Szenario'!G6 -> 30 | E11: Revenue, Personal | F11: Mehr Tage = mehr Einmal-Revenue, aber auch mehr Personalaufwand.
A12: Buchungsquote | B12: ='1_Szenario'!E7 -> 0.8 | C12: ='1_Szenario'!F7 -> 1 | D12: ='1_Szenario'!G7 -> 1 | E12: Revenue | F12: Anteil Neukunden die Impl.-Support buchen.
A13: Churn Rate | B13: ='1_Szenario'!E10 -> 0.05 | C13: ='1_Szenario'!F10 -> 0.05 | D13: ='1_Szenario'!G10 -> 0.03 | E13: Revenue, LTV | F13: SME-Churn kann 15-30% p.a. erreichen, Enterprise liegt bei 5-8%.
A14: Preiserhöhung/Jahr | B14: ='1_Szenario'!E20 -> 0.03 | C14: ='1_Szenario'!F20 -> 0.04 | D14: ='1_Szenario'!G20 -> 0.06 | E14: Revenue, ARR | F14: SaaS-Preise steigen durchschnittlich 8-12% pro Jahr (2025).
A15: NRR | B15: ='1_Szenario'!E9 -> 1.15 | C15: ='1_Szenario'!F9 -> 1.15 | D15: ='1_Szenario'!G9 -> 1.3 | E15: Revenue, ARR | F15: Best-in-class NRR: SME 110-120%, Mid 120-130%, Enterprise 130-140%.
A17: 2. REVENUE-AUSWIRKUNG JE KUNDENSEGMENT (pro Kunde/Monat)
A18: KPI | B18: Gering | C18: Normal | D18: Stark | E18: Einheit | F18: Berechnung
A19: MRR je SME-Kunde | B19: ='1_Szenario'!E15*'1_Szenario'!E17 -> 1400 | C19: ='1_Szenario'!F15*'1_Szenario'!F17 -> 2760 | D19: ='1_Szenario'!G15*'1_Szenario'!G17 -> 5000 | E19: €/Monat | F19: Seats/Kunde × Seat-Preis
A20: ARR je SME-Kunde | B20: =B19*12 -> 16800 | C20: =C19*12 -> 33120 | D20: =D19*12 -> 60000 | E20: €/Jahr | F20: MRR × 12
A21: MRR je Mid-Kunde | B21: ='1_Szenario'!E16*'1_Szenario'!E18 -> 3600 | C21: ='1_Szenario'!F16*'1_Szenario'!F18 -> 6360 | D21: ='1_Szenario'!G16*'1_Szenario'!G18 -> 8250 | E21: €/Monat | F21: Seats/Kunde × Seat-Preis
A22: ARR je Mid-Kunde | B22: =B21*12 -> 43200 | C22: =C21*12 -> 76320 | D22: =D21*12 -> 99000 | E22: €/Jahr | F22: MRR × 12
A23: Revenue je Enterprise/Monat | B23: ='1_Szenario'!E19/12 -> 2500 | C23: ='1_Szenario'!F19/12 -> 4166.6667 | D23: ='1_Szenario'!G19/12 -> 3750 | E23: €/Monat | F23: Jahres-Fee / 12
A24: Impl.-Support je Neukunde | B24: ='1_Szenario'!E14 -> 15000 | C24: ='1_Szenario'!F14 -> 30000 | D24: ='1_Szenario'!G14 -> 75000 | E24: € (einmalig) | F24: Tagessatz × Tage (wenn gebucht)
A26: 3. SALES CYCLE & PIPELINE BENCHMARKS (Branchendaten)
A27: Segment | B27: Sales Cycle | C27: Close Rate | D27: Typischer ACV | E27: Churn Rate | F27: Quelle
A28: SME | B28: 14-30 Tage | C28: 15-25% | D28: <15k€/Jahr | E28: 15-30% p.a. | F28: Optifai 2025, Marketing LTB
A29: Mid-Market | B29: 30-90 Tage | C29: 15-25% | D29: 15-100k€/Jahr | E29: 5-15% p.a. | F29: Optifai 2025, DollarPocket
A30: Enterprise | B30: 90-180+ Tage | C30: 15-25% | D30: >100k€/Jahr | E30: 5-8% p.a. | F30: Optifai 2025, Marketing LTB
A32: 4. PIPELINE & ADDRESSABLE COMPANIES
A33: Um die Sales-Targets zu erreichen, müssen deutlich MEHR Unternehmen angesprochen werden als Neukunden geplant sind:
A34: Berechnung | B34: SME (Close Rate 20%) | C34: Mid (Close Rate 15%) | D34: Enterprise (Close Rate 10%) | E34: Formel | F34: Hinweis
A35: Für 1 Neukunde müssen angesprochen werden: | B35: 5 Unternehmen | C35: 7 Unternehmen | D35: 10 Unternehmen | E35: 1 / Close Rate | F35: Ohne Berücksichtigung Awareness-Phase
A37: 5. POTENZIELLE ENGPÄSSE & RISIKEN (Shortfalls)
A38: Risiko | B38: Gering (Worst Case) | C38: Normal (Base Case) | D38: Stark (Best Case) | E38: Mitigierung | F38: Quelle / Benchmark
A39: Personal für Entwicklung | B39: ='1_Szenario'!E13&" FTE" -> 0 FTE | C39: ='1_Szenario'!F13&" FTE" -> 0 FTE | D39: ='1_Szenario'!G13&" FTE" -> 0 FTE | E39: Frühzeitig Key Hires planen | F39: Median ARR/FTE: 125k€ (Vena 2024)
A40: Personal für Testing/QA | B40: Keine dediz. QA | C40: Dev + QA kombiniert | D40: Dedizierte QA-Rolle | E40: Testautomatisierung investieren | F40: SaaS-Standard ab Series A
A41: Implementation & Training | B41: ='1_Szenario'!E6&" Tage/Kunde, low-touch" -> 10 Tage/Kunde, low-touch | C41: ='1_Szenario'!F6&" Tage/Kunde, medium" -> 20 Tage/Kunde, medium | D41: ='1_Szenario'!G6&" Tage/Kunde, high-touch" -> 30 Tage/Kunde, high-touch | E41: Skalierbare Onboarding-Plattform | F41: Onboarding beeinflusst 75% der Churn
A42: Customer Success | B42: Kein CS-Team, Founder | C42: 1 CS ab M24 | D42: 2 CS-Manager | E42: CS reduziert Churn um 10-35% | F42: Marketing LTB 2025
A43: Sales Cycle Überlappung | B43: Ent. Deals: 6-18 Mo Vorlauf | C43: Mid: 1-3 Mo Vorlauf | D43: SME: 2-4 Wochen | E43: Pipeline 3x Target aufbauen | F43: Optifai 2025 (N=687)
A44: Lead-to-Close Verzögerung | B44: =_xludf.CONCAT("M",'1_Szenario'!E4," Start → Revenue erst M",'1_Szenario'!E4+2,"+") -> #NAME? | C44: =_xludf.CONCAT("M",'1_Szenario'!F4," Start → Revenue M",'1_Szenario'!F4+1,"+") -> #NAME? | D44: =_xludf.CONCAT("M",'1_Szenario'!G4," Start → Revenue M",'1_Szenario'!G4+1,"+") -> #NAME? | E44: Früh Marketing starten | F44: Sales Cycles +22% seit 2022
A45: Runway-Risiko | B45: Burn >50k€/Mo, Cash <12Mo | C45: Burn ∼100k€/Mo, Cash 18Mo | D45: Burn ∼150k€/Mo, Cash 24Mo+ | E45: Bridge-Finanzierung planen | F45: Break-Even abhängig von Wachstum
...

Sheet 2_Inputs
A1: ZENTRALE EINGABEWERTE | B1: Wert | C1: Einheit / Hinweis | D1: Quelle
A2: ALLGEMEIN
A3: Firmenname | B3: LoopforgeLab GmbH | C3: Name des Unternehmens
A4: Startdatum | B4: 46113 | C4: Beginn Projektionen
A5: Währung | B5: EUR
A6: Steuersatz | B6: 0.3 | C6: KSt + GewSt (~30%)
A8: FINANZIERUNGSRUNDEN
A9: Ideation Betrag | B9: 120000 | C9: € | D9: C13 funding + GmbH Stammeinlage
A10: Ideation Monat | B10: 4
A11: Pre-Seed Betrag | B11: 0 | C11: € | D11: no funding round but Angels
A12: Pre-Seed Monat | B12: 0
A13: Seed Betrag | B13: 2000000 | C13: €
A14: Seed Monat | B14: 17
A15: Series A Betrag | B15: 10000000 | C15: €
A16: Series A Monat | B16: 29
A17: BUSINESS ANGELS
A18: Business Angel A Betrag | B18: 200000 | C18: €
A19: Business Angel A Monat | B19: 4 | C19: 0 = nicht aktiv
A20: Business Angel B Betrag | B20: 200000 | C20: €
A21: Business Angel B Monat | B21: 5 | C21: 0 = nicht aktiv
A22: Business Angel C Betrag | B22: 200000 | C22: € | D22: probably 4 small Angels here
A23: Business Angel C Monat | B23: 8 | C23: 0 = nicht aktiv
A24: GRANTS / FÖRDERMITTEL
A25: Grant A Betrag | B25: 0 | C25: €
A26: Grant A Monat | B26: 0 | C26: 0 = nicht aktiv
A27: Grant B Betrag | B27: 0 | C27: €
A28: Grant B Monat | B28: 0 | C28: 0 = nicht aktiv
A29: Grant C Betrag | B29: 0 | C29: €
A30: Grant C Monat | B30: 0 | C30: 0 = nicht aktiv
A32: REVENUE-ANNAHMEN
A33: Seats/Kunde SME | B33: ='1_Szenario'!C15 -> 6 | C33: → Szenario
A34: Seats/Kunde Mid-Company | B34: ='1_Szenario'!C16 -> 12 | C34: → Szenario
A35: Seat-Preis SME (€/Monat) | B35: ='1_Szenario'!C17 -> 460 | C35: → Szenario
A36: Seat-Preis Mid-Company (€/Monat) | B36: ='1_Szenario'!C18 -> 530 | C36: → Szenario
A37: Enterprise Jahres-Fee (€/Jahr) | B37: ='1_Szenario'!C19 -> 50000 | C37: → Szenario
A38: Preiserhöhung/Jahr | B38: ='1_Szenario'!C20 -> 0.04 | C38: → Szenario
A39: Erste zahlende Kunden Monat | B39: ='1_Szenario'!C4 -> 8 | C39: → Szenario
A40: Churn Rate / Net Revenue Retention | B40: ='1_Szenario'!C10 -> 0.05 | C40: → Szenario
A42: IMPL.-SUPPORT
A43: Tagessatz (€/Tag) | B43: ='1_Szenario'!C5 -> 1500 | C43: → Szenario
...

Sheet 3_Roadmap
A1: BUSINESS ROADMAP & ÜBERSICHT
A3: 1. PRODUKTENTWICKLUNGSPHASEN
A4: Phase | B4: Zeitraum | C4: Monate | D4: Kernfeatures / Inhalte | E4: Meilensteine | G4: Bemerkungen Rene | H4: Bemerkungen Mouaz | I4: Bemerkungen Olaf
A5: Ideation | B5: M1–M4 | C5: 4 | D5: MVP-Konzept, Technologie-Stack, Marktvalidierung, IP-Aufbau | E5: MVP-Design abgeschlossen
A6: Pre-Seed | B6: M5–M16 | C6: 12 | D6: MVP-Entwicklung, Beta-Tests, erste Pilotkunden, DPP-Modul v1 | E6: Erster zahlender Kunde | G6: DPP Modul?
A7: Seed | B7: M17–M28 | C7: 12 | D7: Product-Market-Fit, Skalierung Vertrieb, Material-Analytics, Multi-Werk | E7: PMF validiert, >50 Kunden
A8: Series A | B8: M29–M40 | C8: 12 | D8: Internationale Expansion Central Europe, Enterprise-Features, API-Plattform | E8: ARR >1M€, Profitabilitätspfad
A9: Series B | B9: M41–M52 | C9: 12 | D9: Marktführerschaft, Konsolidierung, Premium-Analytics, AI-Plattform | E9: Marktführerschaft Nische
A11: 2. INVESTITIONSZEITPUNKTE & -HÖHEN
A12: Runde | B12: Monat | C12: Betrag (€) | D12: Kumuliert (€)
A13: Ideation | B13: ='2_Inputs'!B10 -> 4 | C13: ='2_Inputs'!B9 -> 120000 | D13: =C13 -> 120000
A14: Pre-Seed | B14: ='2_Inputs'!B12 -> 0 | C14: ='2_Inputs'!B11 -> 0 | D14: =D13+C14 -> 120000
A15: Seed | B15: ='2_Inputs'!B14 -> 17 | C15: ='2_Inputs'!B13 -> 2000000 | D15: =D14+C15 -> 2120000
A16: Series A | B16: ='2_Inputs'!B16 -> 29 | C16: ='2_Inputs'!B15 -> 10000000 | D16: =D15+C16 -> 12120000
A18: 3. UMSATZENTWICKLUNG & KUNDENGEWINNUNG (je Phase, kumuliert zum Phasenende)
A19: Kennzahl | B19: Ideation (M4) | C19: Pre-Seed (M16) | D19: Seed (M28) | E19: Series A (M40) | F19: Series B (M52)
A20: Neue SME-Kunden (kum.) | B20: =SUMPRODUCT('4_Revenue'!B5:E5) -> 0 | C20: =SUMPRODUCT('4_Revenue'!B5:Q5) -> 3 | D20: =SUMPRODUCT('4_Revenue'!B5:AC5) -> 13 | E20: =SUMPRODUCT('4_Revenue'!B5:AO5) -> 33 | F20: =SUMPRODUCT('4_Revenue'!B5:BA5) -> 93
A21: Neue Mid-Company-Kunden (kum.) | B21: =SUMPRODUCT('4_Revenue'!B12:E12) -> 0 | C21: =SUMPRODUCT('4_Revenue'!B12:Q12) -> 0 | D21: =SUMPRODUCT('4_Revenue'!B12:AC12) -> 15 | E21: =SUMPRODUCT('4_Revenue'!B12:AO12) -> 45 | F21: =SUMPRODUCT('4_Revenue'!B12:BA12) -> 95
A22: Neue Enterprise-Kunden (kum.) | B22: =SUMPRODUCT('4_Revenue'!B19:E19) -> 0 | C22: =SUMPRODUCT('4_Revenue'!B19:Q19) -> 0 | D22: =SUMPRODUCT('4_Revenue'!B19:AC19) -> 2 | E22: =SUMPRODUCT('4_Revenue'!B19:AO19) -> 5 | F22: =SUMPRODUCT('4_Revenue'!B19:BA19) -> 11
A23: Total Active Seats (SME+Mid) | B23: ='4_Revenue'!E8+'4_Revenue'!E15 -> 0 | C23: ='4_Revenue'!Q8+'4_Revenue'!Q15 -> 18 | D23: ='4_Revenue'!AC8+'4_Revenue'!AC15 -> 254 | E23: ='4_Revenue'!AO8+'4_Revenue'!AO15 -> 710 | F23: ='4_Revenue'!BA8+'4_Revenue'!BA15 -> 1614
A24: MRR zum Phasenende (€) | B24: ='4_Revenue'!E25 -> 0 | C24: ='4_Revenue'!Q25 -> 8611.2 | D24: ='4_Revenue'!AC25 -> 148712.79 | E24: ='4_Revenue'!AO25 -> 431681.56 | F24: ='4_Revenue'!BA25 -> 1010609.6
A26: 4. KOSTENPOSITIONEN NACH OBERTHEMEN (monatl. Durchschnitt je Phase)
A27: Kostenposition | B27: Ideation | C27: Pre-Seed | D27: Seed | E27: Series A | F27: Series B
A28: Personal | B28: =AVERAGE('5_Costs'!B13:E13) -> 0 | C28: =AVERAGE('5_Costs'!F13:Q13) -> 42980.108 | D28: =AVERAGE('5_Costs'!R13:AC13) -> 86826.037 | E28: =AVERAGE('5_Costs'!AD13:AO13) -> 106374.32 | F28: =AVERAGE('5_Costs'!AP13:BA13) -> 113786.18
A29: Technologie (IT) | B29: =AVERAGE('5_Costs'!B18:E18) -> 0 | C29: =AVERAGE('5_Costs'!F18:Q18) -> 1850 | D29: =AVERAGE('5_Costs'!R18:AC18) -> 16948.333 | E29: =AVERAGE('5_Costs'!AD18:AO18) -> 49542.5 | F29: =AVERAGE('5_Costs'!AP18:BA18) -> 117542.5
A30: Bürokosten | B30: =AVERAGE('5_Costs'!B24:E24) -> 0 | C30: =AVERAGE('5_Costs'!F24:Q24) -> 1133.3333 | D30: =AVERAGE('5_Costs'!R24:AC24) -> 4040 | E30: =AVERAGE('5_Costs'!AD24:AO24) -> 5040 | F30: =AVERAGE('5_Costs'!AP24:BA24) -> 5040
A31: Professional Services | B31: =AVERAGE('5_Costs'!B30:E30) -> 0 | C31: =AVERAGE('5_Costs'!F30:Q30) -> 1100 | D31: =AVERAGE('5_Costs'!R30:AC30) -> 6766.6667 | E31: =AVERAGE('5_Costs'!AD30:AO30) -> 14033.333 | F31: =AVERAGE('5_Costs'!AP30:BA30) -> 15333.333
A32: Versicherung & Bank | B32: =AVERAGE('5_Costs'!B35:E35) -> 92 | C32: =AVERAGE('5_Costs'!F35:Q35) -> 750 | D32: =AVERAGE('5_Costs'!R35:AC35) -> 1150 | E32: =AVERAGE('5_Costs'!AD35:AO35) -> 1500 | F32: =AVERAGE('5_Costs'!AP35:BA35) -> 1850
A33: Marketing & Sales | B33: =AVERAGE('5_Costs'!B40:E40) -> 1633.3333 | C33: =AVERAGE('5_Costs'!F40:Q40) -> 3227.5413 | D33: =AVERAGE('5_Costs'!R40:AC40) -> 7723.8174 | E33: =AVERAGE('5_Costs'!AD40:AO40) -> 18084.773 | F33: =AVERAGE('5_Costs'!AP40:BA40) -> 32006.948
A34: Sonstige Kosten | B34: =AVERAGE('5_Costs'!B45:E45) -> 350 | C34: =AVERAGE('5_Costs'!F45:Q45) -> 1733.3333 | D34: =AVERAGE('5_Costs'!R45:AC45) -> 3791.6667 | E34: =AVERAGE('5_Costs'!AD45:AO45) -> 6150 | F34: =AVERAGE('5_Costs'!AP45:BA45) -> 8400
A35: Payment Processing | B35: =AVERAGE('5_Costs'!B48:E48) -> 0 | C35: =AVERAGE('5_Costs'!F48:Q48) -> 117.76 | D35: =AVERAGE('5_Costs'!R48:AC48) -> 2092.2717 | E35: =AVERAGE('5_Costs'!AD48:AO48) -> 7126.7997 | F35: =AVERAGE('5_Costs'!AP48:BA48) -> 18279.518
A36: TOTAL (Ø/Monat) | B36: =SUM(B28:B35) -> 2075.3333 | C36: =SUM(C28:C35) -> 52892.076 | D36: =SUM(D28:D35) -> 129338.79 | E36: =SUM(E28:E35) -> 207851.73 | F36: =SUM(F28:F35) -> 312238.48

Sheet 4_Revenue
A1: UMSATZMODELL | AP1: Series B not modelled yet | AR1: `-->
A2: Monat | B2: M1 | C2: M2 | D2: M3 | E2: M4 | F2: M5 | G2: M6 | H2: M7 | I2: M8 | J2: M9 | K2: M10 | L2: M11 | M2: M12 | N2: M13 | O2: M14 | P2: M15 | Q2: M16 | R2: M17 | S2: M18 | T2: M19 | U2: M20 | V2: M21 | W2: M22 | X2: M23 | Y2: M24 | Z2: M25 | AA2: M26 | AB2: M27 | AC2: M28 | AD2: M29 | AE2: M30 | AF2: M31 | AG2: M32 | AH2: M33 | AI2: M34 | AJ2: M35 | AK2: M36 | AL2: M37 | AM2: M38 | AN2: M39 | AO2: M40 | AP2: M41 | AQ2: M42 | AR2: M43 | AS2: M44 | AT2: M45 | AU2: M46 | AV2: M47 | AW2: M48 | AX2: M49 | AY2: M50 | AZ2: M51 | BA2: M52
A3: Startup-Phasen | B3: Ideation | C3: Ideation | D3: Ideation | E3: Ideation | F3: Pre-Seed | G3: Pre-Seed | H3: Pre-Seed | I3: Pre-Seed | J3: Pre-Seed | K3: Pre-Seed | L3: Pre-Seed | M3: Pre-Seed | N3: Pre-Seed | O3: Pre-Seed | P3: Pre-Seed | Q3: Pre-Seed | R3: Seed | S3: Seed | T3: Seed | U3: Seed | V3: Seed | W3: Seed | X3: Seed | Y3: Seed | Z3: Seed | AA3: Seed | AB3: Seed | AC3: Seed | AD3: Series A | AE3: Series A | AF3: Series A | AG3: Series A | AH3: Series A | AI3: Series A | AJ3: Series A | AK3: Series A | AL3: Series A | AM3: Series A | AN3: Series A | AO3: Series A | AP3: Series B | AQ3: Series B | AR3: Series B | AS3: Series B | AT3: Series B | AU3: Series B | AV3: Series B | AW3: Series B | AX3: Series B | AY3: Series B | AZ3: Series B | BA3: Series B
A4: ── SME KUNDEN (Seat-Modell) ──
A5: Neue SME-Kunden | B5: ='2_Inputs'!B217 -> 0 | C5: ='2_Inputs'!C217 -> 0 | D5: ='2_Inputs'!D217 -> 0 | E5: ='2_Inputs'!E217 -> 0 | F5: ='2_Inputs'!F217 -> 0 | G5: ='2_Inputs'!G217 -> 0 | H5: ='2_Inputs'!H217 -> 1 | I5: ='2_Inputs'!I217 -> 0 | ... BA5: ='2_Inputs'!BA217 -> 5
A6: Neue SME-Seats | B6: =B5*'2_Inputs'!$B$33 -> 0 | C6: =C5*'2_Inputs'!$B$33 -> 0 | D6: =D5*'2_Inputs'!$B$33 -> 0 | E6: =E5*'2_Inputs'!$B$33 -> 0 | F6: =F5*'2_Inputs'!$B$33 -> 0 | G6: =G5*'2_Inputs'!$B$33 -> 0 | H6: =H5*'2_Inputs'!$B$33 -> 6 | I6: =I5*'2_Inputs'!$B$33 -> 0 | ... BA6: =BA5*'2_Inputs'!$B$33 -> 30
A7: Churned SME-Seats | B7: =0 -> 0 | C7: =-ROUND(B8*'2_Inputs'!$B$40/12,0) -> 0 | D7: =-ROUND(C8*'2_Inputs'!$B$40/12,0) -> 0 | E7: =-ROUND(D8*'2_Inputs'!$B$40/12,0) -> 0 | F7: =-ROUND(E8*'2_Inputs'!$B$40/12,0) -> 0 | G7: =-ROUND(F8*'2_Inputs'!$B$40/12,0) -> 0 | H7: =-ROUND(G8*'2_Inputs'!$B$40/12,0) -> 0 | I7: =-ROUND(H8*'2_Inputs'!$B$40/12,0) -> 0 | J7: =-ROUND(I8*'2_Inputs'!$B$40/12,0) -> 0 | ... BA7: =-ROUND(AZ8*'2_Inputs'!$B$40/12,0) -> -2
A8: Active SME-Seats (kum.) | B8: =B6 -> 0 | C8: =B8+C6+C7 -> 0 | D8: =C8+D6+D7 -> 0 | E8: =D8+E6+E7 -> 0 | F8: =E8+F6+F7 -> 0 | G8: =F8+G6+G7 -> 0 | H8: =G8+H6+H7 -> 6 | I8: =H8+I6+I7 -> 6 | J8: =I8+J6+J7 -> 6 | ... BA8: =AZ8+BA6+BA7 -> 534
A9: SME Seat-Preis (€/Monat) | B9: ='2_Inputs'!$B$35*(1+'2_Inputs'!$B$38)^INT((COLUMN()-2)/12) -> 460 | C9: ='2_Inputs'!$B$35*(1+'2_Inputs'!$B$38)^INT((COLUMN()-2)/12) -> 460 | D9: ='2_Inputs'!$B$35*(1+'2_Inputs'!$B$38)^INT((COLUMN()-2)/12) -> 460 | E9: ='2_Inputs'!$B$35*(1+'2_Inputs'!$B$38)^INT((COLUMN()-2)/12) -> 460 | F9: ='2_Inputs'!$B$35*(1+'2_Inputs'!$B$38)^INT((COLUMN()-2)/12) -> 460 | G9: ='2_Inputs'!$B$35*(1+'2_Inputs'!$B$38)^INT((COLUMN()-2)/12) -> 460 | H9: ='2_Inputs'!$B$35*(1+'2_Inputs'!$B$38)^INT((COLUMN()-2)/12) -> 460 | I9: ='2_Inputs'!$B$35*(1+'2_Inputs'!$B$38)^INT((COLUMN()-2)/12) -> 460 | ... BA9: ='2_Inputs'!$B$35*(1+'2_Inputs'!$B$38)^INT((COLUMN()-2)/12) -> 538.13494
A10: SME Monthly Revenue (€) | B10: =B8*B9 -> 0 | C10: =C8*C9 -> 0 | D10: =D8*D9 -> 0 | E10: =E8*E9 -> 0 | F10: =F8*F9 -> 0 | G10: =G8*G9 -> 0 | H10: =H8*H9 -> 2760 | I10: =I8*I9 -> 2760 | ... BA10: =BA8*BA9 -> 287364.06
A11: ── MID-COMPANY KUNDEN (Seat-Modell) ──
A12: Neue Mid-Company-Kunden | B12: ='2_Inputs'!B218 -> 0 | C12: ='2_Inputs'!C218 -> 0 | D12: ='2_Inputs'!D218 -> 0 | E12: ='2_Inputs'!E218 -> 0 | F12: ='2_Inputs'!F218 -> 0 | G12: ='2_Inputs'!G218 -> 0 | H12: ='2_Inputs'!H218 -> 0 | I12: ='2_Inputs'!I218 -> 0 | ... BA12: ='2_Inputs'!BA218 -> 5
A13: Neue Mid-Seats | B13: =B12*'2_Inputs'!$B$34 -> 0 | C13: =C12*'2_Inputs'!$B$34 -> 0 | D13: =D12*'2_Inputs'!$B$34 -> 0 | E13: =E12*'2_Inputs'!$B$34 -> 0 | F13: =F12*'2_Inputs'!$B$34 -> 0 | G13: =G12*'2_Inputs'!$B$34 -> 0 | H13: =H12*'2_Inputs'!$B$34 -> 0 | I13: =I12*'2_Inputs'!$B$34 -> 0 | ... BA13: =BA12*'2_Inputs'!$B$34 -> 60
A14: Churned Mid-Seats | B14: =0 -> 0 | C14: =-ROUND(B15*'2_Inputs'!$B$40/12,0) -> 0 | D14: =-ROUND(C15*'2_Inputs'!$B$40/12,0) -> 0 | E14: =-ROUND(D15*'2_Inputs'!$B$40/12,0) -> 0 | F14: =-ROUND(E15*'2_Inputs'!$B$40/12,0) -> 0 | G14: =-ROUND(F15*'2_Inputs'!$B$40/12,0) -> 0 | H14: =-ROUND(G15*'2_Inputs'!$B$40/12,0) -> 0 | I14: =-ROUND(H15*'2_Inputs'!$B$40/12,0) -> 0 | J14: =-ROUND(I15*'2_Inputs'!$B$40/12,0) -> 0 | ... BA14: =-ROUND(AZ15*'2_Inputs'!$B$40/12,0) -> -4
A15: Active Mid-Seats (kum.) | B15: =B13 -> 0 | C15: =B15+C13+C14 -> 0 | D15: =C15+D13+D14 -> 0 | E15: =D15+E13+E14 -> 0 | F15: =E15+F13+F14 -> 0 | G15: =F15+G13+G14 -> 0 | H15: =G15+H13+H14 -> 0 | I15: =H15+I13+I14 -> 0 | J15: =I15+J13+J14 -> 0 | ... BA15: =AZ15+BA13+BA14 -> 1080
A16: Mid Seat-Preis (€/Monat) | B16: ='2_Inputs'!$B$36*(1+'2_Inputs'!$B$38)^INT((COLUMN()-2)/12) -> 530 | C16: ='2_Inputs'!$B$36*(1+'2_Inputs'!$B$38)^INT((COLUMN()-2)/12) -> 530 | D16: ='2_Inputs'!$B$36*(1+'2_Inputs'!$B$38)^INT((COLUMN()-2)/12) -> 530 | E16: ='2_Inputs'!$B$36*(1+'2_Inputs'!$B$38)^INT((COLUMN()-2)/12) -> 530 | F16: ='2_Inputs'!$B$36*(1+'2_Inputs'!$B$38)^INT((COLUMN()-2)/12) -> 530 | G16: ='2_Inputs'!$B$36*(1+'2_Inputs'!$B$38)^INT((COLUMN()-2)/12) -> 530 | H16: ='2_Inputs'!$B$36*(1+'2_Inputs'!$B$38)^INT((COLUMN()-2)/12) -> 530 | I16: ='2_Inputs'!$B$36*(1+'2_Inputs'!$B$38)^INT((COLUMN()-2)/12) -> 530 | ... BA16: ='2_Inputs'!$B$36*(1+'2_Inputs'!$B$38)^INT((COLUMN()-2)/12) -> 620.02504
A17: Mid Monthly Revenue (€) | B17: =B15*B16 -> 0 | C17: =C15*C16 -> 0 | D17: =D15*D16 -> 0 | E17: =E15*E16 -> 0 | F17: =F15*F16 -> 0 | G17: =G15*G16 -> 0 | H17: =H15*H16 -> 0 | I17: =I15*I16 -> 0 | ... BA17: =BA15*BA16 -> 669627.04
A18: ── ENTERPRISE (Jahres-Fee) ──
A19: Neue Enterprise-Kunden | B19: ='2_Inputs'!B219 -> 0 | C19: ='2_Inputs'!C219 -> 0 | D19: ='2_Inputs'!D219 -> 0 | E19: ='2_Inputs'!E219 -> 0 | F19: ='2_Inputs'!F219 -> 0 | G19: ='2_Inputs'!G219 -> 0 | H19: ='2_Inputs'!H219 -> 0 | I19: ='2_Inputs'!I219 -> 0 | ... BA19: ='2_Inputs'!BA219 -> 0
A20: Churned Enterprise | B20: =0 -> 0 | C20: =-ROUND(B21*'2_Inputs'!$B$40/12,0) -> 0 | D20: =-ROUND(C21*'2_Inputs'!$B$40/12,0) -> 0 | E20: =-ROUND(D21*'2_Inputs'!$B$40/12,0) -> 0 | F20: =-ROUND(E21*'2_Inputs'!$B$40/12,0) -> 0 | G20: =-ROUND(F21*'2_Inputs'!$B$40/12,0) -> 0 | H20: =-ROUND(G21*'2_Inputs'!$B$40/12,0) -> 0 | I20: =-ROUND(H21*'2_Inputs'!$B$40/12,0) -> 0 | J20: =-ROUND(I21*'2_Inputs'!$B$40/12,0) -> 0 | ... BA20: =-ROUND(AZ21*'2_Inputs'!$B$40/12,0) -> 0
A21: Active Enterprise (kum.) | B21: =B19 -> 0 | C21: =B21+C19+C20 -> 0 | D21: =C21+D19+D20 -> 0 | E21: =D21+E19+E20 -> 0 | F21: =E21+F19+F20 -> 0 | G21: =F21+G19+G20 -> 0 | H21: =G21+H19+H20 -> 0 | I21: =H21+I19+I20 -> 0 | J21: =I21+J19+J20 -> 0 | ... BA21: =AZ21+BA19+BA20 -> 11
A22: Enterprise Fee/Monat (€) | B22: ='2_Inputs'!$B$37*(1+'2_Inputs'!$B$38)^INT((COLUMN()-2)/12)/12 -> 4166.6667 | C22: ='2_Inputs'!$B$37*(1+'2_Inputs'!$B$38)^INT((COLUMN()-2)/12)/12 -> 4166.6667 | D22: ='2_Inputs'!$B$37*(1+'2_Inputs'!$B$38)^INT((COLUMN()-2)/12)/12 -> 4166.6667 | E22: ='2_Inputs'!$B$37*(1+'2_Inputs'!$B$38)^INT((COLUMN()-2)/12)/12 -> 4166.6667 | F22: ='2_Inputs'!$B$37*(1+'2_Inputs'!$B$38)^INT((COLUMN()-2)/12)/12 -> 4166.6667 | G22: ='2_Inputs'!$B$37*(1+'2_Inputs'!$B$38)^INT((COLUMN()-2)/12)/12 -> 4166.6667 | H22: ='2_Inputs'!$B$37*(1+'2_Inputs'!$B$38)^INT((COLUMN()-2)/12)/12 -> 4166.6667 | I22: ='2_Inputs'!$B$37*(1+'2_Inputs'!$B$38)^INT((COLUMN()-2)/12)/12 -> 4166.6667 | ... BA22: ='2_Inputs'!$B$37*(1+'2_Inputs'!$B$38)^INT((COLUMN()-2)/12)/12 -> 4874.4107
A23: Enterprise Monthly Revenue (€) | B23: =B21*B22 -> 0 | C23: =C21*C22 -> 0 | D23: =D21*D22 -> 0 | E23: =E21*E22 -> 0 | F23: =F21*F22 -> 0 | G23: =G21*G22 -> 0 | H23: =H21*H22 -> 0 | I23: =I21*I22 -> 0 | ... BA23: =BA21*BA22 -> 53618.517
A24: ── TOTAL RECURRING REVENUE ──
A25: MRR – Monthly Recurring Revenue | B25: =B10+B17+B23 -> 0 | C25: =C10+C17+C23 -> 0 | D25: =D10+D17+D23 -> 0 | E25: =E10+E17+E23 -> 0 | F25: =F10+F17+F23 -> 0 | G25: =G10+G17+G23 -> 0 | H25: =H10+H17+H23 -> 2760 | I25: =I10+I17+I23 -> 2760 | ... BA25: =BA10+BA17+BA23 -> 1010609.6
A26: ARR – Annual Recurring Revenue | B26: =B25*12 -> 0 | C26: =C25*12 -> 0 | D26: =D25*12 -> 0 | E26: =E25*12 -> 0 | F26: =F25*12 -> 0 | G26: =G25*12 -> 0 | H26: =H25*12 -> 33120 | I26: =I25*12 -> 33120 | ... BA26: =BA25*12 -> 12127315
A27: ── IMPLEMENTATION-SUPPORT ──
A28: Neue Kunden im Monat (gesamt) | B28: =B5+B12+B19 -> 0 | C28: =C5+C12+C19 -> 0 | D28: =D5+D12+D19 -> 0 | E28: =E5+E12+E19 -> 0 | F28: =F5+F12+F19 -> 0 | G28: =G5+G12+G19 -> 0 | H28: =H5+H12+H19 -> 1 | I28: =I5+I12+I19 -> 0 | ... BA28: =BA5+BA12+BA19 -> 10
A29: Impl.-Support Tage/Monat | B29: =IF(COLUMN()-1>='2_Inputs'!$B$46,B28*'2_Inputs'!$B$45*'2_Inputs'!$B$44,0) -> 0 | C29: =IF(COLUMN()-1>='2_Inputs'!$B$46,C28*'2_Inputs'!$B$45*'2_Inputs'!$B$44,0) -> 0 | D29: =IF(COLUMN()-1>='2_Inputs'!$B$46,D28*'2_Inputs'!$B$45*'2_Inputs'!$B$44,0) -> 0 | E29: =IF(COLUMN()-1>='2_Inputs'!$B$46,E28*'2_Inputs'!$B$45*'2_Inputs'!$B$44,0) -> 0 | F29: =IF(COLUMN()-1>='2_Inputs'!$B$46,F28*'2_Inputs'!$B$45*'2_Inputs'!$B$44,0) -> 0 | G29: =IF(COLUMN()-1>='2_Inputs'!$B$46,G28*'2_Inputs'!$B$45*'2_Inputs'!$B$44,0) -> 0 | H29: =IF(COLUMN()-1>='2_Inputs'!$B$46,H28*'2_Inputs'!$B$45*'2_Inputs'!$B$44,0) -> 20 | I29: =IF(COLUMN()-1>='2_Inputs'!$B$46,I28*'2_Inputs'!$B$45*'2_Inputs'!$B$44,0) -> 0 | ... BA29: =IF(COLUMN()-1>='2_Inputs'!$B$46,BA28*'2_Inputs'!$B$45*'2_Inputs'!$B$44,0) -> 200
A30: Impl.-Support Revenue (€/Monat) | B30: =B29*'2_Inputs'!$B$43 -> 0 | C30: =C29*'2_Inputs'!$B$43 -> 0 | D30: =D29*'2_Inputs'!$B$43 -> 0 | E30: =E29*'2_Inputs'!$B$43 -> 0 | F30: =F29*'2_Inputs'!$B$43 -> 0 | G30: =G29*'2_Inputs'!$B$43 -> 0 | H30: =H29*'2_Inputs'!$B$43 -> 30000 | I30: =I29*'2_Inputs'!$B$43 -> 0 | ... BA30: =BA29*'2_Inputs'!$B$43 -> 300000
A31: ── TOTAL MONTHLY REVENUE ──
A32: Total Revenue (€/Monat) | B32: =B25+B30 -> 0 | C32: =C25+C30 -> 0 | D32: =D25+D30 -> 0 | E32: =E25+E30 -> 0 | F32: =F25+F30 -> 0 | G32: =G25+G30 -> 0 | H32: =H25+H30 -> 32760 | I32: =I25+I30 -> 2760 | ... BA32: =BA25+BA30 -> 1310609.6
A33: ARR Growth % (MoM) | B33: =IFERROR((B25-0)/1,0) -> 0 | C33: =IFERROR((C25-B25)/B25,0) -> 0 | D33: =IFERROR((D25-C25)/C25,0) -> 0 | E33: =IFERROR((E25-D25)/D25,0) -> 0 | F33: =IFERROR((F25-E25)/E25,0) -> 0 | G33: =IFERROR((G25-F25)/F25,0) -> 0 | H33: =IFERROR((H25-G25)/G25,0) -> 0 | I33: =IFERROR((I25-H25)/H25,0) -> 0 | J33: =IFERROR((J25-I25)/I25,0) -> 0 | ... BA33: =IFERROR((BA25-AZ25)/AZ25,0) -> 0.051819444
A34: ARR Total (inkl. Impl.-Support) | B34: =B32*12 -> 0 | C34: =C32*12 -> 0 | D34: =D32*12 -> 0 | E34: =E32*12 -> 0 | F34: =F32*12 -> 0 | G34: =G32*12 -> 0 | H34: =H32*12 -> 393120 | I34: =I32*12 -> 33120 | ... BA34: =BA32*12 -> 15727315

Sheet 5_Costs
A1: KOSTENDETAILS | AP1: Series B not modelled yet | AR1: `-->
A2: Monat | B2: M1 | C2: M2 | D2: M3 | E2: M4 | F2: M5 | G2: M6 | H2: M7 | I2: M8 | J2: M9 | K2: M10 | L2: M11 | M2: M12 | N2: M13 | O2: M14 | P2: M15 | Q2: M16 | R2: M17 | S2: M18 | T2: M19 | U2: M20 | V2: M21 | W2: M22 | X2: M23 | Y2: M24 | Z2: M25 | AA2: M26 | AB2: M27 | AC2: M28 | AD2: M29 | AE2: M30 | AF2: M31 | AG2: M32 | AH2: M33 | AI2: M34 | AJ2: M35 | AK2: M36 | AL2: M37 | AM2: M38 | AN2: M39 | AO2: M40 | AP2: M41 | AQ2: M42 | AR2: M43 | AS2: M44 | AT2: M45 | AU2: M46 | AV2: M47 | AW2: M48 | AX2: M49 | AY2: M50 | AZ2: M51 | BA2: M52
A3: Startup-Phasen | B3: Ideation | C3: Ideation | D3: Ideation | E3: Ideation | F3: Pre-Seed | G3: Pre-Seed | H3: Pre-Seed | I3: Pre-Seed | J3: Pre-Seed | K3: Pre-Seed | L3: Pre-Seed | M3: Pre-Seed | N3: Pre-Seed | O3: Pre-Seed | P3: Pre-Seed | Q3: Pre-Seed | R3: Seed | S3: Seed | T3: Seed | U3: Seed | V3: Seed | W3: Seed | X3: Seed | Y3: Seed | Z3: Seed | AA3: Seed | AB3: Seed | AC3: Seed | AD3: Series A | AE3: Series A | AF3: Series A | AG3: Series A | AH3: Series A | AI3: Series A | AJ3: Series A | AK3: Series A | AL3: Series A | AM3: Series A | AN3: Series A | AO3: Series A | AP3: Series B | AQ3: Series B | AR3: Series B | AS3: Series B | AT3: Series B | AU3: Series B | AV3: Series B | AW3: Series B | AX3: Series B | AY3: Series B | AZ3: Series B | BA3: Series B
A4: Kostenposition | B4: M1 | C4: M2 | D4: M3 | E4: M4 | F4: M5 | G4: M6 | H4: M7 | I4: M8 | J4: M9 | K4: M10 | L4: M11 | M4: M12 | N4: M13 | O4: M14 | P4: M15 | Q4: M16 | R4: M17 | S4: M18 | T4: M19 | U4: M20 | V4: M21 | W4: M22 | X4: M23 | Y4: M24 | Z4: M25 | AA4: M26 | AB4: M27 | AC4: M28 | AD4: M29 | AE4: M30 | AF4: M31 | AG4: M32 | AH4: M33 | AI4: M34 | AJ4: M35 | AK4: M36 | AL4: M37 | AM4: M38 | AN4: M39 | AO4: M40 | AP4: M41 | AQ4: M42 | AR4: M43 | AS4: M44 | AT4: M45 | AU4: M46 | AV4: M47 | AW4: M48 | AX4: M49 | AY4: M50 | AZ4: M51 | BA4: M52
A5: ── PERSONAL ──
A6: CEO | B6: =IF(COLUMN()-1<=4,'2_Inputs'!$B$53,IF(COLUMN()-1<=16,'2_Inputs'!$B$54,IF(COLUMN()-1<=28,'2_Inputs'!$B$55,IF(COLUMN()-1<=40,'2_Inputs'!$B$56,'2_Inputs'!$B$57))))/12 -> 0 | C6: =IF(COLUMN()-1<=4,'2_Inputs'!$B$53,IF(COLUMN()-1<=16,'2_Inputs'!$B$54,IF(COLUMN()-1<=28,'2_Inputs'!$B$55,IF(COLUMN()-1<=40,'2_Inputs'!$B$56,'2_Inputs'!$B$57))))/12 -> 0 | D6: =IF(COLUMN()-1<=4,'2_Inputs'!$B$53,IF(COLUMN()-1<=16,'2_Inputs'!$B$54,IF(COLUMN()-1<=28,'2_Inputs'!$B$55,IF(COLUMN()-1<=40,'2_Inputs'!$B$56,'2_Inputs'!$B$57))))/12 -> 0 | E6: =IF(COLUMN()-1<=4,'2_Inputs'!$B$53,IF(COLUMN()-1<=16,'2_Inputs'!$B$54,IF(COLUMN()-1<=28,'2_Inputs'!$B$55,IF(COLUMN()-1<=40,'2_Inputs'!$B$56,'2_Inputs'!$B$57))))/12 -> 0 | F6: =IF(COLUMN()-1<=4,'2_Inputs'!$B$53,IF(COLUMN()-1<=16,'2_Inputs'!$B$54,IF(COLUMN()-1<=28,'2_Inputs'!$B$55,IF(COLUMN()-1<=40,'2_Inputs'!$B$56,'2_Inputs'!$B$57))))/12 -> 8333.3333 | G6: =IF(COLUMN()-1<=4,'2_Inputs'!$B$53,IF(COLUMN()-1<=16,'2_Inputs'!$B$54,IF(COLUMN()-1<=28,'2_Inputs'!$B$55,IF(COLUMN()-1<=40,'2_Inputs'!$B$56,'2_Inputs'!$B$57))))/12 -> 8333.3333 | H6: =IF(COLUMN()-1<=4,'2_Inputs'!$B$53,IF(COLUMN()-1<=16,'2_Inputs'!$B$54,IF(COLUMN()-1<=28,'2_Inputs'!$B$55,IF(COLUMN()-1<=40,'2_Inputs'!$B$56,'2_Inputs'!$B$57))))/12 -> 8333.3333 | I6: =IF(COLUMN()-1<=4,'2_Inputs'!$B$53,IF(COLUMN()-1<=16,'2_Inputs'!$B$54,IF(COLUMN()-1<=28,'2_Inputs'!$B$55,IF(COLUMN()-1<=40,'2_Inputs'!$B$56,'2_Inputs'!$B$57))))/12 -> 8333.3333 | ... BA6: =IF(COLUMN()-1<=4,'2_Inputs'!$B$53,IF(COLUMN()-1<=16,'2_Inputs'!$B$54,IF(COLUMN()-1<=28,'2_Inputs'!$B$55,IF(COLUMN()-1<=40,'2_Inputs'!$B$56,'2_Inputs'!$B$57))))/12 -> 10000
A7: CTO | B7: =IF(COLUMN()-1<=4,'2_Inputs'!$B$59,IF(COLUMN()-1<=16,'2_Inputs'!$B$60,IF(COLUMN()-1<=28,'2_Inputs'!$B$61,IF(COLUMN()-1<=40,'2_Inputs'!$B$62,'2_Inputs'!$B$63))))/12 -> 0 | C7: =IF(COLUMN()-1<=4,'2_Inputs'!$B$59,IF(COLUMN()-1<=16,'2_Inputs'!$B$60,IF(COLUMN()-1<=28,'2_Inputs'!$B$61,IF(COLUMN()-1<=40,'2_Inputs'!$B$62,'2_Inputs'!$B$63))))/12 -> 0 | D7: =IF(COLUMN()-1<=4,'2_Inputs'!$B$59,IF(COLUMN()-1<=16,'2_Inputs'!$B$60,IF(COLUMN()-1<=28,'2_Inputs'!$B$61,IF(COLUMN()-1<=40,'2_Inputs'!$B$62,'2_Inputs'!$B$63))))/12 -> 0 | E7: =IF(COLUMN()-1<=4,'2_Inputs'!$B$59,IF(COLUMN()-1<=16,'2_Inputs'!$B$60,IF(COLUMN()-1<=28,'2_Inputs'!$B$61,IF(COLUMN()-1<=40,'2_Inputs'!$B$62,'2_Inputs'!$B$63))))/12 -> 0 | F7: =IF(COLUMN()-1<=4,'2_Inputs'!$B$59,IF(COLUMN()-1<=16,'2_Inputs'!$B$60,IF(COLUMN()-1<=28,'2_Inputs'!$B$61,IF(COLUMN()-1<=40,'2_Inputs'!$B$62,'2_Inputs'!$B$63))))/12 -> 8333.3333 | G7: =IF(COLUMN()-1<=4,'2_Inputs'!$B$59,IF(COLUMN()-1<=16,'2_Inputs'!$B$60,IF(COLUMN()-1<=28,'2_Inputs'!$B$61,IF(COLUMN()-1<=40,'2_Inputs'!$B$62,'2_Inputs'!$B$63))))/12 -> 8333.3333 | H7: =IF(COLUMN()-1<=4,'2_Inputs'!$B$59,IF(COLUMN()-1<=16,'2_Inputs'!$B$60,IF(COLUMN()-1<=28,'2_Inputs'!$B$61,IF(COLUMN()-1<=40,'2_Inputs'!$B$62,'2_Inputs'!$B$63))))/12 -> 8333.3333 | I7: =IF(COLUMN()-1<=4,'2_Inputs'!$B$59,IF(COLUMN()-1<=16,'2_Inputs'!$B$60,IF(COLUMN()-1<=28,'2_Inputs'!$B$61,IF(COLUMN()-1<=40,'2_Inputs'!$B$62,'2_Inputs'!$B$63))))/12 -> 8333.3333 | ... BA7: =IF(COLUMN()-1<=4,'2_Inputs'!$B$59,IF(COLUMN()-1<=16,'2_Inputs'!$B$60,IF(COLUMN()-1<=28,'2_Inputs'!$B$61,IF(COLUMN()-1<=40,'2_Inputs'!$B$62,'2_Inputs'!$B$63))))/12 -> 10000
A8: CCO | B8: =IF(COLUMN()-1<=4,'2_Inputs'!$B$65,IF(COLUMN()-1<=16,'2_Inputs'!$B$66,IF(COLUMN()-1<=28,'2_Inputs'!$B$67,IF(COLUMN()-1<=40,'2_Inputs'!$B$68,'2_Inputs'!$B$69))))/12 -> 0 | C8: =IF(COLUMN()-1<=4,'2_Inputs'!$B$65,IF(COLUMN()-1<=16,'2_Inputs'!$B$66,IF(COLUMN()-1<=28,'2_Inputs'!$B$67,IF(COLUMN()-1<=40,'2_Inputs'!$B$68,'2_Inputs'!$B$69))))/12 -> 0 | D8: =IF(COLUMN()-1<=4,'2_Inputs'!$B$65,IF(COLUMN()-1<=16,'2_Inputs'!$B$66,IF(COLUMN()-1<=28,'2_Inputs'!$B$67,IF(COLUMN()-1<=40,'2_Inputs'!$B$68,'2_Inputs'!$B$69))))/12 -> 0 | E8: =IF(COLUMN()-1<=4,'2_Inputs'!$B$65,IF(COLUMN()-1<=16,'2_Inputs'!$B$66,IF(COLUMN()-1<=28,'2_Inputs'!$B$67,IF(COLUMN()-1<=40,'2_Inputs'!$B$68,'2_Inputs'!$B$69))))/12 -> 0 | F8: =IF(COLUMN()-1<=4,'2_Inputs'!$B$65,IF(COLUMN()-1<=16,'2_Inputs'!$B$66,IF(COLUMN()-1<=28,'2_Inputs'!$B$67,IF(COLUMN()-1<=40,'2_Inputs'!$B$68,'2_Inputs'!$B$69))))/12 -> 8333.3333 | G8: =IF(COLUMN()-1<=4,'2_Inputs'!$B$65,IF(COLUMN()-1<=16,'2_Inputs'!$B$66,IF(COLUMN()-1<=28,'2_Inputs'!$B$67,IF(COLUMN()-1<=40,'2_Inputs'!$B$68,'2_Inputs'!$B$69))))/12 -> 8333.3333 | H8: =IF(COLUMN()-1<=4,'2_Inputs'!$B$65,IF(COLUMN()-1<=16,'2_Inputs'!$B$66,IF(COLUMN()-1<=28,'2_Inputs'!$B$67,IF(COLUMN()-1<=40,'2_Inputs'!$B$68,'2_Inputs'!$B$69))))/12 -> 8333.3333 | I8: =IF(COLUMN()-1<=4,'2_Inputs'!$B$65,IF(COLUMN()-1<=16,'2_Inputs'!$B$66,IF(COLUMN()-1<=28,'2_Inputs'!$B$67,IF(COLUMN()-1<=40,'2_Inputs'!$B$68,'2_Inputs'!$B$69))))/12 -> 8333.3333 | ... BA8: =IF(COLUMN()-1<=4,'2_Inputs'!$B$65,IF(COLUMN()-1<=16,'2_Inputs'!$B$66,IF(COLUMN()-1<=28,'2_Inputs'!$B$67,IF(COLUMN()-1<=40,'2_Inputs'!$B$68,'2_Inputs'!$B$69))))/12 -> 10000
A9: Executives (3 Gründer) | B9: =SUM(B6:B8) -> 0 | C9: =SUM(C6:C8) -> 0 | D9: =SUM(D6:D8) -> 0 | E9: =SUM(E6:E8) -> 0 | F9: =SUM(F6:F8) -> 25000 | G9: =SUM(G6:G8) -> 25000 | H9: =SUM(H6:H8) -> 25000 | I9: =SUM(I6:I8) -> 25000 | ... BA9: =SUM(BA6:BA8) -> 30000
A10: Mitarbeiter (Gehälter) | B10: =IF(AND(COLUMN()-1>='2_Inputs'!$B$177,'2_Inputs'!$C$177="JA"),'2_Inputs'!$C$71/12*(1+'2_Inputs'!$B$84)^INT((COLUMN()-2)/12),0)+IF(AND(COLUMN()-1>='2_Inputs'!$B$178,'2_Inputs'!$C$178="JA"),'2_Inputs'!$C$71/12*(1+'2_Inputs'!$B$84)^INT((COLUMN()-2)/12),0)+IF(AND(COLUMN()-1>='2_Inputs'!$B$179,'2_Inputs'!$C$179="JA"),'2_Inputs'!$C$72/12*(1+'2_Inputs'!$B$84)^INT((COLUMN()-2)/12),0)+IF(AND(COLUMN()-1>='2_Inputs'!$B$180,'2_Inputs'!$C$180="JA"),'2_Inputs'!$C$73/12*(1+'2_Inputs'!$B$84)^INT((COLUMN()-2)/12),0)+IF(AND(COLUMN()-1>='2_Inputs'!$B$181,'2_Inputs'!$C$181="JA"),'2_Inputs'!$C$74/12*(1+'2_Inputs'!$B$84)^INT((COLUMN()-2)/12),0)+IF(AND(COLUMN()-1>='2_Inputs'!$B$182,'2_Inputs'!$C$182="JA"),'2_Inputs'!$C$82/12*(1+'2_Inputs'!$B$84)^INT((COLUMN()-2)/12),0)+IF(AND(COLUMN()-1>='2_Inputs'!$B$183,'2_Inputs'!$C$183="JA"),'2_Inputs'!$C$75/12*(1+'2_Inputs'!$B$84)^INT((COLUMN()-2)/12),0)+IF(AND(COLUMN()-1>='2_Inputs'!$B$184,'2_Inputs'!$C$184="JA"),'2_Inputs'!$C$76/12*(1+'2_Inputs'!$B$84)^INT((COLUMN()-2)/12),0)+IF(AND(COLUMN()-1>='2_Inputs'!$B$185,'2_Inputs'!$C$185="JA"),'2_Inputs'!$C$76/12*(1+'2_Inputs'!$B$84)^INT((COLUMN()-2)/12),0)+IF(AND(COLUMN()-1>='2_Inputs'!$B$186,'2_Inputs'!$C$186="JA"),'2_Inputs'!$C$76/12*(1+'2_Inputs'!$B$84)^INT((COLUMN()-2)/12),0)+IF(AND(COLUMN()-1>='2_Inputs'!$B$187,'2_Inputs'!$C$187="JA"),'2_Inputs'!$C$78/12*(1+'2_Inputs'!$B$84)^INT((COLUMN()-2)/12),0)+IF(AND(COLUMN()-1>='2_Inputs'!$B$188,'2_Inputs'!$C$188="JA"),'2_Inputs'!$C$78/12*(1+'2_Inputs'!$B$84)^INT((COLUMN()-2)/12),0)+IF(AND(COLUMN()-1>='2_Inputs'!$B$189,'2_Inputs'!$C$189="JA"),'2_Inputs'!$C$77/12*(1+'2_Inputs'!$B$84)^INT((COLUMN()-2)/12),0)+IF(AND(COLUMN()-1>='2_Inputs'!$B$190,'2_Inputs'!$C$190="JA"),'2_Inputs'!$C$79/12*(1+'2_Inputs'!$B$84)^INT((COLUMN()-2)/12),0)+IF(AND(COLUMN()-1>='2_Inputs'!$B$191,'2_Inputs'!$C$191="JA"),'2_Inputs'!$C$80/12*(1+'2_Inputs'!$B$84)^INT((COLUMN()-2)/12),0)+IF(AND(COLUMN()-1>='2_Inputs'!$B$192,'2_Inputs'!$C$192="JA"),'2_Inputs'!$C$81/12*(1+'2_Inputs'!$B$84)^INT((COLUMN()-2)/12),0) -> 0 | C10: =IF(AND(COLUMN()-1>='2_Inputs'!$B$177,'2_Inputs'!$C$177="JA"),'2_Inputs'!$C$71/12*(1+'2_Inputs'!$B$84)^INT((COLUMN()-2)/12),0)+IF(AND(COLUMN()-1>='2_Inputs'!$B$178,'2_Inputs'!$C$178="JA"),'2_Inputs'!$C$71/12*(1+'2_Inputs'!$B$84)^INT((COLUMN()-2)/12),0)+IF(AND(COLUMN()-1>='2_Inputs'!$B$179,'2_Inputs'!$C$179="JA"),'2_Inputs'!$C$72/12*(1+'2_Inputs'!$B$84)^INT((COLUMN()-2)/12),0)+IF(AND(COLUMN()-1>='2_Inputs'!$B$180,'2_Inputs'!$C$180="JA"),'2_Inputs'!$C$73/12*(1+'2_Inputs'!$B$84)^INT((COLUMN()-2)/12),0)+IF(AND(COLUMN()-1>='2_Inputs'!$B$181,'2_Inputs'!$C$181="JA"),'2_Inputs'!$C$74/12*(1+'2_Inputs'!$B$84)^INT((COLUMN()-2)/12),0)+IF(AND(COLUMN()-1>='2_Inputs'!$B$182,'2_Inputs'!$C$182="JA"),'2_Inputs'!$C$82/12*(1+'2_Inputs'!$B$84)^INT((COLUMN()-2)/12),0)+IF(AND(COLUMN()-1>='2_Inputs'!$B$183,'2_Inputs'!$C$183="JA"),'2_Inputs'!$C$75/12*(1+'2_Inputs'!$B$84)^INT((COLUMN()-2)/12),0)+IF(AND(COLUMN()-1>='2_Inputs'!$B$184,'2_Inputs'!$C$184="JA"),'2_Inputs'!$C$76/12*(1+'2_Inputs'!$B$84)^INT((COLUMN()-2)/12),0)+IF(AND(COLUMN()-1>='2_Inputs'!$B$185,'2_Inputs'!$C$185="JA"),'2_Inputs'!$C$76/12*(1+'2_Inputs'!$B$84)^INT((COLUMN()-2)/12),0)+IF(AND(COLUMN()-1>='2_Inputs'!$B$186,'2_Inputs'!$C$186="JA"),'2_Inputs'!$C$76/12*(1+'2_Inputs'!$B$84)^INT((COLUMN()-2)/12),0)+IF(AND(COLUMN()-1>='2_Inputs'!$B$187,'2_Inputs'!$C$187="JA"),'2_Inputs'!$C$78/12*(1+'2_Inputs'!$B$84)^INT((COLUMN()-2)/12),0)+IF(AND(COLUMN()-1>='2_Inputs'!$B$188,'2_Inputs'!$C$188="JA"),'2_Inputs'!$C$78/12*(1+'2_Inputs'!$B$84)^INT((COLUMN()-2)/12),0)+IF(AND(COLUMN()-1>='2_Inputs'!$B$189,'2_Inputs'!$C$189="JA"),'2_Inputs'!$C$77/12*(1+'2_Inputs'!$B$84)^INT((COLUMN()-2)/12),0)+IF(AND(COLUMN()-1>='2_Inputs'!$B$190,'2_Inputs'!$C$190="JA"),'2_Inputs'!$C$79/12*(1+'2_Inputs'!$B$84)^INT((COLUMN()-2)/12),0)+IF(AND(COLUMN()-1>='2_Inputs'!$B$191,'2_Inputs'!$C$191="JA"),'2_Inputs'!$C$80/12*(1+'2_Inputs'!$B$84)^INT((COLUMN()-2)/12),0)+IF(AND(COLUMN()-1>='2_Inputs'!$B$192,'2_Inputs'!$C$192="JA"),'2_Inputs'!$C$81/12*(1+'2_Inputs'!$B$84)^INT((COLUMN()-2)/12),0) -> 0 | D10: =IF(AND(COLUMN()-1>='2_Inputs'!$B$177,'2_Inputs'!$C$177="JA"),'2_Inputs'!$C$71/12*(1+'2_Inputs'!$B$84)^INT((COLUMN()-2)/12),0)+IF(AND(COLUMN()-1>='2_Inputs'!$B$178,'2_Inputs'!$C$178="JA"),'2_Inputs'!$C$71/12*(1+'2_Inputs'!$B$84)^INT((COLUMN()-2)/12),0)+IF(AND(COLUMN()-1>='2_Inputs'!$B$179,'2_Inputs'!$C$179="JA"),'2_Inputs'!$C$72/12*(1+'2_Inputs'!$B$84)^INT((COLUMN()-2)/12),0)+IF(AND(COLUMN()-1>='2_Inputs'!$B$180,'2_Inputs'!$C$180="JA"),'2_Inputs'!$C$73/12*(1+'2_Inputs'!$B$84)^INT((COLUMN()-2)/12),0)+IF(AND(COLUMN()-1>='2_Inputs'!$B$181,'2_Inputs'!$C$181="JA"),'2_Inputs'!$C$74/12*(1+'2_Inputs'!$B$84)^INT((COLUMN()-2)/12),0)+IF(AND(COLUMN()-1>='2_Inputs'!$B$182,'2_Inputs'!$C$182="JA"),'2_Inputs'!$C$82/12*(1+'2_Inputs'!$B$84)^INT((COLUMN()-2)/12),0)+IF(AND(COLUMN()-1>='2_Inputs'!$B$183,'2_Inputs'!$C$183="JA"),'2_Inputs'!$C$75/12*(1+'2_Inputs'!$B$84)^INT((COLUMN()-2)/12),0)+IF(AND(COLUMN()-1>='2_Inputs'!$B$184,'2_Inputs'!$C$184="JA"),'2_Inputs'!$C$76/12*(1+'2_Inputs'!$B$84)^INT((COLUMN()-2)/12),0)+IF(AND(COLUMN()-1>='2_Inputs'!$B$185,'2_Inputs'!$C$185="JA"),'2_Inputs'!$C$76/12*(1+'2_Inputs'!$B$84)^INT((COLUMN()-2)/12),0)+IF(AND(COLUMN()-1>='2_Inputs'!$B$186,'2_Inputs'!$C$186="JA"),'2_Inputs'!$C$76/12*(1+'2_Inputs'!$B$84)^INT((COLUMN()-2)/12),0)+IF(AND(COLUMN()-1>='2_Inputs'!$B$187,'2_Inputs'!$C$187="JA"),'2_Inputs'!$C$78/12*(1+'2_Inputs'!$B$84)^INT((COLUMN()-2)/12),0)+IF(AND(COLUMN()-1>='2_Inputs'!$B$188,'2_Inputs'!$C$188="JA"),'2_Inputs'!$C$78/12*(1+'2_Inputs'!$B$84)^INT((COLUMN()-2)/12),0)+IF(AND(COLUMN()-1>='2_Inputs'!$B$189,'2_Inputs'!$C$189="JA"),'2_Inputs'!$C$77/12*(1+'2_Inputs'!$B$84)^INT((COLUMN()-2)/12),0)+IF(AND(COLUMN()-1>='2_Inputs'!$B$190,'2_Inputs'!$C$190="JA"),'2_Inputs'!$C$79/12*(1+'2_Inputs'!$B$84)^INT((COLUMN()-2)/12),0)+IF(AND(COLUMN()-1>='2_Inputs'!$B$191,'2_Inputs'!$C$191="JA"),'2_Inputs'!$C$80/12*(1+'2_Inputs'!$B$84)^INT((COLUMN()-2)/12),0)+IF(AND(COLUMN()-1>='2_Inputs'!$B$192,'2_Inputs'!$C$192="JA"),'2_Inputs'!$C$81/12*(1+'2_Inputs'!$B$84)^INT((COLUMN()-2)/12),0) -> 0 | E10: =IF(AND(COLUMN()-1>='2_Inputs'!$B$177,'2_Inputs'!$C$177="JA"),'2_Inputs'!$C$71/12*(1+'2_Inputs'!$B$84)^INT((COLUMN()-2)/12),0)+IF(AND(COLUMN()-1>='2_Inputs'!$B$178,'2_Inputs'!$C$178="JA"),'2_Inputs'!$C$71/12*(1+'2_Inputs'!$B$84)^INT((COLUMN()-2)/12),0)+IF(AND(COLUMN()-1>='2_Inputs'!$B$179,'2_Inputs'!$C$179="JA"),'2_Inputs'!$C$72/12*(1+'2_Inputs'!$B$84)^INT((COLUMN()-2)/12),0)+IF(AND(COLUMN()-1>='2_Inputs'!$B$180,'2_Inputs'!$C$180="JA"),'2_Inputs'!$C$73/12*(1+'2_Inputs'!$B$84)^INT((COLUMN()-2)/12),0)+IF(AND(COLUMN()-1>='2_Inputs'!$B$181,'2_Inputs'!$C$181="JA"),'2_Inputs'!$C$74/12*(1+'2_Inputs'!$B$84)^INT((COLUMN()-2)/12),0)+IF(AND(COLUMN()-1>='2_Inputs'!$B$182,'2_Inputs'!$C$182="JA"),'2_Inputs'!$C$82/12*(1+'2_Inputs'!$B$84)^INT((COLUMN()-2)/12),0)+IF(AND(COLUMN()-1>='2_Inputs'!$B$183,'2_Inputs'!$C$183="JA"),'2_Inputs'!$C$75/12*(1+'2_Inputs'!$B$84)^INT((COLUMN()-2)/12),0)+IF(AND(COLUMN()-1>='2_Inputs'!$B$184,'2_Inputs'!$C$184="JA"),'2_Inputs'!$C$76/12*(1+'2_Inputs'!$B$84)^INT((COLUMN()-2)/12),0)+IF(AND(COLUMN()-1>='2_Inputs'!$B$185,'2_Inputs'!$C$185="JA"),'2_Inputs'!$C$76/12*(1+'2_Inputs'!$B$84)^INT((COLUMN()-2)/12),0)+IF(AND(COLUMN()-1>='2_Inputs'!$B$186,'2_Inputs'!$C$186="JA"),'2_Inputs'!$C$76/12*(1+'2_Inputs'!$B$84)^INT((COLUMN()-2)/12),0)+IF(AND(COLUMN()-1>='2_Inputs'!$B$187,'2_Inputs'!$C$187="JA"),'2_Inputs'!$C$78/12*(1+'2_Inputs'!$B$84)^INT((COLUMN()-2)/12),0)+IF(AND(COLUMN()-1>='2_Inputs'!$B$188,'2_Inputs'!$C$188="JA"),'2_Inputs'!$C$78/12*(1+'2_Inputs'!$B$84)^INT((COLUMN()-2)/12),0)+IF(AND(COLUMN()-1>='2_Inputs'!$B$189,'2_Inputs'!$C$189="JA"),'2_Inputs'!$C$77/12*(1+'2_Inputs'!$B$84)^INT((COLUMN()-2)/12),0)+IF(AND(COLUMN()-1>='2_Inputs'!$B$190,'2_Inputs'!$C$190="JA"),'2_Inputs'!$C$79/12*(1+'2_Inputs'!$B$84)^INT((COLUMN()-2)/12),0)+IF(AND(COLUMN()-1>='2_Inputs'!$B$191,'2_Inputs'!$C$191="JA"),'2_Inputs'!$C$80/12*(1+'2_Inputs'!$B$84)^INT((COLUMN()-2)/12),0)+IF(AND(COLUMN()-1>='2_Inputs'!$B$192,'2_Inputs'!$C$192="JA"),'2_Inputs'!$C$81/12*(1+'2_Inputs'!$B$84)^INT((COLUMN()-2)/12),0) -> 0 | F10: =IF(AND(COLUMN()-1>='2_Inputs'!$B$177,'2_Inputs'!$C$177="JA"),'2_Inputs'!$C$71/12*(1+'2_Inputs'!$B$84)^INT((COLUMN()-2)/12),0)+IF(AND(COLUMN()-1>='2_Inputs'!$B$178,'2_Inputs'!$C$178="JA"),'2_Inputs'!$C$71/12*(1+'2_Inputs'!$B$84)^INT((COLUMN()-2)/12),0)+IF(AND(COLUMN()-1>='2_Inputs'!$B$179,'2_Inputs'!$C$179="JA"),'2_Inputs'!$C$72/12*(1+'2_Inputs'!$B$84)^INT((COLUMN()-2)/12),0)+IF(AND(COLUMN()-1>='2_Inputs'!$B$180,'2_Inputs'!$C$180="JA"),'2_Inputs'!$C$73/12*(1+'2_Inputs'!$B$84)^INT((COLUMN()-2)/12),0)+IF(AND(COLUMN()-1>='2_Inputs'!$B$181,'2_Inputs'!$C$181="JA"),'2_Inputs'!$C$74/12*(1+'2_Inputs'!$B$84)^INT((COLUMN()-2)/12),0)+IF(AND(COLUMN()-1>='2_Inputs'!$B$182,'2_Inputs'!$C$182="JA"),'2_Inputs'!$C$82/12*(1+'2_Inputs'!$B$84)^INT((COLUMN()-2)/12),0)+IF(AND(COLUMN()-1>='2_Inputs'!$B$183,'2_Inputs'!$C$183="JA"),'2_Inputs'!$C$75/12*(1+'2_Inputs'!$B$84)^INT((COLUMN()-2)/12),0)+IF(AND(COLUMN()-1>='2_Inputs'!$B$184,'2_Inputs'!$C$184="JA"),'2_Inputs'!$C$76/12*(1+'2_Inputs'!$B$84)^INT((COLUMN()-2)/12),0)+IF(AND(COLUMN()-1>='2_Inputs'!$B$185,'2_Inputs'!$C$185="JA"),'2_Inputs'!$C$76/12*(1+'2_Inputs'!$B$84)^INT((COLUMN()-2)/12),0)+IF(AND(COLUMN()-1>='2_Inputs'!$B$186,'2_Inputs'!$C$186="JA"),'2_Inputs'!$C$76/12*(1+'2_Inputs'!$B$84)^INT((COLUMN()-2)/12),0)+IF(AND(COLUMN()-1>='2_Inputs'!$B$187,'2_Inputs'!$C$187="JA"),'2_Inputs'!$C$78/12*(1+'2_Inputs'!$B$84)^INT((COLUMN()-2)/12),0)+IF(AND(COLUMN()-1>='2_Inputs'!$B$188,'2_Inputs'!$C$188="JA"),'2_Inputs'!$C$78/12*(1+'2_Inputs'!$B$84)^INT((COLUMN()-2)/12),0)+IF(AND(COLUMN()-1>='2_Inputs'!$B$189,'2_Inputs'!$C$189="JA"),'2_Inputs'!$C$77/12*(1+'2_Inputs'!$B$84)^INT((COLUMN()-2)/12),0)+IF(AND(COLUMN()-1>='2_Inputs'!$B$190,'2_Inputs'!$C$190="JA"),'2_Inputs'!$C$79/12*(1+'2_Inputs'!$B$84)^INT((COLUMN()-2)/12),0)+IF(AND(COLUMN()-1>='2_Inputs'!$B$191,'2_Inputs'!$C$191="JA"),'2_Inputs'!$C$80/12*(1+'2_Inputs'!$B$84)^INT((COLUMN()-2)/12),0)+IF(AND(COLUMN()-1>='2_Inputs'!$B$192,'2_Inputs'!$C$192="JA"),'2_Inputs'!$C$81/12*(1+'2_Inputs'!$B$84)^INT((COLUMN()-2)/12),0) -> 0 | G10: =IF(AND(COLUMN()-1>='2_Inputs'!$B$177,'2_Inputs'!$C$177="JA"),'2_Inputs'!$C$71/12*(1+'2_Inputs'!$B$84)^INT((COLUMN()-2)/12),0)+IF(AND(COLUMN()-1>='2_Inputs'!$B$178,'2_Inputs'!$C$178="JA"),'2_Inputs'!$C$71/12*(1+'2_Inputs'!$B$84)^INT((COLUMN()-2)/12),0)+IF(AND(COLUMN()-1>='2_Inputs'!$B$179,'2_Inputs'!$C$179="JA"),'2_Inputs'!$C$72/12*(1+'2_Inputs'!$B$84)^INT((COLUMN()-2)/12),0)+IF(AND(COLUMN()-1>='2_Inputs'!$B$180,'2_Inputs'!$C$180="JA"),'2_Inputs'!$C$73/12*(1+'2_Inputs'!$B$84)^INT((COLUMN()-2)/12),0)+IF(AND(COLUMN()-1>='2_Inputs'!$B$181,'2_Inputs'!$C$181="JA"),'2_Inputs'!$C$74/12*(1+'2_Inputs'!$B$84)^INT((COLUMN()-2)/12),0)+IF(AND(COLUMN()-1>='2_Inputs'!$B$182,'2_Inputs'!$C$182="JA"),'2_Inputs'!$C$82/12*(1+'2_Inputs'!$B$84)^INT((COLUMN()-2)/12),0)+IF(AND(COLUMN()-1>='2_Inputs'!$B$183,'2_Inputs'!$C$183="JA"),'2_Inputs'!$C$75/12*(1+'2_Inputs'!$B$84)^INT((COLUMN()-2)/12),0)+IF(AND(COLUMN()-1>='2_Inputs'!$B$184,'2_Inputs'!$C$184="JA"),'2_Inputs'!$C$76/12*(1+'2_Inputs'!$B$84)^INT((COLUMN()-2)/12),0)+IF(AND(COLUMN()-1>='2_Inputs'!$B$185,'2_Inputs'!$C$185="JA"),'2_Inputs'!$C$76/12*(1+'2_Inputs'!$B$84)^INT((COLUMN()-2)/12),0)+IF(AND(COLUMN()-1>='2_Inputs'!$B$186,'2_Inputs'!$C$186="JA"),'2_Inputs'!$C$76/12*(1+'2_Inputs'!$B$84)^INT((COLUMN()-2)/12),0)+IF(AND(COLUMN()-1>='2_Inputs'!$B$187,'2_Inputs'!$C$187="JA"),'2_Inputs'!$C$78/12*(1+'2_Inputs'!$B$84)^INT((COLUMN()-2)/12),0)+IF(AND(COLUMN()-1>='2_Inputs'!$B$188,'2_Inputs'!$C$188="JA"),'2_Inputs'!$C$78/12*(1+'2_Inputs'!$B$84)^INT((COLUMN()-2)/12),0)+IF(AND(COLUMN()-1>='2_Inputs'!$B$189,'2_Inputs'!$C$189="JA"),'2_Inputs'!$C$77/12*(1+'2_Inputs'!$B$84)^INT((COLUMN()-2)/12),0)+IF(AND(COLUMN()-1>='2_Inputs'!$B$190,'2_Inputs'!$C$190="JA"),'2_Inputs'!$C$79/12*(1+'2_Inputs'!$B$84)^INT((COLUMN()-2)/12),0)+IF(AND(COLUMN()-1>='2_Inputs'!$B$191,'2_Inputs'!$C$191="JA"),'2_Inputs'!$C$80/12*(1+'2_Inputs'!$B$84)^INT((COLUMN()-2)/12),0)+IF(AND(COLUMN()-1>='2_Inputs'!$B$192,'2_Inputs'!$C$192="JA"),'2_Inputs'!$C$81/12*(1+'2_Inputs'!$B$84)^INT((COLUMN()-2)/12),0) -> 7625 | H10: =IF(AND(COLUMN()-1>='2_Inputs'!$B$177,'2_Inputs'!$C$177="JA"),'2_Inputs'!$C$71/12*(1+'2_Inputs'!$B$84)^INT((COLUMN()-2)/12),0)+IF(AND(COLUMN()-1>='2_Inputs'!$B$178,'2_Inputs'!$C$178="JA"),'2_Inputs'!$C$71/12*(1+'2_Inputs'!$B$84)^INT((COLUMN()-2)/12),0)+IF(AND(COLUMN()-1>='2_Inputs'!$B$179,'2_Inputs'!$C$179="JA"),'2_Inputs'!$C$72/12*(1+'2_Inputs'!$B$84)^INT((COLUMN()-2)/12),0)+IF(AND(COLUMN()-1>='2_Inputs'!$B$180,'2_Inputs'!$C$180="JA"),'2_Inputs'!$C$73/12*(1+'2_Inputs'!$B$84)^INT((COLUMN()-2)/12),0)+IF(AND(COLUMN()-1>='2_Inputs'!$B$181,'2_Inputs'!$C$181="JA"),'2_Inputs'!$C$74/12*(1+'2_Inputs'!$B$84)^INT((COLUMN()-2)/12),0)+IF(AND(COLUMN()-1>='2_Inputs'!$B$182,'2_Inputs'!$C$182="JA"),'2_Inputs'!$C$82/12*(1+'2_Inputs'!$B$84)^INT((COLUMN()-2)/12),0)+IF(AND(COLUMN()-1>='2_Inputs'!$B$183,'2_Inputs'!$C$183="JA"),'2_Inputs'!$C$75/12*(1+'2_Inputs'!$B$84)^INT((COLUMN()-2)/12),0)+IF(AND(COLUMN()-1>='2_Inputs'!$B$184,'2_Inputs'!$C$184="JA"),'2_Inputs'!$C$76/12*(1+'2_Inputs'!$B$84)^INT((COLUMN()-2)/12),0)+IF(AND(COLUMN()-1>='2_Inputs'!$B$185,'2_Inputs'!$C$185="JA"),'2_Inputs'!$C$76/12*(1+'2_Inputs'!$B$84)^INT((COLUMN()-2)/12),0)+IF(AND(COLUMN()-1>='2_Inputs'!$B$186,'2_Inputs'!$C$186="JA"),'2_Inputs'!$C$76/12*(1+'2_Inputs'!$B$84)^INT((COLUMN()-2)/12),0)+IF(AND(COLUMN()-1>='2_Inputs'!$B$187,'2_Inputs'!$C$187="JA"),'2_Inputs'!$C$78/12*(1+'2_Inputs'!$B$84)^INT((COLUMN()-2)/12),0)+IF(AND(COLUMN()-1>='2_Inputs'!$B$188,'2_Inputs'!$C$188="JA"),'2_Inputs'!$C$78/12*(1+'2_Inputs'!$B$84)^INT((COLUMN()-2)/12),0)+IF(AND(COLUMN()-1>='2_Inputs'!$B$189,'2_Inputs'!$C$189="JA"),'2_Inputs'!$C$77/12*(1+'2_Inputs'!$B$84)^INT((COLUMN()-2)/12),0)+IF(AND(COLUMN()-1>='2_Inputs'!$B$190,'2_Inputs'!$C$190="JA"),'2_Inputs'!$C$79/12*(1+'2_Inputs'!$B$84)^INT((COLUMN()-2)/12),0)+IF(AND(COLUMN()-1>='2_Inputs'!$B$191,'2_Inputs'!$C$191="JA"),'2_Inputs'!$C$80/12*(1+'2_Inputs'!$B$84)^INT((COLUMN()-2)/12),0)+IF(AND(COLUMN()-1>='2_Inputs'!$B$192,'2_Inputs'!$C$192="JA"),'2_Inputs'!$C$81/12*(1+'2_Inputs'!$B$84)^INT((COLUMN()-2)/12),0) -> 7625 | I10: =IF(AND(COLUMN()-1>='2_Inputs'!$B$177,'2_Inputs'!$C$177="JA"),'2_Inputs'!$C$71/12*(1+'2_Inputs'!$B$84)^INT((COLUMN()-2)/12),0)+IF(AND(COLUMN()-1>='2_Inputs'!$B$178,'2_Inputs'!$C$178="JA"),'2_Inputs'!$C$71/12*(1+'2_Inputs'!$B$84)^INT((COLUMN()-2)/12),0)+IF(AND(COLUMN()-1>='2_Inputs'!$B$179,'2_Inputs'!$C$179="JA"),'2_Inputs'!$C$72/12*(1+'2_Inputs'!$B$84)^INT((COLUMN()-2)/12),0)+IF(AND(COLUMN()-1>='2_Inputs'!$B$180,'2_Inputs'!$C$180="JA"),'2_Inputs'!$C$73/12*(1+'2_Inputs'!$B$84)^INT((COLUMN()-2)/12),0)+IF(AND(COLUMN()-1>='2_Inputs'!$B$181,'2_Inputs'!$C$181="JA"),'2_Inputs'!$C$74/12*(1+'2_Inputs'!$B$84)^INT((COLUMN()-2)/12),0)+IF(AND(COLUMN()-1>='2_Inputs'!$B$182,'2_Inputs'!$C$182="JA"),'2_Inputs'!$C$82/12*(1+'2_Inputs'!$B$84)^INT((COLUMN()-2)/12),0)+IF(AND(COLUMN()-1>='2_Inputs'!$B$183,'2_Inputs'!$C$183="JA"),'2_Inputs'!$C$75/12*(1+'2_Inputs'!$B$84)^INT((COLUMN()-2)/12),0)+IF(AND(COLUMN()-1>='2_Inputs'!$B$184,'2_Inputs'!$C$184="JA"),'2_Inputs'!$C$76/12*(1+'2_Inputs'!$B$84)^INT((COLUMN()-2)/12),0)+IF(AND(COLUMN()-1>='2_Inputs'!$B$185,'2_Inputs'!$C$185="JA"),'2_Inputs'!$C$76/12*(1+'2_Inputs'!$B$84)^INT((COLUMN()-2)/12),0)+IF(AND(COLUMN()-1>='2_Inputs'!$B$186,'2_Inputs'!$C$186="JA"),'2_Inputs'!$C$76/12*(1+'2_Inputs'!$B$84)^INT((COLUMN()-2)/12),0)+IF(AND(COLUMN()-1>='2_Inputs'!$B$187,'2_Inputs'!$C$187="JA"),'2_Inputs'!$C$78/12*(1+'2_Inputs'!$B$84)^INT((COLUMN()-2)/12),0)+IF(AND(COLUMN()-1>='2_Inputs'!$B$188,'2_Inputs'!$C$188="JA"),'2_Inputs'!$C$78/12*(1+'2_Inputs'!$B$84)^INT((COLUMN()-2)/12),0)+IF(AND(COLUMN()-1>='2_Inputs'!$B$189,'2_Inputs'!$C$189="JA"),'2_Inputs'!$C$77/12*(1+'2_Inputs'!$B$84)^INT((COLUMN()-2)/12),0)+IF(AND(COLUMN()-1>='2_Inputs'!$B$190,'2_Inputs'!$C$190="JA"),'2_Inputs'!$C$79/12*(1+'2_Inputs'!$B$84)^INT((COLUMN()-2)/12),0)+IF(AND(COLUMN()-1>='2_Inputs'!$B$191,'2_Inputs'!$C$191="JA"),'2_Inputs'!$C$80/12*(1+'2_Inputs'!$B$84)^INT((COLUMN()-2)/12),0)+IF(AND(COLUMN()-1>='2_Inputs'!$B$192,'2_Inputs'!$C$192="JA"),'2_Inputs'!$C$81/12*(1+'2_Inputs'!$B$84)^INT((COLUMN()-2)/12),0) -> 7625 | ... BA10: =IF(AND(COLUMN()-1>='2_Inputs'!$B$177,'2_Inputs'!$C$177="JA"),'2_Inputs'!$C$71/12*(1+'2_Inputs'!$B$84)^INT((COLUMN()-2)/12),0)+IF(AND(COLUMN()-1>='2_Inputs'!$B$178,'2_Inputs'!$C$178="JA"),'2_Inputs'!$C$71/12*(1+'2_Inputs'!$B$84)^INT((COLUMN()-2)/12),0)+IF(AND(COLUMN()-1>='2_Inputs'!$B$179,'2_Inputs'!$C$179="JA"),'2_Inputs'!$C$72/12*(1+'2_Inputs'!$B$84)^INT((COLUMN()-2)/12),0)+IF(AND(COLUMN()-1>='2_Inputs'!$B$180,'2_Inputs'!$C$180="JA"),'2_Inputs'!$C$73/12*(1+'2_Inputs'!$B$84)^INT((COLUMN()-2)/12),0)+IF(AND(COLUMN()-1>='2_Inputs'!$B$181,'2_Inputs'!$C$181="JA"),'2_Inputs'!$C$74/12*(1+'2_Inputs'!$B$84)^INT((COLUMN()-2)/12),0)+IF(AND(COLUMN()-1>='2_Inputs'!$B$182,'2_Inputs'!$C$182="JA"),'2_Inputs'!$C$82/12*(1+'2_Inputs'!$B$84)^INT((COLUMN()-2)/12),0)+IF(AND(COLUMN()-1>='2_Inputs'!$B$183,'2_Inputs'!$C$183="JA"),'2_Inputs'!$C$75/12*(1+'2_Inputs'!$B$84)^INT((COLUMN()-2)/12),0)+IF(AND(COLUMN()-1>='2_Inputs'!$B$184,'2_Inputs'!$C$184="JA"),'2_Inputs'!$C$76/12*(1+'2_Inputs'!$B$84)^INT((COLUMN()-2)/12),0)+IF(AND(COLUMN()-1>='2_Inputs'!$B$185,'2_Inputs'!$C$185="JA"),'2_Inputs'!$C$76/12*(1+'2_Inputs'!$B$84)^INT((COLUMN()-2)/12),0)+IF(AND(COLUMN()-1>='2_Inputs'!$B$186,'2_Inputs'!$C$186="JA"),'2_Inputs'!$C$76/12*(1+'2_Inputs'!$B$84)^INT((COLUMN()-2)/12),0)+IF(AND(COLUMN()-1>='2_Inputs'!$B$187,'2_Inputs'!$C$187="JA"),'2_Inputs'!$C$78/12*(1+'2_Inputs'!$B$84)^INT((COLUMN()-2)/12),0)+IF(AND(COLUMN()-1>='2_Inputs'!$B$188,'2_Inputs'!$C$188="JA"),'2_Inputs'!$C$78/12*(1+'2_Inputs'!$B$84)^INT((COLUMN()-2)/12),0)+IF(AND(COLUMN()-1>='2_Inputs'!$B$189,'2_Inputs'!$C$189="JA"),'2_Inputs'!$C$77/12*(1+'2_Inputs'!$B$84)^INT((COLUMN()-2)/12),0)+IF(AND(COLUMN()-1>='2_Inputs'!$B$190,'2_Inputs'!$C$190="JA"),'2_Inputs'!$C$79/12*(1+'2_Inputs'!$B$84)^INT((COLUMN()-2)/12),0)+IF(AND(COLUMN()-1>='2_Inputs'!$B$191,'2_Inputs'!$C$191="JA"),'2_Inputs'!$C$80/12*(1+'2_Inputs'!$B$84)^INT((COLUMN()-2)/12),0)+IF(AND(COLUMN()-1>='2_Inputs'!$B$192,'2_Inputs'!$C$192="JA"),'2_Inputs'!$C$81/12*(1+'2_Inputs'!$B$84)^INT((COLUMN()-2)/12),0) -> 84446.926
A11: Lohnnebenkosten (in AG-Brutto enthalten) | B11: 0 | C11: 0 | D11: 0 | E11: 0 | F11: 0 | G11: 0 | H11: 0 | I11: 0 | J11: 0 | K11: 0 | L11: 0 | M11: 0 | N11: 0 | O11: 0 | P11: 0 | Q11: 0 | R11: 0 | S11: 0 | T11: 0 | U11: 0 | V11: 0 | W11: 0 | X11: 0 | Y11: 0 | Z11: 0 | AA11: 0 | AB11: 0 | AC11: 0 | AD11: 0 | AE11: 0 | AF11: 0 | AG11: 0 | AH11: 0 | AI11: 0 | AJ11: 0 | AK11: 0 | AL11: 0 | AM11: 0 | AN11: 0 | AO11: 0 | AP11: 0 | AQ11: 0 | AR11: 0 | AS11: 0 | AT11: 0 | AU11: 0 | AV11: 0 | AW11: 0 | AX11: 0 | AY11: 0 | AZ11: 0 | BA11: 0
