Workbook

Sheet Performance Dashboard
B1: Year 1 | C1: Year 2 | D1: Year 3 | E1: Year 4 | F1: Year 5
A2: Gross Margin | B2: ='Financial Statements'!B7/'Financial Statements'!B3 -> 0.65 | C2: ='Financial Statements'!C7/'Financial Statements'!C3 -> 0.65 | D2: ='Financial Statements'!D7/'Financial Statements'!D3 -> 0.65 | E2: ='Financial Statements'!E7/'Financial Statements'!E3 -> 0.65 | F2: ='Financial Statements'!F7/'Financial Statements'!F3 -> 0.65
A3: Net Margin | B3: ='Financial Statements'!B13/'Financial Statements'!B3 -> -0.20982282 | C3: ='Financial Statements'!C13/'Financial Statements'!C3 -> 0.28172748 | D3: ='Financial Statements'!D13/'Financial Statements'!D3 -> 0.30032037 | E3: ='Financial Statements'!E13/'Financial Statements'!E3 -> 0.32738363 | F3: ='Financial Statements'!F13/'Financial Statements'!F3 -> 0.362235
A4: Quick Ratio | B4: ='Financial Statements'!B19/'Financial Statements'!B22 -> 23.902717 | C4: ='Financial Statements'!C19/'Financial Statements'!C22 -> 31.910652 | D4: ='Financial Statements'!D19/'Financial Statements'!D22 -> 38.645878 | E4: ='Financial Statements'!E19/'Financial Statements'!E22 -> 43.390137 | F4: ='Financial Statements'!F19/'Financial Statements'!F22 -> 45.526631
A5: EBITDA | B5: ='Financial Statements'!B13 -> -40265 | C5: ='Financial Statements'!C13 -> 56754 | D5: ='Financial Statements'!D13 -> 65620 | E5: ='Financial Statements'!E13 -> 81584 | F5: ='Financial Statements'!F13 -> 110210
A7: Customers | B7: ='Year 1 Cash Budget'!O4 -> 3838 | C7: ='Year 2 Cash Budget'!N4 -> 4029 | D7: ='Year 3 Cash Budget'!N4 -> 4370 | E7: ='Year 4 Cash Budget'!N4 -> 4984 | F7: ='Year 5 Cash Budget'!N4 -> 6085
A8: Market Share % | B8: =B7/('Control Panel'!$B$3*12) -> 0.031983333 | C8: =C7/('Control Panel'!$B$3*12) -> 0.033575 | D8: =D7/('Control Panel'!$B$3*12) -> 0.036416667 | E8: =E7/('Control Panel'!$B$3*12) -> 0.041533333 | F8: =F7/('Control Panel'!$B$3*12) -> 0.050708333
A10: ='Financial Statements'!A3 -> Revenue | B10: ='Financial Statements'!B3 -> 191900 | C10: ='Financial Statements'!C3 -> 201450 | D10: ='Financial Statements'!D3 -> 218500 | E10: ='Financial Statements'!E3 -> 249200 | F10: ='Financial Statements'!F3 -> 304250
A11: ='Financial Statements'!A7 -> Gross Profit | B11: ='Financial Statements'!B7 -> 124735 | C11: ='Financial Statements'!C7 -> 130942.5 | D11: ='Financial Statements'!D7 -> 142025 | E11: ='Financial Statements'!E7 -> 161980 | F11: ='Financial Statements'!F7 -> 197762.5
A12: ='Financial Statements'!A11 -> Founder Profit Share | B12: ='Financial Statements'!B11 -> 0 | C12: ='Financial Statements'!C11 -> 14188.5 | D12: ='Financial Statements'!D11 -> 16405 | E12: ='Financial Statements'!E11 -> 20396 | F12: ='Financial Statements'!F11 -> 27552.5
A13: ='Financial Statements'!A13 -> Net Profit | B13: ='Financial Statements'!B13 -> -40265 | C13: ='Financial Statements'!C13 -> 56754 | D13: ='Financial Statements'!D13 -> 65620 | E13: ='Financial Statements'!E13 -> 81584 | F13: ='Financial Statements'!F13 -> 110210
A15: ='Financial Statements'!A19 -> Cash | B15: ='Financial Statements'!B19 -> 136365 | C15: ='Financial Statements'!C19 -> 193219 | D15: ='Financial Statements'!D19 -> 259024 | E15: ='Financial Statements'!E19 -> 340938 | F15: ='Financial Statements'!F19 -> 451738
A16: ='Financial Statements'!A24 -> Net Worth | B16: ='Financial Statements'!B24 -> 144735 | C16: ='Financial Statements'!C24 -> 201489 | D16: ='Financial Statements'!D24 -> 267109 | E16: ='Financial Statements'!E24 -> 348693 | F16: ='Financial Statements'!F24 -> 458903
A18: Operational Break Even | B18: =IF(ISNA(HLOOKUP("OBE",Balances!A7:BI8,2,FALSE)),"Never",CONCATENATE("Month ",HLOOKUP("OBE",Balances!A7:BI8,2,FALSE))) -> Month 19 | D18: Worth > | E18: =IF(ISNA(HLOOKUP("Yes",'Financial Statements'!B31:F34,4,FALSE)),"Never",HLOOKUP("Yes",'Financial Statements'!B31:F34,4,FALSE)) -> Year 2
A19: Cash Break Even | B19: =IF(ISNA(HLOOKUP("CBE",Balances!A5:BI8,4,FALSE)),"Never",CONCATENATE("Month ",HLOOKUP("CBE",Balances!A5:BI8,4,FALSE))) -> Month 21 | D19: Buyout | E19: =IF(ISNA(HLOOKUP("Yes",'Financial Statements'!B33:F34,2,FALSE)),"Never",HLOOKUP("Yes",'Financial Statements'!B33:F34,2,FALSE)) -> Year 4
A21: Investment Required | B21: ='Startup & Pre-Opening Costs'!B29 -> 185000 | D21: Buyout | E21: =IF(E19="Never","N/A",HLOOKUP(E19,'Financial Statements'!B34:F35,2,FALSE)) -> 273800
A23: Market Share % | B23: ='Control Panel'!B2/'Control Panel'!B3 -> 0.03 | D23: Investor ROI % | E23: =(E21-B21)/B21 -> 0.48

Sheet Control Panel
A1: Average Sale per Customer | B1: 50 | E1: ='Performance Dashboard'!B1 -> Year 1 | F1: ='Performance Dashboard'!C1 -> Year 2 | G1: ='Performance Dashboard'!D1 -> Year 3 | H1: ='Performance Dashboard'!E1 -> Year 4 | I1: ='Performance Dashboard'!F1 -> Year 5
A2: Base Number of Customers per Month | B2: 300 | D2: ='Performance Dashboard'!A2 -> Gross Margin | E2: ='Performance Dashboard'!B2 -> 0.65 | F2: ='Performance Dashboard'!C2 -> 0.65 | G2: ='Performance Dashboard'!D2 -> 0.65 | H2: ='Performance Dashboard'!E2 -> 0.65 | I2: ='Performance Dashboard'!F2 -> 0.65
A3: Potential Customers per Month | B3: 10000 | D3: ='Performance Dashboard'!A3 -> Net Margin | E3: ='Performance Dashboard'!B3 -> -0.20982282 | F3: ='Performance Dashboard'!C3 -> 0.28172748 | G3: ='Performance Dashboard'!D3 -> 0.30032037 | H3: ='Performance Dashboard'!E3 -> 0.32738363 | I3: ='Performance Dashboard'!F3 -> 0.362235
A4: Customer Growth per month | B4: 0.05 | D4: ='Performance Dashboard'!A4 -> Quick Ratio | E4: ='Performance Dashboard'!B4 -> 23.902717 | F4: ='Performance Dashboard'!C4 -> 31.910652 | G4: ='Performance Dashboard'!D4 -> 38.645878 | H4: ='Performance Dashboard'!E4 -> 43.390137 | I4: ='Performance Dashboard'!F4 -> 45.526631
D5: ='Performance Dashboard'!A5 -> EBITDA | E5: ='Performance Dashboard'!B5 -> -40265 | F5: ='Performance Dashboard'!C5 -> 56754 | G5: ='Performance Dashboard'!D5 -> 65620 | H5: ='Performance Dashboard'!E5 -> 81584 | I5: ='Performance Dashboard'!F5 -> 110210
A6: Revenue Payments
A7: Cash | D7: ='Performance Dashboard'!A7 -> Customers | E7: ='Performance Dashboard'!B7 -> 3838 | F7: ='Performance Dashboard'!C7 -> 4029 | G7: ='Performance Dashboard'!D7 -> 4370 | H7: ='Performance Dashboard'!E7 -> 4984 | I7: ='Performance Dashboard'!F7 -> 6085
A8: 1 Week Credit (Credit Card) | B8: 1
A9: 1 Month Credit (Invoice) | D9: ='Performance Dashboard'!A10 -> Revenue | E9: ='Performance Dashboard'!B10 -> 191900 | F9: ='Performance Dashboard'!C10 -> 201450 | G9: ='Performance Dashboard'!D10 -> 218500 | H9: ='Performance Dashboard'!E10 -> 249200 | I9: ='Performance Dashboard'!F10 -> 304250
D10: ='Performance Dashboard'!A11 -> Gross Profit | E10: ='Performance Dashboard'!B11 -> 124735 | F10: ='Performance Dashboard'!C11 -> 130942.5 | G10: ='Performance Dashboard'!D11 -> 142025 | H10: ='Performance Dashboard'!E11 -> 161980 | I10: ='Performance Dashboard'!F11 -> 197762.5
A11: Cost of Revenue | B11: 0.35 | D11: ='Performance Dashboard'!A12 -> Founder Profit Share | E11: ='Performance Dashboard'!B12 -> 0 | F11: ='Performance Dashboard'!C12 -> 14188.5 | G11: ='Performance Dashboard'!D12 -> 16405 | H11: ='Performance Dashboard'!E12 -> 20396 | I11: ='Performance Dashboard'!F12 -> 27552.5
D12: ='Performance Dashboard'!A13 -> Net Profit | E12: ='Performance Dashboard'!B13 -> -40265 | F12: ='Performance Dashboard'!C13 -> 56754 | G12: ='Performance Dashboard'!D13 -> 65620 | H12: ='Performance Dashboard'!E13 -> 81584 | I12: ='Performance Dashboard'!F13 -> 110210
A13: 1 Month Supplier Credit | B13: 1
D14: ='Performance Dashboard'!A15 -> Cash | E14: ='Performance Dashboard'!B15 -> 136365 | F14: ='Performance Dashboard'!C15 -> 193219 | G14: ='Performance Dashboard'!D15 -> 259024 | H14: ='Performance Dashboard'!E15 -> 340938 | I14: ='Performance Dashboard'!F15 -> 451738
A15: Investor Return | B15: 0.12 | D15: ='Performance Dashboard'!A16 -> Net Worth | E15: ='Performance Dashboard'!B16 -> 144735 | F15: ='Performance Dashboard'!C16 -> 201489 | G15: ='Performance Dashboard'!D16 -> 267109 | H15: ='Performance Dashboard'!E16 -> 348693 | I15: ='Performance Dashboard'!F16 -> 458903
A16: Founder Profit % | B16: 0.2
D17: ='Performance Dashboard'!A18 -> Operational Break Even | E17: ='Performance Dashboard'!B18 -> Month 19 | G17: ='Performance Dashboard'!D18 -> Worth > | H17: ='Performance Dashboard'!E18 -> Year 2
D18: ='Performance Dashboard'!A19 -> Cash Break Even | E18: ='Performance Dashboard'!B19 -> Month 21 | G18: ='Performance Dashboard'!D19 -> Buyout | H18: ='Performance Dashboard'!E19 -> Year 4
D20: ='Performance Dashboard'!A21 -> Investment Required | E20: ='Performance Dashboard'!B21 -> 185000 | G20: ='Performance Dashboard'!D21 -> Buyout | H20: ='Performance Dashboard'!E21 -> 273800
D22: ='Performance Dashboard'!A23 -> Market Share % | E22: ='Performance Dashboard'!B23 -> 0.03 | G22: ='Performance Dashboard'!D23 -> Investor ROI % | H22: ='Performance Dashboard'!E23 -> 0.48

Sheet Startup & Pre-Opening Costs
B1: Asset | C1: Expense
A2: Contracts, Terms, GPDR | C2: 5000
A3: Stationery, etc.
A4: Brochures
A5: Consultants | C5: 50000
A6: Insurance
A7: Rent
A8: R & D Design | C8: 50000
A9: R & D Maintenance
A10: Computer Equpment | B10: 10000
A11: Staff
A12: Communications Hardware
A13: Communications Contracts
A14: Furniture
A15: Incorporation Fees
A16: Website Design
A17: Website Maintenance
A18: Travel
A19: Buildings
A20: Vehicles
A21: Marketing | C21: 50000
A23: Total | B23: =SUM(B2:B22) -> 10000 | C23: =SUM(C2:C22) -> 155000
A25: Preopening Period?
A27: Investment Required | B27: =B23+C23 -> 165000
A28: Working Capital Required | B28: 20000 | C28: =IF(MIN('Year 1 Cash Budget'!B46:N46,'Year 2 Cash Budget'!B46:M46,'Year 3 Cash Budget'!B46:M46)<0,CONCATENATE("I suggest an additional ",ROUNDUP(-MIN('Year 1 Cash Budget'!B46:N46,'Year 2 Cash Budget'!B46:M46,'Year 3 Cash Budget'!B46:M46),-4)),"")
A29: Investment Total | B29: =SUM(B27:B28) -> 185000

Sheet Year 1 Cash Budget
B1: Pre-Opening | C1: Month 1 | D1: Month 2 | E1: Month 3 | F1: Month 4 | G1: Month 5 | H1: Month 6 | I1: Month 7 | J1: Month 8 | K1: Month 9 | L1: Month 10 | M1: Month 11 | N1: Month 12 | O1: Year 1
A2: Revenue Calculations
A3: Average Sale | C3: ='Control Panel'!$B$1 -> 50 | D3: =C3 -> 50 | E3: =D3 -> 50 | F3: =E3 -> 50 | G3: =F3 -> 50 | H3: =G3 -> 50 | I3: =H3 -> 50 | J3: =I3 -> 50 | K3: =J3 -> 50 | ... N3: =M3 -> 50
A4: Customers | C4: =ROUND((('Control Panel'!$B$2*(C5+1))*C6),0) -> 315 | D4: =ROUND((('Control Panel'!$B$2*(D5+1))*D6),0) -> 316 | E4: =ROUND((('Control Panel'!$B$2*(E5+1))*E6),0) -> 317 | F4: =ROUND((('Control Panel'!$B$2*(F5+1))*F6),0) -> 317 | G4: =ROUND((('Control Panel'!$B$2*(G5+1))*G6),0) -> 318 | H4: =ROUND((('Control Panel'!$B$2*(H5+1))*H6),0) -> 319 | I4: =ROUND((('Control Panel'!$B$2*(I5+1))*I6),0) -> 320 | J4: =ROUND((('Control Panel'!$B$2*(J5+1))*J6),0) -> 321 | ... N4: =ROUND((('Control Panel'!$B$2*(N5+1))*N6),0) -> 326 | O4: =SUM(C4:N4) -> 3838
A5: Customer Growth Factor | C5: ='Control Panel'!B4 -> 0.05 | D5: =C5*(1+'Control Panel'!$B$4) -> 0.0525 | E5: =D5*(1+'Control Panel'!$B$4) -> 0.055125 | F5: =E5*(1+'Control Panel'!$B$4) -> 0.05788125 | G5: =F5*(1+'Control Panel'!$B$4) -> 0.060775313 | H5: =G5*(1+'Control Panel'!$B$4) -> 0.063814078 | I5: =H5*(1+'Control Panel'!$B$4) -> 0.067004782 | J5: =I5*(1+'Control Panel'!$B$4) -> 0.070355021 | K5: =J5*(1+'Control Panel'!$B$4) -> 0.073872772 | ... N5: =M5*(1+'Control Panel'!$B$4) -> 0.085516968
A6: Seasonality Index | C6: 1 | D6: =C6 -> 1 | E6: =D6 -> 1 | F6: =E6 -> 1 | G6: =F6 -> 1 | H6: =G6 -> 1 | I6: =H6 -> 1 | J6: =I6 -> 1 | K6: =J6 -> 1 | ... N6: =M6 -> 1
A7: Revenue | C7: =C3*C4 -> 15750 | D7: =D3*D4 -> 15800 | E7: =E3*E4 -> 15850 | F7: =F3*F4 -> 15850 | G7: =G3*G4 -> 15900 | H7: =H3*H4 -> 15950 | I7: =I3*I4 -> 16000 | J7: =J3*J4 -> 16050 | ... N7: =N3*N4 -> 16300 | O7: =SUM(C7:N7) -> 191900 | P7: Debtors | Q7: =(N7*'Control Panel'!$B$8)*(1/4)+(N7*'Control Panel'!$B$9) -> 4075
A9: Opening Cash | B9: 0 | C9: =B46 -> 70000 | D9: =C46 -> 76812.5 | E9: =D46 -> 82087.5 | F9: =E46 -> 87395 | G9: =F46 -> 92697.5 | H9: =G46 -> 98037.5 | I9: =H46 -> 103410 | J9: =I46 -> 108815 | ... N9: =M46 -> 130760
A10: Revenue (this month) | C10: =C7*'Control Panel'!$B$7 -> 0 | D10: =D7*'Control Panel'!$B$7 -> 0 | E10: =E7*'Control Panel'!$B$7 -> 0 | F10: =F7*'Control Panel'!$B$7 -> 0 | G10: =G7*'Control Panel'!$B$7 -> 0 | H10: =H7*'Control Panel'!$B$7 -> 0 | I10: =I7*'Control Panel'!$B$7 -> 0 | J10: =J7*'Control Panel'!$B$7 -> 0 | ... N10: =N7*'Control Panel'!$B$7 -> 0 | O10: =SUM(B10:N10) -> 0
A11: Revenue (1 Week Credit) (this month) | C11: =(C7*'Control Panel'!$B$8)*(3/4) -> 11812.5 | D11: =(D7*'Control Panel'!$B$8)*(3/4) -> 11850 | E11: =(E7*'Control Panel'!$B$8)*(3/4) -> 11887.5 | F11: =(F7*'Control Panel'!$B$8)*(3/4) -> 11887.5 | G11: =(G7*'Control Panel'!$B$8)*(3/4) -> 11925 | H11: =(H7*'Control Panel'!$B$8)*(3/4) -> 11962.5 | I11: =(I7*'Control Panel'!$B$8)*(3/4) -> 12000 | J11: =(J7*'Control Panel'!$B$8)*(3/4) -> 12037.5 | ... N11: =(N7*'Control Panel'!$B$8)*(3/4) -> 12225 | O11: =SUM(B11:N11) -> 143925
A12: Revenue (1 Week Credit) (last month) | D12: =(C7*'Control Panel'!$B$8)*(1/4) -> 3937.5 | E12: =(D7*'Control Panel'!$B$8)*(1/4) -> 3950 | F12: =(E7*'Control Panel'!$B$8)*(1/4) -> 3962.5 | G12: =(F7*'Control Panel'!$B$8)*(1/4) -> 3962.5 | H12: =(G7*'Control Panel'!$B$8)*(1/4) -> 3975 | I12: =(H7*'Control Panel'!$B$8)*(1/4) -> 3987.5 | J12: =(I7*'Control Panel'!$B$8)*(1/4) -> 4000 | K12: =(J7*'Control Panel'!$B$8)*(1/4) -> 4012.5 | ... N12: =(M7*'Control Panel'!$B$8)*(1/4) -> 4050 | O12: =SUM(B12:N12) -> 43900
A13: Revenue (1 Month Credit) | D13: =(C7*'Control Panel'!$B$9) -> 0 | E13: =(D7*'Control Panel'!$B$9) -> 0 | F13: =(E7*'Control Panel'!$B$9) -> 0 | G13: =(F7*'Control Panel'!$B$9) -> 0 | H13: =(G7*'Control Panel'!$B$9) -> 0 | I13: =(H7*'Control Panel'!$B$9) -> 0 | J13: =(I7*'Control Panel'!$B$9) -> 0 | K13: =(J7*'Control Panel'!$B$9) -> 0 | ... N13: =(M7*'Control Panel'!$B$9) -> 0 | O13: =SUM(B13:N13) -> 0
A14: Total Revenue Cash In | B14: =SUM(B10:B13) -> 0 | C14: =SUM(C10:C13) -> 11812.5 | D14: =SUM(D10:D13) -> 15787.5 | E14: =SUM(E10:E13) -> 15837.5 | F14: =SUM(F10:F13) -> 15850 | G14: =SUM(G10:G13) -> 15887.5 | H14: =SUM(H10:H13) -> 15937.5 | I14: =SUM(I10:I13) -> 15987.5 | ... O14: =SUM(O10:O13) -> 187825
A16: Investment Received | B16: ='Startup & Pre-Opening Costs'!B29 -> 185000 | O16: =SUM(B16:N16) -> 185000
A18: Cost of Revenue (this month) | C18: =(C7*'Control Panel'!$B$11)*(1-'Control Panel'!$B$13) -> 0 | D18: =(D7*'Control Panel'!$B$11)*(1-'Control Panel'!$B$13) -> 0 | E18: =(E7*'Control Panel'!$B$11)*(1-'Control Panel'!$B$13) -> 0 | F18: =(F7*'Control Panel'!$B$11)*(1-'Control Panel'!$B$13) -> 0 | G18: =(G7*'Control Panel'!$B$11)*(1-'Control Panel'!$B$13) -> 0 | H18: =(H7*'Control Panel'!$B$11)*(1-'Control Panel'!$B$13) -> 0 | I18: =(I7*'Control Panel'!$B$11)*(1-'Control Panel'!$B$13) -> 0 | J18: =(J7*'Control Panel'!$B$11)*(1-'Control Panel'!$B$13) -> 0 | ... N18: =(N7*'Control Panel'!$B$11)*(1-'Control Panel'!$B$13) -> 0 | O18: =SUM(B18:N18) -> 0
A19: Cost of Revenue (1 month supplier credit) | D19: =(C7*'Control Panel'!$B$11)*('Control Panel'!$B$13) -> 5512.5 | E19: =(D7*'Control Panel'!$B$11)*('Control Panel'!$B$13) -> 5530 | F19: =(E7*'Control Panel'!$B$11)*('Control Panel'!$B$13) -> 5547.5 | G19: =(F7*'Control Panel'!$B$11)*('Control Panel'!$B$13) -> 5547.5 | H19: =(G7*'Control Panel'!$B$11)*('Control Panel'!$B$13) -> 5565 | I19: =(H7*'Control Panel'!$B$11)*('Control Panel'!$B$13) -> 5582.5 | J19: =(I7*'Control Panel'!$B$11)*('Control Panel'!$B$13) -> 5600 | K19: =(J7*'Control Panel'!$B$11)*('Control Panel'!$B$13) -> 5617.5 | ... N19: =(M7*'Control Panel'!$B$11)*('Control Panel'!$B$13) -> 5670 | O19: =SUM(B19:N19) -> 61460
A20: Total Cost of Revenue Cash Out | B20: =SUM(B18:B19) -> 0 | C20: =SUM(C18:C19) -> 0 | D20: =SUM(D18:D19) -> 5512.5 | E20: =SUM(E18:E19) -> 5530 | F20: =SUM(F18:F19) -> 5547.5 | G20: =SUM(G18:G19) -> 5547.5 | H20: =SUM(H18:H19) -> 5565 | I20: =SUM(I18:I19) -> 5582.5 | ... O20: =SUM(O18:O19) -> 61460 | P20: Creditors | Q20: =(N7*'Control Panel'!$B$11)*('Control Panel'!$B$13) -> 5705
A22: Contracts, Terms, GPDR | B22: ='Startup & Pre-Opening Costs'!C2 -> 5000 | O22: =SUM(B22:N22) -> 5000
A23: Stationery, etc. | B23: ='Startup & Pre-Opening Costs'!C3 -> 0 | F23: =B23 -> 0 | G23: =C23 -> 0 | H23: =D23 -> 0 | I23: =E23 -> 0 | J23: =F23 -> 0 | K23: =G23 -> 0 | L23: =H23 -> 0 | M23: =I23 -> 0 | N23: =J23 -> 0 | O23: =SUM(B23:N23) -> 0
A24: Brochures | B24: ='Startup & Pre-Opening Costs'!C4 -> 0 | F24: =B24 -> 0 | G24: =C24 -> 0 | H24: =D24 -> 0 | I24: =E24 -> 0 | J24: =F24 -> 0 | K24: =G24 -> 0 | L24: =H24 -> 0 | M24: =I24 -> 0 | N24: =J24 -> 0 | O24: =SUM(B24:N24) -> 0
A25: Consultants | B25: ='Startup & Pre-Opening Costs'!C6 -> 0 | O25: =SUM(B25:N25) -> 0
A26: Insurance | B26: ='Startup & Pre-Opening Costs'!C6 -> 0 | C26: =B26 -> 0 | O26: =SUM(B26:N26) -> 0
A27: Rent | B27: ='Startup & Pre-Opening Costs'!C7 -> 0 | C27: =B27 -> 0 | D27: =C27 -> 0 | E27: =D27 -> 0 | F27: =E27 -> 0 | G27: =F27 -> 0 | H27: =G27 -> 0 | I27: =H27 -> 0 | J27: =I27 -> 0 | ... N27: =M27 -> 0 | O27: =SUM(B27:N27) -> 0
A28: R & D Design | B28: ='Startup & Pre-Opening Costs'!C8 -> 50000 | O28: =SUM(B28:N28) -> 50000
A29: R & D Maintenance | C29: ='Startup & Pre-Opening Costs'!C9 -> 0 | O29: =SUM(B29:N29) -> 0
A30: Staff | B30: ='Startup & Pre-Opening Costs'!C11 -> 0 | C30: =B30 -> 0 | D30: =C30 -> 0 | E30: =D30 -> 0 | F30: =E30 -> 0 | G30: =F30 -> 0 | H30: =G30 -> 0 | I30: =H30 -> 0 | J30: =I30 -> 0 | ... N30: =M30 -> 0 | O30: =SUM(B30:N30) -> 0
A31: Communications | B31: ='Startup & Pre-Opening Costs'!C13 -> 0 | C31: =B31 -> 0 | D31: =C31 -> 0 | E31: =D31 -> 0 | F31: =E31 -> 0 | G31: =F31 -> 0 | H31: =G31 -> 0 | I31: =H31 -> 0 | J31: =I31 -> 0 | ... N31: =M31 -> 0 | O31: =SUM(B31:N31) -> 0
A32: Incorporation Fees | B32: ='Startup & Pre-Opening Costs'!C15 -> 0 | O32: =SUM(B32:N32) -> 0
A33: Website Design | B33: ='Startup & Pre-Opening Costs'!C16 -> 0 | O33: =SUM(B33:N33) -> 0
A34: Website Maintenance | C34: ='Startup & Pre-Opening Costs'!C17 -> 0 | O34: =SUM(B34:N34) -> 0
A35: Travel | B35: ='Startup & Pre-Opening Costs'!C18 -> 0 | C35: =B35 -> 0 | D35: =C35 -> 0 | E35: =D35 -> 0 | F35: =E35 -> 0 | G35: =F35 -> 0 | H35: =G35 -> 0 | I35: =H35 -> 0 | J35: =I35 -> 0 | ... N35: =M35 -> 0 | O35: =SUM(B35:N35) -> 0
A36: Vehicle Rental | B36: ='Startup & Pre-Opening Costs'!C20 -> 0 | C36: =B36 -> 0 | D36: =C36 -> 0 | E36: =D36 -> 0 | F36: =E36 -> 0 | G36: =F36 -> 0 | H36: =G36 -> 0 | I36: =H36 -> 0 | J36: =I36 -> 0 | ... N36: =M36 -> 0 | O36: =SUM(B36:N36) -> 0
A37: Marketing | B37: ='Startup & Pre-Opening Costs'!C21 -> 50000 | C37: 5000 | D37: =C37 -> 5000 | E37: =D37 -> 5000 | F37: =E37 -> 5000 | G37: =F37 -> 5000 | H37: =G37 -> 5000 | I37: =H37 -> 5000 | J37: =I37 -> 5000 | K37: =J37 -> 5000 | ... N37: =M37 -> 5000 | O37: =SUM(B37:N37) -> 110000
A38: Total Expenses Cash Out | B38: =SUM(B22:B37) -> 105000 | C38: =SUM(C22:C37) -> 5000 | D38: =SUM(D22:D37) -> 5000 | E38: =SUM(E22:E37) -> 5000 | F38: =SUM(F22:F37) -> 5000 | G38: =SUM(G22:G37) -> 5000 | H38: =SUM(H22:H37) -> 5000 | I38: =SUM(I22:I37) -> 5000 | ... O38: =SUM(O22:O37) -> 165000
A40: Computer Equpment | B40: ='Startup & Pre-Opening Costs'!B10 -> 10000 | O40: =SUM(B40:N40) -> 10000
A41: Communications | B41: ='Startup & Pre-Opening Costs'!B12 -> 0 | O41: =SUM(B41:N41) -> 0
A42: Furniture | B42: ='Startup & Pre-Opening Costs'!B14 -> 0 | O42: =SUM(B42:N42) -> 0
A43: Buildings | B43: ='Startup & Pre-Opening Costs'!B19 -> 0 | O43: =SUM(B43:N43) -> 0
A44: Total Assets Cash Out | B44: =SUM(B40:B43) -> 10000 | C44: =SUM(C40:C43) -> 0 | D44: =SUM(D40:D43) -> 0 | E44: =SUM(E40:E43) -> 0 | F44: =SUM(F40:F43) -> 0 | G44: =SUM(G40:G43) -> 0 | H44: =SUM(H40:H43) -> 0 | I44: =SUM(I40:I43) -> 0 | ... O44: =SUM(O40:O43) -> 10000
A46: Closing Cash | B46: =B9+B14-B20-B38-B44+B16 -> 70000 | C46: =C9+C14-C20-C38-C44+C16 -> 76812.5 | D46: =D9+D14-D20-D38-D44+D16 -> 82087.5 | E46: =E9+E14-E20-E38-E44+E16 -> 87395 | F46: =F9+F14-F20-F38-F44+F16 -> 92697.5 | G46: =G9+G14-G20-G38-G44+G16 -> 98037.5 | H46: =H9+H14-H20-H38-H44+H16 -> 103410 | I46: =I9+I14-I20-I38-I44+I16 -> 108815 | ... N46: =N9+N14-N20-N38-N44+N16 -> 136365
...

Sheet Financial Statements
A1: Income Statement
B2: 1 | C2: 2 | D2: 3 | E2: 4 | F2: 5
A3: Revenue | B3: ='Year 1 Cash Budget'!O7 -> 191900 | C3: ='Year 2 Cash Budget'!N7 -> 201450 | D3: ='Year 3 Cash Budget'!N7 -> 218500 | E3: ='Year 4 Cash Budget'!N7 -> 249200 | F3: ='Year 5 Cash Budget'!N7 -> 304250
A5: Cost of Revenue | B5: ='Control Panel'!$B$11*B3 -> 67165 | C5: ='Control Panel'!$B$11*C3 -> 70507.5 | D5: ='Control Panel'!$B$11*D3 -> 76475 | E5: ='Control Panel'!$B$11*E3 -> 87220 | F5: ='Control Panel'!$B$11*F3 -> 106487.5
A7: Gross Profit | B7: =B3-B5 -> 124735 | C7: =C3-C5 -> 130942.5 | D7: =D3-D5 -> 142025 | E7: =E3-E5 -> 161980 | F7: =F3-F5 -> 197762.5
A9: Expenses | B9: ='Year 1 Cash Budget'!O38 -> 165000 | C9: ='Year 2 Cash Budget'!N38 -> 60000 | D9: ='Year 3 Cash Budget'!N38 -> 60000 | E9: ='Year 4 Cash Budget'!N38 -> 60000 | F9: ='Year 5 Cash Budget'!N38 -> 60000
A11: Founder Profit Share | B11: =IF(B7-B9<=0,0,'Control Panel'!$B$16*(B7-B9)) -> 0 | C11: =IF(C7-C9<=0,0,'Control Panel'!$B$16*(C7-C9)) -> 14188.5 | D11: =IF(D7-D9<=0,0,'Control Panel'!$B$16*(D7-D9)) -> 16405 | E11: =IF(E7-E9<=0,0,'Control Panel'!$B$16*(E7-E9)) -> 20396 | F11: =IF(F7-F9<=0,0,'Control Panel'!$B$16*(F7-F9)) -> 27552.5
A13: Net Profit | B13: =B7-B9-B11 -> -40265 | C13: =C7-C9-C11 -> 56754 | D13: =D7-D9-D11 -> 65620 | E13: =E7-E9-E11 -> 81584 | F13: =F7-F9-F11 -> 110210
A15: Balance Sheet
B16: 1 | C16: 2 | D16: 3 | E16: 4 | F16: 5
A17: Assets | B17: ='Year 1 Cash Budget'!O44 -> 10000 | C17: ='Year 2 Cash Budget'!O44+B17 -> 10000 | D17: ='Year 3 Cash Budget'!O44+C17 -> 10000 | E17: ='Year 4 Cash Budget'!O44+D17 -> 10000 | F17: ='Year 5 Cash Budget'!O44+E17 -> 10000
A19: Cash | B19: ='Year 1 Cash Budget'!N46-B11 -> 136365 | C19: ='Year 2 Cash Budget'!M46-C11 -> 193219 | D19: ='Year 3 Cash Budget'!M46-D11 -> 259024 | E19: ='Year 4 Cash Budget'!M46-E11 -> 340938 | F19: ='Year 5 Cash Budget'!M46-F11 -> 451738
A20: Debtors | B20: ='Year 1 Cash Budget'!Q7 -> 4075 | C20: ='Year 2 Cash Budget'!P7 -> 4325 | D20: ='Year 3 Cash Budget'!P7 -> 4787.5 | E20: ='Year 4 Cash Budget'!P7 -> 5612.5 | F20: ='Year 5 Cash Budget'!P7 -> 7087.5
A22: Creditors | B22: ='Year 1 Cash Budget'!Q20 -> 5705 | C22: ='Year 2 Cash Budget'!P20 -> 6055 | D22: ='Year 3 Cash Budget'!P20 -> 6702.5 | E22: ='Year 4 Cash Budget'!P20 -> 7857.5 | F22: ='Year 5 Cash Budget'!P20 -> 9922.5
A24: Net Worth | B24: =B17+B19+B20-B22 -> 144735 | C24: =C17+C19+C20-C22 -> 201489 | D24: =D17+D19+D20-D22 -> 267109 | E24: =E17+E19+E20-E22 -> 348693 | F24: =F17+F19+F20-F22 -> 458903
A26: Profit | B26: =B13 -> -40265 | C26: =C13 -> 56754 | D26: =D13 -> 65620 | E26: =E13 -> 81584 | F26: =F13 -> 110210
A27: Retained Profit | B27: 0 | C27: =SUM(B26:B27) -> -40265 | D27: =SUM(C26:C27) -> 16489 | E27: =SUM(D26:D27) -> 82109 | F27: =SUM(E26:E27) -> 163693
A28: Investment | B28: ='Year 1 Cash Budget'!O16 -> 185000 | C28: ='Year 2 Cash Budget'!P16+B28 -> 185000 | D28: ='Year 3 Cash Budget'!P16+C28 -> 185000 | E28: ='Year 4 Cash Budget'!P16+D28 -> 185000 | F28: ='Year 5 Cash Budget'!P16+E28 -> 185000
A29: Net Worth | B29: =SUM(B26:B28) -> 144735 | C29: =SUM(C26:C28) -> 201489 | D29: =SUM(D26:D28) -> 267109 | E29: =SUM(E26:E28) -> 348693 | F29: =SUM(F26:F28) -> 458903
A31: Company Worth > Investment | B31: =IF(B24>=B28,"Yes","No") -> No | C31: =IF(AND(C24>=C28,B24<B28),"Yes","No") -> Yes | D31: =IF(AND(D24>=D28,C24<C28),"Yes","No") -> No | E31: =IF(AND(E24>=E28,D24<D28),"Yes","No") -> No | F31: =IF(AND(F24>=F28,E24<E28),"Yes","No") -> No
A32: Investor Return | B32: =B28*'Control Panel'!$B$15 -> 22200 | C32: =B32+(C28*'Control Panel'!$B$15) -> 44400 | D32: =C32+(D28*'Control Panel'!$B$15) -> 66600 | E32: =D32+(E28*'Control Panel'!$B$15) -> 88800 | F32: =E32+(F28*'Control Panel'!$B$15) -> 111000
A33: Investor Buyout | B33: =IF(B35<B19,"Yes","No") -> No | C33: =IF(AND(C35<C19,B35<B19),"Yes","No") -> No | D33: =IF(AND(D35<D19,C35<C19),"Yes","No") -> No | E33: =IF(AND(E35<E19,D35<D19),"Yes","No") -> Yes | F33: =IF(AND(F35<F19,E35<E19),"Yes","No") -> Yes
B34: ='Performance Dashboard'!B1 -> Year 1 | C34: ='Performance Dashboard'!C1 -> Year 2 | D34: ='Performance Dashboard'!D1 -> Year 3 | E34: ='Performance Dashboard'!E1 -> Year 4 | F34: ='Performance Dashboard'!F1 -> Year 5
A35: Investor Buyout Cost | B35: =B32+B28 -> 207200 | C35: =C32+C28 -> 229400 | D35: =D32+D28 -> 251600 | E35: =E32+E28 -> 273800 | F35: =F32+F28 -> 296000

Sheet Year 2 Cash Budget
B1: Month 13 | C1: Month 14 | D1: Month 15 | E1: Month 16 | F1: Month 17 | G1: Month 18 | H1: Month 19 | I1: Month 20 | J1: Month 21 | K1: Month 22 | L1: Month 23 | M1: Month 24 | N1: Year 2
A2: Revenue Calculations
A3: Average Sale | B3: ='Control Panel'!$B$1 -> 50 | C3: =B3 -> 50 | D3: =C3 -> 50 | E3: =D3 -> 50 | F3: =E3 -> 50 | G3: =F3 -> 50 | H3: =G3 -> 50 | I3: =H3 -> 50 | J3: =I3 -> 50 | ... M3: =L3 -> 50
A4: Customers | B4: =ROUND((('Control Panel'!$B$2*(B5+1))*B6),0) -> 327 | C4: =ROUND((('Control Panel'!$B$2*(C5+1))*C6),0) -> 328 | D4: =ROUND((('Control Panel'!$B$2*(D5+1))*D6),0) -> 330 | E4: =ROUND((('Control Panel'!$B$2*(E5+1))*E6),0) -> 331 | F4: =ROUND((('Control Panel'!$B$2*(F5+1))*F6),0) -> 333 | G4: =ROUND((('Control Panel'!$B$2*(G5+1))*G6),0) -> 334 | H4: =ROUND((('Control Panel'!$B$2*(H5+1))*H6),0) -> 336 | I4: =ROUND((('Control Panel'!$B$2*(I5+1))*I6),0) -> 338 | ... M4: =ROUND((('Control Panel'!$B$2*(M5+1))*M6),0) -> 346 | N4: =SUM(B4:M4) -> 4029
A5: Customer Growth Factor | B5: ='Year 1 Cash Budget'!N5*(1+'Control Panel'!$B$4) -> 0.089792816 | C5: =B5*(1+'Control Panel'!$B$4) -> 0.094282457 | D5: =C5*1.05 -> 0.09899658 | E5: =D5*1.05 -> 0.10394641 | F5: =E5*1.05 -> 0.10914373 | G5: =F5*1.05 -> 0.11460092 | H5: =G5*1.05 -> 0.12033096 | I5: =H5*1.05 -> 0.12634751 | J5: =I5*1.05 -> 0.13266489 | K5: =J5*1.05 -> 0.13929813 | ... M5: =L5*1.05 -> 0.15357619
A6: Seasonality Index | B6: ='Year 1 Cash Budget'!C6 -> 1 | C6: ='Year 1 Cash Budget'!D6 -> 1 | D6: ='Year 1 Cash Budget'!E6 -> 1 | E6: ='Year 1 Cash Budget'!F6 -> 1 | F6: ='Year 1 Cash Budget'!G6 -> 1 | G6: ='Year 1 Cash Budget'!H6 -> 1 | H6: ='Year 1 Cash Budget'!I6 -> 1 | I6: ='Year 1 Cash Budget'!J6 -> 1 | ... M6: ='Year 1 Cash Budget'!N6 -> 1
A7: Revenue | B7: =B3*B4 -> 16350 | C7: =C3*C4 -> 16400 | D7: =D3*D4 -> 16500 | E7: =E3*E4 -> 16550 | F7: =F3*F4 -> 16650 | G7: =G3*G4 -> 16700 | H7: =H3*H4 -> 16800 | I7: =I3*I4 -> 16900 | ... M7: =M3*M4 -> 17300 | N7: =SUM(B7:M7) -> 201450 | O7: Debtors | P7: =(M7*'Control Panel'!$B$8)*(1/4)+(M7*'Control Panel'!$B$9) -> 4325
A9: Opening Cash | B9: ='Financial Statements'!B19 -> 136365 | C9: =B46 -> 141997.5 | D9: =C46 -> 147662.5 | E9: =D46 -> 153397.5 | F9: =E46 -> 159160 | G9: =F46 -> 164992.5 | H9: =G46 -> 170852.5 | I9: =H46 -> 176782.5 | J9: =I46 -> 182777.5 | ... M9: =L46 -> 201152.5
A10: Revenue (this month) | B10: =B7*'Control Panel'!$B$7 -> 0 | C10: =C7*'Control Panel'!$B$7 -> 0 | D10: =D7*'Control Panel'!$B$7 -> 0 | E10: =E7*'Control Panel'!$B$7 -> 0 | F10: =F7*'Control Panel'!$B$7 -> 0 | G10: =G7*'Control Panel'!$B$7 -> 0 | H10: =H7*'Control Panel'!$B$7 -> 0 | I10: =I7*'Control Panel'!$B$7 -> 0 | ... M10: =M7*'Control Panel'!$B$7 -> 0 | N10: =SUM(B10:M10) -> 0
A11: Revenue (1 Week Credit) (this month) | B11: =(B7*'Control Panel'!$B$8)*(3/4) -> 12262.5 | C11: =(C7*'Control Panel'!$B$8)*(3/4) -> 12300 | D11: =(D7*'Control Panel'!$B$8)*(3/4) -> 12375 | E11: =(E7*'Control Panel'!$B$8)*(3/4) -> 12412.5 | F11: =(F7*'Control Panel'!$B$8)*(3/4) -> 12487.5 | G11: =(G7*'Control Panel'!$B$8)*(3/4) -> 12525 | H11: =(H7*'Control Panel'!$B$8)*(3/4) -> 12600 | I11: =(I7*'Control Panel'!$B$8)*(3/4) -> 12675 | ... M11: =(M7*'Control Panel'!$B$8)*(3/4) -> 12975 | N11: =SUM(B11:M11) -> 151087.5
A12: Revenue (1 Week Credit) (last month) | B12: =('Year 1 Cash Budget'!N7*'Control Panel'!$B$8)*(1/4) -> 4075 | C12: =(B7*'Control Panel'!$B$8)*(1/4) -> 4087.5 | D12: =(C7*'Control Panel'!$B$8)*(1/4) -> 4100 | E12: =(D7*'Control Panel'!$B$8)*(1/4) -> 4125 | F12: =(E7*'Control Panel'!$B$8)*(1/4) -> 4137.5 | G12: =(F7*'Control Panel'!$B$8)*(1/4) -> 4162.5 | H12: =(G7*'Control Panel'!$B$8)*(1/4) -> 4175 | I12: =(H7*'Control Panel'!$B$8)*(1/4) -> 4200 | J12: =(I7*'Control Panel'!$B$8)*(1/4) -> 4225 | ... M12: =(L7*'Control Panel'!$B$8)*(1/4) -> 4300 | N12: =SUM(B12:M12) -> 50112.5
A13: Revenue (1 Month Credit) | B13: =('Year 1 Cash Budget'!N7*'Control Panel'!$B$9) -> 0 | C13: =(B7*'Control Panel'!$B$9) -> 0 | D13: =(C7*'Control Panel'!$B$9) -> 0 | E13: =(D7*'Control Panel'!$B$9) -> 0 | F13: =(E7*'Control Panel'!$B$9) -> 0 | G13: =(F7*'Control Panel'!$B$9) -> 0 | H13: =(G7*'Control Panel'!$B$9) -> 0 | I13: =(H7*'Control Panel'!$B$9) -> 0 | J13: =(I7*'Control Panel'!$B$9) -> 0 | ... M13: =(L7*'Control Panel'!$B$9) -> 0 | N13: =SUM(B13:M13) -> 0
A14: Total Revenue Cash In | B14: =SUM(B10:B13) -> 16337.5 | C14: =SUM(C10:C13) -> 16387.5 | D14: =SUM(D10:D13) -> 16475 | E14: =SUM(E10:E13) -> 16537.5 | F14: =SUM(F10:F13) -> 16625 | G14: =SUM(G10:G13) -> 16687.5 | H14: =SUM(H10:H13) -> 16775 | I14: =SUM(I10:I13) -> 16875 | ... N14: =SUM(N10:N13) -> 201200
A16: Investment Received | N16: =SUM(B16:M16) -> 0
A18: Cost of Revenue (this month) | B18: =(B7*'Control Panel'!$B$11)*(1-'Control Panel'!$B$13) -> 0 | C18: =(C7*'Control Panel'!$B$11)*(1-'Control Panel'!$B$13) -> 0 | D18: =(D7*'Control Panel'!$B$11)*(1-'Control Panel'!$B$13) -> 0 | E18: =(E7*'Control Panel'!$B$11)*(1-'Control Panel'!$B$13) -> 0 | F18: =(F7*'Control Panel'!$B$11)*(1-'Control Panel'!$B$13) -> 0 | G18: =(G7*'Control Panel'!$B$11)*(1-'Control Panel'!$B$13) -> 0 | H18: =(H7*'Control Panel'!$B$11)*(1-'Control Panel'!$B$13) -> 0 | I18: =(I7*'Control Panel'!$B$11)*(1-'Control Panel'!$B$13) -> 0 | ... M18: =(M7*'Control Panel'!$B$11)*(1-'Control Panel'!$B$13) -> 0 | N18: =SUM(B18:M18) -> 0
A19: Cost of Revenue (1 month supplier credit) | B19: =('Year 1 Cash Budget'!N7*'Control Panel'!$B$11)*('Control Panel'!$B$13) -> 5705 | C19: =(B7*'Control Panel'!$B$11)*('Control Panel'!$B$13) -> 5722.5 | D19: =(C7*'Control Panel'!$B$11)*('Control Panel'!$B$13) -> 5740 | E19: =(D7*'Control Panel'!$B$11)*('Control Panel'!$B$13) -> 5775 | F19: =(E7*'Control Panel'!$B$11)*('Control Panel'!$B$13) -> 5792.5 | G19: =(F7*'Control Panel'!$B$11)*('Control Panel'!$B$13) -> 5827.5 | H19: =(G7*'Control Panel'!$B$11)*('Control Panel'!$B$13) -> 5845 | I19: =(H7*'Control Panel'!$B$11)*('Control Panel'!$B$13) -> 5880 | J19: =(I7*'Control Panel'!$B$11)*('Control Panel'!$B$13) -> 5915 | ... M19: =(L7*'Control Panel'!$B$11)*('Control Panel'!$B$13) -> 6020 | N19: =SUM(B19:M19) -> 70157.5
A20: Total Cost of Revenue Cash Out | B20: =SUM(B18:B19) -> 5705 | C20: =SUM(C18:C19) -> 5722.5 | D20: =SUM(D18:D19) -> 5740 | E20: =SUM(E18:E19) -> 5775 | F20: =SUM(F18:F19) -> 5792.5 | G20: =SUM(G18:G19) -> 5827.5 | H20: =SUM(H18:H19) -> 5845 | I20: =SUM(I18:I19) -> 5880 | ... N20: =SUM(N18:N19) -> 70157.5 | O20: Creditors | P20: =(M7*'Control Panel'!$B$11)*('Control Panel'!$B$13) -> 6055
A22: Contracts, Terms, GPDR | B22: ='Year 1 Cash Budget'!C22 -> 0 | C22: ='Year 1 Cash Budget'!D22 -> 0 | D22: ='Year 1 Cash Budget'!E22 -> 0 | E22: ='Year 1 Cash Budget'!F22 -> 0 | F22: ='Year 1 Cash Budget'!G22 -> 0 | G22: ='Year 1 Cash Budget'!H22 -> 0 | H22: ='Year 1 Cash Budget'!I22 -> 0 | I22: ='Year 1 Cash Budget'!J22 -> 0 | ... M22: ='Year 1 Cash Budget'!N22 -> 0 | N22: =SUM(B22:M22) -> 0
A23: Stationery, etc. | B23: ='Year 1 Cash Budget'!C23 -> 0 | C23: ='Year 1 Cash Budget'!D23 -> 0 | D23: ='Year 1 Cash Budget'!E23 -> 0 | E23: ='Year 1 Cash Budget'!F23 -> 0 | F23: ='Year 1 Cash Budget'!G23 -> 0 | G23: ='Year 1 Cash Budget'!H23 -> 0 | H23: ='Year 1 Cash Budget'!I23 -> 0 | I23: ='Year 1 Cash Budget'!J23 -> 0 | ... M23: ='Year 1 Cash Budget'!N23 -> 0 | N23: =SUM(B23:M23) -> 0
A24: Brochures | B24: ='Year 1 Cash Budget'!C24 -> 0 | C24: ='Year 1 Cash Budget'!D24 -> 0 | D24: ='Year 1 Cash Budget'!E24 -> 0 | E24: ='Year 1 Cash Budget'!F24 -> 0 | F24: ='Year 1 Cash Budget'!G24 -> 0 | G24: ='Year 1 Cash Budget'!H24 -> 0 | H24: ='Year 1 Cash Budget'!I24 -> 0 | I24: ='Year 1 Cash Budget'!J24 -> 0 | ... M24: ='Year 1 Cash Budget'!N24 -> 0 | N24: =SUM(B24:M24) -> 0
A25: Consultants | B25: ='Year 1 Cash Budget'!C25 -> 0 | C25: ='Year 1 Cash Budget'!D25 -> 0 | D25: ='Year 1 Cash Budget'!E25 -> 0 | E25: ='Year 1 Cash Budget'!F25 -> 0 | F25: ='Year 1 Cash Budget'!G25 -> 0 | G25: ='Year 1 Cash Budget'!H25 -> 0 | H25: ='Year 1 Cash Budget'!I25 -> 0 | I25: ='Year 1 Cash Budget'!J25 -> 0 | ... M25: ='Year 1 Cash Budget'!N25 -> 0 | N25: =SUM(B25:M25) -> 0
A26: Insurance | B26: ='Year 1 Cash Budget'!C26 -> 0 | C26: ='Year 1 Cash Budget'!D26 -> 0 | D26: ='Year 1 Cash Budget'!E26 -> 0 | E26: ='Year 1 Cash Budget'!F26 -> 0 | F26: ='Year 1 Cash Budget'!G26 -> 0 | G26: ='Year 1 Cash Budget'!H26 -> 0 | H26: ='Year 1 Cash Budget'!I26 -> 0 | I26: ='Year 1 Cash Budget'!J26 -> 0 | ... M26: ='Year 1 Cash Budget'!N26 -> 0 | N26: =SUM(B26:M26) -> 0
A27: Rent | B27: ='Year 1 Cash Budget'!C27 -> 0 | C27: ='Year 1 Cash Budget'!D27 -> 0 | D27: ='Year 1 Cash Budget'!E27 -> 0 | E27: ='Year 1 Cash Budget'!F27 -> 0 | F27: ='Year 1 Cash Budget'!G27 -> 0 | G27: ='Year 1 Cash Budget'!H27 -> 0 | H27: ='Year 1 Cash Budget'!I27 -> 0 | I27: ='Year 1 Cash Budget'!J27 -> 0 | ... M27: ='Year 1 Cash Budget'!N27 -> 0 | N27: =SUM(B27:M27) -> 0
A28: R & D Design | B28: ='Year 1 Cash Budget'!C28 -> 0 | C28: ='Year 1 Cash Budget'!D28 -> 0 | D28: ='Year 1 Cash Budget'!E28 -> 0 | E28: ='Year 1 Cash Budget'!F28 -> 0 | F28: ='Year 1 Cash Budget'!G28 -> 0 | G28: ='Year 1 Cash Budget'!H28 -> 0 | H28: ='Year 1 Cash Budget'!I28 -> 0 | I28: ='Year 1 Cash Budget'!J28 -> 0 | ... M28: ='Year 1 Cash Budget'!N28 -> 0 | N28: =SUM(B28:M28) -> 0
A29: R & D Maintenance | B29: ='Year 1 Cash Budget'!C29 -> 0 | C29: ='Year 1 Cash Budget'!D29 -> 0 | D29: ='Year 1 Cash Budget'!E29 -> 0 | E29: ='Year 1 Cash Budget'!F29 -> 0 | F29: ='Year 1 Cash Budget'!G29 -> 0 | G29: ='Year 1 Cash Budget'!H29 -> 0 | H29: ='Year 1 Cash Budget'!I29 -> 0 | I29: ='Year 1 Cash Budget'!J29 -> 0 | ... M29: ='Year 1 Cash Budget'!N29 -> 0 | N29: =SUM(B29:M29) -> 0
A30: Staff | B30: ='Year 1 Cash Budget'!C30 -> 0 | C30: ='Year 1 Cash Budget'!D30 -> 0 | D30: ='Year 1 Cash Budget'!E30 -> 0 | E30: ='Year 1 Cash Budget'!F30 -> 0 | F30: ='Year 1 Cash Budget'!G30 -> 0 | G30: ='Year 1 Cash Budget'!H30 -> 0 | H30: ='Year 1 Cash Budget'!I30 -> 0 | I30: ='Year 1 Cash Budget'!J30 -> 0 | ... M30: ='Year 1 Cash Budget'!N30 -> 0 | N30: =SUM(B30:M30) -> 0
A31: Communications | B31: ='Year 1 Cash Budget'!C31 -> 0 | C31: ='Year 1 Cash Budget'!D31 -> 0 | D31: ='Year 1 Cash Budget'!E31 -> 0 | E31: ='Year 1 Cash Budget'!F31 -> 0 | F31: ='Year 1 Cash Budget'!G31 -> 0 | G31: ='Year 1 Cash Budget'!H31 -> 0 | H31: ='Year 1 Cash Budget'!I31 -> 0 | I31: ='Year 1 Cash Budget'!J31 -> 0 | ... M31: ='Year 1 Cash Budget'!N31 -> 0 | N31: =SUM(B31:M31) -> 0
A32: Incorporation Fees | B32: ='Year 1 Cash Budget'!C32 -> 0 | C32: ='Year 1 Cash Budget'!D32 -> 0 | D32: ='Year 1 Cash Budget'!E32 -> 0 | E32: ='Year 1 Cash Budget'!F32 -> 0 | F32: ='Year 1 Cash Budget'!G32 -> 0 | G32: ='Year 1 Cash Budget'!H32 -> 0 | H32: ='Year 1 Cash Budget'!I32 -> 0 | I32: ='Year 1 Cash Budget'!J32 -> 0 | ... M32: ='Year 1 Cash Budget'!N32 -> 0 | N32: =SUM(B32:M32) -> 0
A33: Website Design | B33: ='Year 1 Cash Budget'!C33 -> 0 | C33: ='Year 1 Cash Budget'!D33 -> 0 | D33: ='Year 1 Cash Budget'!E33 -> 0 | E33: ='Year 1 Cash Budget'!F33 -> 0 | F33: ='Year 1 Cash Budget'!G33 -> 0 | G33: ='Year 1 Cash Budget'!H33 -> 0 | H33: ='Year 1 Cash Budget'!I33 -> 0 | I33: ='Year 1 Cash Budget'!J33 -> 0 | ... M33: ='Year 1 Cash Budget'!N33 -> 0 | N33: =SUM(B33:M33) -> 0
... A37: Marketing | B37: ='Year 1 Cash Budget'!C37 -> 5000 | C37: ='Year 1 Cash Budget'!D37 -> 5000 | D37: ='Year 1 Cash Budget'!E37 -> 5000 | E37: ='Year 1 Cash Budget'!F37 -> 5000 | F37: ='Year 1 Cash Budget'!G37 -> 5000 | G37: ='Year 1 Cash Budget'!H37 -> 5000 | H37: ='Year 1 Cash Budget'!I37 -> 5000 | I37: ='Year 1 Cash Budget'!J37 -> 5000 | ... M37: ='Year 1 Cash Budget'!N37 -> 5000 | N37: =SUM(B37:M37) -> 60000
A38: Total Expenses Cash Out | B38: =SUM(B22:B37) -> 5000 | C38: =SUM(C22:C37) -> 5000 | D38: =SUM(D22:D37) -> 5000 | E38: =SUM(E22:E37) -> 5000 | F38: =SUM(F22:F37) -> 5000 | G38: =SUM(G22:G37) -> 5000 | H38: =SUM(H22:H37) -> 5000 | I38: =SUM(I22:I37) -> 5000 | ... N38: =SUM(N22:N37) -> 60000
A40: Computer Equpment | N40: =SUM(B40:M40) -> 0
A41: Communications | N41: =SUM(B41:M41) -> 0
A42: Furniture | N42: =SUM(B42:M42) -> 0
A43: Buildings | N43: =SUM(B43:M43) -> 0
A44: Total Assets Cash Out | B44: =SUM(B40:B43) -> 0 | C44: =SUM(C40:C43) -> 0 | D44: =SUM(D40:D43) -> 0 | E44: =SUM(E40:E43) -> 0 | F44: =SUM(F40:F43) -> 0 | G44: =SUM(G40:G43) -> 0 | H44: =SUM(H40:H43) -> 0 | I44: =SUM(I40:I43) -> 0 | ... N44: =SUM(N40:N43) -> 0
A46: Closing Cash | B46: =B9+B14-B20-B38-B44+B16 -> 141997.5 | C46: =C9+C14-C20-C38-C44+C16 -> 147662.5 | D46: =D9+D14-D20-D38-D44+D16 -> 153397.5 | E46: =E9+E14-E20-E38-E44+E16 -> 159160 | F46: =F9+F14-F20-F38-F44+F16 -> 164992.5 | G46: =G9+G14-G20-G38-G44+G16 -> 170852.5 | H46: =H9+H14-H20-H38-H44+H16 -> 176782.5 | I46: =I9+I14-I20-I38-I44+I16 -> 182777.5 | ... M46: =M9+M14-M20-M38-M44+M16 -> 207407.5
A49: Revenue | B49: =B7 -> 16350 | C49: =C7 -> 16400 | D49: =D7 -> 16500 | E49: =E7 -> 16550 | F49: =F7 -> 16650 | G49: =G7 -> 16700 | H49: =H7 -> 16800 | I49: =I7 -> 16900 | ... M49: =M7 -> 17300
A51: Cost of Revenue | B51: =B49*'Control Panel'!$B$11 -> 5722.5 | C51: =C49*'Control Panel'!$B$11 -> 5740 | D51: =D49*'Control Panel'!$B$11 -> 5775 | E51: =E49*'Control Panel'!$B$11 -> 5792.5 | F51: =F49*'Control Panel'!$B$11 -> 5827.5 | G51: =G49*'Control Panel'!$B$11 -> 5845 | H51: =H49*'Control Panel'!$B$11 -> 5880 | I51: =I49*'Control Panel'!$B$11 -> 5915 | ... M51: =M49*'Control Panel'!$B$11 -> 6055
A53: Gross Profit | B53: =B49-B51 -> 10627.5 | C53: =C49-C51 -> 10660 | D53: =D49-D51 -> 10725 | E53: =E49-E51 -> 10757.5 | F53: =F49-F51 -> 10822.5 | G53: =G49-G51 -> 10855 | H53: =H49-H51 -> 10920 | I53: =I49-I51 -> 10985 | ... M53: =M49-M51 -> 11245
...

Sheet Year 3 Cash Budget
B1: Month 25 | C1: Month 26 | D1: Month 27 | E1: Month 28 | F1: Month 29 | G1: Month 30 | H1: Month 31 | I1: Month 32 | J1: Month 33 | K1: Month 34 | L1: Month 35 | M1: Month 36 | N1: Year 3
A2: Revenue Calculations
A3: Average Sale | B3: ='Control Panel'!$B$1 -> 50 | C3: =B3 -> 50 | D3: =C3 -> 50 | E3: =D3 -> 50 | F3: =E3 -> 50 | G3: =F3 -> 50 | H3: =G3 -> 50 | I3: =H3 -> 50 | J3: =I3 -> 50 | ... M3: =L3 -> 50
A4: Customers | B4: =ROUND((('Control Panel'!$B$2*(B5+1))*B6),0) -> 348 | C4: =ROUND((('Control Panel'!$B$2*(C5+1))*C6),0) -> 351 | D4: =ROUND((('Control Panel'!$B$2*(D5+1))*D6),0) -> 353 | E4: =ROUND((('Control Panel'!$B$2*(E5+1))*E6),0) -> 356 | F4: =ROUND((('Control Panel'!$B$2*(F5+1))*F6),0) -> 359 | G4: =ROUND((('Control Panel'!$B$2*(G5+1))*G6),0) -> 362 | H4: =ROUND((('Control Panel'!$B$2*(H5+1))*H6),0) -> 365 | I4: =ROUND((('Control Panel'!$B$2*(I5+1))*I6),0) -> 368 | ... M4: =ROUND((('Control Panel'!$B$2*(M5+1))*M6),0) -> 383 | N4: =SUM(B4:M4) -> 4370
A5: Customer Growth Factor | B5: ='Year 2 Cash Budget'!M5*(1+'Control Panel'!$B$4) -> 0.161255 | C5: =B5*(1+'Control Panel'!$B$4) -> 0.16931775 | D5: =C5*(1+'Control Panel'!$B$4) -> 0.17778363 | E5: =D5*(1+'Control Panel'!$B$4) -> 0.18667282 | F5: =E5*(1+'Control Panel'!$B$4) -> 0.19600646 | G5: =F5*(1+'Control Panel'!$B$4) -> 0.20580678 | H5: =G5*(1+'Control Panel'!$B$4) -> 0.21609712 | I5: =H5*(1+'Control Panel'!$B$4) -> 0.22690197 | J5: =I5*(1+'Control Panel'!$B$4) -> 0.23824707 | ... M5: =L5*(1+'Control Panel'!$B$4) -> 0.27580077
A6: Seasonality Index | B6: ='Year 2 Cash Budget'!B6 -> 1 | C6: ='Year 2 Cash Budget'!C6 -> 1 | D6: ='Year 2 Cash Budget'!D6 -> 1 | E6: ='Year 2 Cash Budget'!E6 -> 1 | F6: ='Year 2 Cash Budget'!F6 -> 1 | G6: ='Year 2 Cash Budget'!G6 -> 1 | H6: ='Year 2 Cash Budget'!H6 -> 1 | I6: ='Year 2 Cash Budget'!I6 -> 1 | ... M6: ='Year 2 Cash Budget'!M6 -> 1
A7: Revenue | B7: =B3*B4 -> 17400 | C7: =C3*C4 -> 17550 | D7: =D3*D4 -> 17650 | E7: =E3*E4 -> 17800 | F7: =F3*F4 -> 17950 | G7: =G3*G4 -> 18100 | H7: =H3*H4 -> 18250 | I7: =I3*I4 -> 18400 | ... M7: =M3*M4 -> 19150 | N7: =SUM(B7:M7) -> 218500 | O7: Debtors | P7: =(M7*'Control Panel'!$B$8)*(1/4)+(M7*'Control Panel'!$B$9) -> 4787.5
A9: Opening Cash | B9: ='Financial Statements'!C19 -> 193219 | C9: =B46 -> 199539 | D9: =C46 -> 205961.5 | E9: =D46 -> 212444 | F9: =E46 -> 219029 | G9: =F46 -> 225711.5 | H9: =G46 -> 232491.5 | I9: =H46 -> 239369 | J9: =I46 -> 246344 | ... M9: =L46 -> 267961.5
A10: Revenue (this month) | B10: =B7*'Control Panel'!$B$7 -> 0 | C10: =C7*'Control Panel'!$B$7 -> 0 | D10: =D7*'Control Panel'!$B$7 -> 0 | E10: =E7*'Control Panel'!$B$7 -> 0 | F10: =F7*'Control Panel'!$B$7 -> 0 | G10: =G7*'Control Panel'!$B$7 -> 0 | H10: =H7*'Control Panel'!$B$7 -> 0 | I10: =I7*'Control Panel'!$B$7 -> 0 | ... M10: =M7*'Control Panel'!$B$7 -> 0 | N10: =SUM(B10:M10) -> 0
A11: Revenue (1 Week Credit) (this month) | B11: =(B7*'Control Panel'!$B$8)*(3/4) -> 13050 | C11: =(C7*'Control Panel'!$B$8)*(3/4) -> 13162.5 | D11: =(D7*'Control Panel'!$B$8)*(3/4) -> 13237.5 | E11: =(E7*'Control Panel'!$B$8)*(3/4) -> 13350 | F11: =(F7*'Control Panel'!$B$8)*(3/4) -> 13462.5 | G11: =(G7*'Control Panel'!$B$8)*(3/4) -> 13575 | H11: =(H7*'Control Panel'!$B$8)*(3/4) -> 13687.5 | I11: =(I7*'Control Panel'!$B$8)*(3/4) -> 13800 | ... M11: =(M7*'Control Panel'!$B$8)*(3/4) -> 14362.5 | N11: =SUM(B11:M11) -> 163875
A12: Revenue (1 Week Credit) (last month) | B12: =('Year 2 Cash Budget'!M7*'Control Panel'!$B$8)*(1/4) -> 4325 | C12: =(B7*'Control Panel'!$B$8)*(1/4) -> 4350 | D12: =(C7*'Control Panel'!$B$8)*(1/4) -> 4387.5 | E12: =(D7*'Control Panel'!$B$8)*(1/4) -> 4412.5 | F12: =(E7*'Control Panel'!$B$8)*(1/4) -> 4450 | G12: =(F7*'Control Panel'!$B$8)*(1/4) -> 4487.5 | H12: =(G7*'Control Panel'!$B$8)*(1/4) -> 4525 | I12: =(H7*'Control Panel'!$B$8)*(1/4) -> 4562.5 | J12: =(I7*'Control Panel'!$B$8)*(1/4) -> 4600 | ... M12: =(L7*'Control Panel'!$B$8)*(1/4) -> 4737.5 | N12: =SUM(B12:M12) -> 54162.5
A13: Revenue (1 Month Credit) | B13: =('Year 2 Cash Budget'!M7*'Control Panel'!$B$9) -> 0 | C13: =(B7*'Control Panel'!$B$9) -> 0 | D13: =(C7*'Control Panel'!$B$9) -> 0 | E13: =(D7*'Control Panel'!$B$9) -> 0 | F13: =(E7*'Control Panel'!$B$9) -> 0 | G13: =(F7*'Control Panel'!$B$9) -> 0 | H13: =(G7*'Control Panel'!$B$9) -> 0 | I13: =(H7*'Control Panel'!$B$9) -> 0 | J13: =(I7*'Control Panel'!$B$9) -> 0 | ... M13: =(L7*'Control Panel'!$B$9) -> 0 | N13: =SUM(B13:M13) -> 0
A14: Total Revenue Cash In | B14: =SUM(B10:B13) -> 17375 | C14: =SUM(C10:C13) -> 17512.5 | D14: =SUM(D10:D13) -> 17625 | E14: =SUM(E10:E13) -> 17762.5 | F14: =SUM(F10:F13) -> 17912.5 | G14: =SUM(G10:G13) -> 18062.5 | H14: =SUM(H10:H13) -> 18212.5 | I14: =SUM(I10:I13) -> 18362.5 | ... N14: =SUM(N10:N13) -> 218037.5
A16: Investment Received | N16: =SUM(B16:M16) -> 0
A18: Cost of Revenue (this month) | B18: =(B7*'Control Panel'!$B$11)*(1-'Control Panel'!$B$13) -> 0 | C18: =(C7*'Control Panel'!$B$11)*(1-'Control Panel'!$B$13) -> 0 | D18: =(D7*'Control Panel'!$B$11)*(1-'Control Panel'!$B$13) -> 0 | E18: =(E7*'Control Panel'!$B$11)*(1-'Control Panel'!$B$13) -> 0 | F18: =(F7*'Control Panel'!$B$11)*(1-'Control Panel'!$B$13) -> 0 | G18: =(G7*'Control Panel'!$B$11)*(1-'Control Panel'!$B$13) -> 0 | H18: =(H7*'Control Panel'!$B$11)*(1-'Control Panel'!$B$13) -> 0 | I18: =(I7*'Control Panel'!$B$11)*(1-'Control Panel'!$B$13) -> 0 | ... M18: =(M7*'Control Panel'!$B$11)*(1-'Control Panel'!$B$13) -> 0 | N18: =SUM(B18:M18) -> 0
A19: Cost of Revenue (1 month supplier credit) | B19: =('Year 2 Cash Budget'!M7*'Control Panel'!$B$11)*('Control Panel'!$B$13) -> 6055 | C19: =(B7*'Control Panel'!$B$11)*('Control Panel'!$B$13) -> 6090 | D19: =(C7*'Control Panel'!$B$11)*('Control Panel'!$B$13) -> 6142.5 | E19: =(D7*'Control Panel'!$B$11)*('Control Panel'!$B$13) -> 6177.5 | F19: =(E7*'Control Panel'!$B$11)*('Control Panel'!$B$13) -> 6230 | G19: =(F7*'Control Panel'!$B$11)*('Control Panel'!$B$13) -> 6282.5 | H19: =(G7*'Control Panel'!$B$11)*('Control Panel'!$B$13) -> 6335 | I19: =(H7*'Control Panel'!$B$11)*('Control Panel'!$B$13) -> 6387.5 | J19: =(I7*'Control Panel'!$B$11)*('Control Panel'!$B$13) -> 6440 | ... M19: =(L7*'Control Panel'!$B$11)*('Control Panel'!$B$13) -> 6632.5 | N19: =SUM(B19:M19) -> 75827.5
A20: Total Cost of Revenue Cash Out | B20: =SUM(B18:B19) -> 6055 | C20: =SUM(C18:C19) -> 6090 | D20: =SUM(D18:D19) -> 6142.5 | E20: =SUM(E18:E19) -> 6177.5 | F20: =SUM(F18:F19) -> 6230 | G20: =SUM(G18:G19) -> 6282.5 | H20: =SUM(H18:H19) -> 6335 | I20: =SUM(I18:I19) -> 6387.5 | ... N20: =SUM(N18:N19) -> 75827.5 | O20: Creditors | P20: =(M7*'Control Panel'!$B$11)*('Control Panel'!$B$13) -> 6702.5
A22: Contracts, Terms, GPDR | B22: ='Year 2 Cash Budget'!B22 -> 0 | C22: ='Year 2 Cash Budget'!C22 -> 0 | D22: ='Year 2 Cash Budget'!D22 -> 0 | E22: ='Year 2 Cash Budget'!E22 -> 0 | F22: ='Year 2 Cash Budget'!F22 -> 0 | G22: ='Year 2 Cash Budget'!G22 -> 0 | H22: ='Year 2 Cash Budget'!H22 -> 0 | I22: ='Year 2 Cash Budget'!I22 -> 0 | ... M22: ='Year 2 Cash Budget'!M22 -> 0 | N22: =SUM(B22:M22) -> 0
A23: Stationery, etc. | B23: ='Year 2 Cash Budget'!B23 -> 0 | C23: ='Year 2 Cash Budget'!C23 -> 0 | D23: ='Year 2 Cash Budget'!D23 -> 0 | E23: ='Year 2 Cash Budget'!E23 -> 0 | F23: ='Year 2 Cash Budget'!F23 -> 0 | G23: ='Year 2 Cash Budget'!G23 -> 0 | H23: ='Year 2 Cash Budget'!H23 -> 0 | I23: ='Year 2 Cash Budget'!I23 -> 0 | ... M23: ='Year 2 Cash Budget'!M23 -> 0 | N23: =SUM(B23:M23) -> 0
A24: Brochures | B24: ='Year 2 Cash Budget'!B24 -> 0 | C24: ='Year 2 Cash Budget'!C24 -> 0 | D24: ='Year 2 Cash Budget'!D24 -> 0 | E24: ='Year 2 Cash Budget'!E24 -> 0 | F24: ='Year 2 Cash Budget'!F24 -> 0 | G24: ='Year 2 Cash Budget'!G24 -> 0 | H24: ='Year 2 Cash Budget'!H24 -> 0 | I24: ='Year 2 Cash Budget'!I24 -> 0 | ... M24: ='Year 2 Cash Budget'!M24 -> 0 | N24: =SUM(B24:M24) -> 0
A25: Consultants | B25: ='Year 2 Cash Budget'!B25 -> 0 | C25: ='Year 2 Cash Budget'!C25 -> 0 | D25: ='Year 2 Cash Budget'!D25 -> 0 | E25: ='Year 2 Cash Budget'!E25 -> 0 | F25: ='Year 2 Cash Budget'!F25 -> 0 | G25: ='Year 2 Cash Budget'!G25 -> 0 | H25: ='Year 2 Cash Budget'!H25 -> 0 | I25: ='Year 2 Cash Budget'!I25 -> 0 | ... M25: ='Year 2 Cash Budget'!M25 -> 0 | N25: =SUM(B25:M25) -> 0
A26: Insurance | B26: ='Year 2 Cash Budget'!B26 -> 0 | C26: ='Year 2 Cash Budget'!C26 -> 0 | D26: ='Year 2 Cash Budget'!D26 -> 0 | E26: ='Year 2 Cash Budget'!E26 -> 0 | F26: ='Year 2 Cash Budget'!F26 -> 0 | G26: ='Year 2 Cash Budget'!G26 -> 0 | H26: ='Year 2 Cash Budget'!H26 -> 0 | I26: ='Year 2 Cash Budget'!I26 -> 0 | ... M26: ='Year 2 Cash Budget'!M26 -> 0 | N26: =SUM(B26:M26) -> 0
A27: Rent | B27: ='Year 2 Cash Budget'!B27 -> 0 | C27: ='Year 2 Cash Budget'!C27 -> 0 | D27: ='Year 2 Cash Budget'!D27 -> 0 | E27: ='Year 2 Cash Budget'!E27 -> 0 | F27: ='Year 2 Cash Budget'!F27 -> 0 | G27: ='Year 2 Cash Budget'!G27 -> 0 | H27: ='Year 2 Cash Budget'!H27 -> 0 | I27: ='Year 2 Cash Budget'!I27 -> 0 | ... M27: ='Year 2 Cash Budget'!M27 -> 0 | N27: =SUM(B27:M27) -> 0
A28: R & D Design | B28: ='Year 2 Cash Budget'!B28 -> 0 | C28: ='Year 2 Cash Budget'!C28 -> 0 | D28: ='Year 2 Cash Budget'!D28 -> 0 | E28: ='Year 2 Cash Budget'!E28 -> 0 | F28: ='Year 2 Cash Budget'!F28 -> 0 | G28: ='Year 2 Cash Budget'!G28 -> 0 | H28: ='Year 2 Cash Budget'!H28 -> 0 | I28: ='Year 2 Cash Budget'!I28 -> 0 | ... M28: ='Year 2 Cash Budget'!M28 -> 0 | N28: =SUM(B28:M28) -> 0
A29: R & D Maintenance | B29: ='Year 2 Cash Budget'!B29 -> 0 | C29: ='Year 2 Cash Budget'!C29 -> 0 | D29: ='Year 2 Cash Budget'!D29 -> 0 | E29: ='Year 2 Cash Budget'!E29 -> 0 | F29: ='Year 2 Cash Budget'!F29 -> 0 | G29: ='Year 2 Cash Budget'!G29 -> 0 | H29: ='Year 2 Cash Budget'!H29 -> 0 | I29: ='Year 2 Cash Budget'!I29 -> 0 | ... M29: ='Year 2 Cash Budget'!M29 -> 0 | N29: =SUM(B29:M29) -> 0
A30: Staff | B30: ='Year 2 Cash Budget'!B30 -> 0 | C30: ='Year 2 Cash Budget'!C30 -> 0 | D30: ='Year 2 Cash Budget'!D30 -> 0 | E30: ='Year 2 Cash Budget'!E30 -> 0 | F30: ='Year 2 Cash Budget'!F30 -> 0 | G30: ='Year 2 Cash Budget'!G30 -> 0 | H30: ='Year 2 Cash Budget'!H30 -> 0 | I30: ='Year 2 Cash Budget'!I30 -> 0 | ... M30: ='Year 2 Cash Budget'!M30 -> 0 | N30: =SUM(B30:M30) -> 0
A31: Communications | B31: ='Year 2 Cash Budget'!B31 -> 0 | C31: ='Year 2 Cash Budget'!C31 -> 0 | D31: ='Year 2 Cash Budget'!D31 -> 0 | E31: ='Year 2 Cash Budget'!E31 -> 0 | F31: ='Year 2 Cash Budget'!F31 -> 0 | G31: ='Year 2 Cash Budget'!G31 -> 0 | H31: ='Year 2 Cash Budget'!H31 -> 0 | I31: ='Year 2 Cash Budget'!I31 -> 0 | ... M31: ='Year 2 Cash Budget'!M31 -> 0 | N31: =SUM(B31:M31) -> 0
A32: Incorporation Fees | B32: ='Year 2 Cash Budget'!B32 -> 0 | C32: ='Year 2 Cash Budget'!C32 -> 0 | D32: ='Year 2 Cash Budget'!D32 -> 0 | E32: ='Year 2 Cash Budget'!E32 -> 0 | F32: ='Year 2 Cash Budget'!F32 -> 0 | G32: ='Year 2 Cash Budget'!G32 -> 0 | H32: ='Year 2 Cash Budget'!H32 -> 0 | I32: ='Year 2 Cash Budget'!I32 -> 0 | ... M32: ='Year 2 Cash Budget'!M32 -> 0 | N32: =SUM(B32:M32) -> 0
A33: Website Design | B33: ='Year 2 Cash Budget'!B33 -> 0 | C33: ='Year 2 Cash Budget'!C33 -> 0 | D33: ='Year 2 Cash Budget'!D33 -> 0 | E33: ='Year 2 Cash Budget'!E33 -> 0 | F33: ='Year 2 Cash Budget'!F33 -> 0 | G33: ='Year 2 Cash Budget'!G33 -> 0 | H33: ='Year 2 Cash Budget'!H33 -> 0 | I33: ='Year 2 Cash Budget'!I33 -> 0 | ... M33: ='Year 2 Cash Budget'!M33 -> 0 | N33: =SUM(B33:M33) -> 0
... A37: Marketing | B37: ='Year 2 Cash Budget'!B37 -> 5000 | C37: ='Year 2 Cash Budget'!C37 -> 5000 | D37: ='Year 2 Cash Budget'!D37 -> 5000 | E37: ='Year 2 Cash Budget'!E37 -> 5000 | F37: ='Year 2 Cash Budget'!F37 -> 5000 | G37: ='Year 2 Cash Budget'!G37 -> 5000 | H37: ='Year 2 Cash Budget'!H37 -> 5000 | I37: ='Year 2 Cash Budget'!I37 -> 5000 | ... M37: ='Year 2 Cash Budget'!M37 -> 5000 | N37: =SUM(B37:M37) -> 60000
A38: Total Expenses Cash Out | B38: =SUM(B22:B37) -> 5000 | C38: =SUM(C22:C37) -> 5000 | D38: =SUM(D22:D37) -> 5000 | E38: =SUM(E22:E37) -> 5000 | F38: =SUM(F22:F37) -> 5000 | G38: =SUM(G22:G37) -> 5000 | H38: =SUM(H22:H37) -> 5000 | I38: =SUM(I22:I37) -> 5000 | ... N38: =SUM(N22:N37) -> 60000
A40: Computer Equpment | N40: =SUM(B40:M40) -> 0
A41: Communications | N41: =SUM(B41:M41) -> 0
A42: Furniture | N42: =SUM(B42:M42) -> 0
A43: Buildings | N43: =SUM(B43:M43) -> 0
A44: Total Assets Cash Out | B44: =SUM(B40:B43) -> 0 | C44: =SUM(C40:C43) -> 0 | D44: =SUM(D40:D43) -> 0 | E44: =SUM(E40:E43) -> 0 | F44: =SUM(F40:F43) -> 0 | G44: =SUM(G40:G43) -> 0 | H44: =SUM(H40:H43) -> 0 | I44: =SUM(I40:I43) -> 0 | ... N44: =SUM(N40:N43) -> 0
A46: Closing Cash | B46: =B9+B14-B20-B38-B44+B16 -> 199539 | C46: =C9+C14-C20-C38-C44+C16 -> 205961.5 | D46: =D9+D14-D20-D38-D44+D16 -> 212444 | E46: =E9+E14-E20-E38-E44+E16 -> 219029 | F46: =F9+F14-F20-F38-F44+F16 -> 225711.5 | G46: =G9+G14-G20-G38-G44+G16 -> 232491.5 | H46: =H9+H14-H20-H38-H44+H16 -> 239369 | I46: =I9+I14-I20-I38-I44+I16 -> 246344 | ... M46: =M9+M14-M20-M38-M44+M16 -> 275429
A49: Revenue | B49: =B7 -> 17400 | C49: =C7 -> 17550 | D49: =D7 -> 17650 | E49: =E7 -> 17800 | F49: =F7 -> 17950 | G49: =G7 -> 18100 | H49: =H7 -> 18250 | I49: =I7 -> 18400 | ... M49: =M7 -> 19150
A51: Cost of Revenue | B51: =B49*'Control Panel'!$B$11 -> 6090 | C51: =C49*'Control Panel'!$B$11 -> 6142.5 | D51: =D49*'Control Panel'!$B$11 -> 6177.5 | E51: =E49*'Control Panel'!$B$11 -> 6230 | F51: =F49*'Control Panel'!$B$11 -> 6282.5 | G51: =G49*'Control Panel'!$B$11 -> 6335 | H51: =H49*'Control Panel'!$B$11 -> 6387.5 | I51: =I49*'Control Panel'!$B$11 -> 6440 | ... M51: =M49*'Control Panel'!$B$11 -> 6702.5
A53: Gross Profit | B53: =B49-B51 -> 11310 | C53: =C49-C51 -> 11407.5 | D53: =D49-D51 -> 11472.5 | E53: =E49-E51 -> 11570 | F53: =F49-F51 -> 11667.5 | G53: =G49-G51 -> 11765 | H53: =H49-H51 -> 11862.5 | I53: =I49-I51 -> 11960 | ... M53: =M49-M51 -> 12447.5
...

Sheet Year 4 Cash Budget
B1: Month 37 | C1: Month 38 | D1: Month 39 | E1: Month 40 | F1: Month 41 | G1: Month 42 | H1: Month 43 | I1: Month 44 | J1: Month 45 | K1: Month 46 | L1: Month 47 | M1: Month 48 | N1: Year 4
A2: Revenue Calculations
A3: Average Sale | B3: ='Control Panel'!$B$1 -> 50 | C3: =B3 -> 50 | D3: =C3 -> 50 | E3: =D3 -> 50 | F3: =E3 -> 50 | G3: =F3 -> 50 | H3: =G3 -> 50 | I3: =H3 -> 50 | J3: =I3 -> 50 | ... M3: =L3 -> 50
A4: Customers | B4: =ROUND((('Control Panel'!$B$2*(B5+1))*B6),0) -> 387 | C4: =ROUND((('Control Panel'!$B$2*(C5+1))*C6),0) -> 391 | D4: =ROUND((('Control Panel'!$B$2*(D5+1))*D6),0) -> 396 | E4: =ROUND((('Control Panel'!$B$2*(E5+1))*E6),0) -> 401 | F4: =ROUND((('Control Panel'!$B$2*(F5+1))*F6),0) -> 406 | G4: =ROUND((('Control Panel'!$B$2*(G5+1))*G6),0) -> 411 | H4: =ROUND((('Control Panel'!$B$2*(H5+1))*H6),0) -> 416 | I4: =ROUND((('Control Panel'!$B$2*(I5+1))*I6),0) -> 422 | ... M4: =ROUND((('Control Panel'!$B$2*(M5+1))*M6),0) -> 449 | N4: =SUM(B4:M4) -> 4984
A5: Customer Growth Factor | B5: ='Year 3 Cash Budget'!M5*(1+'Control Panel'!$B$4) -> 0.28959081 | C5: =B5*(1+'Control Panel'!$B$4) -> 0.30407035 | D5: =C5*(1+'Control Panel'!$B$4) -> 0.31927386 | E5: =D5*(1+'Control Panel'!$B$4) -> 0.33523756 | F5: =E5*(1+'Control Panel'!$B$4) -> 0.35199944 | G5: =F5*(1+'Control Panel'!$B$4) -> 0.36959941 | H5: =G5*(1+'Control Panel'!$B$4) -> 0.38807938 | I5: =H5*(1+'Control Panel'!$B$4) -> 0.40748335 | J5: =I5*(1+'Control Panel'!$B$4) -> 0.42785751 | ... M5: =L5*(1+'Control Panel'!$B$4) -> 0.49529855
A6: Seasonality Index | B6: ='Year 3 Cash Budget'!B6 -> 1 | C6: ='Year 3 Cash Budget'!C6 -> 1 | D6: ='Year 3 Cash Budget'!D6 -> 1 | E6: ='Year 3 Cash Budget'!E6 -> 1 | F6: ='Year 3 Cash Budget'!F6 -> 1 | G6: ='Year 3 Cash Budget'!G6 -> 1 | H6: ='Year 3 Cash Budget'!H6 -> 1 | I6: ='Year 3 Cash Budget'!I6 -> 1 | ... M6: ='Year 3 Cash Budget'!M6 -> 1
A7: Revenue | B7: =B3*B4 -> 19350 | C7: =C3*C4 -> 19550 | D7: =D3*D4 -> 19800 | E7: =E3*E4 -> 20050 | F7: =F3*F4 -> 20300 | G7: =G3*G4 -> 20550 | H7: =H3*H4 -> 20800 | I7: =I3*I4 -> 21100 | ... M7: =M3*M4 -> 22450 | N7: =SUM(B7:M7) -> 249200 | O7: Debtors | P7: =(M7*'Control Panel'!$B$8)*(1/4)+(M7*'Control Panel'!$B$9) -> 5612.5
A9: Opening Cash | B9: ='Financial Statements'!D19 -> 259024 | C9: =B46 -> 266621.5 | D9: =C46 -> 274349 | E9: =D46 -> 282244 | F9: =E46 -> 290301.5 | G9: =F46 -> 298521.5 | H9: =G46 -> 306904 | I9: =H46 -> 315449 | J9: =I46 -> 324194 | ... M9: =L46 -> 351706.5
A10: Revenue (this month) | B10: =B7*'Control Panel'!$B$7 -> 0 | C10: =C7*'Control Panel'!$B$7 -> 0 | D10: =D7*'Control Panel'!$B$7 -> 0 | E10: =E7*'Control Panel'!$B$7 -> 0 | F10: =F7*'Control Panel'!$B$7 -> 0 | G10: =G7*'Control Panel'!$B$7 -> 0 | H10: =H7*'Control Panel'!$B$7 -> 0 | I10: =I7*'Control Panel'!$B$7 -> 0 | ... M10: =M7*'Control Panel'!$B$7 -> 0 | N10: =SUM(B10:M10) -> 0
A11: Revenue (1 Week Credit) (this month) | B11: =(B7*'Control Panel'!$B$8)*(3/4) -> 14512.5 | C11: =(C7*'Control Panel'!$B$8)*(3/4) -> 14662.5 | D11: =(D7*'Control Panel'!$B$8)*(3/4) -> 14850 | E11: =(E7*'Control Panel'!$B$8)*(3/4) -> 15037.5 | F11: =(F7*'Control Panel'!$B$8)*(3/4) -> 15225 | G11: =(G7*'Control Panel'!$B$8)*(3/4) -> 15412.5 | H11: =(H7*'Control Panel'!$B$8)*(3/4) -> 15600 | I11: =(I7*'Control Panel'!$B$8)*(3/4) -> 15825 | ... M11: =(M7*'Control Panel'!$B$8)*(3/4) -> 16837.5 | N11: =SUM(B11:M11) -> 186900
A12: Revenue (1 Week Credit) (last month) | B12: =('Year 3 Cash Budget'!M7*'Control Panel'!$B$8)*(1/4) -> 4787.5 | C12: =(B7*'Control Panel'!$B$8)*(1/4) -> 4837.5 | D12: =(C7*'Control Panel'!$B$8)*(1/4) -> 4887.5 | E12: =(D7*'Control Panel'!$B$8)*(1/4) -> 4950 | F12: =(E7*'Control Panel'!$B$8)*(1/4) -> 5012.5 | G12: =(F7*'Control Panel'!$B$8)*(1/4) -> 5075 | H12: =(G7*'Control Panel'!$B$8)*(1/4) -> 5137.5 | I12: =(H7*'Control Panel'!$B$8)*(1/4) -> 5200 | J12: =(I7*'Control Panel'!$B$8)*(1/4) -> 5275 | ... M12: =(L7*'Control Panel'!$B$8)*(1/4) -> 5525 | N12: =SUM(B12:M12) -> 61475
A13: Revenue (1 Month Credit) | B13: =('Year 3 Cash Budget'!M7*'Control Panel'!$B$9) -> 0 | C13: =(B7*'Control Panel'!$B$9) -> 0 | D13: =(C7*'Control Panel'!$B$9) -> 0 | E13: =(D7*'Control Panel'!$B$9) -> 0 | F13: =(E7*'Control Panel'!$B$9) -> 0 | G13: =(F7*'Control Panel'!$B$9) -> 0 | H13: =(G7*'Control Panel'!$B$9) -> 0 | I13: =(H7*'Control Panel'!$B$9) -> 0 | J13: =(I7*'Control Panel'!$B$9) -> 0 | ... M13: =(L7*'Control Panel'!$B$9) -> 0 | N13: =SUM(B13:M13) -> 0
A14: Total Revenue Cash In | B14: =SUM(B10:B13) -> 19300 | C14: =SUM(C10:C13) -> 19500 | D14: =SUM(D10:D13) -> 19737.5 | E14: =SUM(E10:E13) -> 19987.5 | F14: =SUM(F10:F13) -> 20237.5 | G14: =SUM(G10:G13) -> 20487.5 | H14: =SUM(H10:H13) -> 20737.5 | I14: =SUM(I10:I13) -> 21025 | ... N14: =SUM(N10:N13) -> 248375
A16: Investment Received | N16: =SUM(B16:M16) -> 0
A18: Cost of Revenue (this month) | B18: =(B7*'Control Panel'!$B$11)*(1-'Control Panel'!$B$13) -> 0 | C18: =(C7*'Control Panel'!$B$11)*(1-'Control Panel'!$B$13) -> 0 | D18: =(D7*'Control Panel'!$B$11)*(1-'Control Panel'!$B$13) -> 0 | E18: =(E7*'Control Panel'!$B$11)*(1-'Control Panel'!$B$13) -> 0 | F18: =(F7*'Control Panel'!$B$11)*(1-'Control Panel'!$B$13) -> 0 | G18: =(G7*'Control Panel'!$B$11)*(1-'Control Panel'!$B$13) -> 0 | H18: =(H7*'Control Panel'!$B$11)*(1-'Control Panel'!$B$13) -> 0 | I18: =(I7*'Control Panel'!$B$11)*(1-'Control Panel'!$B$13) -> 0 | ... M18: =(M7*'Control Panel'!$B$11)*(1-'Control Panel'!$B$13) -> 0 | N18: =SUM(B18:M18) -> 0
A19: Cost of Revenue (1 month supplier credit) | B19: =('Year 3 Cash Budget'!M7*'Control Panel'!$B$11)*('Control Panel'!$B$13) -> 6702.5 | C19: =(B7*'Control Panel'!$B$11)*('Control Panel'!$B$13) -> 6772.5 | D19: =(C7*'Control Panel'!$B$11)*('Control Panel'!$B$13) -> 6842.5 | E19: =(D7*'Control Panel'!$B$11)*('Control Panel'!$B$13) -> 6930 | F19: =(E7*'Control Panel'!$B$11)*('Control Panel'!$B$13) -> 7017.5 | G19: =(F7*'Control Panel'!$B$11)*('Control Panel'!$B$13) -> 7105 | H19: =(G7*'Control Panel'!$B$11)*('Control Panel'!$B$13) -> 7192.5 | I19: =(H7*'Control Panel'!$B$11)*('Control Panel'!$B$13) -> 7280 | J19: =(I7*'Control Panel'!$B$11)*('Control Panel'!$B$13) -> 7385 | ... M19: =(L7*'Control Panel'!$B$11)*('Control Panel'!$B$13) -> 7735 | N19: =SUM(B19:M19) -> 86065
A20: Total Cost of Revenue Cash Out | B20: =SUM(B18:B19) -> 6702.5 | C20: =SUM(C18:C19) -> 6772.5 | D20: =SUM(D18:D19) -> 6842.5 | E20: =SUM(E18:E19) -> 6930 | F20: =SUM(F18:F19) -> 7017.5 | G20: =SUM(G18:G19) -> 7105 | H20: =SUM(H18:H19) -> 7192.5 | I20: =SUM(I18:I19) -> 7280 | ... N20: =SUM(N18:N19) -> 86065 | O20: Creditors | P20: =(M7*'Control Panel'!$B$11)*('Control Panel'!$B$13) -> 7857.5
A22: Contracts, Terms, GPDR | B22: ='Year 3 Cash Budget'!B22 -> 0 | C22: ='Year 3 Cash Budget'!C22 -> 0 | D22: ='Year 3 Cash Budget'!D22 -> 0 | E22: ='Year 3 Cash Budget'!E22 -> 0 | F22: ='Year 3 Cash Budget'!F22 -> 0 | G22: ='Year 3 Cash Budget'!G22 -> 0 | H22: ='Year 3 Cash Budget'!H22 -> 0 | I22: ='Year 3 Cash Budget'!I22 -> 0 | ... M22: ='Year 3 Cash Budget'!M22 -> 0 | N22: =SUM(B22:M22) -> 0
A23: Stationery, etc. | B23: ='Year 3 Cash Budget'!B23 -> 0 | C23: ='Year 3 Cash Budget'!C23 -> 0 | D23: ='Year 3 Cash Budget'!D23 -> 0 | E23: ='Year 3 Cash Budget'!E23 -> 0 | F23: ='Year 3 Cash Budget'!F23 -> 0 | G23: ='Year 3 Cash Budget'!G23 -> 0 | H23: ='Year 3 Cash Budget'!H23 -> 0 | I23: ='Year 3 Cash Budget'!I23 -> 0 | ... M23: ='Year 3 Cash Budget'!M23 -> 0 | N23: =SUM(B23:M23) -> 0
