Workbook

Sheet Performance Dashboard
B1: Year 1 | C1: Year 2 | D1: Year 3 | E1: Year 4 | F1: Year 5
A2: Gross Margin | B2: ='Financial Statements'!B7/'Financial Statements'!B3 | C2: ='Financial Statements'!C7/'Financial Statements'!C3 | D2: ='Financial Statements'!D7/'Financial Statements'!D3 | E2: ='Financial Statements'!E7/'Financial Statements'!E3 | F2: ='Financial Statements'!F7/'Financial Statements'!F3
A3: Net Margin | B3: ='Financial Statements'!B13/'Financial Statements'!B3 | C3: ='Financial Statements'!C13/'Financial Statements'!C3 | D3: ='Financial Statements'!D13/'Financial Statements'!D3 | E3: ='Financial Statements'!E13/'Financial Statements'!E3 | F3: ='Financial Statements'!F13/'Financial Statements'!F3
A4: Quick Ratio | B4: ='Financial Statements'!B19/'Financial Statements'!B22 | C4: ='Financial Statements'!C19/'Financial Statements'!C22 | D4: ='Financial Statements'!D19/'Financial Statements'!D22 | E4: ='Financial Statements'!E19/'Financial Statements'!E22 | F4: ='Financial Statements'!F19/'Financial Statements'!F22
A5: EBITDA | B5: ='Financial Statements'!B13 | C5: ='Financial Statements'!C13 | D5: ='Financial Statements'!D13 | E5: ='Financial Statements'!E13 | F5: ='Financial Statements'!F13
A7: Customers | B7: ='Year 1 Cash Budget'!O4 | C7: ='Year 2 Cash Budget'!N4 | D7: ='Year 3 Cash Budget'!N4 | E7: ='Year 4 Cash Budget'!N4 | F7: ='Year 5 Cash Budget'!N4
A8: Market Share % | B8: =B7/('Control Panel'!$B$3*12) | C8: =C7/('Control Panel'!$B$3*12) | D8: =D7/('Control Panel'!$B$3*12) | E8: =E7/('Control Panel'!$B$3*12) | F8: =F7/('Control Panel'!$B$3*12)
A10: ='Financial Statements'!A3 | B10: ='Financial Statements'!B3 | C10: ='Financial Statements'!C3 | D10: ='Financial Statements'!D3 | E10: ='Financial Statements'!E3 | F10: ='Financial Statements'!F3
A11: ='Financial Statements'!A7 | B11: ='Financial Statements'!B7 | C11: ='Financial Statements'!C7 | D11: ='Financial Statements'!D7 | E11: ='Financial Statements'!E7 | F11: ='Financial Statements'!F7
A12: ='Financial Statements'!A11 | B12: ='Financial Statements'!B11 | C12: ='Financial Statements'!C11 | D12: ='Financial Statements'!D11 | E12: ='Financial Statements'!E11 | F12: ='Financial Statements'!F11
A13: ='Financial Statements'!A13 | B13: ='Financial Statements'!B13 | C13: ='Financial Statements'!C13 | D13: ='Financial Statements'!D13 | E13: ='Financial Statements'!E13 | F13: ='Financial Statements'!F13
A15: ='Financial Statements'!A19 | B15: ='Financial Statements'!B19 | C15: ='Financial Statements'!C19 | D15: ='Financial Statements'!D19 | E15: ='Financial Statements'!E19 | F15: ='Financial Statements'!F19
A16: ='Financial Statements'!A24 | B16: ='Financial Statements'!B24 | C16: ='Financial Statements'!C24 | D16: ='Financial Statements'!D24 | E16: ='Financial Statements'!E24 | F16: ='Financial Statements'!F24
A18: Operational Break Even | B18: =IF(ISNA(HLOOKUP("OBE",Balances!A7:BI8,2,FALSE)),"Never",CONCATENATE("Month ",HLOOKUP("OBE",Balances!A7:BI8,2,FALSE))) | D18: Worth > | E18: =IF(ISNA(HLOOKUP("Yes",'Financial Statements'!B31:F34,4,FALSE)),"Never",HLOOKUP("Yes",'Financial Statements'!B31:F34,4,FALSE))
A19: Cash Break Even | B19: =IF(ISNA(HLOOKUP("CBE",Balances!A5:BI8,4,FALSE)),"Never",CONCATENATE("Month ",HLOOKUP("CBE",Balances!A5:BI8,4,FALSE))) | D19: Buyout | E19: =IF(ISNA(HLOOKUP("Yes",'Financial Statements'!B33:F34,2,FALSE)),"Never",HLOOKUP("Yes",'Financial Statements'!B33:F34,2,FALSE))
A21: Investment Required | B21: ='Startup & Pre-Opening Costs'!B29 | D21: Buyout | E21: =IF(E19="Never","N/A",HLOOKUP(E19,'Financial Statements'!B34:F35,2,FALSE))
A23: Market Share % | B23: ='Control Panel'!B2/'Control Panel'!B3 | D23: Investor ROI % | E23: =(E21-B21)/B21

Sheet LFL_Parameters
A1: LFL Financial Model – Schlüsselparameter & Datenherkunft
A2: Quelldatei: | B2: 260315_LFL_BM_Szen_normal_final.xlsx
A3: Zieldatei (v03): | B3: C13_Template_financial_projections_ext_2026_v03.xlsx
A5: Parameter | B5: Wert | C5: Einheit | D5: Quelle / Erläuterung
A6: ▶ KUNDENMODELL – REVENUE-ANNAHMEN
A7: SME Seat-Preis | B7: 460 | C7: €/Monat/Seat | D7: 2_Inputs!B35
A8: SME Seats je Kunde | B8: 6 | C8: Seats/Kunde | D8: 2_Inputs!B33
A9: SME Monatsumsatz je Kunde | B9: =B7*B8 | C9: €/Monat | D9: =B8 × B9 (Seat-Preis × Seats)
A10: Mid-Company Seat-Preis | B10: 530 | C10: €/Monat/Seat | D10: 2_Inputs!B36
A11: Mid-Company Seats je Kunde | B11: 12 | C11: Seats/Kunde | D11: 2_Inputs!B34
A12: Mid-Company Monatsumsatz je Kunde | B12: =B10*B11 | C12: €/Monat | D12: =B11 × B12 (Seat-Preis × Seats)
A13: Enterprise Jahres-Fee | B13: 80000 | C13: €/Jahr | D13: 2_Inputs!B37
A14: Enterprise Monatsumsatz je Kunde | B14: =B13/12 | C14: €/Monat | D14: =B14 / 12
A15: Jährliche Preiserhöhung | B15: 0.04 | C15: % p.a. | D15: 2_Inputs!B38
A16: Erster zahlender Kunde (Ziel-Mo.) | B16: 4 | C16: Ziel-Monat | D16: 2_Inputs!B39 (Quell-M8 → Ziel-M4)
A17: Jährliche Churn Rate | B17: 0.05 | C17: % p.a. | D17: 2_Inputs!B40
A19: ▶ ZAHLUNGSBEDINGUNGEN (LFL: 100 % Barverkauf)
A20: Zahlungseingang sofort (Bar-Anteil) | B20: 1 | C20: Anteil 0–1 | D20: LFL: sofortige Zahlung, kein Zahlungsziel
A21: 1-Wochen-Kredit (Kreditkarte) | B21: 0 | C21: Anteil 0–1 | D21: LFL: keine Kreditkartenzahlungsziele
A22: 1-Monats-Kredit (Rechnung/Invoice) | B22: 0 | C22: Anteil 0–1 | D22: LFL: keine Rechnungszahlungsziele
A23: Lieferantenkredit (COGS, 1 Monat) | B23: 0 | C23: Anteil 0–1 | D23: LFL: COGS werden sofort bezahlt
A25: ▶ UMSATZKOSTENQUOTE (COGS) – Gesamtperiode M5–M52
A26: Gesamtumsatz Pre-Seed bis Series B | B26: 19662455 | C26: € | D26: 6_P&L!R8, Quell-Spalten M5–M52 (= Ziel M1–M48)
A27: Gesamte COGS Pre-Seed bis Series B | B27: 2510511.4 | C27: € | D27: 6_P&L!R14, Quell-Spalten M5–M52 (= Ziel M1–M48)
A28: Effektive COGS-Quote (gewichteter Durchschnitt) | B28: =B27/B26 | C28: % des Umsatzes | D28: =Gesamt-COGS / Gesamt-Umsatz → Quelle: berechnete Formel
A30: ▶ FINANZIERUNGSRUNDEN (Quelle: 2_Inputs + 7_BS_CF)
A31: Pre-Seed + Business Angels (Ziel M1) | B31: 720000 | C31: € | D31: 2_Inputs: R11 + R18 + R20 + R22
A32: Seed (Ziel M13) | B32: 2000000 | C32: € | D32: 2_Inputs!B13
A33: Series A (Ziel M25) | B33: 10000000 | C33: € | D33: 2_Inputs!B15
A35: ▶ PERSONAL & STEUERN (Quelle: 2_Inputs)
A36: Gehaltserhöhung p.a. | B36: 0.03 | C36: % p.a. | D36: 2_Inputs!B84
A37: AG-Aufschlag (SV + Umlagen) | B37: 0.22 | C37: % | D37: 2_Inputs!B85
A38: Ertragssteuersatz | B38: 0.3 | C38: % | D38: 2_Inputs!B6

Sheet Control Panel
A1: Average Sale per Customer (SME) | B1: ='LFL_Parameters'!B9 | C1: LFL_Parameters!B9: SME Seat-Preis × Seats/Kunde = 460 × 6 | E1: ='Performance Dashboard'!B1 | F1: ='Performance Dashboard'!C1 | G1: ='Performance Dashboard'!D1 | H1: ='Performance Dashboard'!E1 | I1: ='Performance Dashboard'!F1
A2: Base Number of Customers per Month | B2: 0 | C2: LFL: kein Kundenstamm zu Start. Erster Kunde Ziel-M4 (Quell-M8). Kundenzahlen je Monat direkt in R4 der Jahressheets hinterlegt. | D2: ='Performance Dashboard'!A2 | E2: ='Performance Dashboard'!B2 | F2: ='Performance Dashboard'!C2 | G2: ='Performance Dashboard'!D2 | H2: ='Performance Dashboard'!E2 | I2: ='Performance Dashboard'!F2
A3: Potential Customers per Month | B3: 10000 | C3: Externe Marktannahme (TAM). Nicht in Quelldatei definiert. Einflussgröße für Marktanteil-Berechnung im Performance Dashboard. | D3: ='Performance Dashboard'!A3 | E3: ='Performance Dashboard'!B3 | F3: ='Performance Dashboard'!C3 | G3: ='Performance Dashboard'!D3 | H3: ='Performance Dashboard'!E3 | I3: ='Performance Dashboard'!F3
A4: Customer Growth per month | B4: 0.05 | C4: Entspricht dem monatlichen Seat-Wachstum im LFL-Modell. Achtung: R4-Werte (Kundenzahl/Monat) sind Ist-Werte aus der Quelldatei, nicht aus dieser Wachstumsformel abgeleitet. | D4: ='Performance Dashboard'!A4 | E4: ='Performance Dashboard'!B4 | F4: ='Performance Dashboard'!C4 | G4: ='Performance Dashboard'!D4 | H4: ='Performance Dashboard'!E4 | I4: ='Performance Dashboard'!F4
C5: ◀ Quelle / Erläuterung | D5: ='Performance Dashboard'!A5 | E5: ='Performance Dashboard'!B5 | F5: ='Performance Dashboard'!C5 | G5: ='Performance Dashboard'!D5 | H5: ='Performance Dashboard'!E5 | I5: ='Performance Dashboard'!F5
A6: Revenue Payments
A7: Cash | B7: ='LFL_Parameters'!B20 | C7: LFL_Parameters!B20: 100 % Bareingang im Buchungsmonat. Keine Zahlungsziele. | D7: ='Performance Dashboard'!A7 | E7: ='Performance Dashboard'!B7 | F7: ='Performance Dashboard'!C7 | G7: ='Performance Dashboard'!D7 | H7: ='Performance Dashboard'!E7 | I7: ='Performance Dashboard'!F7
A8: 1 Week Credit (Credit Card) | B8: ='LFL_Parameters'!B21 | C8: LFL_Parameters!B21: Kein 1-Wochen-Kredit. LFL = 100 % sofort.
A9: 1 Month Credit (Invoice) | B9: ='LFL_Parameters'!B22 | C9: LFL_Parameters!B22: Kein Rechnungszahlungsziel. LFL = B2B SaaS, sofortige Zahlung. | D9: ='Performance Dashboard'!A10 | E9: ='Performance Dashboard'!B10 | F9: ='Performance Dashboard'!C10 | G9: ='Performance Dashboard'!D10 | H9: ='Performance Dashboard'!E10 | I9: ='Performance Dashboard'!F10
D10: ='Performance Dashboard'!A11 | E10: ='Performance Dashboard'!B11 | F10: ='Performance Dashboard'!C11 | G10: ='Performance Dashboard'!D11 | H10: ='Performance Dashboard'!E11 | I10: ='Performance Dashboard'!F11
A11: Cost of Revenue (COGS) — gewichtet | B11: =IFERROR((SUM('Year 1 Cash Budget'!C18:N18)+SUM('Year 2 Cash Budget'!B18:M18)+SUM('Year 3 Cash Budget'!B18:M18)+SUM('Year 4 Cash Budget'!B18:M18))/(SUM('Year 1 Cash Budget'!C7:N7)+SUM('Year 2 Cash Budget'!B7:M7)+SUM('Year 3 Cash Budget'!B7:M7)+SUM('Year 4 Cash Budget'!B7:M7)),0) | C11: Formel: Σ COGS (R18, Jahressheets Y1–Y4) / Σ Umsatz (R7, Jahressheets Y1–Y4). Ist-Wert aus Quelldatei: 12.8% | D11: ='Performance Dashboard'!A12 | E11: ='Performance Dashboard'!B12 | F11: ='Performance Dashboard'!C12 | G11: ='Performance Dashboard'!D12 | H11: ='Performance Dashboard'!E12 | I11: ='Performance Dashboard'!F12
D12: ='Performance Dashboard'!A13 | E12: ='Performance Dashboard'!B13 | F12: ='Performance Dashboard'!C13 | G12: ='Performance Dashboard'!D13 | H12: ='Performance Dashboard'!E13 | I12: ='Performance Dashboard'!F13
A13: 1 Month Supplier Credit | B13: ='LFL_Parameters'!B23 | C13: LFL_Parameters!B23: LFL zahlt COGS sofort (kein Lieferantenkredit). COGS = Cloud-Hosting (variabel) + AI/ML APIs + Payment Processing.
D14: ='Performance Dashboard'!A15 | E14: ='Performance Dashboard'!B15 | F14: ='Performance Dashboard'!C15 | G14: ='Performance Dashboard'!D15 | H14: ='Performance Dashboard'!E15 | I14: ='Performance Dashboard'!F15
A15: Investor Return | B15: 0.12 | C15: Externe Annahme: erwartete Rendite der Investoren. Nicht in Quelldatei definiert. | D15: ='Performance Dashboard'!A16 | E15: ='Performance Dashboard'!B16 | F15: ='Performance Dashboard'!C16 | G15: ='Performance Dashboard'!D16 | H15: ='Performance Dashboard'!E16 | I15: ='Performance Dashboard'!F16
A16: Founder Profit % | B16: 0.2 | C16: Externe Annahme: Gründer-Gewinnbeteiligung. Nicht direkt aus Quelldatei; kann im LFL-Shareholder-Agreement definiert werden.
D17: ='Performance Dashboard'!A18 | E17: ='Performance Dashboard'!B18 | G17: ='Performance Dashboard'!D18 | H17: ='Performance Dashboard'!E18
D18: ='Performance Dashboard'!A19 | E18: ='Performance Dashboard'!B19 | G18: ='Performance Dashboard'!D19 | H18: ='Performance Dashboard'!E19
D20: ='Performance Dashboard'!A21 | E20: ='Performance Dashboard'!B21 | G20: ='Performance Dashboard'!D21 | H20: ='Performance Dashboard'!E21
D22: ='Performance Dashboard'!A23 | E22: ='Performance Dashboard'!B23 | G22: ='Performance Dashboard'!D23 | H22: ='Performance Dashboard'!E23

Sheet Startup & Pre-Opening Costs
B1: Asset | C1: Expense
A2: Contracts, Terms, GPDR | C2: 0
A3: Stationery, etc.
A4: Brochures
A5: Consultants | C5: 0
A6: Insurance
A7: Rent
A8: R & D Design | C8: 0
A9: R & D Maintenance
A10: Computer Equpment | B10: 0
A11: Staff
A12: Communications Hardware
A13: Communications Contracts
A14: Furniture
A15: Incorporation Fees
A16: Website Design
A17: Website Maintenance
A18: Travel
A19: Buildings
A20: Vehicles
A21: Marketing | C21: 0
A23: Total | B23: =SUM(B2:B22) | C23: =SUM(C2:C22)
A25: Preopening Period?
A27: Investment Required | B27: =B23+C23
A28: Working Capital Required | B28: 0 | C28: =IF(MIN('Year 1 Cash Budget'!B46:N46,'Year 2 Cash Budget'!B46:M46,'Year 3 Cash Budget'!B46:M46)<0,CONCATENATE("I suggest an additional ",ROUNDUP(-MIN('Year 1 Cash Budget'!B46:N46,'Year 2 Cash Budget'!B46:M46,'Year 3 Cash Budget'!B46:M46),-4)),"")
A29: Investment Total | B29: =SUM(B27:B28)

Sheet Year 1 Cash Budget
B1: Pre-Opening (Ideation M1–M4: 0) | C1: Month 1 | D1: Month 2 | E1: Month 3 | F1: Month 4 | G1: Month 5 | H1: Month 6 | I1: Month 7 | J1: Month 8 | K1: Month 9 | L1: Month 10 | M1: Month 11 | N1: Month 12 | O1: Year 1
A2: Revenue Calculations
A3: Average Sale | B3: 0 | C3: 2760 | D3: 2760 | E3: 2760 | F3: 2760 | G3: 2760 | H3: 2760 | I3: 2760 | J3: 2760 | K3: 2870 | L3: 2870 | M3: 2870 | N3: 2870
A4: Customers | B4: 0 | C4: 0 | D4: 0 | E4: 1 | F4: 1 | G4: 1 | H4: 1 | I4: 2 | J4: 2 | K4: 3 | L4: 3 | M4: 3 | N4: 3 | O4: =SUM(C4:N4)
A5: Customer Growth Factor | B5: 0 | C5: ='Control Panel'!B4 | D5: =C5*(1+'Control Panel'!$B$4) | E5: =D5*(1+'Control Panel'!$B$4) | F5: =E5*(1+'Control Panel'!$B$4) | G5: =F5*(1+'Control Panel'!$B$4) | H5: =G5*(1+'Control Panel'!$B$4) | I5: =H5*(1+'Control Panel'!$B$4) | J5: =I5*(1+'Control Panel'!$B$4) | K5: =J5*(1+'Control Panel'!$B$4) | ... N5: =M5*(1+'Control Panel'!$B$4)
A6: Seasonality Index | B6: 0 | C6: 1 | D6: =C6 | E6: =D6 | F6: =E6 | G6: =F6 | H6: =G6 | I6: =H6 | J6: =I6 | K6: =J6 | ... N6: =M6
A7: Revenue | B7: 0 | C7: 0 | D7: 0 | E7: 32760 | F7: 2760 | G7: 2760 | H7: 2760 | I7: 35520 | J7: 5520 | K7: 38611.2 | L7: 8611.2 | M7: 8611.2 | N7: 8611.2 | O7: =SUM(C7:N7) | P7: Debtors | Q7: =(N7*'Control Panel'!$B$8)*(1/4)+(N7*'Control Panel'!$B$9)
A9: Opening Cash | B9: 0 | C9: =B46 | D9: =C46 | E9: =D46 | F9: =E46 | G9: =F46 | H9: =G46 | I9: =H46 | J9: =I46 | ... N9: =M46
A10: Revenue (this month) | B10: 0 | C10: 0 | D10: 0 | E10: 32760 | F10: 2760 | G10: 2760 | H10: 2760 | I10: 35520 | J10: 5520 | K10: 38611.2 | L10: 8611.2 | M10: 8611.2 | N10: 8611.2 | O10: =SUM(B10:N10)
A11: Revenue (1 Week Credit) (this month) | B11: 0 | C11: 0 | D11: 0 | E11: 0 | F11: 0 | G11: 0 | H11: 0 | I11: 0 | J11: 0 | K11: 0 | L11: 0 | M11: 0 | N11: 0 | O11: =SUM(B11:N11)
A12: Revenue (1 Week Credit) (last month) | B12: 0 | C12: 0 | D12: 0 | E12: 0 | F12: 0 | G12: 0 | H12: 0 | I12: 0 | J12: 0 | K12: 0 | L12: 0 | M12: 0 | N12: 0 | O12: =SUM(B12:N12)
A13: Revenue (1 Month Credit) | B13: 0 | C13: 0 | D13: 0 | E13: 0 | F13: 0 | G13: 0 | H13: 0 | I13: 0 | J13: 0 | K13: 0 | L13: 0 | M13: 0 | N13: 0 | O13: =SUM(B13:N13)
A14: Total Revenue Cash In | B14: =SUM(B10:B13) | C14: =SUM(C10:C13) | D14: =SUM(D10:D13) | E14: =SUM(E10:E13) | F14: =SUM(F10:F13) | G14: =SUM(G10:G13) | H14: =SUM(H10:H13) | I14: =SUM(I10:I13) | ... O14: =SUM(O10:O13)
A16: Investment Received | B16: ='Startup & Pre-Opening Costs'!B29 | C16: 720000 | D16: 0 | E16: 0 | F16: 0 | G16: 0 | H16: 0 | I16: 0 | J16: 0 | K16: 0 | L16: 0 | M16: 0 | N16: 0 | O16: =SUM(B16:N16)
A18: Cost of Revenue (this month) | B18: 0 | C18: 300 | D18: 400 | E18: 1009 | F18: 1009 | G18: 1009 | H18: 1109 | I18: 1818 | J18: 1818 | K18: 2435.28 | L18: 2635.28 | M18: 2635.28 | N18: 2635.28 | O18: =SUM(B18:N18)
A19: Cost of Revenue (1 month supplier credit) | B19: 0 | C19: 0 | D19: 0 | E19: 0 | F19: 0 | G19: 0 | H19: 0 | I19: 0 | J19: 0 | K19: 0 | L19: 0 | M19: 0 | N19: 0 | O19: =SUM(B19:N19)
A20: Total Cost of Revenue Cash Out | B20: =SUM(B18:B19) | C20: =SUM(C18:C19) | D20: =SUM(D18:D19) | E20: =SUM(E18:E19) | F20: =SUM(F18:F19) | G20: =SUM(G18:G19) | H20: =SUM(H18:H19) | I20: =SUM(I18:I19) | ... O20: =SUM(O18:O19) | P20: Creditors | Q20: =(N7*'Control Panel'!$B$11)*('Control Panel'!$B$13)
A22: Contracts, Terms, GPDR | B22: ='Startup & Pre-Opening Costs'!C2 | C22: 0 | D22: 0 | E22: 0 | F22: 0 | G22: 0 | H22: 0 | I22: 0 | J22: 0 | K22: 0 | L22: 0 | M22: 0 | N22: 0 | O22: =SUM(B22:N22)
A23: Stationery, etc. | B23: ='Startup & Pre-Opening Costs'!C3 | F23: =B23 | G23: =C23 | H23: =D23 | I23: =E23 | J23: =F23 | K23: =G23 | L23: =H23 | M23: =I23 | N23: =J23 | O23: =SUM(B23:N23)
A24: Brochures | B24: ='Startup & Pre-Opening Costs'!C4 | F24: =B24 | G24: =C24 | H24: =D24 | I24: =E24 | J24: =F24 | K24: =G24 | L24: =H24 | M24: =I24 | N24: =J24 | O24: =SUM(B24:N24)
A25: Consultants | B25: ='Startup & Pre-Opening Costs'!C6 | C25: 4100 | D25: 1100 | E25: 1100 | F25: 1100 | G25: 1100 | H25: 1100 | I25: 1100 | J25: 1100 | K25: 1100 | L25: 1100 | M25: 1100 | N25: 1100 | O25: =SUM(B25:N25)
A26: Insurance | B26: ='Startup & Pre-Opening Costs'!C6 | C26: 600 | D26: 600 | E26: 600 | F26: 600 | G26: 600 | H26: 600 | I26: 600 | J26: 600 | K26: 600 | L26: 600 | M26: 600 | N26: 600 | O26: =SUM(B26:N26)
A27: Rent | B27: ='Startup & Pre-Opening Costs'!C7 | C27: 800 | D27: 800 | E27: 800 | F27: 800 | G27: 800 | H27: 1200 | I27: 1200 | J27: 1200 | K27: 1200 | L27: 1600 | M27: 1600 | N27: 1600 | O27: =SUM(B27:N27)
A28: R & D Design | B28: ='Startup & Pre-Opening Costs'!C8 | C28: 0 | D28: 0 | E28: 0 | F28: 0 | G28: 0 | H28: 0 | I28: 0 | J28: 0 | K28: 0 | L28: 0 | M28: 0 | N28: 0 | O28: =SUM(B28:N28)
A29: R & D Maintenance | B29: 0 | C29: 700 | D29: 800 | E29: 1340 | F29: 1340 | G29: 1340 | H29: 1440 | I29: 2080 | J29: 2080 | K29: 2620 | L29: 2820 | M29: 2820 | N29: 2820 | O29: =SUM(B29:N29)
A30: Staff | B30: ='Startup & Pre-Opening Costs'!C11 | C30: 25000 | D30: 32714 | E30: 32714 | F30: 32714 | G30: 32714 | H30: 40733 | I30: 47735.33 | J30: 47735.33 | K30: 48409.38 | L30: 58430.75 | M30: 58430.75 | N30: 58430.75 | O30: =SUM(B30:N30)
A31: Communications | B31: ='Startup & Pre-Opening Costs'!C13 | C31: 0 | D31: 0 | E31: 0 | F31: 0 | G31: 0 | H31: 0 | I31: 0 | J31: 0 | K31: 0 | L31: 0 | M31: 0 | N31: 0 | O31: =SUM(B31:N31)
A32: Incorporation Fees | B32: ='Startup & Pre-Opening Costs'!C15 | C32: 0 | D32: 0 | E32: 0 | F32: 0 | G32: 0 | H32: 0 | I32: 0 | J32: 0 | K32: 0 | L32: 0 | M32: 0 | N32: 0 | O32: =SUM(B32:N32)
A33: Website Design | B33: ='Startup & Pre-Opening Costs'!C16 | C33: 0 | D33: 0 | E33: 0 | F33: 0 | G33: 0 | H33: 0 | I33: 0 | J33: 0 | K33: 0 | L33: 0 | M33: 0 | N33: 0 | O33: =SUM(B33:N33)
A34: Website Maintenance | B34: 0 | C34: 0 | D34: 0 | E34: 0 | F34: 0 | G34: 0 | H34: 0 | I34: 0 | J34: 0 | K34: 0 | L34: 0 | M34: 0 | N34: 0 | O34: =SUM(B34:N34)
A35: Travel | B35: ='Startup & Pre-Opening Costs'!C18 | C35: 1650 | D35: 1650 | E35: 1719 | F35: 1719 | G35: 1719 | H35: 1819 | I35: 1888 | J35: 1888 | K35: 1965.28 | L35: 2065.28 | M35: 2065.28 | N35: 2065.28 | O35: =SUM(B35:N35)
A36: Vehicle Rental | B36: ='Startup & Pre-Opening Costs'!C20 | C36: 0 | D36: 0 | E36: 0 | F36: 0 | G36: 0 | H36: 0 | I36: 0 | J36: 0 | K36: 0 | L36: 0 | M36: 0 | N36: 0 | O36: =SUM(B36:N36)
A37: Marketing | B37: ='Startup & Pre-Opening Costs'!C21 | C37: 3133.33 | D37: 3133.33 | E37: 3188.53 | F37: 3188.53 | G37: 3188.53 | H37: 3188.53 | I37: 3243.73 | J37: 3243.73 | K37: 3305.56 | L37: 3305.56 | M37: 3305.56 | N37: 3305.56 | O37: =SUM(B37:N37)
A38: Total Expenses Cash Out | B38: =SUM(B22:B37) | C38: =SUM(C22:C37) | D38: =SUM(D22:D37) | E38: =SUM(E22:E37) | F38: =SUM(F22:F37) | G38: =SUM(G22:G37) | H38: =SUM(H22:H37) | I38: =SUM(I22:I37) | ... O38: =SUM(O22:O37)
A40: Computer Equpment | B40: ='Startup & Pre-Opening Costs'!B10 | C40: 0 | D40: 0 | E40: 0 | F40: 0 | G40: 0 | H40: 0 | I40: 0 | J40: 0 | K40: 0 | L40: 0 | M40: 0 | N40: 0 | O40: =SUM(B40:N40)
A41: Communications | B41: ='Startup & Pre-Opening Costs'!B12 | C41: 0 | D41: 0 | E41: 0 | F41: 0 | G41: 0 | H41: 0 | I41: 0 | J41: 0 | K41: 0 | L41: 0 | M41: 0 | N41: 0 | O41: =SUM(B41:N41)
A42: Furniture | B42: ='Startup & Pre-Opening Costs'!B14 | C42: 0 | D42: 0 | E42: 0 | F42: 0 | G42: 0 | H42: 0 | I42: 0 | J42: 0 | K42: 0 | L42: 0 | M42: 0 | N42: 0 | O42: =SUM(B42:N42)
A43: Buildings | B43: ='Startup & Pre-Opening Costs'!B19 | C43: 0 | D43: 0 | E43: 0 | F43: 0 | G43: 0 | H43: 0 | I43: 0 | J43: 0 | K43: 0 | L43: 0 | M43: 0 | N43: 0 | O43: =SUM(B43:N43)
A44: Total Assets Cash Out | B44: =SUM(B40:B43) | C44: =SUM(C40:C43) | D44: =SUM(D40:D43) | E44: =SUM(E40:E43) | F44: =SUM(F40:F43) | G44: =SUM(G40:G43) | H44: =SUM(H40:H43) | I44: =SUM(I40:I43) | ... O44: =SUM(O40:O43)
A46: Closing Cash | B46: =B9+B14-B20-B38-B44+B16 | C46: =C9+C14-C20-C38-C44+C16 | D46: =D9+D14-D20-D38-D44+D16 | E46: =E9+E14-E20-E38-E44+E16 | F46: =F9+F14-F20-F38-F44+F16 | G46: =G9+G14-G20-G38-G44+G16 | H46: =H9+H14-H20-H38-H44+H16 | I46: =I9+I14-I20-I38-I44+I16 | ... N46: =N9+N14-N20-N38-N44+N16
...

Sheet Financial Statements
A1: Income Statement
B2: 1 | C2: 2 | D2: 3 | E2: 4 | F2: 5
A3: Revenue | B3: ='Year 1 Cash Budget'!O7 | C3: ='Year 2 Cash Budget'!N7 | D3: ='Year 3 Cash Budget'!N7 | E3: ='Year 4 Cash Budget'!N7 | F3: ='Year 5 Cash Budget'!N7
A5: Cost of Revenue | B5: ='Control Panel'!$B$11*B3 | C5: ='Control Panel'!$B$11*C3 | D5: ='Control Panel'!$B$11*D3 | E5: ='Control Panel'!$B$11*E3 | F5: ='Control Panel'!$B$11*F3
A7: Gross Profit | B7: =B3-B5 | C7: =C3-C5 | D7: =D3-D5 | E7: =E3-E5 | F7: =F3-F5
A9: Expenses | B9: ='Year 1 Cash Budget'!O38 | C9: ='Year 2 Cash Budget'!N38 | D9: ='Year 3 Cash Budget'!N38 | E9: ='Year 4 Cash Budget'!N38 | F9: ='Year 5 Cash Budget'!N38
A11: Founder Profit Share | B11: =IF(B7-B9<=0,0,'Control Panel'!$B$16*(B7-B9)) | C11: =IF(C7-C9<=0,0,'Control Panel'!$B$16*(C7-C9)) | D11: =IF(D7-D9<=0,0,'Control Panel'!$B$16*(D7-D9)) | E11: =IF(E7-E9<=0,0,'Control Panel'!$B$16*(E7-E9)) | F11: =IF(F7-F9<=0,0,'Control Panel'!$B$16*(F7-F9))
A13: Net Profit | B13: =B7-B9-B11 | C13: =C7-C9-C11 | D13: =D7-D9-D11 | E13: =E7-E9-E11 | F13: =F7-F9-F11
A15: Balance Sheet
B16: 1 | C16: 2 | D16: 3 | E16: 4 | F16: 5
A17: Assets | B17: ='Year 1 Cash Budget'!O44 | C17: ='Year 2 Cash Budget'!O44+B17 | D17: ='Year 3 Cash Budget'!O44+C17 | E17: ='Year 4 Cash Budget'!O44+D17 | F17: ='Year 5 Cash Budget'!O44+E17
A19: Cash | B19: ='Year 1 Cash Budget'!N46-B11 | C19: ='Year 2 Cash Budget'!M46-C11 | D19: ='Year 3 Cash Budget'!M46-D11 | E19: ='Year 4 Cash Budget'!M46-E11 | F19: ='Year 5 Cash Budget'!M46-F11
A20: Debtors | B20: ='Year 1 Cash Budget'!Q7 | C20: ='Year 2 Cash Budget'!P7 | D20: ='Year 3 Cash Budget'!P7 | E20: ='Year 4 Cash Budget'!P7 | F20: ='Year 5 Cash Budget'!P7
A22: Creditors | B22: ='Year 1 Cash Budget'!Q20 | C22: ='Year 2 Cash Budget'!P20 | D22: ='Year 3 Cash Budget'!P20 | E22: ='Year 4 Cash Budget'!P20 | F22: ='Year 5 Cash Budget'!P20
A24: Net Worth | B24: =B17+B19+B20-B22 | C24: =C17+C19+C20-C22 | D24: =D17+D19+D20-D22 | E24: =E17+E19+E20-E22 | F24: =F17+F19+F20-F22
A26: Profit | B26: =B13 | C26: =C13 | D26: =D13 | E26: =E13 | F26: =F13
A27: Retained Profit | B27: 0 | C27: =SUM(B26:B27) | D27: =SUM(C26:C27) | E27: =SUM(D26:D27) | F27: =SUM(E26:E27)
A28: Investment | B28: ='Year 1 Cash Budget'!O16 | C28: ='Year 2 Cash Budget'!P16+B28 | D28: ='Year 3 Cash Budget'!P16+C28 | E28: ='Year 4 Cash Budget'!P16+D28 | F28: ='Year 5 Cash Budget'!P16+E28
A29: Net Worth | B29: =SUM(B26:B28) | C29: =SUM(C26:C28) | D29: =SUM(D26:D28) | E29: =SUM(E26:E28) | F29: =SUM(F26:F28)
A31: Company Worth > Investment | B31: =IF(B24>=B28,"Yes","No") | C31: =IF(AND(C24>=C28,B24<B28),"Yes","No") | D31: =IF(AND(D24>=D28,C24<C28),"Yes","No") | E31: =IF(AND(E24>=E28,D24<D28),"Yes","No") | F31: =IF(AND(F24>=F28,E24<E28),"Yes","No")
A32: Investor Return | B32: =B28*'Control Panel'!$B$15 | C32: =B32+(C28*'Control Panel'!$B$15) | D32: =C32+(D28*'Control Panel'!$B$15) | E32: =D32+(E28*'Control Panel'!$B$15) | F32: =E32+(F28*'Control Panel'!$B$15)
A33: Investor Buyout | B33: =IF(B35<B19,"Yes","No") | C33: =IF(AND(C35<C19,B35<B19),"Yes","No") | D33: =IF(AND(D35<D19,C35<C19),"Yes","No") | E33: =IF(AND(E35<E19,D35<D19),"Yes","No") | F33: =IF(AND(F35<F19,E35<E19),"Yes","No")
B34: ='Performance Dashboard'!B1 | C34: ='Performance Dashboard'!C1 | D34: ='Performance Dashboard'!D1 | E34: ='Performance Dashboard'!E1 | F34: ='Performance Dashboard'!F1
A35: Investor Buyout Cost | B35: =B32+B28 | C35: =C32+C28 | D35: =D32+D28 | E35: =E32+E28 | F35: =F32+F28

Sheet Year 2 Cash Budget
B1: Month 13 | C1: Month 14 | D1: Month 15 | E1: Month 16 | F1: Month 17 | G1: Month 18 | H1: Month 19 | I1: Month 20 | J1: Month 21 | K1: Month 22 | L1: Month 23 | M1: Month 24 | N1: Year 2
A2: Revenue Calculations
A3: Average Sale | B3: 2870 | C3: 4368 | D3: 4534 | E3: 4232 | F3: 4598 | G3: 4598 | H3: 4742 | I3: 5062 | J3: 5533 | K3: 5288 | L3: 5334 | M3: 5315
A4: Customers | B4: 3 | C4: 5 | D4: 9 | E4: 11 | F4: 13 | G4: 13 | H4: 20 | I4: 20 | J4: 24 | K4: 28 | L4: 29 | M4: 29 | N4: =SUM(B4:M4)
A5: Customer Growth Factor | B5: ='Year 1 Cash Budget'!N5*(1+'Control Panel'!$B$4) | C5: =B5*(1+'Control Panel'!$B$4) | D5: =C5*1.05 | E5: =D5*1.05 | F5: =E5*1.05 | G5: =F5*1.05 | H5: =G5*1.05 | I5: =H5*1.05 | J5: =I5*1.05 | K5: =J5*1.05 | ... M5: =L5*1.05
A6: Seasonality Index | B6: ='Year 1 Cash Budget'!C6 | C6: ='Year 1 Cash Budget'!D6 | D6: ='Year 1 Cash Budget'!E6 | E6: ='Year 1 Cash Budget'!F6 | F6: ='Year 1 Cash Budget'!G6 | G6: ='Year 1 Cash Budget'!H6 | H6: ='Year 1 Cash Budget'!I6 | I6: ='Year 1 Cash Budget'!J6 | ... M6: ='Year 1 Cash Budget'!N6
A7: Revenue | B7: 8611.2 | C7: 81840 | D7: 160809.6 | E7: 106550.4 | F7: 119779.2 | G7: 59779.2 | H7: 304848 | I7: 131230.13 | J7: 252795.24 | K7: 268056.62 | L7: 184694.04 | M7: 154120.79 | N7: =SUM(B7:M7) | O7: Debtors | P7: =(M7*'Control Panel'!$B$8)*(1/4)+(M7*'Control Panel'!$B$9)
A9: Opening Cash | B9: ='Financial Statements'!B19 | C9: =B46 | D9: =C46 | E9: =D46 | F9: =E46 | G9: =F46 | H9: =G46 | I9: =H46 | J9: =I46 | ... M9: =L46
A10: Revenue (this month) | B10: 8611.2 | C10: 81840 | D10: 160809.6 | E10: 106550.4 | F10: 119779.2 | G10: 59779.2 | H10: 304848 | I10: 131230.13 | J10: 252795.24 | K10: 268056.62 | L10: 184694.04 | M10: 154120.79 | N10: =SUM(B10:M10)
A11: Revenue (1 Week Credit) (this month) | B11: 0 | C11: 0 | D11: 0 | E11: 0 | F11: 0 | G11: 0 | H11: 0 | I11: 0 | J11: 0 | K11: 0 | L11: 0 | M11: 0 | N11: =SUM(B11:M11)
A12: Revenue (1 Week Credit) (last month) | B12: 0 | C12: 0 | D12: 0 | E12: 0 | F12: 0 | G12: 0 | H12: 0 | I12: 0 | J12: 0 | K12: 0 | L12: 0 | M12: 0 | N12: =SUM(B12:M12)
A13: Revenue (1 Month Credit) | B13: 0 | C13: 0 | D13: 0 | E13: 0 | F13: 0 | G13: 0 | H13: 0 | I13: 0 | J13: 0 | K13: 0 | L13: 0 | M13: 0 | N13: =SUM(B13:M13)
A14: Total Revenue Cash In | B14: =SUM(B10:B13) | C14: =SUM(C10:C13) | D14: =SUM(D10:D13) | E14: =SUM(E10:E13) | F14: =SUM(F10:F13) | G14: =SUM(G10:G13) | H14: =SUM(H10:H13) | I14: =SUM(I10:I13) | ... N14: =SUM(N10:N13)
A16: Investment Received | B16: 2000000 | C16: 0 | D16: 0 | E16: 0 | F16: 0 | G16: 0 | H16: 0 | I16: 0 | J16: 0 | K16: 0 | L16: 0 | M16: 0 | N16: =SUM(B16:M16)
A18: Cost of Revenue (this month) | B18: 3435.28 | C18: 5926 | D18: 10040.24 | E18: 11263.76 | F18: 13954.48 | G18: 14154.48 | H18: 20971.2 | I18: 21690.75 | J18: 26999.88 | K18: 29991.42 | L18: 30517.35 | M18: 30413.02 | N18: =SUM(B18:M18)
A19: Cost of Revenue (1 month supplier credit) | B19: 0 | C19: 0 | D19: 0 | E19: 0 | F19: 0 | G19: 0 | H19: 0 | I19: 0 | J19: 0 | K19: 0 | L19: 0 | M19: 0 | N19: =SUM(B19:M19)
A20: Total Cost of Revenue Cash Out | B20: =SUM(B18:B19) | C20: =SUM(C18:C19) | D20: =SUM(D18:D19) | E20: =SUM(E18:E19) | F20: =SUM(F18:F19) | G20: =SUM(G18:G19) | H20: =SUM(H18:H19) | I20: =SUM(I18:I19) | ... N20: =SUM(N18:N19) | O20: Creditors | P20: =(M7*'Control Panel'!$B$11)*('Control Panel'!$B$13)
A22: Contracts, Terms, GPDR | B22: 0 | C22: 0 | D22: 0 | E22: 0 | F22: 0 | G22: 0 | H22: 0 | I22: 0 | J22: 0 | K22: 0 | L22: 0 | M22: 0 | N22: =SUM(B22:M22)
A23: Stationery, etc. | B23: ='Year 1 Cash Budget'!C23 | C23: ='Year 1 Cash Budget'!D23 | D23: ='Year 1 Cash Budget'!E23 | E23: ='Year 1 Cash Budget'!F23 | F23: ='Year 1 Cash Budget'!G23 | G23: ='Year 1 Cash Budget'!H23 | H23: ='Year 1 Cash Budget'!I23 | I23: ='Year 1 Cash Budget'!J23 | ... M23: ='Year 1 Cash Budget'!N23 | N23: =SUM(B23:M23)
A24: Brochures | B24: ='Year 1 Cash Budget'!C24 | C24: ='Year 1 Cash Budget'!D24 | D24: ='Year 1 Cash Budget'!E24 | E24: ='Year 1 Cash Budget'!F24 | F24: ='Year 1 Cash Budget'!G24 | G24: ='Year 1 Cash Budget'!H24 | H24: ='Year 1 Cash Budget'!I24 | I24: ='Year 1 Cash Budget'!J24 | ... M24: ='Year 1 Cash Budget'!N24 | N24: =SUM(B24:M24)
A25: Consultants | B25: 52600 | C25: 2600 | D25: 2600 | E25: 2600 | F25: 2600 | G25: 2600 | H25: 2600 | I25: 2600 | J25: 2600 | K25: 2600 | L25: 2600 | M25: 2600 | N25: =SUM(B25:M25)
A26: Insurance | B26: 1150 | C26: 1150 | D26: 1150 | E26: 1150 | F26: 1150 | G26: 1150 | H26: 1150 | I26: 1150 | J26: 1150 | K26: 1150 | L26: 1150 | M26: 1150 | N26: =SUM(B26:M26)
A27: Rent | B27: 4040 | C27: 4040 | D27: 4040 | E27: 4040 | F27: 4040 | G27: 4040 | H27: 4040 | I27: 4040 | J27: 4040 | K27: 4040 | L27: 4040 | M27: 4040 | N27: =SUM(B27:M27)
A28: R & D Design | B28: 0 | C28: 0 | D28: 0 | E28: 0 | F28: 0 | G28: 0 | H28: 0 | I28: 0 | J28: 0 | K28: 0 | L28: 0 | M28: 0 | N28: =SUM(B28:M28)
A29: R & D Maintenance | B29: 4020 | C29: 6180 | D29: 9820 | E29: 10900 | F29: 13260 | G29: 13460 | H29: 19400 | I29: 19960 | J29: 24480 | K29: 27090 | L29: 27450 | M29: 27360 | N29: =SUM(B29:M29)
A30: Staff | B30: 58430.75 | C30: 58430.75 | D30: 73478.52 | E30: 73478.52 | F30: 81421.27 | G30: 89678.17 | H30: 89678.17 | I30: 95003 | J30: 105578.33 | K30: 105578.33 | L30: 105578.33 | M30: 105578.33 | N30: =SUM(B30:M30)
A31: Communications | B31: 0 | C31: 0 | D31: 0 | E31: 0 | F31: 0 | G31: 0 | H31: 0 | I31: 0 | J31: 0 | K31: 0 | L31: 0 | M31: 0 | N31: =SUM(B31:M31)
A32: Incorporation Fees | B32: 0 | C32: 0 | D32: 0 | E32: 0 | F32: 0 | G32: 0 | H32: 0 | I32: 0 | J32: 0 | K32: 0 | L32: 0 | M32: 0 | N32: =SUM(B32:M32)
A33: Website Design | B33: 0 | C33: 0 | D33: 0 | E33: 0 | F33: 0 | G33: 0 | H33: 0 | I33: 0 | J33: 0 | K33: 0 | L33: 0 | M33: 0 | N33: =SUM(B33:M33)
A34: Website Maintenance | B34: 0 | C34: 0 | D34: 0 | E34: 0 | F34: 0 | G34: 0 | H34: 0 | I34: 0 | J34: 0 | K34: 0 | L34: 0 | M34: 0 | N34: =SUM(B34:M34)
A35: Travel | B35: 3915.28 | C35: 4246 | D35: 4720.24 | E35: 4863.76 | F35: 5194.48 | G35: 5294.48 | H35: 6171.2 | I35: 6330.75 | J35: 7219.88 | K35: 7601.42 | L35: 7767.35 | M35: 7753.02 | N35: =SUM(B35:M35)
A36: Vehicle Rental | B36: 0 | C36: 0 | D36: 0 | E36: 0 | F36: 0 | G36: 0 | H36: 0 | I36: 0 | J36: 0 | K36: 0 | L36: 0 | M36: 0 | N36: =SUM(B36:M36)
A37: Marketing | B37: 6222.22 | C37: 6486.8 | D37: 6866.19 | E37: 6981.01 | F37: 7245.58 | G37: 7245.58 | H37: 7946.96 | I37: 8074.6 | J37: 8705.9 | K37: 9011.13 | L37: 9143.88 | M37: 9132.42 | N37: =SUM(B37:M37)
A38: Total Expenses Cash Out | B38: =SUM(B22:B37) | C38: =SUM(C22:C37) | D38: =SUM(D22:D37) | E38: =SUM(E22:E37) | F38: =SUM(F22:F37) | G38: =SUM(G22:G37) | H38: =SUM(H22:H37) | I38: =SUM(I22:I37) | ... N38: =SUM(N22:N37)
A40: Computer Equpment | B40: 0 | C40: 0 | D40: 0 | E40: 0 | F40: 0 | G40: 0 | H40: 0 | I40: 0 | J40: 0 | K40: 0 | L40: 0 | M40: 0 | N40: =SUM(B40:M40)
A41: Communications | B41: 0 | C41: 0 | D41: 0 | E41: 0 | F41: 0 | G41: 0 | H41: 0 | I41: 0 | J41: 0 | K41: 0 | L41: 0 | M41: 0 | N41: =SUM(B41:M41)
A42: Furniture | B42: 0 | C42: 0 | D42: 0 | E42: 0 | F42: 0 | G42: 0 | H42: 0 | I42: 0 | J42: 0 | K42: 0 | L42: 0 | M42: 0 | N42: =SUM(B42:M42)
A43: Buildings | B43: 0 | C43: 0 | D43: 0 | E43: 0 | F43: 0 | G43: 0 | H43: 0 | I43: 0 | J43: 0 | K43: 0 | L43: 0 | M43: 0 | N43: =SUM(B43:M43)
A44: Total Assets Cash Out | B44: =SUM(B40:B43) | C44: =SUM(C40:C43) | D44: =SUM(D40:D43) | E44: =SUM(E40:E43) | F44: =SUM(F40:F43) | G44: =SUM(G40:G43) | H44: =SUM(H40:H43) | I44: =SUM(I40:I43) | ... N44: =SUM(N40:N43)
A46: Closing Cash | B46: =B9+B14-B20-B38-B44+B16 | C46: =C9+C14-C20-C38-C44+C16 | D46: =D9+D14-D20-D38-D44+D16 | E46: =E9+E14-E20-E38-E44+E16 | F46: =F9+F14-F20-F38-F44+F16 | G46: =G9+G14-G20-G38-G44+G16 | H46: =H9+H14-H20-H38-H44+H16 | I46: =I9+I14-I20-I38-I44+I16 | ... M46: =M9+M14-M20-M38-M44+M16
...

Sheet Year 3 Cash Budget
B1: Month 25 | C1: Month 26 | D1: Month 27 | E1: Month 28 | F1: Month 29 | G1: Month 30 | H1: Month 31 | I1: Month 32 | J1: Month 33 | K1: Month 34 | L1: Month 35 | M1: Month 36 | N1: Year 3
A2: Revenue Calculations
A3: Average Sale | B3: 5295 | C3: 5521 | D3: 5181 | E3: 5326 | F3: 5320 | G3: 5402 | H3: 5488 | I3: 5498 | J3: 5561 | K3: 5568 | L3: 5631 | M3: 5642
A4: Customers | B4: 29 | C4: 34 | D4: 39 | E4: 43 | F4: 53 | G4: 52 | H4: 56 | I4: 58 | J4: 61 | K4: 70 | L4: 74 | M4: 79 | N4: =SUM(B4:M4)
A5: Customer Growth Factor | B5: ='Year 2 Cash Budget'!M5*(1+'Control Panel'!$B$4) | C5: =B5*(1+'Control Panel'!$B$4) | D5: =C5*(1+'Control Panel'!$B$4) | E5: =D5*(1+'Control Panel'!$B$4) | F5: =E5*(1+'Control Panel'!$B$4) | G5: =F5*(1+'Control Panel'!$B$4) | H5: =G5*(1+'Control Panel'!$B$4) | I5: =H5*(1+'Control Panel'!$B$4) | J5: =I5*(1+'Control Panel'!$B$4) | ... M5: =L5*(1+'Control Panel'!$B$4)
A6: Seasonality Index | B6: ='Year 2 Cash Budget'!B6 | C6: ='Year 2 Cash Budget'!C6 | D6: ='Year 2 Cash Budget'!D6 | E6: ='Year 2 Cash Budget'!E6 | F6: ='Year 2 Cash Budget'!F6 | G6: ='Year 2 Cash Budget'!G6 | H6: ='Year 2 Cash Budget'!H6 | I6: ='Year 2 Cash Budget'!I6 | ... M6: ='Year 2 Cash Budget'!M6
A7: Revenue | B7: 153547.54 | C7: 337700.86 | D7: 352053.7 | E7: 348996.35 | F7: 581969.51 | G7: 280898.73 | H7: 427343.85 | I7: 408880.92 | J7: 429240.23 | K7: 659769.13 | L7: 536675.87 | M7: 625742.36 | N7: =SUM(B7:M7) | O7: Debtors | P7: =(M7*'Control Panel'!$B$8)*(1/4)+(M7*'Control Panel'!$B$9)
A9: Opening Cash | B9: ='Financial Statements'!C19 | C9: =B46 | D9: =C46 | E9: =D46 | F9: =E46 | G9: =F46 | H9: =G46 | I9: =H46 | J9: =I46 | ... M9: =L46
A10: Revenue (this month) | B10: 153547.54 | C10: 337700.86 | D10: 352053.7 | E10: 348996.35 | F10: 581969.51 | G10: 280898.73 | H10: 427343.85 | I10: 408880.92 | J10: 429240.23 | K10: 659769.13 | L10: 536675.87 | M10: 625742.36 | N10: =SUM(B10:M10)
A11: Revenue (1 Week Credit) (this month) | B11: 0 | C11: 0 | D11: 0 | E11: 0 | F11: 0 | G11: 0 | H11: 0 | I11: 0 | J11: 0 | K11: 0 | L11: 0 | M11: 0 | N11: =SUM(B11:M11)
A12: Revenue (1 Week Credit) (last month) | B12: 0 | C12: 0 | D12: 0 | E12: 0 | F12: 0 | G12: 0 | H12: 0 | I12: 0 | J12: 0 | K12: 0 | L12: 0 | M12: 0 | N12: =SUM(B12:M12)
A13: Revenue (1 Month Credit) | B13: 0 | C13: 0 | D13: 0 | E13: 0 | F13: 0 | G13: 0 | H13: 0 | I13: 0 | J13: 0 | K13: 0 | L13: 0 | M13: 0 | N13: =SUM(B13:M13)
A14: Total Revenue Cash In | B14: =SUM(B10:B13) | C14: =SUM(C10:C13) | D14: =SUM(D10:D13) | E14: =SUM(E10:E13) | F14: =SUM(F10:F13) | G14: =SUM(G10:G13) | H14: =SUM(H10:H13) | I14: =SUM(I10:I13) | ... N14: =SUM(N10:N13)
A16: Investment Received | B16: 10000000 | C16: 0 | D16: 0 | E16: 0 | F16: 0 | G16: 0 | H16: 0 | I16: 0 | J16: 0 | K16: 0 | L16: 0 | M16: 0 | N16: =SUM(B16:M16)
A18: Cost of Revenue (this month) | B18: 31008.69 | C18: 36542.52 | D18: 39511.34 | E18: 44414.91 | F18: 53659.24 | G18: 53452.47 | H18: 58253.6 | I18: 59802.02 | J18: 61661.01 | K18: 70754.23 | L18: 75476.9 | M18: 80793.56 | N18: =SUM(B18:M18)
A19: Cost of Revenue (1 month supplier credit) | B19: 0 | C19: 0 | D19: 0 | E19: 0 | F19: 0 | G19: 0 | H19: 0 | I19: 0 | J19: 0 | K19: 0 | L19: 0 | M19: 0 | N19: =SUM(B19:M19)
A20: Total Cost of Revenue Cash Out | B20: =SUM(B18:B19) | C20: =SUM(C18:C19) | D20: =SUM(D18:D19) | E20: =SUM(E18:E19) | F20: =SUM(F18:F19) | G20: =SUM(G18:G19) | H20: =SUM(H18:H19) | I20: =SUM(I18:I19) | ... N20: =SUM(N18:N19) | O20: Creditors | P20: =(M7*'Control Panel'!$B$11)*('Control Panel'!$B$13)
A22: Contracts, Terms, GPDR | B22: 0 | C22: 0 | D22: 0 | E22: 0 | F22: 0 | G22: 0 | H22: 0 | I22: 0 | J22: 0 | K22: 0 | L22: 0 | M22: 0 | N22: =SUM(B22:M22)
A23: Stationery, etc. | B23: ='Year 2 Cash Budget'!B23 | C23: ='Year 2 Cash Budget'!C23 | D23: ='Year 2 Cash Budget'!D23 | E23: ='Year 2 Cash Budget'!E23 | F23: ='Year 2 Cash Budget'!F23 | G23: ='Year 2 Cash Budget'!G23 | H23: ='Year 2 Cash Budget'!H23 | I23: ='Year 2 Cash Budget'!I23 | ... M23: ='Year 2 Cash Budget'!M23 | N23: =SUM(B23:M23)
A24: Brochures | B24: ='Year 2 Cash Budget'!B24 | C24: ='Year 2 Cash Budget'!C24 | D24: ='Year 2 Cash Budget'!D24 | E24: ='Year 2 Cash Budget'!E24 | F24: ='Year 2 Cash Budget'!F24 | G24: ='Year 2 Cash Budget'!G24 | H24: ='Year 2 Cash Budget'!H24 | I24: ='Year 2 Cash Budget'!I24 | ... M24: ='Year 2 Cash Budget'!M24 | N24: =SUM(B24:M24)
A25: Consultants | B25: 105700 | C25: 5700 | D25: 5700 | E25: 5700 | F25: 5700 | G25: 5700 | H25: 5700 | I25: 5700 | J25: 5700 | K25: 5700 | L25: 5700 | M25: 5700 | N25: =SUM(B25:M25)
A26: Insurance | B26: 1500 | C26: 1500 | D26: 1500 | E26: 1500 | F26: 1500 | G26: 1500 | H26: 1500 | I26: 1500 | J26: 1500 | K26: 1500 | L26: 1500 | M26: 1500 | N26: =SUM(B26:M26)
A27: Rent | B27: 5040 | C27: 5040 | D27: 5040 | E27: 5040 | F27: 5040 | G27: 5040 | H27: 5040 | I27: 5040 | J27: 5040 | K27: 5040 | L27: 5040 | M27: 5040 | N27: =SUM(B27:M27)
A28: R & D Design | B28: 0 | C28: 0 | D28: 0 | E28: 0 | F28: 0 | G28: 0 | H28: 0 | I28: 0 | J28: 0 | K28: 0 | L28: 0 | M28: 0 | N28: =SUM(B28:M28)
A29: R & D Maintenance | B29: 28670 | C29: 33350 | D29: 35960 | E29: 40190 | F29: 48110 | G29: 47930 | H29: 52070 | I29: 53330 | J29: 54680 | K29: 62510 | L29: 66560 | M29: 71150 | N29: =SUM(B29:M29)
A30: Staff | B30: 105578.33 | C30: 105578.33 | D30: 105578.33 | E30: 105578.33 | F30: 105578.33 | G30: 105578.33 | H30: 105578.33 | I30: 105578.33 | J30: 107966.31 | K30: 107966.31 | L30: 107966.31 | M30: 107966.31 | N30: =SUM(B30:M30)
A31: Communications | B31: 0 | C31: 0 | D31: 0 | E31: 0 | F31: 0 | G31: 0 | H31: 0 | I31: 0 | J31: 0 | K31: 0 | L31: 0 | M31: 0 | N31: =SUM(B31:M31)
A32: Incorporation Fees | B32: 0 | C32: 0 | D32: 0 | E32: 0 | F32: 0 | G32: 0 | H32: 0 | I32: 0 | J32: 0 | K32: 0 | L32: 0 | M32: 0 | N32: =SUM(B32:M32)
A33: Website Design | B33: 0 | C33: 0 | D33: 0 | E33: 0 | F33: 0 | G33: 0 | H33: 0 | I33: 0 | J33: 0 | K33: 0 | L33: 0 | M33: 0 | N33: =SUM(B33:M33)
A34: Website Maintenance | B34: 0 | C34: 0 | D34: 0 | E34: 0 | F34: 0 | G34: 0 | H34: 0 | I34: 0 | J34: 0 | K34: 0 | L34: 0 | M34: 0 | N34: =SUM(B34:M34)
A35: Travel | B35: 9988.69 | C35: 10842.52 | D35: 11201.34 | E35: 11874.91 | F35: 13199.24 | G35: 13172.47 | H35: 13833.6 | I35: 14122.02 | J35: 14631.01 | K35: 15894.23 | L35: 16566.9 | M35: 17293.56 | N35: =SUM(B35:M35)
A36: Vehicle Rental | B36: 0 | C36: 0 | D36: 0 | E36: 0 | F36: 0 | G36: 0 | H36: 0 | I36: 0 | J36: 0 | K36: 0 | L36: 0 | M36: 0 | N36: =SUM(B36:M36)
A37: Marketing | B37: 15454.28 | C37: 16137.35 | D37: 16424.41 | E37: 16963.26 | F37: 18022.72 | G37: 18001.31 | H37: 18530.21 | I37: 18760.95 | J37: 19168.14 | K37: 20178.72 | L37: 20716.85 | M37: 21298.18 | N37: =SUM(B37:M37)
A38: Total Expenses Cash Out | B38: =SUM(B22:B37) | C38: =SUM(C22:C37) | D38: =SUM(D22:D37) | E38: =SUM(E22:E37) | F38: =SUM(F22:F37) | G38: =SUM(G22:G37) | H38: =SUM(H22:H37) | I38: =SUM(I22:I37) | ... N38: =SUM(N22:N37)
A40: Computer Equpment | B40: 0 | C40: 0 | D40: 0 | E40: 0 | F40: 0 | G40: 0 | H40: 0 | I40: 0 | J40: 0 | K40: 0 | L40: 0 | M40: 0 | N40: =SUM(B40:M40)
A41: Communications | B41: 0 | C41: 0 | D41: 0 | E41: 0 | F41: 0 | G41: 0 | H41: 0 | I41: 0 | J41: 0 | K41: 0 | L41: 0 | M41: 0 | N41: =SUM(B41:M41)
A42: Furniture | B42: 0 | C42: 0 | D42: 0 | E42: 0 | F42: 0 | G42: 0 | H42: 0 | I42: 0 | J42: 0 | K42: 0 | L42: 0 | M42: 0 | N42: =SUM(B42:M42)
A43: Buildings | B43: 0 | C43: 0 | D43: 0 | E43: 0 | F43: 0 | G43: 0 | H43: 0 | I43: 0 | J43: 0 | K43: 0 | L43: 0 | M43: 0 | N43: =SUM(B43:M43)
A44: Total Assets Cash Out | B44: =SUM(B40:B43) | C44: =SUM(C40:C43) | D44: =SUM(D40:D43) | E44: =SUM(E40:E43) | F44: =SUM(F40:F43) | G44: =SUM(G40:G43) | H44: =SUM(H40:H43) | I44: =SUM(I40:I43) | ... N44: =SUM(N40:N43)
A46: Closing Cash | B46: =B9+B14-B20-B38-B44+B16 | C46: =C9+C14-C20-C38-C44+C16 | D46: =D9+D14-D20-D38-D44+D16 | E46: =E9+E14-E20-E38-E44+E16 | F46: =F9+F14-F20-F38-F44+F16 | G46: =G9+G14-G20-G38-G44+G16 | H46: =H9+H14-H20-H38-H44+H16 | I46: =I9+I14-I20-I38-I44+I16 | ... M46: =M9+M14-M20-M38-M44+M16
...

Sheet Year 4 Cash Budget
B1: Month 37 | C1: Month 38 | D1: Month 39 | E1: Month 40 | F1: Month 41 | G1: Month 42 | H1: Month 43 | I1: Month 44 | J1: Month 45 | K1: Month 46 | L1: Month 47 | M1: Month 48 | N1: Year 4
A2: Revenue Calculations
A3: Average Sale | B3: 5575 | C3: 5609 | D3: 5490 | E3: 5410 | F3: 5404 | G3: 5434 | H3: 5413 | I3: 5392 | J3: 5554 | K3: 5546 | L3: 5517 | M3: 5488
A4: Customers | B4: 87 | C4: 98 | D4: 107 | E4: 115 | F4: 125 | G4: 132 | H4: 141 | I4: 148 | J4: 159 | K4: 170 | L4: 180 | M4: 190 | N4: =SUM(B4:M4)
A5: Customer Growth Factor | B5: ='Year 3 Cash Budget'!M5*(1+'Control Panel'!$B$4) | C5: =B5*(1+'Control Panel'!$B$4) | D5: =C5*(1+'Control Panel'!$B$4) | E5: =D5*(1+'Control Panel'!$B$4) | F5: =E5*(1+'Control Panel'!$B$4) | G5: =F5*(1+'Control Panel'!$B$4) | H5: =G5*(1+'Control Panel'!$B$4) | I5: =H5*(1+'Control Panel'!$B$4) | J5: =I5*(1+'Control Panel'!$B$4) | ... M5: =L5*(1+'Control Panel'!$B$4)
A6: Seasonality Index | B6: ='Year 3 Cash Budget'!B6 | C6: ='Year 3 Cash Budget'!C6 | D6: ='Year 3 Cash Budget'!D6 | E6: ='Year 3 Cash Budget'!E6 | F6: ='Year 3 Cash Budget'!F6 | G6: ='Year 3 Cash Budget'!G6 | H6: ='Year 3 Cash Budget'!H6 | I6: ='Year 3 Cash Budget'!I6 | ... M6: ='Year 3 Cash Budget'!M6
A7: Revenue | B7: 725067.6 | C7: 909649.8 | D7: 857433.98 | E7: 862113.53 | F7: 975495.83 | G7: 987329.52 | H7: 1033212.7 | I7: 1008068.5 | J7: 1213009.2 | K7: 1332843.6 | L7: 1292991.5 | M7: 1342780.7 | N7: =SUM(B7:M7) | O7: Debtors | P7: =(M7*'Control Panel'!$B$8)*(1/4)+(M7*'Control Panel'!$B$9)
A9: Opening Cash | B9: ='Financial Statements'!D19 | C9: =B46 | D9: =C46 | E9: =D46 | F9: =E46 | G9: =F46 | H9: =G46 | I9: =H46 | J9: =I46 | ... M9: =L46
A10: Revenue (this month) | B10: 725067.6 | C10: 909649.8 | D10: 857433.98 | E10: 862113.53 | F10: 975495.83 | G10: 987329.52 | H10: 1033212.7 | I10: 1008068.5 | J10: 1213009.2 | K10: 1332843.6 | L10: 1292991.5 | M10: 1342780.7 | N10: =SUM(B10:M10)
A11: Revenue (1 Week Credit) (this month) | B11: 0 | C11: 0 | D11: 0 | E11: 0 | F11: 0 | G11: 0 | H11: 0 | I11: 0 | J11: 0 | K11: 0 | L11: 0 | M11: 0 | N11: =SUM(B11:M11)
A12: Revenue (1 Week Credit) (last month) | B12: 0 | C12: 0 | D12: 0 | E12: 0 | F12: 0 | G12: 0 | H12: 0 | I12: 0 | J12: 0 | K12: 0 | L12: 0 | M12: 0 | N12: =SUM(B12:M12)
A13: Revenue (1 Month Credit) | B13: 0 | C13: 0 | D13: 0 | E13: 0 | F13: 0 | G13: 0 | H13: 0 | I13: 0 | J13: 0 | K13: 0 | L13: 0 | M13: 0 | N13: =SUM(B13:M13)
A14: Total Revenue Cash In | B14: =SUM(B10:B13) | C14: =SUM(C10:C13) | D14: =SUM(D10:D13) | E14: =SUM(E10:E13) | F14: =SUM(F10:F13) | G14: =SUM(G10:G13) | H14: =SUM(H10:H13) | I14: =SUM(I10:I13) | ... N14: =SUM(N10:N13)
A16: Investment Received | B16: 0 | C16: 0 | D16: 0 | E16: 0 | F16: 0 | G16: 0 | H16: 0 | I16: 0 | J16: 0 | K16: 0 | L16: 0 | M16: 0 | N16: =SUM(B16:M16)
A18: Cost of Revenue (this month) | B18: 88686.69 | C18: 99031.24 | D18: 106095.85 | E18: 112542.84 | F18: 121527.4 | G18: 129233.24 | H18: 137580.32 | I18: 143221.71 | J18: 153445.23 | K18: 163491.09 | L18: 171674.79 | M18: 180479.52 | N18: =SUM(B18:M18)
A19: Cost of Revenue (1 month supplier credit) | B19: 0 | C19: 0 | D19: 0 | E19: 0 | F19: 0 | G19: 0 | H19: 0 | I19: 0 | J19: 0 | K19: 0 | L19: 0 | M19: 0 | N19: =SUM(B19:M19)
A20: Total Cost of Revenue Cash Out | B20: =SUM(B18:B19) | C20: =SUM(C18:C19) | D20: =SUM(D18:D19) | E20: =SUM(E18:E19) | F20: =SUM(F18:F19) | G20: =SUM(G18:G19) | H20: =SUM(H18:H19) | I20: =SUM(I18:I19) | ... N20: =SUM(N18:N19) | O20: Creditors | P20: =(M7*'Control Panel'!$B$11)*('Control Panel'!$B$13)
A22: Contracts, Terms, GPDR | B22: 0 | C22: 0 | D22: 0 | E22: 0 | F22: 0 | G22: 0 | H22: 0 | I22: 0 | J22: 0 | K22: 0 | L22: 0 | M22: 0 | N22: =SUM(B22:M22)
A23: Stationery, etc. | B23: ='Year 3 Cash Budget'!B23 | C23: ='Year 3 Cash Budget'!C23 | D23: ='Year 3 Cash Budget'!D23 | E23: ='Year 3 Cash Budget'!E23 | F23: ='Year 3 Cash Budget'!F23 | G23: ='Year 3 Cash Budget'!G23 | H23: ='Year 3 Cash Budget'!H23 | I23: ='Year 3 Cash Budget'!I23 | ... M23: ='Year 3 Cash Budget'!M23 | N23: =SUM(B23:M23)
A24: Brochures | B24: ='Year 3 Cash Budget'!B24 | C24: ='Year 3 Cash Budget'!C24 | D24: ='Year 3 Cash Budget'!D24 | E24: ='Year 3 Cash Budget'!E24 | F24: ='Year 3 Cash Budget'!F24 | G24: ='Year 3 Cash Budget'!G24 | H24: ='Year 3 Cash Budget'!H24 | I24: ='Year 3 Cash Budget'!I24 | ... M24: ='Year 3 Cash Budget'!M24 | N24: =SUM(B24:M24)
A25: Consultants | B25: 107000 | C25: 7000 | D25: 7000 | E25: 7000 | F25: 7000 | G25: 7000 | H25: 7000 | I25: 7000 | J25: 7000 | K25: 7000 | L25: 7000 | M25: 7000 | N25: =SUM(B25:M25)
A26: Insurance | B26: 1850 | C26: 1850 | D26: 1850 | E26: 1850 | F26: 1850 | G26: 1850 | H26: 1850 | I26: 1850 | J26: 1850 | K26: 1850 | L26: 1850 | M26: 1850 | N26: =SUM(B26:M26)
A27: Rent | B27: 5040 | C27: 5040 | D27: 5040 | E27: 5040 | F27: 5040 | G27: 5040 | H27: 5040 | I27: 5040 | J27: 5040 | K27: 5040 | L27: 5040 | M27: 5040 | N27: =SUM(B27:M27)
A28: R & D Design | B28: 0 | C28: 0 | D28: 0 | E28: 0 | F28: 0 | G28: 0 | H28: 0 | I28: 0 | J28: 0 | K28: 0 | L28: 0 | M28: 0 | N28: =SUM(B28:M28)
A29: R & D Maintenance | B29: 79060 | C29: 87790 | D29: 93910 | E29: 99490 | F29: 107140 | G29: 113800 | H29: 121000 | I29: 125770 | J29: 133870 | K29: 142420 | L29: 149350 | M29: 156910 | N29: =SUM(B29:M29)
A30: Staff | B30: 112966.31 | C30: 112966.31 | D30: 112966.31 | E30: 112966.31 | F30: 112966.31 | G30: 112966.31 | H30: 112966.31 | I30: 112966.31 | J30: 115425.93 | K30: 115425.93 | L30: 115425.93 | M30: 115425.93 | N30: =SUM(B30:M30)
A31: Communications | B31: 0 | C31: 0 | D31: 0 | E31: 0 | F31: 0 | G31: 0 | H31: 0 | I31: 0 | J31: 0 | K31: 0 | L31: 0 | M31: 0 | N31: =SUM(B31:M31)
A32: Incorporation Fees | B32: 0 | C32: 0 | D32: 0 | E32: 0 | F32: 0 | G32: 0 | H32: 0 | I32: 0 | J32: 0 | K32: 0 | L32: 0 | M32: 0 | N32: =SUM(B32:M32)
A33: Website Design | B33: 0 | C33: 0 | D33: 0 | E33: 0 | F33: 0 | G33: 0 | H33: 0 | I33: 0 | J33: 0 | K33: 0 | L33: 0 | M33: 0 | N33: =SUM(B33:M33)
A34: Website Maintenance | B34: 0 | C34: 0 | D34: 0 | E34: 0 | F34: 0 | G34: 0 | H34: 0 | I34: 0 | J34: 0 | K34: 0 | L34: 0 | M34: 0 | N34: =SUM(B34:M34)
A35: Travel | B35: 20526.69 | C35: 22141.24 | D35: 23085.85 | E35: 23952.84 | F35: 25287.4 | G35: 26333.24 | H35: 27480.32 | I35: 28351.71 | J35: 30475.23 | K35: 31971.09 | L35: 33224.79 | M35: 34469.52 | N35: =SUM(B35:M35)
A36: Vehicle Rental | B36: 0 | C36: 0 | D36: 0 | E36: 0 | F36: 0 | G36: 0 | H36: 0 | I36: 0 | J36: 0 | K36: 0 | L36: 0 | M36: 0 | N36: =SUM(B36:M36)
A37: Marketing | B37: 27084.69 | C37: 28376.33 | D37: 29132.01 | E37: 29825.6 | F37: 30893.25 | G37: 31729.92 | H37: 32647.59 | I37: 33344.7 | J37: 35043.52 | K37: 36240.21 | L37: 37243.16 | M37: 38238.95 | N37: =SUM(B37:M37)
A38: Total Expenses Cash Out | B38: =SUM(B22:B37) | C38: =SUM(C22:C37) | D38: =SUM(D22:D37) | E38: =SUM(E22:E37) | F38: =SUM(F22:F37) | G38: =SUM(G22:G37) | H38: =SUM(H22:H37) | I38: =SUM(I22:I37) | ... N38: =SUM(N22:N37)
A40: Computer Equpment | B40: 0 | C40: 0 | D40: 0 | E40: 0 | F40: 0 | G40: 0 | H40: 0 | I40: 0 | J40: 0 | K40: 0 | L40: 0 | M40: 0 | N40: =SUM(B40:M40)
A41: Communications | B41: 0 | C41: 0 | D41: 0 | E41: 0 | F41: 0 | G41: 0 | H41: 0 | I41: 0 | J41: 0 | K41: 0 | L41: 0 | M41: 0 | N41: =SUM(B41:M41)
A42: Furniture | B42: 0 | C42: 0 | D42: 0 | E42: 0 | F42: 0 | G42: 0 | H42: 0 | I42: 0 | J42: 0 | K42: 0 | L42: 0 | M42: 0 | N42: =SUM(B42:M42)
A43: Buildings | B43: 0 | C43: 0 | D43: 0 | E43: 0 | F43: 0 | G43: 0 | H43: 0 | I43: 0 | J43: 0 | K43: 0 | L43: 0 | M43: 0 | N43: =SUM(B43:M43)
A44: Total Assets Cash Out | B44: =SUM(B40:B43) | C44: =SUM(C40:C43) | D44: =SUM(D40:D43) | E44: =SUM(E40:E43) | F44: =SUM(F40:F43) | G44: =SUM(G40:G43) | H44: =SUM(H40:H43) | I44: =SUM(I40:I43) | ... N44: =SUM(N40:N43)
A46: Closing Cash | B46: =B9+B14-B20-B38-B44+B16 | C46: =C9+C14-C20-C38-C44+C16 | D46: =D9+D14-D20-D38-D44+D16 | E46: =E9+E14-E20-E38-E44+E16 | F46: =F9+F14-F20-F38-F44+F16 | G46: =G9+G14-G20-G38-G44+G16 | H46: =H9+H14-H20-H38-H44+H16 | I46: =I9+I14-I20-I38-I44+I16 | ... M46: =M9+M14-M20-M38-M44+M16
...

Sheet Year 5 Cash Budget
B1: Month 49 | C1: Month 50 | D1: Month 51 | E1: Month 52 | F1: Month 53 | G1: Month 54 | H1: Month 55 | I1: Month 56 | J1: Month 57 | K1: Month 58 | L1: Month 59 | M1: Month 60 | N1: Year 5
A2: Revenue Calculations
A3: Average Sale | B3: 2760 | C3: 2760 | D3: 2760 | E3: 2760 | F3: 2760 | G3: 2760 | H3: 2760 | I3: 2760 | J3: 2760 | K3: 2760 | L3: 2760 | M3: 2760
A4: Customers | B4: 0 | C4: 0 | D4: 0 | E4: 0 | F4: 0 | G4: 0 | H4: 0 | I4: 0 | J4: 0 | K4: 0 | L4: 0 | M4: 0 | N4: =SUM(B4:M4)
A5: Customer Growth Factor | B5: ='Year 4 Cash Budget'!M5*(1+'Control Panel'!$B$4) | C5: =B5*(1+'Control Panel'!$B$4) | D5: =C5*(1+'Control Panel'!$B$4) | E5: =D5*(1+'Control Panel'!$B$4) | F5: =E5*(1+'Control Panel'!$B$4) | G5: =F5*(1+'Control Panel'!$B$4) | H5: =G5*(1+'Control Panel'!$B$4) | I5: =H5*(1+'Control Panel'!$B$4) | J5: =I5*(1+'Control Panel'!$B$4) | ... M5: =L5*(1+'Control Panel'!$B$4)
A6: Seasonality Index | B6: ='Year 4 Cash Budget'!B6 | C6: ='Year 3 Cash Budget'!C6 | D6: ='Year 3 Cash Budget'!D6 | E6: ='Year 3 Cash Budget'!E6 | F6: ='Year 3 Cash Budget'!F6 | G6: ='Year 3 Cash Budget'!G6 | H6: ='Year 3 Cash Budget'!H6 | I6: ='Year 3 Cash Budget'!I6 | J6: ='Year 3 Cash Budget'!J6 | ... M6: ='Year 3 Cash Budget'!M6
A7: Revenue | B7: 0 | C7: 0 | D7: 0 | E7: 0 | F7: 0 | G7: 0 | H7: 0 | I7: 0 | J7: 0 | K7: 0 | L7: 0 | M7: 0 | N7: =SUM(B7:M7) | O7: Debtors | P7: =(M7*'Control Panel'!$B$8)*(1/4)+(M7*'Control Panel'!$B$9)
A9: Opening Cash | B9: ='Financial Statements'!E19 | C9: =B46 | D9: =C46 | E9: =D46 | F9: =E46 | G9: =F46 | H9: =G46 | I9: =H46 | J9: =I46 | ... M9: =L46
A10: Revenue (this month) | B10: 0 | C10: 0 | D10: 0 | E10: 0 | F10: 0 | G10: 0 | H10: 0 | I10: 0 | J10: 0 | K10: 0 | L10: 0 | M10: 0 | N10: =SUM(B10:M10)
A11: Revenue (1 Week Credit) (this month) | B11: 0 | C11: 0 | D11: 0 | E11: 0 | F11: 0 | G11: 0 | H11: 0 | I11: 0 | J11: 0 | K11: 0 | L11: 0 | M11: 0 | N11: =SUM(B11:M11)
A12: Revenue (1 Week Credit) (last month) | B12: 0 | C12: 0 | D12: 0 | E12: 0 | F12: 0 | G12: 0 | H12: 0 | I12: 0 | J12: 0 | K12: 0 | L12: 0 | M12: 0 | N12: =SUM(B12:M12)
A13: Revenue (1 Month Credit) | B13: 0 | C13: 0 | D13: 0 | E13: 0 | F13: 0 | G13: 0 | H13: 0 | I13: 0 | J13: 0 | K13: 0 | L13: 0 | M13: 0 | N13: =SUM(B13:M13)
A14: Total Revenue Cash In | B14: =SUM(B10:B13) | C14: =SUM(C10:C13) | D14: =SUM(D10:D13) | E14: =SUM(E10:E13) | F14: =SUM(F10:F13) | G14: =SUM(G10:G13) | H14: =SUM(H10:H13) | I14: =SUM(I10:I13) | ... N14: =SUM(N10:N13)
A16: Investment Received | B16: 0 | C16: 0 | D16: 0 | E16: 0 | F16: 0 | G16: 0 | H16: 0 | I16: 0 | J16: 0 | K16: 0 | L16: 0 | M16: 0 | N16: =SUM(B16:M16)
A18: Cost of Revenue (this month) | B18: 0 | C18: 0 | D18: 0 | E18: 0 | F18: 0 | G18: 0 | H18: 0 | I18: 0 | J18: 0 | K18: 0 | L18: 0 | M18: 0 | N18: =SUM(B18:M18)
A19: Cost of Revenue (1 month supplier credit) | B19: 0 | C19: 0 | D19: 0 | E19: 0 | F19: 0 | G19: 0 | H19: 0 | I19: 0 | J19: 0 | K19: 0 | L19: 0 | M19: 0 | N19: =SUM(B19:M19)
A20: Total Cost of Revenue Cash Out | B20: =SUM(B18:B19) | C20: =SUM(C18:C19) | D20: =SUM(D18:D19) | E20: =SUM(E18:E19) | F20: =SUM(F18:F19) | G20: =SUM(G18:G19) | H20: =SUM(H18:H19) | I20: =SUM(I18:I19) | ... N20: =SUM(N18:N19) | O20: Creditors | P20: =(M7*'Control Panel'!$B$11)*('Control Panel'!$B$13)
A22: Contracts, Terms, GPDR | B22: 0 | C22: 0 | D22: 0 | E22: 0 | F22: 0 | G22: 0 | H22: 0 | I22: 0 | J22: 0 | K22: 0 | L22: 0 | M22: 0 | N22: =SUM(B22:M22)
A23: Stationery, etc. | B23: ='Year 4 Cash Budget'!B23 | C23: ='Year 4 Cash Budget'!C23 | D23: ='Year 4 Cash Budget'!D23 | E23: ='Year 4 Cash Budget'!E23 | F23: ='Year 4 Cash Budget'!F23 | G23: ='Year 4 Cash Budget'!G23 | H23: ='Year 4 Cash Budget'!H23 | I23: ='Year 4 Cash Budget'!I23 | ... M23: ='Year 4 Cash Budget'!M23 | N23: =SUM(B23:M23)
A24: Brochures | B24: ='Year 4 Cash Budget'!B24 | C24: ='Year 4 Cash Budget'!C24 | D24: ='Year 4 Cash Budget'!D24 | E24: ='Year 4 Cash Budget'!E24 | F24: ='Year 4 Cash Budget'!F24 | G24: ='Year 4 Cash Budget'!G24 | H24: ='Year 4 Cash Budget'!H24 | I24: ='Year 4 Cash Budget'!I24 | ... M24: ='Year 4 Cash Budget'!M24 | N24: =SUM(B24:M24)
A25: Consultants | B25: 0 | C25: 0 | D25: 0 | E25: 0 | F25: 0 | G25: 0 | H25: 0 | I25: 0 | J25: 0 | K25: 0 | L25: 0 | M25: 0 | N25: =SUM(B25:M25)
A26: Insurance | B26: 0 | C26: 0 | D26: 0 | E26: 0 | F26: 0 | G26: 0 | H26: 0 | I26: 0 | J26: 0 | K26: 0 | L26: 0 | M26: 0 | N26: =SUM(B26:M26)
A27: Rent | B27: 0 | C27: 0 | D27: 0 | E27: 0 | F27: 0 | G27: 0 | H27: 0 | I27: 0 | J27: 0 | K27: 0 | L27: 0 | M27: 0 | N27: =SUM(B27:M27)
A28: R & D Design | B28: 0 | C28: 0 | D28: 0 | E28: 0 | F28: 0 | G28: 0 | H28: 0 | I28: 0 | J28: 0 | K28: 0 | L28: 0 | M28: 0 | N28: =SUM(B28:M28)
A29: R & D Maintenance | B29: 0 | C29: 0 | D29: 0 | E29: 0 | F29: 0 | G29: 0 | H29: 0 | I29: 0 | J29: 0 | K29: 0 | L29: 0 | M29: 0 | N29: =SUM(B29:M29)
A30: Staff | B30: 0 | C30: 0 | D30: 0 | E30: 0 | F30: 0 | G30: 0 | H30: 0 | I30: 0 | J30: 0 | K30: 0 | L30: 0 | M30: 0 | N30: =SUM(B30:M30)
A31: Communications | B31: 0 | C31: 0 | D31: 0 | E31: 0 | F31: 0 | G31: 0 | H31: 0 | I31: 0 | J31: 0 | K31: 0 | L31: 0 | M31: 0 | N31: =SUM(B31:M31)
A32: Incorporation Fees | B32: 0 | C32: 0 | D32: 0 | E32: 0 | F32: 0 | G32: 0 | H32: 0 | I32: 0 | J32: 0 | K32: 0 | L32: 0 | M32: 0 | N32: =SUM(B32:M32)
A33: Website Design | B33: 0 | C33: 0 | D33: 0 | E33: 0 | F33: 0 | G33: 0 | H33: 0 | I33: 0 | J33: 0 | K33: 0 | L33: 0 | M33: 0 | N33: =SUM(B33:M33)
A34: Website Maintenance | B34: 0 | C34: 0 | D34: 0 | E34: 0 | F34: 0 | G34: 0 | H34: 0 | I34: 0 | J34: 0 | K34: 0 | L34: 0 | M34: 0 | N34: =SUM(B34:M34)
A35: Travel | B35: 0 | C35: 0 | D35: 0 | E35: 0 | F35: 0 | G35: 0 | H35: 0 | I35: 0 | J35: 0 | K35: 0 | L35: 0 | M35: 0 | N35: =SUM(B35:M35)
A36: Vehicle Rental | B36: 0 | C36: 0 | D36: 0 | E36: 0 | F36: 0 | G36: 0 | H36: 0 | I36: 0 | J36: 0 | K36: 0 | L36: 0 | M36: 0 | N36: =SUM(B36:M36)
A37: Marketing | B37: 0 | C37: 0 | D37: 0 | E37: 0 | F37: 0 | G37: 0 | H37: 0 | I37: 0 | J37: 0 | K37: 0 | L37: 0 | M37: 0 | N37: =SUM(B37:M37)
A38: Total Expenses Cash Out | B38: =SUM(B22:B37) | C38: =SUM(C22:C37) | D38: =SUM(D22:D37) | E38: =SUM(E22:E37) | F38: =SUM(F22:F37) | G38: =SUM(G22:G37) | H38: =SUM(H22:H37) | I38: =SUM(I22:I37) | ... N38: =SUM(N22:N37)
A40: Computer Equpment | B40: 0 | C40: 0 | D40: 0 | E40: 0 | F40: 0 | G40: 0 | H40: 0 | I40: 0 | J40: 0 | K40: 0 | L40: 0 | M40: 0 | N40: =SUM(B40:M40)
A41: Communications | B41: 0 | C41: 0 | D41: 0 | E41: 0 | F41: 0 | G41: 0 | H41: 0 | I41: 0 | J41: 0 | K41: 0 | L41: 0 | M41: 0 | N41: =SUM(B41:M41)
A42: Furniture | B42: 0 | C42: 0 | D42: 0 | E42: 0 | F42: 0 | G42: 0 | H42: 0 | I42: 0 | J42: 0 | K42: 0 | L42: 0 | M42: 0 | N42: =SUM(B42:M42)
A43: Buildings | B43: 0 | C43: 0 | D43: 0 | E43: 0 | F43: 0 | G43: 0 | H43: 0 | I43: 0 | J43: 0 | K43: 0 | L43: 0 | M43: 0 | N43: =SUM(B43:M43)
A44: Total Assets Cash Out | B44: =SUM(B40:B43) | C44: =SUM(C40:C43) | D44: =SUM(D40:D43) | E44: =SUM(E40:E43) | F44: =SUM(F40:F43) | G44: =SUM(G40:G43) | H44: =SUM(H40:H43) | I44: =SUM(I40:I43) | ... N44: =SUM(N40:N43)
A46: Closing Cash | B46: =B9+B14-B20-B38-B44+B16 | C46: =C9+C14-C20-C38-C44+C16 | D46: =D9+D14-D20-D38-D44+D16 | E46: =E9+E14-E20-E38-E44+E16 | F46: =F9+F14-F20-F38-F44+F16 | G46: =G9+G14-G20-G38-G44+G16 | H46: =H9+H14-H20-H38-H44+H16 | I46: =I9+I14-I20-I38-I44+I16 | ... M46: =M9+M14-M20-M38-M44+M16
...

Sheet Balances
B1: 1 | C1: 2 | D1: 3 | E1: 4 | F1: 5 | G1: 6 | H1: 7 | I1: 8 | J1: 9 | K1: 10 | L1: 11 | M1: 12 | N1: 13 | O1: 14 | P1: 15 | Q1: 16 | R1: 17 | S1: 18 | T1: 19 | U1: 20 | V1: 21 | W1: 22 | X1: 23 | Y1: 24 | Z1: 25 | AA1: 26 | AB1: 27 | AC1: 28 | AD1: 29 | AE1: 30 | AF1: 31 | AG1: 32 | AH1: 33 | AI1: 34 | AJ1: 35 | AK1: 36 | AL1: 37 | AM1: 38 | AN1: 39 | AO1: 40 | AP1: 41 | AQ1: 42 | AR1: 43 | AS1: 44 | AT1: 45 | AU1: 46 | AV1: 47 | AW1: 48 | AX1: 49 | AY1: 50 | AZ1: 51 | BA1: 52 | BB1: 53 | BC1: 54 | BD1: 55 | BE1: 56 | BF1: 57 | BG1: 58 | BH1: 59 | BI1: 60
A2: Customers
A3: Closing Cash Balance | B3: ='Year 1 Cash Budget'!C46 | C3: ='Year 1 Cash Budget'!D46 | D3: ='Year 1 Cash Budget'!E46 | E3: ='Year 1 Cash Budget'!F46 | F3: ='Year 1 Cash Budget'!G46 | G3: ='Year 1 Cash Budget'!H46 | H3: ='Year 1 Cash Budget'!I46 | I3: ='Year 1 Cash Budget'!J46 | ... M3: ='Year 1 Cash Budget'!N46 | N3: ='Year 2 Cash Budget'!B46 | O3: ='Year 2 Cash Budget'!C46 | P3: ='Year 2 Cash Budget'!D46 | Q3: ='Year 2 Cash Budget'!E46 | R3: ='Year 2 Cash Budget'!F46 | S3: ='Year 2 Cash Budget'!G46 | T3: ='Year 2 Cash Budget'!H46 | U3: ='Year 2 Cash Budget'!I46 | ... Y3: ='Year 2 Cash Budget'!M46 | Z3: ='Year 3 Cash Budget'!B46 | AA3: ='Year 3 Cash Budget'!C46 | AB3: ='Year 3 Cash Budget'!D46 | AC3: ='Year 3 Cash Budget'!E46 | AD3: ='Year 3 Cash Budget'!F46 | AE3: ='Year 3 Cash Budget'!G46 | AF3: ='Year 3 Cash Budget'!H46 | AG3: ='Year 3 Cash Budget'!I46 | ... AK3: ='Year 3 Cash Budget'!M46 | AL3: ='Year 4 Cash Budget'!B46 | AM3: ='Year 4 Cash Budget'!C46 | AN3: ='Year 4 Cash Budget'!D46 | AO3: ='Year 4 Cash Budget'!E46 | AP3: ='Year 4 Cash Budget'!F46 | AQ3: ='Year 4 Cash Budget'!G46 | AR3: ='Year 4 Cash Budget'!H46 | AS3: ='Year 4 Cash Budget'!I46 | ... AW3: ='Year 4 Cash Budget'!M46 | AX3: ='Year 5 Cash Budget'!B46 | AY3: ='Year 5 Cash Budget'!C46 | AZ3: ='Year 5 Cash Budget'!D46 | BA3: ='Year 5 Cash Budget'!E46 | BB3: ='Year 5 Cash Budget'!F46 | BC3: ='Year 5 Cash Budget'!G46 | BD3: ='Year 5 Cash Budget'!H46 | BE3: ='Year 5 Cash Budget'!I46 | ... BI3: ='Year 5 Cash Budget'!M46
A4: Cash less investment | B4: =B3-'Startup & Pre-Opening Costs'!$B$29 | C4: =C3-'Startup & Pre-Opening Costs'!$B$29 | D4: =D3-'Startup & Pre-Opening Costs'!$B$29 | E4: =E3-'Startup & Pre-Opening Costs'!$B$29 | F4: =F3-'Startup & Pre-Opening Costs'!$B$29 | G4: =G3-'Startup & Pre-Opening Costs'!$B$29 | H4: =H3-'Startup & Pre-Opening Costs'!$B$29 | I4: =I3-'Startup & Pre-Opening Costs'!$B$29 | ... BI4: =BI3-'Startup & Pre-Opening Costs'!$B$29
A5: Cash Break Even | C5: =IF(AND(B4<0,C4>=0), "CBE","") | D5: =IF(AND(C4<0,D4>=0), "CBE","") | E5: =IF(AND(D4<0,E4>=0), "CBE","") | F5: =IF(AND(E4<0,F4>=0), "CBE","") | G5: =IF(AND(F4<0,G4>=0), "CBE","") | H5: =IF(AND(G4<0,H4>=0), "CBE","") | I5: =IF(AND(H4<0,I4>=0), "CBE","") | J5: =IF(AND(I4<0,J4>=0), "CBE","") | ... BI5: =IF(AND(BH4<0,BI4>=0), "CBE","")
A6: Cumulative Net Profit | B6: ='Year 1 Cash Budget'!C59 | C6: ='Year 1 Cash Budget'!D59 | D6: ='Year 1 Cash Budget'!E59 | E6: ='Year 1 Cash Budget'!F59 | F6: ='Year 1 Cash Budget'!G59 | G6: ='Year 1 Cash Budget'!H59 | H6: ='Year 1 Cash Budget'!I59 | I6: ='Year 1 Cash Budget'!J59 | ... M6: ='Year 1 Cash Budget'!N59 | N6: ='Year 2 Cash Budget'!B59 | O6: ='Year 2 Cash Budget'!C59 | P6: ='Year 2 Cash Budget'!D59 | Q6: ='Year 2 Cash Budget'!E59 | R6: ='Year 2 Cash Budget'!F59 | S6: ='Year 2 Cash Budget'!G59 | T6: ='Year 2 Cash Budget'!H59 | U6: ='Year 2 Cash Budget'!I59 | ... Y6: ='Year 2 Cash Budget'!M59 | Z6: ='Year 3 Cash Budget'!B59 | AA6: ='Year 3 Cash Budget'!C59 | AB6: ='Year 3 Cash Budget'!D59 | AC6: ='Year 3 Cash Budget'!E59 | AD6: ='Year 3 Cash Budget'!F59 | AE6: ='Year 3 Cash Budget'!G59 | AF6: ='Year 3 Cash Budget'!H59 | AG6: ='Year 3 Cash Budget'!I59 | ... AK6: ='Year 3 Cash Budget'!M59 | AL6: ='Year 4 Cash Budget'!B59 | AM6: ='Year 4 Cash Budget'!C59 | AN6: ='Year 4 Cash Budget'!D59 | AO6: ='Year 4 Cash Budget'!E59 | AP6: ='Year 4 Cash Budget'!F59 | AQ6: ='Year 4 Cash Budget'!G59 | AR6: ='Year 4 Cash Budget'!H59 | AS6: ='Year 4 Cash Budget'!I59 | ... AW6: ='Year 4 Cash Budget'!M59 | AX6: ='Year 5 Cash Budget'!B59 | AY6: ='Year 5 Cash Budget'!C59 | AZ6: ='Year 5 Cash Budget'!D59 | BA6: ='Year 5 Cash Budget'!E59 | BB6: ='Year 5 Cash Budget'!F59 | BC6: ='Year 5 Cash Budget'!G59 | BD6: ='Year 5 Cash Budget'!H59 | BE6: ='Year 5 Cash Budget'!I59 | ... BI6: ='Year 5 Cash Budget'!M59
